2019-02-23 15:06:39,284 - default - ERROR - Exception occurred
Traceback (most recent call last):
  File "Trading/Dataset/DatasetHolder.py", line 259, in appendTimeframesIntoOneDataset
    ds_h.f_df[cdl] = np.convolve(ds_h.f_df[cdl], fn)[0:len(ds_h.f_df)]
  File "/usr/local/lib/python2.7/dist-packages/pandas/core/frame.py", line 1997, in __getitem__
    return self._getitem_column(key)
  File "/usr/local/lib/python2.7/dist-packages/pandas/core/frame.py", line 2009, in _getitem_column
    result = result[key]
  File "/usr/local/lib/python2.7/dist-packages/pandas/core/frame.py", line 1997, in __getitem__
    return self._getitem_column(key)
  File "/usr/local/lib/python2.7/dist-packages/pandas/core/frame.py", line 2004, in _getitem_column
    return self._get_item_cache(key)
  File "/usr/local/lib/python2.7/dist-packages/pandas/core/generic.py", line 1350, in _get_item_cache
    values = self._data.get(item)
  File "/usr/local/lib/python2.7/dist-packages/pandas/core/internals.py", line 3290, in get
    loc = self.items.get_loc(item)
  File "/usr/local/lib/python2.7/dist-packages/pandas/indexes/base.py", line 1947, in get_loc
    return self._engine.get_loc(self._maybe_cast_indexer(key))
  File "pandas/index.pyx", line 137, in pandas.index.IndexEngine.get_loc (pandas/index.c:4154)
  File "pandas/index.pyx", line 159, in pandas.index.IndexEngine.get_loc (pandas/index.c:4018)
  File "pandas/hashtable.pyx", line 675, in pandas.hashtable.PyObjectHashTable.get_item (pandas/hashtable.c:12368)
  File "pandas/hashtable.pyx", line 683, in pandas.hashtable.PyObjectHashTable.get_item (pandas/hashtable.c:12322)
KeyError: 'CDL2CROW'
2019-02-23 15:06:39,300 - default - ERROR - Exception occurred
Traceback (most recent call last):
  File "Trading/Dataset/DatasetHolder.py", line 259, in appendTimeframesIntoOneDataset
    ds_h.f_df[cdl] = np.convolve(ds_h.f_df[cdl], fn)[0:len(ds_h.f_df)]
  File "/usr/local/lib/python2.7/dist-packages/pandas/core/frame.py", line 1997, in __getitem__
    return self._getitem_column(key)
  File "/usr/local/lib/python2.7/dist-packages/pandas/core/frame.py", line 2009, in _getitem_column
    result = result[key]
  File "/usr/local/lib/python2.7/dist-packages/pandas/core/frame.py", line 1997, in __getitem__
    return self._getitem_column(key)
  File "/usr/local/lib/python2.7/dist-packages/pandas/core/frame.py", line 2004, in _getitem_column
    return self._get_item_cache(key)
  File "/usr/local/lib/python2.7/dist-packages/pandas/core/generic.py", line 1350, in _get_item_cache
    values = self._data.get(item)
  File "/usr/local/lib/python2.7/dist-packages/pandas/core/internals.py", line 3290, in get
    loc = self.items.get_loc(item)
  File "/usr/local/lib/python2.7/dist-packages/pandas/indexes/base.py", line 1947, in get_loc
    return self._engine.get_loc(self._maybe_cast_indexer(key))
  File "pandas/index.pyx", line 137, in pandas.index.IndexEngine.get_loc (pandas/index.c:4154)
  File "pandas/index.pyx", line 159, in pandas.index.IndexEngine.get_loc (pandas/index.c:4018)
  File "pandas/hashtable.pyx", line 675, in pandas.hashtable.PyObjectHashTable.get_item (pandas/hashtable.c:12368)
  File "pandas/hashtable.pyx", line 683, in pandas.hashtable.PyObjectHashTable.get_item (pandas/hashtable.c:12322)
KeyError: 'CDL3BLACKCROW'
2019-02-23 15:06:39,303 - default - ERROR - Exception occurred
Traceback (most recent call last):
  File "Trading/Dataset/DatasetHolder.py", line 259, in appendTimeframesIntoOneDataset
    ds_h.f_df[cdl] = np.convolve(ds_h.f_df[cdl], fn)[0:len(ds_h.f_df)]
  File "/usr/local/lib/python2.7/dist-packages/pandas/core/frame.py", line 1997, in __getitem__
    return self._getitem_column(key)
  File "/usr/local/lib/python2.7/dist-packages/pandas/core/frame.py", line 2009, in _getitem_column
    result = result[key]
  File "/usr/local/lib/python2.7/dist-packages/pandas/core/frame.py", line 1997, in __getitem__
    return self._getitem_column(key)
  File "/usr/local/lib/python2.7/dist-packages/pandas/core/frame.py", line 2004, in _getitem_column
    return self._get_item_cache(key)
  File "/usr/local/lib/python2.7/dist-packages/pandas/core/generic.py", line 1350, in _get_item_cache
    values = self._data.get(item)
  File "/usr/local/lib/python2.7/dist-packages/pandas/core/internals.py", line 3290, in get
    loc = self.items.get_loc(item)
  File "/usr/local/lib/python2.7/dist-packages/pandas/indexes/base.py", line 1947, in get_loc
    return self._engine.get_loc(self._maybe_cast_indexer(key))
  File "pandas/index.pyx", line 137, in pandas.index.IndexEngine.get_loc (pandas/index.c:4154)
  File "pandas/index.pyx", line 159, in pandas.index.IndexEngine.get_loc (pandas/index.c:4018)
  File "pandas/hashtable.pyx", line 675, in pandas.hashtable.PyObjectHashTable.get_item (pandas/hashtable.c:12368)
  File "pandas/hashtable.pyx", line 683, in pandas.hashtable.PyObjectHashTable.get_item (pandas/hashtable.c:12322)
KeyError: 'CDL3INSID'
2019-02-23 15:06:39,307 - default - ERROR - Exception occurred
Traceback (most recent call last):
  File "Trading/Dataset/DatasetHolder.py", line 259, in appendTimeframesIntoOneDataset
    ds_h.f_df[cdl] = np.convolve(ds_h.f_df[cdl], fn)[0:len(ds_h.f_df)]
  File "/usr/local/lib/python2.7/dist-packages/pandas/core/frame.py", line 1997, in __getitem__
    return self._getitem_column(key)
  File "/usr/local/lib/python2.7/dist-packages/pandas/core/frame.py", line 2009, in _getitem_column
    result = result[key]
  File "/usr/local/lib/python2.7/dist-packages/pandas/core/frame.py", line 1997, in __getitem__
    return self._getitem_column(key)
  File "/usr/local/lib/python2.7/dist-packages/pandas/core/frame.py", line 2004, in _getitem_column
    return self._get_item_cache(key)
  File "/usr/local/lib/python2.7/dist-packages/pandas/core/generic.py", line 1350, in _get_item_cache
    values = self._data.get(item)
  File "/usr/local/lib/python2.7/dist-packages/pandas/core/internals.py", line 3290, in get
    loc = self.items.get_loc(item)
  File "/usr/local/lib/python2.7/dist-packages/pandas/indexes/base.py", line 1947, in get_loc
    return self._engine.get_loc(self._maybe_cast_indexer(key))
  File "pandas/index.pyx", line 137, in pandas.index.IndexEngine.get_loc (pandas/index.c:4154)
  File "pandas/index.pyx", line 159, in pandas.index.IndexEngine.get_loc (pandas/index.c:4018)
  File "pandas/hashtable.pyx", line 675, in pandas.hashtable.PyObjectHashTable.get_item (pandas/hashtable.c:12368)
  File "pandas/hashtable.pyx", line 683, in pandas.hashtable.PyObjectHashTable.get_item (pandas/hashtable.c:12322)
KeyError: 'CDL3LINESTRIK'
2019-02-23 15:06:39,310 - default - ERROR - Exception occurred
Traceback (most recent call last):
  File "Trading/Dataset/DatasetHolder.py", line 259, in appendTimeframesIntoOneDataset
    ds_h.f_df[cdl] = np.convolve(ds_h.f_df[cdl], fn)[0:len(ds_h.f_df)]
  File "/usr/local/lib/python2.7/dist-packages/pandas/core/frame.py", line 1997, in __getitem__
    return self._getitem_column(key)
  File "/usr/local/lib/python2.7/dist-packages/pandas/core/frame.py", line 2009, in _getitem_column
    result = result[key]
  File "/usr/local/lib/python2.7/dist-packages/pandas/core/frame.py", line 1997, in __getitem__
    return self._getitem_column(key)
  File "/usr/local/lib/python2.7/dist-packages/pandas/core/frame.py", line 2004, in _getitem_column
    return self._get_item_cache(key)
  File "/usr/local/lib/python2.7/dist-packages/pandas/core/generic.py", line 1350, in _get_item_cache
    values = self._data.get(item)
  File "/usr/local/lib/python2.7/dist-packages/pandas/core/internals.py", line 3290, in get
    loc = self.items.get_loc(item)
  File "/usr/local/lib/python2.7/dist-packages/pandas/indexes/base.py", line 1947, in get_loc
    return self._engine.get_loc(self._maybe_cast_indexer(key))
  File "pandas/index.pyx", line 137, in pandas.index.IndexEngine.get_loc (pandas/index.c:4154)
  File "pandas/index.pyx", line 159, in pandas.index.IndexEngine.get_loc (pandas/index.c:4018)
  File "pandas/hashtable.pyx", line 675, in pandas.hashtable.PyObjectHashTable.get_item (pandas/hashtable.c:12368)
  File "pandas/hashtable.pyx", line 683, in pandas.hashtable.PyObjectHashTable.get_item (pandas/hashtable.c:12322)
KeyError: 'CDL3OUTSID'
2019-02-23 15:06:39,315 - default - ERROR - Exception occurred
Traceback (most recent call last):
  File "Trading/Dataset/DatasetHolder.py", line 259, in appendTimeframesIntoOneDataset
    ds_h.f_df[cdl] = np.convolve(ds_h.f_df[cdl], fn)[0:len(ds_h.f_df)]
  File "/usr/local/lib/python2.7/dist-packages/pandas/core/frame.py", line 1997, in __getitem__
    return self._getitem_column(key)
  File "/usr/local/lib/python2.7/dist-packages/pandas/core/frame.py", line 2009, in _getitem_column
    result = result[key]
  File "/usr/local/lib/python2.7/dist-packages/pandas/core/frame.py", line 1997, in __getitem__
    return self._getitem_column(key)
  File "/usr/local/lib/python2.7/dist-packages/pandas/core/frame.py", line 2004, in _getitem_column
    return self._get_item_cache(key)
  File "/usr/local/lib/python2.7/dist-packages/pandas/core/generic.py", line 1350, in _get_item_cache
    values = self._data.get(item)
  File "/usr/local/lib/python2.7/dist-packages/pandas/core/internals.py", line 3290, in get
    loc = self.items.get_loc(item)
  File "/usr/local/lib/python2.7/dist-packages/pandas/indexes/base.py", line 1947, in get_loc
    return self._engine.get_loc(self._maybe_cast_indexer(key))
  File "pandas/index.pyx", line 137, in pandas.index.IndexEngine.get_loc (pandas/index.c:4154)
  File "pandas/index.pyx", line 159, in pandas.index.IndexEngine.get_loc (pandas/index.c:4018)
  File "pandas/hashtable.pyx", line 675, in pandas.hashtable.PyObjectHashTable.get_item (pandas/hashtable.c:12368)
  File "pandas/hashtable.pyx", line 683, in pandas.hashtable.PyObjectHashTable.get_item (pandas/hashtable.c:12322)
KeyError: 'CDL3STARSINSOUT'
2019-02-23 15:06:39,318 - default - ERROR - Exception occurred
Traceback (most recent call last):
  File "Trading/Dataset/DatasetHolder.py", line 259, in appendTimeframesIntoOneDataset
    ds_h.f_df[cdl] = np.convolve(ds_h.f_df[cdl], fn)[0:len(ds_h.f_df)]
  File "/usr/local/lib/python2.7/dist-packages/pandas/core/frame.py", line 1997, in __getitem__
    return self._getitem_column(key)
  File "/usr/local/lib/python2.7/dist-packages/pandas/core/frame.py", line 2009, in _getitem_column
    result = result[key]
  File "/usr/local/lib/python2.7/dist-packages/pandas/core/frame.py", line 1997, in __getitem__
    return self._getitem_column(key)
  File "/usr/local/lib/python2.7/dist-packages/pandas/core/frame.py", line 2004, in _getitem_column
    return self._get_item_cache(key)
  File "/usr/local/lib/python2.7/dist-packages/pandas/core/generic.py", line 1350, in _get_item_cache
    values = self._data.get(item)
  File "/usr/local/lib/python2.7/dist-packages/pandas/core/internals.py", line 3290, in get
    loc = self.items.get_loc(item)
  File "/usr/local/lib/python2.7/dist-packages/pandas/indexes/base.py", line 1947, in get_loc
    return self._engine.get_loc(self._maybe_cast_indexer(key))
  File "pandas/index.pyx", line 137, in pandas.index.IndexEngine.get_loc (pandas/index.c:4154)
  File "pandas/index.pyx", line 159, in pandas.index.IndexEngine.get_loc (pandas/index.c:4018)
  File "pandas/hashtable.pyx", line 675, in pandas.hashtable.PyObjectHashTable.get_item (pandas/hashtable.c:12368)
  File "pandas/hashtable.pyx", line 683, in pandas.hashtable.PyObjectHashTable.get_item (pandas/hashtable.c:12322)
KeyError: 'CDL3WHITESOLDIER'
2019-02-23 15:06:39,323 - default - ERROR - Exception occurred
Traceback (most recent call last):
  File "Trading/Dataset/DatasetHolder.py", line 259, in appendTimeframesIntoOneDataset
    ds_h.f_df[cdl] = np.convolve(ds_h.f_df[cdl], fn)[0:len(ds_h.f_df)]
  File "/usr/local/lib/python2.7/dist-packages/pandas/core/frame.py", line 1997, in __getitem__
    return self._getitem_column(key)
  File "/usr/local/lib/python2.7/dist-packages/pandas/core/frame.py", line 2009, in _getitem_column
    result = result[key]
  File "/usr/local/lib/python2.7/dist-packages/pandas/core/frame.py", line 1997, in __getitem__
    return self._getitem_column(key)
  File "/usr/local/lib/python2.7/dist-packages/pandas/core/frame.py", line 2004, in _getitem_column
    return self._get_item_cache(key)
  File "/usr/local/lib/python2.7/dist-packages/pandas/core/generic.py", line 1350, in _get_item_cache
    values = self._data.get(item)
  File "/usr/local/lib/python2.7/dist-packages/pandas/core/internals.py", line 3290, in get
    loc = self.items.get_loc(item)
  File "/usr/local/lib/python2.7/dist-packages/pandas/indexes/base.py", line 1947, in get_loc
    return self._engine.get_loc(self._maybe_cast_indexer(key))
  File "pandas/index.pyx", line 137, in pandas.index.IndexEngine.get_loc (pandas/index.c:4154)
  File "pandas/index.pyx", line 159, in pandas.index.IndexEngine.get_loc (pandas/index.c:4018)
  File "pandas/hashtable.pyx", line 675, in pandas.hashtable.PyObjectHashTable.get_item (pandas/hashtable.c:12368)
  File "pandas/hashtable.pyx", line 683, in pandas.hashtable.PyObjectHashTable.get_item (pandas/hashtable.c:12322)
KeyError: 'CDLABANDONEDBAB'
2019-02-23 15:06:39,326 - default - ERROR - Exception occurred
Traceback (most recent call last):
  File "Trading/Dataset/DatasetHolder.py", line 259, in appendTimeframesIntoOneDataset
    ds_h.f_df[cdl] = np.convolve(ds_h.f_df[cdl], fn)[0:len(ds_h.f_df)]
  File "/usr/local/lib/python2.7/dist-packages/pandas/core/frame.py", line 1997, in __getitem__
    return self._getitem_column(key)
  File "/usr/local/lib/python2.7/dist-packages/pandas/core/frame.py", line 2009, in _getitem_column
    result = result[key]
  File "/usr/local/lib/python2.7/dist-packages/pandas/core/frame.py", line 1997, in __getitem__
    return self._getitem_column(key)
  File "/usr/local/lib/python2.7/dist-packages/pandas/core/frame.py", line 2004, in _getitem_column
    return self._get_item_cache(key)
  File "/usr/local/lib/python2.7/dist-packages/pandas/core/generic.py", line 1350, in _get_item_cache
    values = self._data.get(item)
  File "/usr/local/lib/python2.7/dist-packages/pandas/core/internals.py", line 3290, in get
    loc = self.items.get_loc(item)
  File "/usr/local/lib/python2.7/dist-packages/pandas/indexes/base.py", line 1947, in get_loc
    return self._engine.get_loc(self._maybe_cast_indexer(key))
  File "pandas/index.pyx", line 137, in pandas.index.IndexEngine.get_loc (pandas/index.c:4154)
  File "pandas/index.pyx", line 159, in pandas.index.IndexEngine.get_loc (pandas/index.c:4018)
  File "pandas/hashtable.pyx", line 675, in pandas.hashtable.PyObjectHashTable.get_item (pandas/hashtable.c:12368)
  File "pandas/hashtable.pyx", line 683, in pandas.hashtable.PyObjectHashTable.get_item (pandas/hashtable.c:12322)
KeyError: 'CDLADVANCEBLOC'
2019-02-23 15:06:39,330 - default - ERROR - Exception occurred
Traceback (most recent call last):
  File "Trading/Dataset/DatasetHolder.py", line 259, in appendTimeframesIntoOneDataset
    ds_h.f_df[cdl] = np.convolve(ds_h.f_df[cdl], fn)[0:len(ds_h.f_df)]
  File "/usr/local/lib/python2.7/dist-packages/pandas/core/frame.py", line 1997, in __getitem__
    return self._getitem_column(key)
  File "/usr/local/lib/python2.7/dist-packages/pandas/core/frame.py", line 2009, in _getitem_column
    result = result[key]
  File "/usr/local/lib/python2.7/dist-packages/pandas/core/frame.py", line 1997, in __getitem__
    return self._getitem_column(key)
  File "/usr/local/lib/python2.7/dist-packages/pandas/core/frame.py", line 2004, in _getitem_column
    return self._get_item_cache(key)
  File "/usr/local/lib/python2.7/dist-packages/pandas/core/generic.py", line 1350, in _get_item_cache
    values = self._data.get(item)
  File "/usr/local/lib/python2.7/dist-packages/pandas/core/internals.py", line 3290, in get
    loc = self.items.get_loc(item)
  File "/usr/local/lib/python2.7/dist-packages/pandas/indexes/base.py", line 1947, in get_loc
    return self._engine.get_loc(self._maybe_cast_indexer(key))
  File "pandas/index.pyx", line 137, in pandas.index.IndexEngine.get_loc (pandas/index.c:4154)
  File "pandas/index.pyx", line 159, in pandas.index.IndexEngine.get_loc (pandas/index.c:4018)
  File "pandas/hashtable.pyx", line 675, in pandas.hashtable.PyObjectHashTable.get_item (pandas/hashtable.c:12368)
  File "pandas/hashtable.pyx", line 683, in pandas.hashtable.PyObjectHashTable.get_item (pandas/hashtable.c:12322)
KeyError: 'CDLBELTHOL'
2019-02-23 15:06:39,334 - default - ERROR - Exception occurred
Traceback (most recent call last):
  File "Trading/Dataset/DatasetHolder.py", line 259, in appendTimeframesIntoOneDataset
    ds_h.f_df[cdl] = np.convolve(ds_h.f_df[cdl], fn)[0:len(ds_h.f_df)]
  File "/usr/local/lib/python2.7/dist-packages/pandas/core/frame.py", line 1997, in __getitem__
    return self._getitem_column(key)
  File "/usr/local/lib/python2.7/dist-packages/pandas/core/frame.py", line 2009, in _getitem_column
    result = result[key]
  File "/usr/local/lib/python2.7/dist-packages/pandas/core/frame.py", line 1997, in __getitem__
    return self._getitem_column(key)
  File "/usr/local/lib/python2.7/dist-packages/pandas/core/frame.py", line 2004, in _getitem_column
    return self._get_item_cache(key)
  File "/usr/local/lib/python2.7/dist-packages/pandas/core/generic.py", line 1350, in _get_item_cache
    values = self._data.get(item)
  File "/usr/local/lib/python2.7/dist-packages/pandas/core/internals.py", line 3290, in get
    loc = self.items.get_loc(item)
  File "/usr/local/lib/python2.7/dist-packages/pandas/indexes/base.py", line 1947, in get_loc
    return self._engine.get_loc(self._maybe_cast_indexer(key))
  File "pandas/index.pyx", line 137, in pandas.index.IndexEngine.get_loc (pandas/index.c:4154)
  File "pandas/index.pyx", line 159, in pandas.index.IndexEngine.get_loc (pandas/index.c:4018)
  File "pandas/hashtable.pyx", line 675, in pandas.hashtable.PyObjectHashTable.get_item (pandas/hashtable.c:12368)
  File "pandas/hashtable.pyx", line 683, in pandas.hashtable.PyObjectHashTable.get_item (pandas/hashtable.c:12322)
KeyError: 'CDLBREAKAWA'
2019-02-23 15:06:39,337 - default - ERROR - Exception occurred
Traceback (most recent call last):
  File "Trading/Dataset/DatasetHolder.py", line 259, in appendTimeframesIntoOneDataset
    ds_h.f_df[cdl] = np.convolve(ds_h.f_df[cdl], fn)[0:len(ds_h.f_df)]
  File "/usr/local/lib/python2.7/dist-packages/pandas/core/frame.py", line 1997, in __getitem__
    return self._getitem_column(key)
  File "/usr/local/lib/python2.7/dist-packages/pandas/core/frame.py", line 2009, in _getitem_column
    result = result[key]
  File "/usr/local/lib/python2.7/dist-packages/pandas/core/frame.py", line 1997, in __getitem__
    return self._getitem_column(key)
  File "/usr/local/lib/python2.7/dist-packages/pandas/core/frame.py", line 2004, in _getitem_column
    return self._get_item_cache(key)
  File "/usr/local/lib/python2.7/dist-packages/pandas/core/generic.py", line 1350, in _get_item_cache
    values = self._data.get(item)
  File "/usr/local/lib/python2.7/dist-packages/pandas/core/internals.py", line 3290, in get
    loc = self.items.get_loc(item)
  File "/usr/local/lib/python2.7/dist-packages/pandas/indexes/base.py", line 1947, in get_loc
    return self._engine.get_loc(self._maybe_cast_indexer(key))
  File "pandas/index.pyx", line 137, in pandas.index.IndexEngine.get_loc (pandas/index.c:4154)
  File "pandas/index.pyx", line 159, in pandas.index.IndexEngine.get_loc (pandas/index.c:4018)
  File "pandas/hashtable.pyx", line 675, in pandas.hashtable.PyObjectHashTable.get_item (pandas/hashtable.c:12368)
  File "pandas/hashtable.pyx", line 683, in pandas.hashtable.PyObjectHashTable.get_item (pandas/hashtable.c:12322)
KeyError: 'CDLCLOSINGMARUBOZ'
2019-02-23 15:06:39,342 - default - ERROR - Exception occurred
Traceback (most recent call last):
  File "Trading/Dataset/DatasetHolder.py", line 259, in appendTimeframesIntoOneDataset
    ds_h.f_df[cdl] = np.convolve(ds_h.f_df[cdl], fn)[0:len(ds_h.f_df)]
  File "/usr/local/lib/python2.7/dist-packages/pandas/core/frame.py", line 1997, in __getitem__
    return self._getitem_column(key)
  File "/usr/local/lib/python2.7/dist-packages/pandas/core/frame.py", line 2009, in _getitem_column
    result = result[key]
  File "/usr/local/lib/python2.7/dist-packages/pandas/core/frame.py", line 1997, in __getitem__
    return self._getitem_column(key)
  File "/usr/local/lib/python2.7/dist-packages/pandas/core/frame.py", line 2004, in _getitem_column
    return self._get_item_cache(key)
  File "/usr/local/lib/python2.7/dist-packages/pandas/core/generic.py", line 1350, in _get_item_cache
    values = self._data.get(item)
  File "/usr/local/lib/python2.7/dist-packages/pandas/core/internals.py", line 3290, in get
    loc = self.items.get_loc(item)
  File "/usr/local/lib/python2.7/dist-packages/pandas/indexes/base.py", line 1947, in get_loc
    return self._engine.get_loc(self._maybe_cast_indexer(key))
  File "pandas/index.pyx", line 137, in pandas.index.IndexEngine.get_loc (pandas/index.c:4154)
  File "pandas/index.pyx", line 159, in pandas.index.IndexEngine.get_loc (pandas/index.c:4018)
  File "pandas/hashtable.pyx", line 675, in pandas.hashtable.PyObjectHashTable.get_item (pandas/hashtable.c:12368)
  File "pandas/hashtable.pyx", line 683, in pandas.hashtable.PyObjectHashTable.get_item (pandas/hashtable.c:12322)
KeyError: 'CDLCONCEALBABYSWAL'
2019-02-23 15:06:39,345 - default - ERROR - Exception occurred
Traceback (most recent call last):
  File "Trading/Dataset/DatasetHolder.py", line 259, in appendTimeframesIntoOneDataset
    ds_h.f_df[cdl] = np.convolve(ds_h.f_df[cdl], fn)[0:len(ds_h.f_df)]
  File "/usr/local/lib/python2.7/dist-packages/pandas/core/frame.py", line 1997, in __getitem__
    return self._getitem_column(key)
  File "/usr/local/lib/python2.7/dist-packages/pandas/core/frame.py", line 2009, in _getitem_column
    result = result[key]
  File "/usr/local/lib/python2.7/dist-packages/pandas/core/frame.py", line 1997, in __getitem__
    return self._getitem_column(key)
  File "/usr/local/lib/python2.7/dist-packages/pandas/core/frame.py", line 2004, in _getitem_column
    return self._get_item_cache(key)
  File "/usr/local/lib/python2.7/dist-packages/pandas/core/generic.py", line 1350, in _get_item_cache
    values = self._data.get(item)
  File "/usr/local/lib/python2.7/dist-packages/pandas/core/internals.py", line 3290, in get
    loc = self.items.get_loc(item)
  File "/usr/local/lib/python2.7/dist-packages/pandas/indexes/base.py", line 1947, in get_loc
    return self._engine.get_loc(self._maybe_cast_indexer(key))
  File "pandas/index.pyx", line 137, in pandas.index.IndexEngine.get_loc (pandas/index.c:4154)
  File "pandas/index.pyx", line 159, in pandas.index.IndexEngine.get_loc (pandas/index.c:4018)
  File "pandas/hashtable.pyx", line 675, in pandas.hashtable.PyObjectHashTable.get_item (pandas/hashtable.c:12368)
  File "pandas/hashtable.pyx", line 683, in pandas.hashtable.PyObjectHashTable.get_item (pandas/hashtable.c:12322)
KeyError: 'CDLCOUNTERATTAC'
2019-02-23 15:06:39,351 - default - ERROR - Exception occurred
Traceback (most recent call last):
  File "Trading/Dataset/DatasetHolder.py", line 259, in appendTimeframesIntoOneDataset
    ds_h.f_df[cdl] = np.convolve(ds_h.f_df[cdl], fn)[0:len(ds_h.f_df)]
  File "/usr/local/lib/python2.7/dist-packages/pandas/core/frame.py", line 1997, in __getitem__
    return self._getitem_column(key)
  File "/usr/local/lib/python2.7/dist-packages/pandas/core/frame.py", line 2009, in _getitem_column
    result = result[key]
  File "/usr/local/lib/python2.7/dist-packages/pandas/core/frame.py", line 1997, in __getitem__
    return self._getitem_column(key)
  File "/usr/local/lib/python2.7/dist-packages/pandas/core/frame.py", line 2004, in _getitem_column
    return self._get_item_cache(key)
  File "/usr/local/lib/python2.7/dist-packages/pandas/core/generic.py", line 1350, in _get_item_cache
    values = self._data.get(item)
  File "/usr/local/lib/python2.7/dist-packages/pandas/core/internals.py", line 3290, in get
    loc = self.items.get_loc(item)
  File "/usr/local/lib/python2.7/dist-packages/pandas/indexes/base.py", line 1947, in get_loc
    return self._engine.get_loc(self._maybe_cast_indexer(key))
  File "pandas/index.pyx", line 137, in pandas.index.IndexEngine.get_loc (pandas/index.c:4154)
  File "pandas/index.pyx", line 159, in pandas.index.IndexEngine.get_loc (pandas/index.c:4018)
  File "pandas/hashtable.pyx", line 675, in pandas.hashtable.PyObjectHashTable.get_item (pandas/hashtable.c:12368)
  File "pandas/hashtable.pyx", line 683, in pandas.hashtable.PyObjectHashTable.get_item (pandas/hashtable.c:12322)
KeyError: 'CDLDARKCLOUDCOVE'
2019-02-23 15:06:39,354 - default - ERROR - Exception occurred
Traceback (most recent call last):
  File "Trading/Dataset/DatasetHolder.py", line 259, in appendTimeframesIntoOneDataset
    ds_h.f_df[cdl] = np.convolve(ds_h.f_df[cdl], fn)[0:len(ds_h.f_df)]
  File "/usr/local/lib/python2.7/dist-packages/pandas/core/frame.py", line 1997, in __getitem__
    return self._getitem_column(key)
  File "/usr/local/lib/python2.7/dist-packages/pandas/core/frame.py", line 2009, in _getitem_column
    result = result[key]
  File "/usr/local/lib/python2.7/dist-packages/pandas/core/frame.py", line 1997, in __getitem__
    return self._getitem_column(key)
  File "/usr/local/lib/python2.7/dist-packages/pandas/core/frame.py", line 2004, in _getitem_column
    return self._get_item_cache(key)
  File "/usr/local/lib/python2.7/dist-packages/pandas/core/generic.py", line 1350, in _get_item_cache
    values = self._data.get(item)
  File "/usr/local/lib/python2.7/dist-packages/pandas/core/internals.py", line 3290, in get
    loc = self.items.get_loc(item)
  File "/usr/local/lib/python2.7/dist-packages/pandas/indexes/base.py", line 1947, in get_loc
    return self._engine.get_loc(self._maybe_cast_indexer(key))
  File "pandas/index.pyx", line 137, in pandas.index.IndexEngine.get_loc (pandas/index.c:4154)
  File "pandas/index.pyx", line 159, in pandas.index.IndexEngine.get_loc (pandas/index.c:4018)
  File "pandas/hashtable.pyx", line 675, in pandas.hashtable.PyObjectHashTable.get_item (pandas/hashtable.c:12368)
  File "pandas/hashtable.pyx", line 683, in pandas.hashtable.PyObjectHashTable.get_item (pandas/hashtable.c:12322)
KeyError: 'CDLDOJ'
2019-02-23 15:06:39,357 - default - ERROR - Exception occurred
Traceback (most recent call last):
  File "Trading/Dataset/DatasetHolder.py", line 259, in appendTimeframesIntoOneDataset
    ds_h.f_df[cdl] = np.convolve(ds_h.f_df[cdl], fn)[0:len(ds_h.f_df)]
  File "/usr/local/lib/python2.7/dist-packages/pandas/core/frame.py", line 1997, in __getitem__
    return self._getitem_column(key)
  File "/usr/local/lib/python2.7/dist-packages/pandas/core/frame.py", line 2009, in _getitem_column
    result = result[key]
  File "/usr/local/lib/python2.7/dist-packages/pandas/core/frame.py", line 1997, in __getitem__
    return self._getitem_column(key)
  File "/usr/local/lib/python2.7/dist-packages/pandas/core/frame.py", line 2004, in _getitem_column
    return self._get_item_cache(key)
  File "/usr/local/lib/python2.7/dist-packages/pandas/core/generic.py", line 1350, in _get_item_cache
    values = self._data.get(item)
  File "/usr/local/lib/python2.7/dist-packages/pandas/core/internals.py", line 3290, in get
    loc = self.items.get_loc(item)
  File "/usr/local/lib/python2.7/dist-packages/pandas/indexes/base.py", line 1947, in get_loc
    return self._engine.get_loc(self._maybe_cast_indexer(key))
  File "pandas/index.pyx", line 137, in pandas.index.IndexEngine.get_loc (pandas/index.c:4154)
  File "pandas/index.pyx", line 159, in pandas.index.IndexEngine.get_loc (pandas/index.c:4018)
  File "pandas/hashtable.pyx", line 675, in pandas.hashtable.PyObjectHashTable.get_item (pandas/hashtable.c:12368)
  File "pandas/hashtable.pyx", line 683, in pandas.hashtable.PyObjectHashTable.get_item (pandas/hashtable.c:12322)
KeyError: 'CDLDOJISTA'
2019-02-23 15:06:39,361 - default - ERROR - Exception occurred
Traceback (most recent call last):
  File "Trading/Dataset/DatasetHolder.py", line 259, in appendTimeframesIntoOneDataset
    ds_h.f_df[cdl] = np.convolve(ds_h.f_df[cdl], fn)[0:len(ds_h.f_df)]
  File "/usr/local/lib/python2.7/dist-packages/pandas/core/frame.py", line 1997, in __getitem__
    return self._getitem_column(key)
  File "/usr/local/lib/python2.7/dist-packages/pandas/core/frame.py", line 2009, in _getitem_column
    result = result[key]
  File "/usr/local/lib/python2.7/dist-packages/pandas/core/frame.py", line 1997, in __getitem__
    return self._getitem_column(key)
  File "/usr/local/lib/python2.7/dist-packages/pandas/core/frame.py", line 2004, in _getitem_column
    return self._get_item_cache(key)
  File "/usr/local/lib/python2.7/dist-packages/pandas/core/generic.py", line 1350, in _get_item_cache
    values = self._data.get(item)
  File "/usr/local/lib/python2.7/dist-packages/pandas/core/internals.py", line 3290, in get
    loc = self.items.get_loc(item)
  File "/usr/local/lib/python2.7/dist-packages/pandas/indexes/base.py", line 1947, in get_loc
    return self._engine.get_loc(self._maybe_cast_indexer(key))
  File "pandas/index.pyx", line 137, in pandas.index.IndexEngine.get_loc (pandas/index.c:4154)
  File "pandas/index.pyx", line 159, in pandas.index.IndexEngine.get_loc (pandas/index.c:4018)
  File "pandas/hashtable.pyx", line 675, in pandas.hashtable.PyObjectHashTable.get_item (pandas/hashtable.c:12368)
  File "pandas/hashtable.pyx", line 683, in pandas.hashtable.PyObjectHashTable.get_item (pandas/hashtable.c:12322)
KeyError: 'CDLDRAGONFLYDOJ'
2019-02-23 15:06:39,365 - default - ERROR - Exception occurred
Traceback (most recent call last):
  File "Trading/Dataset/DatasetHolder.py", line 259, in appendTimeframesIntoOneDataset
    ds_h.f_df[cdl] = np.convolve(ds_h.f_df[cdl], fn)[0:len(ds_h.f_df)]
  File "/usr/local/lib/python2.7/dist-packages/pandas/core/frame.py", line 1997, in __getitem__
    return self._getitem_column(key)
  File "/usr/local/lib/python2.7/dist-packages/pandas/core/frame.py", line 2009, in _getitem_column
    result = result[key]
  File "/usr/local/lib/python2.7/dist-packages/pandas/core/frame.py", line 1997, in __getitem__
    return self._getitem_column(key)
  File "/usr/local/lib/python2.7/dist-packages/pandas/core/frame.py", line 2004, in _getitem_column
    return self._get_item_cache(key)
  File "/usr/local/lib/python2.7/dist-packages/pandas/core/generic.py", line 1350, in _get_item_cache
    values = self._data.get(item)
  File "/usr/local/lib/python2.7/dist-packages/pandas/core/internals.py", line 3290, in get
    loc = self.items.get_loc(item)
  File "/usr/local/lib/python2.7/dist-packages/pandas/indexes/base.py", line 1947, in get_loc
    return self._engine.get_loc(self._maybe_cast_indexer(key))
  File "pandas/index.pyx", line 137, in pandas.index.IndexEngine.get_loc (pandas/index.c:4154)
  File "pandas/index.pyx", line 159, in pandas.index.IndexEngine.get_loc (pandas/index.c:4018)
  File "pandas/hashtable.pyx", line 675, in pandas.hashtable.PyObjectHashTable.get_item (pandas/hashtable.c:12368)
  File "pandas/hashtable.pyx", line 683, in pandas.hashtable.PyObjectHashTable.get_item (pandas/hashtable.c:12322)
KeyError: 'CDLENGULFIN'
2019-02-23 15:06:39,368 - default - ERROR - Exception occurred
Traceback (most recent call last):
  File "Trading/Dataset/DatasetHolder.py", line 259, in appendTimeframesIntoOneDataset
    ds_h.f_df[cdl] = np.convolve(ds_h.f_df[cdl], fn)[0:len(ds_h.f_df)]
  File "/usr/local/lib/python2.7/dist-packages/pandas/core/frame.py", line 1997, in __getitem__
    return self._getitem_column(key)
  File "/usr/local/lib/python2.7/dist-packages/pandas/core/frame.py", line 2009, in _getitem_column
    result = result[key]
  File "/usr/local/lib/python2.7/dist-packages/pandas/core/frame.py", line 1997, in __getitem__
    return self._getitem_column(key)
  File "/usr/local/lib/python2.7/dist-packages/pandas/core/frame.py", line 2004, in _getitem_column
    return self._get_item_cache(key)
  File "/usr/local/lib/python2.7/dist-packages/pandas/core/generic.py", line 1350, in _get_item_cache
    values = self._data.get(item)
  File "/usr/local/lib/python2.7/dist-packages/pandas/core/internals.py", line 3290, in get
    loc = self.items.get_loc(item)
  File "/usr/local/lib/python2.7/dist-packages/pandas/indexes/base.py", line 1947, in get_loc
    return self._engine.get_loc(self._maybe_cast_indexer(key))
  File "pandas/index.pyx", line 137, in pandas.index.IndexEngine.get_loc (pandas/index.c:4154)
  File "pandas/index.pyx", line 159, in pandas.index.IndexEngine.get_loc (pandas/index.c:4018)
  File "pandas/hashtable.pyx", line 675, in pandas.hashtable.PyObjectHashTable.get_item (pandas/hashtable.c:12368)
  File "pandas/hashtable.pyx", line 683, in pandas.hashtable.PyObjectHashTable.get_item (pandas/hashtable.c:12322)
KeyError: 'CDLEVENINGDOJISTA'
2019-02-23 15:06:39,372 - default - ERROR - Exception occurred
Traceback (most recent call last):
  File "Trading/Dataset/DatasetHolder.py", line 259, in appendTimeframesIntoOneDataset
    ds_h.f_df[cdl] = np.convolve(ds_h.f_df[cdl], fn)[0:len(ds_h.f_df)]
  File "/usr/local/lib/python2.7/dist-packages/pandas/core/frame.py", line 1997, in __getitem__
    return self._getitem_column(key)
  File "/usr/local/lib/python2.7/dist-packages/pandas/core/frame.py", line 2009, in _getitem_column
    result = result[key]
  File "/usr/local/lib/python2.7/dist-packages/pandas/core/frame.py", line 1997, in __getitem__
    return self._getitem_column(key)
  File "/usr/local/lib/python2.7/dist-packages/pandas/core/frame.py", line 2004, in _getitem_column
    return self._get_item_cache(key)
  File "/usr/local/lib/python2.7/dist-packages/pandas/core/generic.py", line 1350, in _get_item_cache
    values = self._data.get(item)
  File "/usr/local/lib/python2.7/dist-packages/pandas/core/internals.py", line 3290, in get
    loc = self.items.get_loc(item)
  File "/usr/local/lib/python2.7/dist-packages/pandas/indexes/base.py", line 1947, in get_loc
    return self._engine.get_loc(self._maybe_cast_indexer(key))
  File "pandas/index.pyx", line 137, in pandas.index.IndexEngine.get_loc (pandas/index.c:4154)
  File "pandas/index.pyx", line 159, in pandas.index.IndexEngine.get_loc (pandas/index.c:4018)
  File "pandas/hashtable.pyx", line 675, in pandas.hashtable.PyObjectHashTable.get_item (pandas/hashtable.c:12368)
  File "pandas/hashtable.pyx", line 683, in pandas.hashtable.PyObjectHashTable.get_item (pandas/hashtable.c:12322)
KeyError: 'CDLEVENINGSTA'
2019-02-23 15:06:39,376 - default - ERROR - Exception occurred
Traceback (most recent call last):
  File "Trading/Dataset/DatasetHolder.py", line 259, in appendTimeframesIntoOneDataset
    ds_h.f_df[cdl] = np.convolve(ds_h.f_df[cdl], fn)[0:len(ds_h.f_df)]
  File "/usr/local/lib/python2.7/dist-packages/pandas/core/frame.py", line 1997, in __getitem__
    return self._getitem_column(key)
  File "/usr/local/lib/python2.7/dist-packages/pandas/core/frame.py", line 2009, in _getitem_column
    result = result[key]
  File "/usr/local/lib/python2.7/dist-packages/pandas/core/frame.py", line 1997, in __getitem__
    return self._getitem_column(key)
  File "/usr/local/lib/python2.7/dist-packages/pandas/core/frame.py", line 2004, in _getitem_column
    return self._get_item_cache(key)
  File "/usr/local/lib/python2.7/dist-packages/pandas/core/generic.py", line 1350, in _get_item_cache
    values = self._data.get(item)
  File "/usr/local/lib/python2.7/dist-packages/pandas/core/internals.py", line 3290, in get
    loc = self.items.get_loc(item)
  File "/usr/local/lib/python2.7/dist-packages/pandas/indexes/base.py", line 1947, in get_loc
    return self._engine.get_loc(self._maybe_cast_indexer(key))
  File "pandas/index.pyx", line 137, in pandas.index.IndexEngine.get_loc (pandas/index.c:4154)
  File "pandas/index.pyx", line 159, in pandas.index.IndexEngine.get_loc (pandas/index.c:4018)
  File "pandas/hashtable.pyx", line 675, in pandas.hashtable.PyObjectHashTable.get_item (pandas/hashtable.c:12368)
  File "pandas/hashtable.pyx", line 683, in pandas.hashtable.PyObjectHashTable.get_item (pandas/hashtable.c:12322)
KeyError: 'CDLGAPSIDESIDEWHIT'
2019-02-23 15:06:39,381 - default - ERROR - Exception occurred
Traceback (most recent call last):
  File "Trading/Dataset/DatasetHolder.py", line 259, in appendTimeframesIntoOneDataset
    ds_h.f_df[cdl] = np.convolve(ds_h.f_df[cdl], fn)[0:len(ds_h.f_df)]
  File "/usr/local/lib/python2.7/dist-packages/pandas/core/frame.py", line 1997, in __getitem__
    return self._getitem_column(key)
  File "/usr/local/lib/python2.7/dist-packages/pandas/core/frame.py", line 2009, in _getitem_column
    result = result[key]
  File "/usr/local/lib/python2.7/dist-packages/pandas/core/frame.py", line 1997, in __getitem__
    return self._getitem_column(key)
  File "/usr/local/lib/python2.7/dist-packages/pandas/core/frame.py", line 2004, in _getitem_column
    return self._get_item_cache(key)
  File "/usr/local/lib/python2.7/dist-packages/pandas/core/generic.py", line 1350, in _get_item_cache
    values = self._data.get(item)
  File "/usr/local/lib/python2.7/dist-packages/pandas/core/internals.py", line 3290, in get
    loc = self.items.get_loc(item)
  File "/usr/local/lib/python2.7/dist-packages/pandas/indexes/base.py", line 1947, in get_loc
    return self._engine.get_loc(self._maybe_cast_indexer(key))
  File "pandas/index.pyx", line 137, in pandas.index.IndexEngine.get_loc (pandas/index.c:4154)
  File "pandas/index.pyx", line 159, in pandas.index.IndexEngine.get_loc (pandas/index.c:4018)
  File "pandas/hashtable.pyx", line 675, in pandas.hashtable.PyObjectHashTable.get_item (pandas/hashtable.c:12368)
  File "pandas/hashtable.pyx", line 683, in pandas.hashtable.PyObjectHashTable.get_item (pandas/hashtable.c:12322)
KeyError: 'CDLGRAVESTONEDOJ'
2019-02-23 15:06:39,385 - default - ERROR - Exception occurred
Traceback (most recent call last):
  File "Trading/Dataset/DatasetHolder.py", line 259, in appendTimeframesIntoOneDataset
    ds_h.f_df[cdl] = np.convolve(ds_h.f_df[cdl], fn)[0:len(ds_h.f_df)]
  File "/usr/local/lib/python2.7/dist-packages/pandas/core/frame.py", line 1997, in __getitem__
    return self._getitem_column(key)
  File "/usr/local/lib/python2.7/dist-packages/pandas/core/frame.py", line 2009, in _getitem_column
    result = result[key]
  File "/usr/local/lib/python2.7/dist-packages/pandas/core/frame.py", line 1997, in __getitem__
    return self._getitem_column(key)
  File "/usr/local/lib/python2.7/dist-packages/pandas/core/frame.py", line 2004, in _getitem_column
    return self._get_item_cache(key)
  File "/usr/local/lib/python2.7/dist-packages/pandas/core/generic.py", line 1350, in _get_item_cache
    values = self._data.get(item)
  File "/usr/local/lib/python2.7/dist-packages/pandas/core/internals.py", line 3290, in get
    loc = self.items.get_loc(item)
  File "/usr/local/lib/python2.7/dist-packages/pandas/indexes/base.py", line 1947, in get_loc
    return self._engine.get_loc(self._maybe_cast_indexer(key))
  File "pandas/index.pyx", line 137, in pandas.index.IndexEngine.get_loc (pandas/index.c:4154)
  File "pandas/index.pyx", line 159, in pandas.index.IndexEngine.get_loc (pandas/index.c:4018)
  File "pandas/hashtable.pyx", line 675, in pandas.hashtable.PyObjectHashTable.get_item (pandas/hashtable.c:12368)
  File "pandas/hashtable.pyx", line 683, in pandas.hashtable.PyObjectHashTable.get_item (pandas/hashtable.c:12322)
KeyError: 'CDLHAMME'
2019-02-23 15:06:39,389 - default - ERROR - Exception occurred
Traceback (most recent call last):
  File "Trading/Dataset/DatasetHolder.py", line 259, in appendTimeframesIntoOneDataset
    ds_h.f_df[cdl] = np.convolve(ds_h.f_df[cdl], fn)[0:len(ds_h.f_df)]
  File "/usr/local/lib/python2.7/dist-packages/pandas/core/frame.py", line 1997, in __getitem__
    return self._getitem_column(key)
  File "/usr/local/lib/python2.7/dist-packages/pandas/core/frame.py", line 2009, in _getitem_column
    result = result[key]
  File "/usr/local/lib/python2.7/dist-packages/pandas/core/frame.py", line 1997, in __getitem__
    return self._getitem_column(key)
  File "/usr/local/lib/python2.7/dist-packages/pandas/core/frame.py", line 2004, in _getitem_column
    return self._get_item_cache(key)
  File "/usr/local/lib/python2.7/dist-packages/pandas/core/generic.py", line 1350, in _get_item_cache
    values = self._data.get(item)
  File "/usr/local/lib/python2.7/dist-packages/pandas/core/internals.py", line 3290, in get
    loc = self.items.get_loc(item)
  File "/usr/local/lib/python2.7/dist-packages/pandas/indexes/base.py", line 1947, in get_loc
    return self._engine.get_loc(self._maybe_cast_indexer(key))
  File "pandas/index.pyx", line 137, in pandas.index.IndexEngine.get_loc (pandas/index.c:4154)
  File "pandas/index.pyx", line 159, in pandas.index.IndexEngine.get_loc (pandas/index.c:4018)
  File "pandas/hashtable.pyx", line 675, in pandas.hashtable.PyObjectHashTable.get_item (pandas/hashtable.c:12368)
  File "pandas/hashtable.pyx", line 683, in pandas.hashtable.PyObjectHashTable.get_item (pandas/hashtable.c:12322)
KeyError: 'CDLHANGINGMA'
2019-02-23 15:06:39,392 - default - ERROR - Exception occurred
Traceback (most recent call last):
  File "Trading/Dataset/DatasetHolder.py", line 259, in appendTimeframesIntoOneDataset
    ds_h.f_df[cdl] = np.convolve(ds_h.f_df[cdl], fn)[0:len(ds_h.f_df)]
  File "/usr/local/lib/python2.7/dist-packages/pandas/core/frame.py", line 1997, in __getitem__
    return self._getitem_column(key)
  File "/usr/local/lib/python2.7/dist-packages/pandas/core/frame.py", line 2009, in _getitem_column
    result = result[key]
  File "/usr/local/lib/python2.7/dist-packages/pandas/core/frame.py", line 1997, in __getitem__
    return self._getitem_column(key)
  File "/usr/local/lib/python2.7/dist-packages/pandas/core/frame.py", line 2004, in _getitem_column
    return self._get_item_cache(key)
  File "/usr/local/lib/python2.7/dist-packages/pandas/core/generic.py", line 1350, in _get_item_cache
    values = self._data.get(item)
  File "/usr/local/lib/python2.7/dist-packages/pandas/core/internals.py", line 3290, in get
    loc = self.items.get_loc(item)
  File "/usr/local/lib/python2.7/dist-packages/pandas/indexes/base.py", line 1947, in get_loc
    return self._engine.get_loc(self._maybe_cast_indexer(key))
  File "pandas/index.pyx", line 137, in pandas.index.IndexEngine.get_loc (pandas/index.c:4154)
  File "pandas/index.pyx", line 159, in pandas.index.IndexEngine.get_loc (pandas/index.c:4018)
  File "pandas/hashtable.pyx", line 675, in pandas.hashtable.PyObjectHashTable.get_item (pandas/hashtable.c:12368)
  File "pandas/hashtable.pyx", line 683, in pandas.hashtable.PyObjectHashTable.get_item (pandas/hashtable.c:12322)
KeyError: 'CDLHARAM'
2019-02-23 15:06:39,396 - default - ERROR - Exception occurred
Traceback (most recent call last):
  File "Trading/Dataset/DatasetHolder.py", line 259, in appendTimeframesIntoOneDataset
    ds_h.f_df[cdl] = np.convolve(ds_h.f_df[cdl], fn)[0:len(ds_h.f_df)]
  File "/usr/local/lib/python2.7/dist-packages/pandas/core/frame.py", line 1997, in __getitem__
    return self._getitem_column(key)
  File "/usr/local/lib/python2.7/dist-packages/pandas/core/frame.py", line 2009, in _getitem_column
    result = result[key]
  File "/usr/local/lib/python2.7/dist-packages/pandas/core/frame.py", line 1997, in __getitem__
    return self._getitem_column(key)
  File "/usr/local/lib/python2.7/dist-packages/pandas/core/frame.py", line 2004, in _getitem_column
    return self._get_item_cache(key)
  File "/usr/local/lib/python2.7/dist-packages/pandas/core/generic.py", line 1350, in _get_item_cache
    values = self._data.get(item)
  File "/usr/local/lib/python2.7/dist-packages/pandas/core/internals.py", line 3290, in get
    loc = self.items.get_loc(item)
  File "/usr/local/lib/python2.7/dist-packages/pandas/indexes/base.py", line 1947, in get_loc
    return self._engine.get_loc(self._maybe_cast_indexer(key))
  File "pandas/index.pyx", line 137, in pandas.index.IndexEngine.get_loc (pandas/index.c:4154)
  File "pandas/index.pyx", line 159, in pandas.index.IndexEngine.get_loc (pandas/index.c:4018)
  File "pandas/hashtable.pyx", line 675, in pandas.hashtable.PyObjectHashTable.get_item (pandas/hashtable.c:12368)
  File "pandas/hashtable.pyx", line 683, in pandas.hashtable.PyObjectHashTable.get_item (pandas/hashtable.c:12322)
KeyError: 'CDLHARAMICROS'
2019-02-23 15:06:39,401 - default - ERROR - Exception occurred
Traceback (most recent call last):
  File "Trading/Dataset/DatasetHolder.py", line 259, in appendTimeframesIntoOneDataset
    ds_h.f_df[cdl] = np.convolve(ds_h.f_df[cdl], fn)[0:len(ds_h.f_df)]
  File "/usr/local/lib/python2.7/dist-packages/pandas/core/frame.py", line 1997, in __getitem__
    return self._getitem_column(key)
  File "/usr/local/lib/python2.7/dist-packages/pandas/core/frame.py", line 2009, in _getitem_column
    result = result[key]
  File "/usr/local/lib/python2.7/dist-packages/pandas/core/frame.py", line 1997, in __getitem__
    return self._getitem_column(key)
  File "/usr/local/lib/python2.7/dist-packages/pandas/core/frame.py", line 2004, in _getitem_column
    return self._get_item_cache(key)
  File "/usr/local/lib/python2.7/dist-packages/pandas/core/generic.py", line 1350, in _get_item_cache
    values = self._data.get(item)
  File "/usr/local/lib/python2.7/dist-packages/pandas/core/internals.py", line 3290, in get
    loc = self.items.get_loc(item)
  File "/usr/local/lib/python2.7/dist-packages/pandas/indexes/base.py", line 1947, in get_loc
    return self._engine.get_loc(self._maybe_cast_indexer(key))
  File "pandas/index.pyx", line 137, in pandas.index.IndexEngine.get_loc (pandas/index.c:4154)
  File "pandas/index.pyx", line 159, in pandas.index.IndexEngine.get_loc (pandas/index.c:4018)
  File "pandas/hashtable.pyx", line 675, in pandas.hashtable.PyObjectHashTable.get_item (pandas/hashtable.c:12368)
  File "pandas/hashtable.pyx", line 683, in pandas.hashtable.PyObjectHashTable.get_item (pandas/hashtable.c:12322)
KeyError: 'CDLHIGHWAV'
2019-02-23 15:06:39,405 - default - ERROR - Exception occurred
Traceback (most recent call last):
  File "Trading/Dataset/DatasetHolder.py", line 259, in appendTimeframesIntoOneDataset
    ds_h.f_df[cdl] = np.convolve(ds_h.f_df[cdl], fn)[0:len(ds_h.f_df)]
  File "/usr/local/lib/python2.7/dist-packages/pandas/core/frame.py", line 1997, in __getitem__
    return self._getitem_column(key)
  File "/usr/local/lib/python2.7/dist-packages/pandas/core/frame.py", line 2009, in _getitem_column
    result = result[key]
  File "/usr/local/lib/python2.7/dist-packages/pandas/core/frame.py", line 1997, in __getitem__
    return self._getitem_column(key)
  File "/usr/local/lib/python2.7/dist-packages/pandas/core/frame.py", line 2004, in _getitem_column
    return self._get_item_cache(key)
  File "/usr/local/lib/python2.7/dist-packages/pandas/core/generic.py", line 1350, in _get_item_cache
    values = self._data.get(item)
  File "/usr/local/lib/python2.7/dist-packages/pandas/core/internals.py", line 3290, in get
    loc = self.items.get_loc(item)
  File "/usr/local/lib/python2.7/dist-packages/pandas/indexes/base.py", line 1947, in get_loc
    return self._engine.get_loc(self._maybe_cast_indexer(key))
  File "pandas/index.pyx", line 137, in pandas.index.IndexEngine.get_loc (pandas/index.c:4154)
  File "pandas/index.pyx", line 159, in pandas.index.IndexEngine.get_loc (pandas/index.c:4018)
  File "pandas/hashtable.pyx", line 675, in pandas.hashtable.PyObjectHashTable.get_item (pandas/hashtable.c:12368)
  File "pandas/hashtable.pyx", line 683, in pandas.hashtable.PyObjectHashTable.get_item (pandas/hashtable.c:12322)
KeyError: 'CDLHIKKAK'
2019-02-23 15:06:39,408 - default - ERROR - Exception occurred
Traceback (most recent call last):
  File "Trading/Dataset/DatasetHolder.py", line 259, in appendTimeframesIntoOneDataset
    ds_h.f_df[cdl] = np.convolve(ds_h.f_df[cdl], fn)[0:len(ds_h.f_df)]
  File "/usr/local/lib/python2.7/dist-packages/pandas/core/frame.py", line 1997, in __getitem__
    return self._getitem_column(key)
  File "/usr/local/lib/python2.7/dist-packages/pandas/core/frame.py", line 2009, in _getitem_column
    result = result[key]
  File "/usr/local/lib/python2.7/dist-packages/pandas/core/frame.py", line 1997, in __getitem__
    return self._getitem_column(key)
  File "/usr/local/lib/python2.7/dist-packages/pandas/core/frame.py", line 2004, in _getitem_column
    return self._get_item_cache(key)
  File "/usr/local/lib/python2.7/dist-packages/pandas/core/generic.py", line 1350, in _get_item_cache
    values = self._data.get(item)
  File "/usr/local/lib/python2.7/dist-packages/pandas/core/internals.py", line 3290, in get
    loc = self.items.get_loc(item)
  File "/usr/local/lib/python2.7/dist-packages/pandas/indexes/base.py", line 1947, in get_loc
    return self._engine.get_loc(self._maybe_cast_indexer(key))
  File "pandas/index.pyx", line 137, in pandas.index.IndexEngine.get_loc (pandas/index.c:4154)
  File "pandas/index.pyx", line 159, in pandas.index.IndexEngine.get_loc (pandas/index.c:4018)
  File "pandas/hashtable.pyx", line 675, in pandas.hashtable.PyObjectHashTable.get_item (pandas/hashtable.c:12368)
  File "pandas/hashtable.pyx", line 683, in pandas.hashtable.PyObjectHashTable.get_item (pandas/hashtable.c:12322)
KeyError: 'CDLHIKKAKEMO'
2019-02-23 15:06:39,412 - default - ERROR - Exception occurred
Traceback (most recent call last):
  File "Trading/Dataset/DatasetHolder.py", line 259, in appendTimeframesIntoOneDataset
    ds_h.f_df[cdl] = np.convolve(ds_h.f_df[cdl], fn)[0:len(ds_h.f_df)]
  File "/usr/local/lib/python2.7/dist-packages/pandas/core/frame.py", line 1997, in __getitem__
    return self._getitem_column(key)
  File "/usr/local/lib/python2.7/dist-packages/pandas/core/frame.py", line 2009, in _getitem_column
    result = result[key]
  File "/usr/local/lib/python2.7/dist-packages/pandas/core/frame.py", line 1997, in __getitem__
    return self._getitem_column(key)
  File "/usr/local/lib/python2.7/dist-packages/pandas/core/frame.py", line 2004, in _getitem_column
    return self._get_item_cache(key)
  File "/usr/local/lib/python2.7/dist-packages/pandas/core/generic.py", line 1350, in _get_item_cache
    values = self._data.get(item)
  File "/usr/local/lib/python2.7/dist-packages/pandas/core/internals.py", line 3290, in get
    loc = self.items.get_loc(item)
  File "/usr/local/lib/python2.7/dist-packages/pandas/indexes/base.py", line 1947, in get_loc
    return self._engine.get_loc(self._maybe_cast_indexer(key))
  File "pandas/index.pyx", line 137, in pandas.index.IndexEngine.get_loc (pandas/index.c:4154)
  File "pandas/index.pyx", line 159, in pandas.index.IndexEngine.get_loc (pandas/index.c:4018)
  File "pandas/hashtable.pyx", line 675, in pandas.hashtable.PyObjectHashTable.get_item (pandas/hashtable.c:12368)
  File "pandas/hashtable.pyx", line 683, in pandas.hashtable.PyObjectHashTable.get_item (pandas/hashtable.c:12322)
KeyError: 'CDLHOMINGPIGEO'
2019-02-23 15:06:39,417 - default - ERROR - Exception occurred
Traceback (most recent call last):
  File "Trading/Dataset/DatasetHolder.py", line 259, in appendTimeframesIntoOneDataset
    ds_h.f_df[cdl] = np.convolve(ds_h.f_df[cdl], fn)[0:len(ds_h.f_df)]
  File "/usr/local/lib/python2.7/dist-packages/pandas/core/frame.py", line 1997, in __getitem__
    return self._getitem_column(key)
  File "/usr/local/lib/python2.7/dist-packages/pandas/core/frame.py", line 2009, in _getitem_column
    result = result[key]
  File "/usr/local/lib/python2.7/dist-packages/pandas/core/frame.py", line 1997, in __getitem__
    return self._getitem_column(key)
  File "/usr/local/lib/python2.7/dist-packages/pandas/core/frame.py", line 2004, in _getitem_column
    return self._get_item_cache(key)
  File "/usr/local/lib/python2.7/dist-packages/pandas/core/generic.py", line 1350, in _get_item_cache
    values = self._data.get(item)
  File "/usr/local/lib/python2.7/dist-packages/pandas/core/internals.py", line 3290, in get
    loc = self.items.get_loc(item)
  File "/usr/local/lib/python2.7/dist-packages/pandas/indexes/base.py", line 1947, in get_loc
    return self._engine.get_loc(self._maybe_cast_indexer(key))
  File "pandas/index.pyx", line 137, in pandas.index.IndexEngine.get_loc (pandas/index.c:4154)
  File "pandas/index.pyx", line 159, in pandas.index.IndexEngine.get_loc (pandas/index.c:4018)
  File "pandas/hashtable.pyx", line 675, in pandas.hashtable.PyObjectHashTable.get_item (pandas/hashtable.c:12368)
  File "pandas/hashtable.pyx", line 683, in pandas.hashtable.PyObjectHashTable.get_item (pandas/hashtable.c:12322)
KeyError: 'CDLIDENTICAL3CROW'
2019-02-23 15:06:39,420 - default - ERROR - Exception occurred
Traceback (most recent call last):
  File "Trading/Dataset/DatasetHolder.py", line 259, in appendTimeframesIntoOneDataset
    ds_h.f_df[cdl] = np.convolve(ds_h.f_df[cdl], fn)[0:len(ds_h.f_df)]
  File "/usr/local/lib/python2.7/dist-packages/pandas/core/frame.py", line 1997, in __getitem__
    return self._getitem_column(key)
  File "/usr/local/lib/python2.7/dist-packages/pandas/core/frame.py", line 2009, in _getitem_column
    result = result[key]
  File "/usr/local/lib/python2.7/dist-packages/pandas/core/frame.py", line 1997, in __getitem__
    return self._getitem_column(key)
  File "/usr/local/lib/python2.7/dist-packages/pandas/core/frame.py", line 2004, in _getitem_column
    return self._get_item_cache(key)
  File "/usr/local/lib/python2.7/dist-packages/pandas/core/generic.py", line 1350, in _get_item_cache
    values = self._data.get(item)
  File "/usr/local/lib/python2.7/dist-packages/pandas/core/internals.py", line 3290, in get
    loc = self.items.get_loc(item)
  File "/usr/local/lib/python2.7/dist-packages/pandas/indexes/base.py", line 1947, in get_loc
    return self._engine.get_loc(self._maybe_cast_indexer(key))
  File "pandas/index.pyx", line 137, in pandas.index.IndexEngine.get_loc (pandas/index.c:4154)
  File "pandas/index.pyx", line 159, in pandas.index.IndexEngine.get_loc (pandas/index.c:4018)
  File "pandas/hashtable.pyx", line 675, in pandas.hashtable.PyObjectHashTable.get_item (pandas/hashtable.c:12368)
  File "pandas/hashtable.pyx", line 683, in pandas.hashtable.PyObjectHashTable.get_item (pandas/hashtable.c:12322)
KeyError: 'CDLINNEC'
2019-02-23 15:06:39,424 - default - ERROR - Exception occurred
Traceback (most recent call last):
  File "Trading/Dataset/DatasetHolder.py", line 259, in appendTimeframesIntoOneDataset
    ds_h.f_df[cdl] = np.convolve(ds_h.f_df[cdl], fn)[0:len(ds_h.f_df)]
  File "/usr/local/lib/python2.7/dist-packages/pandas/core/frame.py", line 1997, in __getitem__
    return self._getitem_column(key)
  File "/usr/local/lib/python2.7/dist-packages/pandas/core/frame.py", line 2009, in _getitem_column
    result = result[key]
  File "/usr/local/lib/python2.7/dist-packages/pandas/core/frame.py", line 1997, in __getitem__
    return self._getitem_column(key)
  File "/usr/local/lib/python2.7/dist-packages/pandas/core/frame.py", line 2004, in _getitem_column
    return self._get_item_cache(key)
  File "/usr/local/lib/python2.7/dist-packages/pandas/core/generic.py", line 1350, in _get_item_cache
    values = self._data.get(item)
  File "/usr/local/lib/python2.7/dist-packages/pandas/core/internals.py", line 3290, in get
    loc = self.items.get_loc(item)
  File "/usr/local/lib/python2.7/dist-packages/pandas/indexes/base.py", line 1947, in get_loc
    return self._engine.get_loc(self._maybe_cast_indexer(key))
  File "pandas/index.pyx", line 137, in pandas.index.IndexEngine.get_loc (pandas/index.c:4154)
  File "pandas/index.pyx", line 159, in pandas.index.IndexEngine.get_loc (pandas/index.c:4018)
  File "pandas/hashtable.pyx", line 675, in pandas.hashtable.PyObjectHashTable.get_item (pandas/hashtable.c:12368)
  File "pandas/hashtable.pyx", line 683, in pandas.hashtable.PyObjectHashTable.get_item (pandas/hashtable.c:12322)
KeyError: 'CDLINVERTEDHAMME'
2019-02-23 15:06:39,428 - default - ERROR - Exception occurred
Traceback (most recent call last):
  File "Trading/Dataset/DatasetHolder.py", line 259, in appendTimeframesIntoOneDataset
    ds_h.f_df[cdl] = np.convolve(ds_h.f_df[cdl], fn)[0:len(ds_h.f_df)]
  File "/usr/local/lib/python2.7/dist-packages/pandas/core/frame.py", line 1997, in __getitem__
    return self._getitem_column(key)
  File "/usr/local/lib/python2.7/dist-packages/pandas/core/frame.py", line 2009, in _getitem_column
    result = result[key]
  File "/usr/local/lib/python2.7/dist-packages/pandas/core/frame.py", line 1997, in __getitem__
    return self._getitem_column(key)
  File "/usr/local/lib/python2.7/dist-packages/pandas/core/frame.py", line 2004, in _getitem_column
    return self._get_item_cache(key)
  File "/usr/local/lib/python2.7/dist-packages/pandas/core/generic.py", line 1350, in _get_item_cache
    values = self._data.get(item)
  File "/usr/local/lib/python2.7/dist-packages/pandas/core/internals.py", line 3290, in get
    loc = self.items.get_loc(item)
  File "/usr/local/lib/python2.7/dist-packages/pandas/indexes/base.py", line 1947, in get_loc
    return self._engine.get_loc(self._maybe_cast_indexer(key))
  File "pandas/index.pyx", line 137, in pandas.index.IndexEngine.get_loc (pandas/index.c:4154)
  File "pandas/index.pyx", line 159, in pandas.index.IndexEngine.get_loc (pandas/index.c:4018)
  File "pandas/hashtable.pyx", line 675, in pandas.hashtable.PyObjectHashTable.get_item (pandas/hashtable.c:12368)
  File "pandas/hashtable.pyx", line 683, in pandas.hashtable.PyObjectHashTable.get_item (pandas/hashtable.c:12322)
KeyError: 'CDLKICKIN'
2019-02-23 15:06:39,432 - default - ERROR - Exception occurred
Traceback (most recent call last):
  File "Trading/Dataset/DatasetHolder.py", line 259, in appendTimeframesIntoOneDataset
    ds_h.f_df[cdl] = np.convolve(ds_h.f_df[cdl], fn)[0:len(ds_h.f_df)]
  File "/usr/local/lib/python2.7/dist-packages/pandas/core/frame.py", line 1997, in __getitem__
    return self._getitem_column(key)
  File "/usr/local/lib/python2.7/dist-packages/pandas/core/frame.py", line 2009, in _getitem_column
    result = result[key]
  File "/usr/local/lib/python2.7/dist-packages/pandas/core/frame.py", line 1997, in __getitem__
    return self._getitem_column(key)
  File "/usr/local/lib/python2.7/dist-packages/pandas/core/frame.py", line 2004, in _getitem_column
    return self._get_item_cache(key)
  File "/usr/local/lib/python2.7/dist-packages/pandas/core/generic.py", line 1350, in _get_item_cache
    values = self._data.get(item)
  File "/usr/local/lib/python2.7/dist-packages/pandas/core/internals.py", line 3290, in get
    loc = self.items.get_loc(item)
  File "/usr/local/lib/python2.7/dist-packages/pandas/indexes/base.py", line 1947, in get_loc
    return self._engine.get_loc(self._maybe_cast_indexer(key))
  File "pandas/index.pyx", line 137, in pandas.index.IndexEngine.get_loc (pandas/index.c:4154)
  File "pandas/index.pyx", line 159, in pandas.index.IndexEngine.get_loc (pandas/index.c:4018)
  File "pandas/hashtable.pyx", line 675, in pandas.hashtable.PyObjectHashTable.get_item (pandas/hashtable.c:12368)
  File "pandas/hashtable.pyx", line 683, in pandas.hashtable.PyObjectHashTable.get_item (pandas/hashtable.c:12322)
KeyError: 'CDLKICKINGBYLENGT'
2019-02-23 15:06:39,436 - default - ERROR - Exception occurred
Traceback (most recent call last):
  File "Trading/Dataset/DatasetHolder.py", line 259, in appendTimeframesIntoOneDataset
    ds_h.f_df[cdl] = np.convolve(ds_h.f_df[cdl], fn)[0:len(ds_h.f_df)]
  File "/usr/local/lib/python2.7/dist-packages/pandas/core/frame.py", line 1997, in __getitem__
    return self._getitem_column(key)
  File "/usr/local/lib/python2.7/dist-packages/pandas/core/frame.py", line 2009, in _getitem_column
    result = result[key]
  File "/usr/local/lib/python2.7/dist-packages/pandas/core/frame.py", line 1997, in __getitem__
    return self._getitem_column(key)
  File "/usr/local/lib/python2.7/dist-packages/pandas/core/frame.py", line 2004, in _getitem_column
    return self._get_item_cache(key)
  File "/usr/local/lib/python2.7/dist-packages/pandas/core/generic.py", line 1350, in _get_item_cache
    values = self._data.get(item)
  File "/usr/local/lib/python2.7/dist-packages/pandas/core/internals.py", line 3290, in get
    loc = self.items.get_loc(item)
  File "/usr/local/lib/python2.7/dist-packages/pandas/indexes/base.py", line 1947, in get_loc
    return self._engine.get_loc(self._maybe_cast_indexer(key))
  File "pandas/index.pyx", line 137, in pandas.index.IndexEngine.get_loc (pandas/index.c:4154)
  File "pandas/index.pyx", line 159, in pandas.index.IndexEngine.get_loc (pandas/index.c:4018)
  File "pandas/hashtable.pyx", line 675, in pandas.hashtable.PyObjectHashTable.get_item (pandas/hashtable.c:12368)
  File "pandas/hashtable.pyx", line 683, in pandas.hashtable.PyObjectHashTable.get_item (pandas/hashtable.c:12322)
KeyError: 'CDLLADDERBOTTO'
2019-02-23 15:06:39,439 - default - ERROR - Exception occurred
Traceback (most recent call last):
  File "Trading/Dataset/DatasetHolder.py", line 259, in appendTimeframesIntoOneDataset
    ds_h.f_df[cdl] = np.convolve(ds_h.f_df[cdl], fn)[0:len(ds_h.f_df)]
  File "/usr/local/lib/python2.7/dist-packages/pandas/core/frame.py", line 1997, in __getitem__
    return self._getitem_column(key)
  File "/usr/local/lib/python2.7/dist-packages/pandas/core/frame.py", line 2009, in _getitem_column
    result = result[key]
  File "/usr/local/lib/python2.7/dist-packages/pandas/core/frame.py", line 1997, in __getitem__
    return self._getitem_column(key)
  File "/usr/local/lib/python2.7/dist-packages/pandas/core/frame.py", line 2004, in _getitem_column
    return self._get_item_cache(key)
  File "/usr/local/lib/python2.7/dist-packages/pandas/core/generic.py", line 1350, in _get_item_cache
    values = self._data.get(item)
  File "/usr/local/lib/python2.7/dist-packages/pandas/core/internals.py", line 3290, in get
    loc = self.items.get_loc(item)
  File "/usr/local/lib/python2.7/dist-packages/pandas/indexes/base.py", line 1947, in get_loc
    return self._engine.get_loc(self._maybe_cast_indexer(key))
  File "pandas/index.pyx", line 137, in pandas.index.IndexEngine.get_loc (pandas/index.c:4154)
  File "pandas/index.pyx", line 159, in pandas.index.IndexEngine.get_loc (pandas/index.c:4018)
  File "pandas/hashtable.pyx", line 675, in pandas.hashtable.PyObjectHashTable.get_item (pandas/hashtable.c:12368)
  File "pandas/hashtable.pyx", line 683, in pandas.hashtable.PyObjectHashTable.get_item (pandas/hashtable.c:12322)
KeyError: 'CDLLONGLEGGEDDOJ'
2019-02-23 15:06:39,443 - default - ERROR - Exception occurred
Traceback (most recent call last):
  File "Trading/Dataset/DatasetHolder.py", line 259, in appendTimeframesIntoOneDataset
    ds_h.f_df[cdl] = np.convolve(ds_h.f_df[cdl], fn)[0:len(ds_h.f_df)]
  File "/usr/local/lib/python2.7/dist-packages/pandas/core/frame.py", line 1997, in __getitem__
    return self._getitem_column(key)
  File "/usr/local/lib/python2.7/dist-packages/pandas/core/frame.py", line 2009, in _getitem_column
    result = result[key]
  File "/usr/local/lib/python2.7/dist-packages/pandas/core/frame.py", line 1997, in __getitem__
    return self._getitem_column(key)
  File "/usr/local/lib/python2.7/dist-packages/pandas/core/frame.py", line 2004, in _getitem_column
    return self._get_item_cache(key)
  File "/usr/local/lib/python2.7/dist-packages/pandas/core/generic.py", line 1350, in _get_item_cache
    values = self._data.get(item)
  File "/usr/local/lib/python2.7/dist-packages/pandas/core/internals.py", line 3290, in get
    loc = self.items.get_loc(item)
  File "/usr/local/lib/python2.7/dist-packages/pandas/indexes/base.py", line 1947, in get_loc
    return self._engine.get_loc(self._maybe_cast_indexer(key))
  File "pandas/index.pyx", line 137, in pandas.index.IndexEngine.get_loc (pandas/index.c:4154)
  File "pandas/index.pyx", line 159, in pandas.index.IndexEngine.get_loc (pandas/index.c:4018)
  File "pandas/hashtable.pyx", line 675, in pandas.hashtable.PyObjectHashTable.get_item (pandas/hashtable.c:12368)
  File "pandas/hashtable.pyx", line 683, in pandas.hashtable.PyObjectHashTable.get_item (pandas/hashtable.c:12322)
KeyError: 'CDLLONGLIN'
2019-02-23 15:06:39,446 - default - ERROR - Exception occurred
Traceback (most recent call last):
  File "Trading/Dataset/DatasetHolder.py", line 259, in appendTimeframesIntoOneDataset
    ds_h.f_df[cdl] = np.convolve(ds_h.f_df[cdl], fn)[0:len(ds_h.f_df)]
  File "/usr/local/lib/python2.7/dist-packages/pandas/core/frame.py", line 1997, in __getitem__
    return self._getitem_column(key)
  File "/usr/local/lib/python2.7/dist-packages/pandas/core/frame.py", line 2009, in _getitem_column
    result = result[key]
  File "/usr/local/lib/python2.7/dist-packages/pandas/core/frame.py", line 1997, in __getitem__
    return self._getitem_column(key)
  File "/usr/local/lib/python2.7/dist-packages/pandas/core/frame.py", line 2004, in _getitem_column
    return self._get_item_cache(key)
  File "/usr/local/lib/python2.7/dist-packages/pandas/core/generic.py", line 1350, in _get_item_cache
    values = self._data.get(item)
  File "/usr/local/lib/python2.7/dist-packages/pandas/core/internals.py", line 3290, in get
    loc = self.items.get_loc(item)
  File "/usr/local/lib/python2.7/dist-packages/pandas/indexes/base.py", line 1947, in get_loc
    return self._engine.get_loc(self._maybe_cast_indexer(key))
  File "pandas/index.pyx", line 137, in pandas.index.IndexEngine.get_loc (pandas/index.c:4154)
  File "pandas/index.pyx", line 159, in pandas.index.IndexEngine.get_loc (pandas/index.c:4018)
  File "pandas/hashtable.pyx", line 675, in pandas.hashtable.PyObjectHashTable.get_item (pandas/hashtable.c:12368)
  File "pandas/hashtable.pyx", line 683, in pandas.hashtable.PyObjectHashTable.get_item (pandas/hashtable.c:12322)
KeyError: 'CDLMARUBOZ'
2019-02-23 15:06:39,450 - default - ERROR - Exception occurred
Traceback (most recent call last):
  File "Trading/Dataset/DatasetHolder.py", line 259, in appendTimeframesIntoOneDataset
    ds_h.f_df[cdl] = np.convolve(ds_h.f_df[cdl], fn)[0:len(ds_h.f_df)]
  File "/usr/local/lib/python2.7/dist-packages/pandas/core/frame.py", line 1997, in __getitem__
    return self._getitem_column(key)
  File "/usr/local/lib/python2.7/dist-packages/pandas/core/frame.py", line 2009, in _getitem_column
    result = result[key]
  File "/usr/local/lib/python2.7/dist-packages/pandas/core/frame.py", line 1997, in __getitem__
    return self._getitem_column(key)
  File "/usr/local/lib/python2.7/dist-packages/pandas/core/frame.py", line 2004, in _getitem_column
    return self._get_item_cache(key)
  File "/usr/local/lib/python2.7/dist-packages/pandas/core/generic.py", line 1350, in _get_item_cache
    values = self._data.get(item)
  File "/usr/local/lib/python2.7/dist-packages/pandas/core/internals.py", line 3290, in get
    loc = self.items.get_loc(item)
  File "/usr/local/lib/python2.7/dist-packages/pandas/indexes/base.py", line 1947, in get_loc
    return self._engine.get_loc(self._maybe_cast_indexer(key))
  File "pandas/index.pyx", line 137, in pandas.index.IndexEngine.get_loc (pandas/index.c:4154)
  File "pandas/index.pyx", line 159, in pandas.index.IndexEngine.get_loc (pandas/index.c:4018)
  File "pandas/hashtable.pyx", line 675, in pandas.hashtable.PyObjectHashTable.get_item (pandas/hashtable.c:12368)
  File "pandas/hashtable.pyx", line 683, in pandas.hashtable.PyObjectHashTable.get_item (pandas/hashtable.c:12322)
KeyError: 'CDLMATCHINGLO'
2019-02-23 15:06:39,454 - default - ERROR - Exception occurred
Traceback (most recent call last):
  File "Trading/Dataset/DatasetHolder.py", line 259, in appendTimeframesIntoOneDataset
    ds_h.f_df[cdl] = np.convolve(ds_h.f_df[cdl], fn)[0:len(ds_h.f_df)]
  File "/usr/local/lib/python2.7/dist-packages/pandas/core/frame.py", line 1997, in __getitem__
    return self._getitem_column(key)
  File "/usr/local/lib/python2.7/dist-packages/pandas/core/frame.py", line 2009, in _getitem_column
    result = result[key]
  File "/usr/local/lib/python2.7/dist-packages/pandas/core/frame.py", line 1997, in __getitem__
    return self._getitem_column(key)
  File "/usr/local/lib/python2.7/dist-packages/pandas/core/frame.py", line 2004, in _getitem_column
    return self._get_item_cache(key)
  File "/usr/local/lib/python2.7/dist-packages/pandas/core/generic.py", line 1350, in _get_item_cache
    values = self._data.get(item)
  File "/usr/local/lib/python2.7/dist-packages/pandas/core/internals.py", line 3290, in get
    loc = self.items.get_loc(item)
  File "/usr/local/lib/python2.7/dist-packages/pandas/indexes/base.py", line 1947, in get_loc
    return self._engine.get_loc(self._maybe_cast_indexer(key))
  File "pandas/index.pyx", line 137, in pandas.index.IndexEngine.get_loc (pandas/index.c:4154)
  File "pandas/index.pyx", line 159, in pandas.index.IndexEngine.get_loc (pandas/index.c:4018)
  File "pandas/hashtable.pyx", line 675, in pandas.hashtable.PyObjectHashTable.get_item (pandas/hashtable.c:12368)
  File "pandas/hashtable.pyx", line 683, in pandas.hashtable.PyObjectHashTable.get_item (pandas/hashtable.c:12322)
KeyError: 'CDLMATHOL'
2019-02-23 15:06:39,457 - default - ERROR - Exception occurred
Traceback (most recent call last):
  File "Trading/Dataset/DatasetHolder.py", line 259, in appendTimeframesIntoOneDataset
    ds_h.f_df[cdl] = np.convolve(ds_h.f_df[cdl], fn)[0:len(ds_h.f_df)]
  File "/usr/local/lib/python2.7/dist-packages/pandas/core/frame.py", line 1997, in __getitem__
    return self._getitem_column(key)
  File "/usr/local/lib/python2.7/dist-packages/pandas/core/frame.py", line 2009, in _getitem_column
    result = result[key]
  File "/usr/local/lib/python2.7/dist-packages/pandas/core/frame.py", line 1997, in __getitem__
    return self._getitem_column(key)
  File "/usr/local/lib/python2.7/dist-packages/pandas/core/frame.py", line 2004, in _getitem_column
    return self._get_item_cache(key)
  File "/usr/local/lib/python2.7/dist-packages/pandas/core/generic.py", line 1350, in _get_item_cache
    values = self._data.get(item)
  File "/usr/local/lib/python2.7/dist-packages/pandas/core/internals.py", line 3290, in get
    loc = self.items.get_loc(item)
  File "/usr/local/lib/python2.7/dist-packages/pandas/indexes/base.py", line 1947, in get_loc
    return self._engine.get_loc(self._maybe_cast_indexer(key))
  File "pandas/index.pyx", line 137, in pandas.index.IndexEngine.get_loc (pandas/index.c:4154)
  File "pandas/index.pyx", line 159, in pandas.index.IndexEngine.get_loc (pandas/index.c:4018)
  File "pandas/hashtable.pyx", line 675, in pandas.hashtable.PyObjectHashTable.get_item (pandas/hashtable.c:12368)
  File "pandas/hashtable.pyx", line 683, in pandas.hashtable.PyObjectHashTable.get_item (pandas/hashtable.c:12322)
KeyError: 'CDLMORNINGDOJISTA'
2019-02-23 15:06:39,462 - default - ERROR - Exception occurred
Traceback (most recent call last):
  File "Trading/Dataset/DatasetHolder.py", line 259, in appendTimeframesIntoOneDataset
    ds_h.f_df[cdl] = np.convolve(ds_h.f_df[cdl], fn)[0:len(ds_h.f_df)]
  File "/usr/local/lib/python2.7/dist-packages/pandas/core/frame.py", line 1997, in __getitem__
    return self._getitem_column(key)
  File "/usr/local/lib/python2.7/dist-packages/pandas/core/frame.py", line 2009, in _getitem_column
    result = result[key]
  File "/usr/local/lib/python2.7/dist-packages/pandas/core/frame.py", line 1997, in __getitem__
    return self._getitem_column(key)
  File "/usr/local/lib/python2.7/dist-packages/pandas/core/frame.py", line 2004, in _getitem_column
    return self._get_item_cache(key)
  File "/usr/local/lib/python2.7/dist-packages/pandas/core/generic.py", line 1350, in _get_item_cache
    values = self._data.get(item)
  File "/usr/local/lib/python2.7/dist-packages/pandas/core/internals.py", line 3290, in get
    loc = self.items.get_loc(item)
  File "/usr/local/lib/python2.7/dist-packages/pandas/indexes/base.py", line 1947, in get_loc
    return self._engine.get_loc(self._maybe_cast_indexer(key))
  File "pandas/index.pyx", line 137, in pandas.index.IndexEngine.get_loc (pandas/index.c:4154)
  File "pandas/index.pyx", line 159, in pandas.index.IndexEngine.get_loc (pandas/index.c:4018)
  File "pandas/hashtable.pyx", line 675, in pandas.hashtable.PyObjectHashTable.get_item (pandas/hashtable.c:12368)
  File "pandas/hashtable.pyx", line 683, in pandas.hashtable.PyObjectHashTable.get_item (pandas/hashtable.c:12322)
KeyError: 'CDLMORNINGSTA'
2019-02-23 15:06:39,466 - default - ERROR - Exception occurred
Traceback (most recent call last):
  File "Trading/Dataset/DatasetHolder.py", line 259, in appendTimeframesIntoOneDataset
    ds_h.f_df[cdl] = np.convolve(ds_h.f_df[cdl], fn)[0:len(ds_h.f_df)]
  File "/usr/local/lib/python2.7/dist-packages/pandas/core/frame.py", line 1997, in __getitem__
    return self._getitem_column(key)
  File "/usr/local/lib/python2.7/dist-packages/pandas/core/frame.py", line 2009, in _getitem_column
    result = result[key]
  File "/usr/local/lib/python2.7/dist-packages/pandas/core/frame.py", line 1997, in __getitem__
    return self._getitem_column(key)
  File "/usr/local/lib/python2.7/dist-packages/pandas/core/frame.py", line 2004, in _getitem_column
    return self._get_item_cache(key)
  File "/usr/local/lib/python2.7/dist-packages/pandas/core/generic.py", line 1350, in _get_item_cache
    values = self._data.get(item)
  File "/usr/local/lib/python2.7/dist-packages/pandas/core/internals.py", line 3290, in get
    loc = self.items.get_loc(item)
  File "/usr/local/lib/python2.7/dist-packages/pandas/indexes/base.py", line 1947, in get_loc
    return self._engine.get_loc(self._maybe_cast_indexer(key))
  File "pandas/index.pyx", line 137, in pandas.index.IndexEngine.get_loc (pandas/index.c:4154)
  File "pandas/index.pyx", line 159, in pandas.index.IndexEngine.get_loc (pandas/index.c:4018)
  File "pandas/hashtable.pyx", line 675, in pandas.hashtable.PyObjectHashTable.get_item (pandas/hashtable.c:12368)
  File "pandas/hashtable.pyx", line 683, in pandas.hashtable.PyObjectHashTable.get_item (pandas/hashtable.c:12322)
KeyError: 'CDLONNEC'
2019-02-23 15:06:39,470 - default - ERROR - Exception occurred
Traceback (most recent call last):
  File "Trading/Dataset/DatasetHolder.py", line 259, in appendTimeframesIntoOneDataset
    ds_h.f_df[cdl] = np.convolve(ds_h.f_df[cdl], fn)[0:len(ds_h.f_df)]
  File "/usr/local/lib/python2.7/dist-packages/pandas/core/frame.py", line 1997, in __getitem__
    return self._getitem_column(key)
  File "/usr/local/lib/python2.7/dist-packages/pandas/core/frame.py", line 2009, in _getitem_column
    result = result[key]
  File "/usr/local/lib/python2.7/dist-packages/pandas/core/frame.py", line 1997, in __getitem__
    return self._getitem_column(key)
  File "/usr/local/lib/python2.7/dist-packages/pandas/core/frame.py", line 2004, in _getitem_column
    return self._get_item_cache(key)
  File "/usr/local/lib/python2.7/dist-packages/pandas/core/generic.py", line 1350, in _get_item_cache
    values = self._data.get(item)
  File "/usr/local/lib/python2.7/dist-packages/pandas/core/internals.py", line 3290, in get
    loc = self.items.get_loc(item)
  File "/usr/local/lib/python2.7/dist-packages/pandas/indexes/base.py", line 1947, in get_loc
    return self._engine.get_loc(self._maybe_cast_indexer(key))
  File "pandas/index.pyx", line 137, in pandas.index.IndexEngine.get_loc (pandas/index.c:4154)
  File "pandas/index.pyx", line 159, in pandas.index.IndexEngine.get_loc (pandas/index.c:4018)
  File "pandas/hashtable.pyx", line 675, in pandas.hashtable.PyObjectHashTable.get_item (pandas/hashtable.c:12368)
  File "pandas/hashtable.pyx", line 683, in pandas.hashtable.PyObjectHashTable.get_item (pandas/hashtable.c:12322)
KeyError: 'CDLPIERCIN'
2019-02-23 15:06:39,474 - default - ERROR - Exception occurred
Traceback (most recent call last):
  File "Trading/Dataset/DatasetHolder.py", line 259, in appendTimeframesIntoOneDataset
    ds_h.f_df[cdl] = np.convolve(ds_h.f_df[cdl], fn)[0:len(ds_h.f_df)]
  File "/usr/local/lib/python2.7/dist-packages/pandas/core/frame.py", line 1997, in __getitem__
    return self._getitem_column(key)
  File "/usr/local/lib/python2.7/dist-packages/pandas/core/frame.py", line 2009, in _getitem_column
    result = result[key]
  File "/usr/local/lib/python2.7/dist-packages/pandas/core/frame.py", line 1997, in __getitem__
    return self._getitem_column(key)
  File "/usr/local/lib/python2.7/dist-packages/pandas/core/frame.py", line 2004, in _getitem_column
    return self._get_item_cache(key)
  File "/usr/local/lib/python2.7/dist-packages/pandas/core/generic.py", line 1350, in _get_item_cache
    values = self._data.get(item)
  File "/usr/local/lib/python2.7/dist-packages/pandas/core/internals.py", line 3290, in get
    loc = self.items.get_loc(item)
  File "/usr/local/lib/python2.7/dist-packages/pandas/indexes/base.py", line 1947, in get_loc
    return self._engine.get_loc(self._maybe_cast_indexer(key))
  File "pandas/index.pyx", line 137, in pandas.index.IndexEngine.get_loc (pandas/index.c:4154)
  File "pandas/index.pyx", line 159, in pandas.index.IndexEngine.get_loc (pandas/index.c:4018)
  File "pandas/hashtable.pyx", line 675, in pandas.hashtable.PyObjectHashTable.get_item (pandas/hashtable.c:12368)
  File "pandas/hashtable.pyx", line 683, in pandas.hashtable.PyObjectHashTable.get_item (pandas/hashtable.c:12322)
KeyError: 'CDLRICKSHAWMA'
2019-02-23 15:06:39,478 - default - ERROR - Exception occurred
Traceback (most recent call last):
  File "Trading/Dataset/DatasetHolder.py", line 259, in appendTimeframesIntoOneDataset
    ds_h.f_df[cdl] = np.convolve(ds_h.f_df[cdl], fn)[0:len(ds_h.f_df)]
  File "/usr/local/lib/python2.7/dist-packages/pandas/core/frame.py", line 1997, in __getitem__
    return self._getitem_column(key)
  File "/usr/local/lib/python2.7/dist-packages/pandas/core/frame.py", line 2009, in _getitem_column
    result = result[key]
  File "/usr/local/lib/python2.7/dist-packages/pandas/core/frame.py", line 1997, in __getitem__
    return self._getitem_column(key)
  File "/usr/local/lib/python2.7/dist-packages/pandas/core/frame.py", line 2004, in _getitem_column
    return self._get_item_cache(key)
  File "/usr/local/lib/python2.7/dist-packages/pandas/core/generic.py", line 1350, in _get_item_cache
    values = self._data.get(item)
  File "/usr/local/lib/python2.7/dist-packages/pandas/core/internals.py", line 3290, in get
    loc = self.items.get_loc(item)
  File "/usr/local/lib/python2.7/dist-packages/pandas/indexes/base.py", line 1947, in get_loc
    return self._engine.get_loc(self._maybe_cast_indexer(key))
  File "pandas/index.pyx", line 137, in pandas.index.IndexEngine.get_loc (pandas/index.c:4154)
  File "pandas/index.pyx", line 159, in pandas.index.IndexEngine.get_loc (pandas/index.c:4018)
  File "pandas/hashtable.pyx", line 675, in pandas.hashtable.PyObjectHashTable.get_item (pandas/hashtable.c:12368)
  File "pandas/hashtable.pyx", line 683, in pandas.hashtable.PyObjectHashTable.get_item (pandas/hashtable.c:12322)
KeyError: 'CDLRISEFALL3METHOD'
2019-02-23 15:06:39,486 - default - ERROR - Exception occurred
Traceback (most recent call last):
  File "Trading/Dataset/DatasetHolder.py", line 259, in appendTimeframesIntoOneDataset
    ds_h.f_df[cdl] = np.convolve(ds_h.f_df[cdl], fn)[0:len(ds_h.f_df)]
  File "/usr/local/lib/python2.7/dist-packages/pandas/core/frame.py", line 1997, in __getitem__
    return self._getitem_column(key)
  File "/usr/local/lib/python2.7/dist-packages/pandas/core/frame.py", line 2009, in _getitem_column
    result = result[key]
  File "/usr/local/lib/python2.7/dist-packages/pandas/core/frame.py", line 1997, in __getitem__
    return self._getitem_column(key)
  File "/usr/local/lib/python2.7/dist-packages/pandas/core/frame.py", line 2004, in _getitem_column
    return self._get_item_cache(key)
  File "/usr/local/lib/python2.7/dist-packages/pandas/core/generic.py", line 1350, in _get_item_cache
    values = self._data.get(item)
  File "/usr/local/lib/python2.7/dist-packages/pandas/core/internals.py", line 3290, in get
    loc = self.items.get_loc(item)
  File "/usr/local/lib/python2.7/dist-packages/pandas/indexes/base.py", line 1947, in get_loc
    return self._engine.get_loc(self._maybe_cast_indexer(key))
  File "pandas/index.pyx", line 137, in pandas.index.IndexEngine.get_loc (pandas/index.c:4154)
  File "pandas/index.pyx", line 159, in pandas.index.IndexEngine.get_loc (pandas/index.c:4018)
  File "pandas/hashtable.pyx", line 675, in pandas.hashtable.PyObjectHashTable.get_item (pandas/hashtable.c:12368)
  File "pandas/hashtable.pyx", line 683, in pandas.hashtable.PyObjectHashTable.get_item (pandas/hashtable.c:12322)
KeyError: 'CDLSEPARATINGLINE'
2019-02-23 15:06:39,490 - default - ERROR - Exception occurred
Traceback (most recent call last):
  File "Trading/Dataset/DatasetHolder.py", line 259, in appendTimeframesIntoOneDataset
    ds_h.f_df[cdl] = np.convolve(ds_h.f_df[cdl], fn)[0:len(ds_h.f_df)]
  File "/usr/local/lib/python2.7/dist-packages/pandas/core/frame.py", line 1997, in __getitem__
    return self._getitem_column(key)
  File "/usr/local/lib/python2.7/dist-packages/pandas/core/frame.py", line 2009, in _getitem_column
    result = result[key]
  File "/usr/local/lib/python2.7/dist-packages/pandas/core/frame.py", line 1997, in __getitem__
    return self._getitem_column(key)
  File "/usr/local/lib/python2.7/dist-packages/pandas/core/frame.py", line 2004, in _getitem_column
    return self._get_item_cache(key)
  File "/usr/local/lib/python2.7/dist-packages/pandas/core/generic.py", line 1350, in _get_item_cache
    values = self._data.get(item)
  File "/usr/local/lib/python2.7/dist-packages/pandas/core/internals.py", line 3290, in get
    loc = self.items.get_loc(item)
  File "/usr/local/lib/python2.7/dist-packages/pandas/indexes/base.py", line 1947, in get_loc
    return self._engine.get_loc(self._maybe_cast_indexer(key))
  File "pandas/index.pyx", line 137, in pandas.index.IndexEngine.get_loc (pandas/index.c:4154)
  File "pandas/index.pyx", line 159, in pandas.index.IndexEngine.get_loc (pandas/index.c:4018)
  File "pandas/hashtable.pyx", line 675, in pandas.hashtable.PyObjectHashTable.get_item (pandas/hashtable.c:12368)
  File "pandas/hashtable.pyx", line 683, in pandas.hashtable.PyObjectHashTable.get_item (pandas/hashtable.c:12322)
KeyError: 'CDLSHOOTINGSTA'
2019-02-23 15:06:39,493 - default - ERROR - Exception occurred
Traceback (most recent call last):
  File "Trading/Dataset/DatasetHolder.py", line 259, in appendTimeframesIntoOneDataset
    ds_h.f_df[cdl] = np.convolve(ds_h.f_df[cdl], fn)[0:len(ds_h.f_df)]
  File "/usr/local/lib/python2.7/dist-packages/pandas/core/frame.py", line 1997, in __getitem__
    return self._getitem_column(key)
  File "/usr/local/lib/python2.7/dist-packages/pandas/core/frame.py", line 2009, in _getitem_column
    result = result[key]
  File "/usr/local/lib/python2.7/dist-packages/pandas/core/frame.py", line 1997, in __getitem__
    return self._getitem_column(key)
  File "/usr/local/lib/python2.7/dist-packages/pandas/core/frame.py", line 2004, in _getitem_column
    return self._get_item_cache(key)
  File "/usr/local/lib/python2.7/dist-packages/pandas/core/generic.py", line 1350, in _get_item_cache
    values = self._data.get(item)
  File "/usr/local/lib/python2.7/dist-packages/pandas/core/internals.py", line 3290, in get
    loc = self.items.get_loc(item)
  File "/usr/local/lib/python2.7/dist-packages/pandas/indexes/base.py", line 1947, in get_loc
    return self._engine.get_loc(self._maybe_cast_indexer(key))
  File "pandas/index.pyx", line 137, in pandas.index.IndexEngine.get_loc (pandas/index.c:4154)
  File "pandas/index.pyx", line 159, in pandas.index.IndexEngine.get_loc (pandas/index.c:4018)
  File "pandas/hashtable.pyx", line 675, in pandas.hashtable.PyObjectHashTable.get_item (pandas/hashtable.c:12368)
  File "pandas/hashtable.pyx", line 683, in pandas.hashtable.PyObjectHashTable.get_item (pandas/hashtable.c:12322)
KeyError: 'CDLSHORTLIN'
2019-02-23 15:06:39,497 - default - ERROR - Exception occurred
Traceback (most recent call last):
  File "Trading/Dataset/DatasetHolder.py", line 259, in appendTimeframesIntoOneDataset
    ds_h.f_df[cdl] = np.convolve(ds_h.f_df[cdl], fn)[0:len(ds_h.f_df)]
  File "/usr/local/lib/python2.7/dist-packages/pandas/core/frame.py", line 1997, in __getitem__
    return self._getitem_column(key)
  File "/usr/local/lib/python2.7/dist-packages/pandas/core/frame.py", line 2009, in _getitem_column
    result = result[key]
  File "/usr/local/lib/python2.7/dist-packages/pandas/core/frame.py", line 1997, in __getitem__
    return self._getitem_column(key)
  File "/usr/local/lib/python2.7/dist-packages/pandas/core/frame.py", line 2004, in _getitem_column
    return self._get_item_cache(key)
  File "/usr/local/lib/python2.7/dist-packages/pandas/core/generic.py", line 1350, in _get_item_cache
    values = self._data.get(item)
  File "/usr/local/lib/python2.7/dist-packages/pandas/core/internals.py", line 3290, in get
    loc = self.items.get_loc(item)
  File "/usr/local/lib/python2.7/dist-packages/pandas/indexes/base.py", line 1947, in get_loc
    return self._engine.get_loc(self._maybe_cast_indexer(key))
  File "pandas/index.pyx", line 137, in pandas.index.IndexEngine.get_loc (pandas/index.c:4154)
  File "pandas/index.pyx", line 159, in pandas.index.IndexEngine.get_loc (pandas/index.c:4018)
  File "pandas/hashtable.pyx", line 675, in pandas.hashtable.PyObjectHashTable.get_item (pandas/hashtable.c:12368)
  File "pandas/hashtable.pyx", line 683, in pandas.hashtable.PyObjectHashTable.get_item (pandas/hashtable.c:12322)
KeyError: 'CDLSPINNINGTO'
2019-02-23 15:06:39,502 - default - ERROR - Exception occurred
Traceback (most recent call last):
  File "Trading/Dataset/DatasetHolder.py", line 259, in appendTimeframesIntoOneDataset
    ds_h.f_df[cdl] = np.convolve(ds_h.f_df[cdl], fn)[0:len(ds_h.f_df)]
  File "/usr/local/lib/python2.7/dist-packages/pandas/core/frame.py", line 1997, in __getitem__
    return self._getitem_column(key)
  File "/usr/local/lib/python2.7/dist-packages/pandas/core/frame.py", line 2009, in _getitem_column
    result = result[key]
  File "/usr/local/lib/python2.7/dist-packages/pandas/core/frame.py", line 1997, in __getitem__
    return self._getitem_column(key)
  File "/usr/local/lib/python2.7/dist-packages/pandas/core/frame.py", line 2004, in _getitem_column
    return self._get_item_cache(key)
  File "/usr/local/lib/python2.7/dist-packages/pandas/core/generic.py", line 1350, in _get_item_cache
    values = self._data.get(item)
  File "/usr/local/lib/python2.7/dist-packages/pandas/core/internals.py", line 3290, in get
    loc = self.items.get_loc(item)
  File "/usr/local/lib/python2.7/dist-packages/pandas/indexes/base.py", line 1947, in get_loc
    return self._engine.get_loc(self._maybe_cast_indexer(key))
  File "pandas/index.pyx", line 137, in pandas.index.IndexEngine.get_loc (pandas/index.c:4154)
  File "pandas/index.pyx", line 159, in pandas.index.IndexEngine.get_loc (pandas/index.c:4018)
  File "pandas/hashtable.pyx", line 675, in pandas.hashtable.PyObjectHashTable.get_item (pandas/hashtable.c:12368)
  File "pandas/hashtable.pyx", line 683, in pandas.hashtable.PyObjectHashTable.get_item (pandas/hashtable.c:12322)
KeyError: 'CDLSTALLEDPATTER'
2019-02-23 15:06:39,506 - default - ERROR - Exception occurred
Traceback (most recent call last):
  File "Trading/Dataset/DatasetHolder.py", line 259, in appendTimeframesIntoOneDataset
    ds_h.f_df[cdl] = np.convolve(ds_h.f_df[cdl], fn)[0:len(ds_h.f_df)]
  File "/usr/local/lib/python2.7/dist-packages/pandas/core/frame.py", line 1997, in __getitem__
    return self._getitem_column(key)
  File "/usr/local/lib/python2.7/dist-packages/pandas/core/frame.py", line 2009, in _getitem_column
    result = result[key]
  File "/usr/local/lib/python2.7/dist-packages/pandas/core/frame.py", line 1997, in __getitem__
    return self._getitem_column(key)
  File "/usr/local/lib/python2.7/dist-packages/pandas/core/frame.py", line 2004, in _getitem_column
    return self._get_item_cache(key)
  File "/usr/local/lib/python2.7/dist-packages/pandas/core/generic.py", line 1350, in _get_item_cache
    values = self._data.get(item)
  File "/usr/local/lib/python2.7/dist-packages/pandas/core/internals.py", line 3290, in get
    loc = self.items.get_loc(item)
  File "/usr/local/lib/python2.7/dist-packages/pandas/indexes/base.py", line 1947, in get_loc
    return self._engine.get_loc(self._maybe_cast_indexer(key))
  File "pandas/index.pyx", line 137, in pandas.index.IndexEngine.get_loc (pandas/index.c:4154)
  File "pandas/index.pyx", line 159, in pandas.index.IndexEngine.get_loc (pandas/index.c:4018)
  File "pandas/hashtable.pyx", line 675, in pandas.hashtable.PyObjectHashTable.get_item (pandas/hashtable.c:12368)
  File "pandas/hashtable.pyx", line 683, in pandas.hashtable.PyObjectHashTable.get_item (pandas/hashtable.c:12322)
KeyError: 'CDLSTICKSANDWIC'
2019-02-23 15:06:39,511 - default - ERROR - Exception occurred
Traceback (most recent call last):
  File "Trading/Dataset/DatasetHolder.py", line 259, in appendTimeframesIntoOneDataset
    ds_h.f_df[cdl] = np.convolve(ds_h.f_df[cdl], fn)[0:len(ds_h.f_df)]
  File "/usr/local/lib/python2.7/dist-packages/pandas/core/frame.py", line 1997, in __getitem__
    return self._getitem_column(key)
  File "/usr/local/lib/python2.7/dist-packages/pandas/core/frame.py", line 2009, in _getitem_column
    result = result[key]
  File "/usr/local/lib/python2.7/dist-packages/pandas/core/frame.py", line 1997, in __getitem__
    return self._getitem_column(key)
  File "/usr/local/lib/python2.7/dist-packages/pandas/core/frame.py", line 2004, in _getitem_column
    return self._get_item_cache(key)
  File "/usr/local/lib/python2.7/dist-packages/pandas/core/generic.py", line 1350, in _get_item_cache
    values = self._data.get(item)
  File "/usr/local/lib/python2.7/dist-packages/pandas/core/internals.py", line 3290, in get
    loc = self.items.get_loc(item)
  File "/usr/local/lib/python2.7/dist-packages/pandas/indexes/base.py", line 1947, in get_loc
    return self._engine.get_loc(self._maybe_cast_indexer(key))
  File "pandas/index.pyx", line 137, in pandas.index.IndexEngine.get_loc (pandas/index.c:4154)
  File "pandas/index.pyx", line 159, in pandas.index.IndexEngine.get_loc (pandas/index.c:4018)
  File "pandas/hashtable.pyx", line 675, in pandas.hashtable.PyObjectHashTable.get_item (pandas/hashtable.c:12368)
  File "pandas/hashtable.pyx", line 683, in pandas.hashtable.PyObjectHashTable.get_item (pandas/hashtable.c:12322)
KeyError: 'CDLTAKUR'
2019-02-23 15:06:39,515 - default - ERROR - Exception occurred
Traceback (most recent call last):
  File "Trading/Dataset/DatasetHolder.py", line 259, in appendTimeframesIntoOneDataset
    ds_h.f_df[cdl] = np.convolve(ds_h.f_df[cdl], fn)[0:len(ds_h.f_df)]
  File "/usr/local/lib/python2.7/dist-packages/pandas/core/frame.py", line 1997, in __getitem__
    return self._getitem_column(key)
  File "/usr/local/lib/python2.7/dist-packages/pandas/core/frame.py", line 2009, in _getitem_column
    result = result[key]
  File "/usr/local/lib/python2.7/dist-packages/pandas/core/frame.py", line 1997, in __getitem__
    return self._getitem_column(key)
  File "/usr/local/lib/python2.7/dist-packages/pandas/core/frame.py", line 2004, in _getitem_column
    return self._get_item_cache(key)
  File "/usr/local/lib/python2.7/dist-packages/pandas/core/generic.py", line 1350, in _get_item_cache
    values = self._data.get(item)
  File "/usr/local/lib/python2.7/dist-packages/pandas/core/internals.py", line 3290, in get
    loc = self.items.get_loc(item)
  File "/usr/local/lib/python2.7/dist-packages/pandas/indexes/base.py", line 1947, in get_loc
    return self._engine.get_loc(self._maybe_cast_indexer(key))
  File "pandas/index.pyx", line 137, in pandas.index.IndexEngine.get_loc (pandas/index.c:4154)
  File "pandas/index.pyx", line 159, in pandas.index.IndexEngine.get_loc (pandas/index.c:4018)
  File "pandas/hashtable.pyx", line 675, in pandas.hashtable.PyObjectHashTable.get_item (pandas/hashtable.c:12368)
  File "pandas/hashtable.pyx", line 683, in pandas.hashtable.PyObjectHashTable.get_item (pandas/hashtable.c:12322)
KeyError: 'CDLTASUKIGA'
2019-02-23 15:06:39,519 - default - ERROR - Exception occurred
Traceback (most recent call last):
  File "Trading/Dataset/DatasetHolder.py", line 259, in appendTimeframesIntoOneDataset
    ds_h.f_df[cdl] = np.convolve(ds_h.f_df[cdl], fn)[0:len(ds_h.f_df)]
  File "/usr/local/lib/python2.7/dist-packages/pandas/core/frame.py", line 1997, in __getitem__
    return self._getitem_column(key)
  File "/usr/local/lib/python2.7/dist-packages/pandas/core/frame.py", line 2009, in _getitem_column
    result = result[key]
  File "/usr/local/lib/python2.7/dist-packages/pandas/core/frame.py", line 1997, in __getitem__
    return self._getitem_column(key)
  File "/usr/local/lib/python2.7/dist-packages/pandas/core/frame.py", line 2004, in _getitem_column
    return self._get_item_cache(key)
  File "/usr/local/lib/python2.7/dist-packages/pandas/core/generic.py", line 1350, in _get_item_cache
    values = self._data.get(item)
  File "/usr/local/lib/python2.7/dist-packages/pandas/core/internals.py", line 3290, in get
    loc = self.items.get_loc(item)
  File "/usr/local/lib/python2.7/dist-packages/pandas/indexes/base.py", line 1947, in get_loc
    return self._engine.get_loc(self._maybe_cast_indexer(key))
  File "pandas/index.pyx", line 137, in pandas.index.IndexEngine.get_loc (pandas/index.c:4154)
  File "pandas/index.pyx", line 159, in pandas.index.IndexEngine.get_loc (pandas/index.c:4018)
  File "pandas/hashtable.pyx", line 675, in pandas.hashtable.PyObjectHashTable.get_item (pandas/hashtable.c:12368)
  File "pandas/hashtable.pyx", line 683, in pandas.hashtable.PyObjectHashTable.get_item (pandas/hashtable.c:12322)
KeyError: 'CDLTHRUSTIN'
2019-02-23 15:06:39,522 - default - ERROR - Exception occurred
Traceback (most recent call last):
  File "Trading/Dataset/DatasetHolder.py", line 259, in appendTimeframesIntoOneDataset
    ds_h.f_df[cdl] = np.convolve(ds_h.f_df[cdl], fn)[0:len(ds_h.f_df)]
  File "/usr/local/lib/python2.7/dist-packages/pandas/core/frame.py", line 1997, in __getitem__
    return self._getitem_column(key)
  File "/usr/local/lib/python2.7/dist-packages/pandas/core/frame.py", line 2009, in _getitem_column
    result = result[key]
  File "/usr/local/lib/python2.7/dist-packages/pandas/core/frame.py", line 1997, in __getitem__
    return self._getitem_column(key)
  File "/usr/local/lib/python2.7/dist-packages/pandas/core/frame.py", line 2004, in _getitem_column
    return self._get_item_cache(key)
  File "/usr/local/lib/python2.7/dist-packages/pandas/core/generic.py", line 1350, in _get_item_cache
    values = self._data.get(item)
  File "/usr/local/lib/python2.7/dist-packages/pandas/core/internals.py", line 3290, in get
    loc = self.items.get_loc(item)
  File "/usr/local/lib/python2.7/dist-packages/pandas/indexes/base.py", line 1947, in get_loc
    return self._engine.get_loc(self._maybe_cast_indexer(key))
  File "pandas/index.pyx", line 137, in pandas.index.IndexEngine.get_loc (pandas/index.c:4154)
  File "pandas/index.pyx", line 159, in pandas.index.IndexEngine.get_loc (pandas/index.c:4018)
  File "pandas/hashtable.pyx", line 675, in pandas.hashtable.PyObjectHashTable.get_item (pandas/hashtable.c:12368)
  File "pandas/hashtable.pyx", line 683, in pandas.hashtable.PyObjectHashTable.get_item (pandas/hashtable.c:12322)
KeyError: 'CDLTRISTA'
2019-02-23 15:06:39,526 - default - ERROR - Exception occurred
Traceback (most recent call last):
  File "Trading/Dataset/DatasetHolder.py", line 259, in appendTimeframesIntoOneDataset
    ds_h.f_df[cdl] = np.convolve(ds_h.f_df[cdl], fn)[0:len(ds_h.f_df)]
  File "/usr/local/lib/python2.7/dist-packages/pandas/core/frame.py", line 1997, in __getitem__
    return self._getitem_column(key)
  File "/usr/local/lib/python2.7/dist-packages/pandas/core/frame.py", line 2009, in _getitem_column
    result = result[key]
  File "/usr/local/lib/python2.7/dist-packages/pandas/core/frame.py", line 1997, in __getitem__
    return self._getitem_column(key)
  File "/usr/local/lib/python2.7/dist-packages/pandas/core/frame.py", line 2004, in _getitem_column
    return self._get_item_cache(key)
  File "/usr/local/lib/python2.7/dist-packages/pandas/core/generic.py", line 1350, in _get_item_cache
    values = self._data.get(item)
  File "/usr/local/lib/python2.7/dist-packages/pandas/core/internals.py", line 3290, in get
    loc = self.items.get_loc(item)
  File "/usr/local/lib/python2.7/dist-packages/pandas/indexes/base.py", line 1947, in get_loc
    return self._engine.get_loc(self._maybe_cast_indexer(key))
  File "pandas/index.pyx", line 137, in pandas.index.IndexEngine.get_loc (pandas/index.c:4154)
  File "pandas/index.pyx", line 159, in pandas.index.IndexEngine.get_loc (pandas/index.c:4018)
  File "pandas/hashtable.pyx", line 675, in pandas.hashtable.PyObjectHashTable.get_item (pandas/hashtable.c:12368)
  File "pandas/hashtable.pyx", line 683, in pandas.hashtable.PyObjectHashTable.get_item (pandas/hashtable.c:12322)
KeyError: 'CDLUNIQUE3RIVE'
2019-02-23 15:06:39,529 - default - ERROR - Exception occurred
Traceback (most recent call last):
  File "Trading/Dataset/DatasetHolder.py", line 259, in appendTimeframesIntoOneDataset
    ds_h.f_df[cdl] = np.convolve(ds_h.f_df[cdl], fn)[0:len(ds_h.f_df)]
  File "/usr/local/lib/python2.7/dist-packages/pandas/core/frame.py", line 1997, in __getitem__
    return self._getitem_column(key)
  File "/usr/local/lib/python2.7/dist-packages/pandas/core/frame.py", line 2009, in _getitem_column
    result = result[key]
  File "/usr/local/lib/python2.7/dist-packages/pandas/core/frame.py", line 1997, in __getitem__
    return self._getitem_column(key)
  File "/usr/local/lib/python2.7/dist-packages/pandas/core/frame.py", line 2004, in _getitem_column
    return self._get_item_cache(key)
  File "/usr/local/lib/python2.7/dist-packages/pandas/core/generic.py", line 1350, in _get_item_cache
    values = self._data.get(item)
  File "/usr/local/lib/python2.7/dist-packages/pandas/core/internals.py", line 3290, in get
    loc = self.items.get_loc(item)
  File "/usr/local/lib/python2.7/dist-packages/pandas/indexes/base.py", line 1947, in get_loc
    return self._engine.get_loc(self._maybe_cast_indexer(key))
  File "pandas/index.pyx", line 137, in pandas.index.IndexEngine.get_loc (pandas/index.c:4154)
  File "pandas/index.pyx", line 159, in pandas.index.IndexEngine.get_loc (pandas/index.c:4018)
  File "pandas/hashtable.pyx", line 675, in pandas.hashtable.PyObjectHashTable.get_item (pandas/hashtable.c:12368)
  File "pandas/hashtable.pyx", line 683, in pandas.hashtable.PyObjectHashTable.get_item (pandas/hashtable.c:12322)
KeyError: 'CDLUPSIDEGAP2CROW'
2019-02-23 15:06:39,532 - default - ERROR - Exception occurred
Traceback (most recent call last):
  File "Trading/Dataset/DatasetHolder.py", line 259, in appendTimeframesIntoOneDataset
    ds_h.f_df[cdl] = np.convolve(ds_h.f_df[cdl], fn)[0:len(ds_h.f_df)]
  File "/usr/local/lib/python2.7/dist-packages/pandas/core/frame.py", line 1997, in __getitem__
    return self._getitem_column(key)
  File "/usr/local/lib/python2.7/dist-packages/pandas/core/frame.py", line 2009, in _getitem_column
    result = result[key]
  File "/usr/local/lib/python2.7/dist-packages/pandas/core/frame.py", line 1997, in __getitem__
    return self._getitem_column(key)
  File "/usr/local/lib/python2.7/dist-packages/pandas/core/frame.py", line 2004, in _getitem_column
    return self._get_item_cache(key)
  File "/usr/local/lib/python2.7/dist-packages/pandas/core/generic.py", line 1350, in _get_item_cache
    values = self._data.get(item)
  File "/usr/local/lib/python2.7/dist-packages/pandas/core/internals.py", line 3290, in get
    loc = self.items.get_loc(item)
  File "/usr/local/lib/python2.7/dist-packages/pandas/indexes/base.py", line 1947, in get_loc
    return self._engine.get_loc(self._maybe_cast_indexer(key))
  File "pandas/index.pyx", line 137, in pandas.index.IndexEngine.get_loc (pandas/index.c:4154)
  File "pandas/index.pyx", line 159, in pandas.index.IndexEngine.get_loc (pandas/index.c:4018)
  File "pandas/hashtable.pyx", line 675, in pandas.hashtable.PyObjectHashTable.get_item (pandas/hashtable.c:12368)
  File "pandas/hashtable.pyx", line 683, in pandas.hashtable.PyObjectHashTable.get_item (pandas/hashtable.c:12322)
KeyError: 'CDLXSIDEGAP3METHOD'
