2019-04-28 12:59:55,968 - default - ERROR - Exception occurred
Traceback (most recent call last):
  File "Trading/Dataset/DatasetHolder.py", line 265, in appendTimeframesIntoOneDataset
    ds_h.f_df[cdl] = np.convolve(ds_h.f_df[cdl], fn)[0:len(ds_h.f_df)]
  File "/usr/local/lib/python2.7/dist-packages/pandas/core/frame.py", line 1997, in __getitem__
    return self._getitem_column(key)
  File "/usr/local/lib/python2.7/dist-packages/pandas/core/frame.py", line 2004, in _getitem_column
    return self._get_item_cache(key)
  File "/usr/local/lib/python2.7/dist-packages/pandas/core/generic.py", line 1350, in _get_item_cache
    values = self._data.get(item)
  File "/usr/local/lib/python2.7/dist-packages/pandas/core/internals.py", line 3290, in get
    loc = self.items.get_loc(item)
  File "/usr/local/lib/python2.7/dist-packages/pandas/indexes/base.py", line 1947, in get_loc
    return self._engine.get_loc(self._maybe_cast_indexer(key))
  File "pandas/index.pyx", line 137, in pandas.index.IndexEngine.get_loc (pandas/index.c:4154)
  File "pandas/index.pyx", line 159, in pandas.index.IndexEngine.get_loc (pandas/index.c:4018)
  File "pandas/hashtable.pyx", line 675, in pandas.hashtable.PyObjectHashTable.get_item (pandas/hashtable.c:12368)
  File "pandas/hashtable.pyx", line 683, in pandas.hashtable.PyObjectHashTable.get_item (pandas/hashtable.c:12322)
KeyError: 'CDL2CROWS>'
2019-04-28 12:59:55,973 - default - ERROR - Exception occurred
Traceback (most recent call last):
  File "Trading/Dataset/DatasetHolder.py", line 265, in appendTimeframesIntoOneDataset
    ds_h.f_df[cdl] = np.convolve(ds_h.f_df[cdl], fn)[0:len(ds_h.f_df)]
  File "/usr/local/lib/python2.7/dist-packages/pandas/core/frame.py", line 1997, in __getitem__
    return self._getitem_column(key)
  File "/usr/local/lib/python2.7/dist-packages/pandas/core/frame.py", line 2004, in _getitem_column
    return self._get_item_cache(key)
  File "/usr/local/lib/python2.7/dist-packages/pandas/core/generic.py", line 1350, in _get_item_cache
    values = self._data.get(item)
  File "/usr/local/lib/python2.7/dist-packages/pandas/core/internals.py", line 3290, in get
    loc = self.items.get_loc(item)
  File "/usr/local/lib/python2.7/dist-packages/pandas/indexes/base.py", line 1947, in get_loc
    return self._engine.get_loc(self._maybe_cast_indexer(key))
  File "pandas/index.pyx", line 137, in pandas.index.IndexEngine.get_loc (pandas/index.c:4154)
  File "pandas/index.pyx", line 159, in pandas.index.IndexEngine.get_loc (pandas/index.c:4018)
  File "pandas/hashtable.pyx", line 675, in pandas.hashtable.PyObjectHashTable.get_item (pandas/hashtable.c:12368)
  File "pandas/hashtable.pyx", line 683, in pandas.hashtable.PyObjectHashTable.get_item (pandas/hashtable.c:12322)
KeyError: 'CDL3BLACKCROWS>'
2019-04-28 12:59:55,976 - default - ERROR - Exception occurred
Traceback (most recent call last):
  File "Trading/Dataset/DatasetHolder.py", line 265, in appendTimeframesIntoOneDataset
    ds_h.f_df[cdl] = np.convolve(ds_h.f_df[cdl], fn)[0:len(ds_h.f_df)]
  File "/usr/local/lib/python2.7/dist-packages/pandas/core/frame.py", line 1997, in __getitem__
    return self._getitem_column(key)
  File "/usr/local/lib/python2.7/dist-packages/pandas/core/frame.py", line 2004, in _getitem_column
    return self._get_item_cache(key)
  File "/usr/local/lib/python2.7/dist-packages/pandas/core/generic.py", line 1350, in _get_item_cache
    values = self._data.get(item)
  File "/usr/local/lib/python2.7/dist-packages/pandas/core/internals.py", line 3290, in get
    loc = self.items.get_loc(item)
  File "/usr/local/lib/python2.7/dist-packages/pandas/indexes/base.py", line 1947, in get_loc
    return self._engine.get_loc(self._maybe_cast_indexer(key))
  File "pandas/index.pyx", line 137, in pandas.index.IndexEngine.get_loc (pandas/index.c:4154)
  File "pandas/index.pyx", line 159, in pandas.index.IndexEngine.get_loc (pandas/index.c:4018)
  File "pandas/hashtable.pyx", line 675, in pandas.hashtable.PyObjectHashTable.get_item (pandas/hashtable.c:12368)
  File "pandas/hashtable.pyx", line 683, in pandas.hashtable.PyObjectHashTable.get_item (pandas/hashtable.c:12322)
KeyError: 'CDL3INSIDE>'
2019-04-28 12:59:55,979 - default - ERROR - Exception occurred
Traceback (most recent call last):
  File "Trading/Dataset/DatasetHolder.py", line 265, in appendTimeframesIntoOneDataset
    ds_h.f_df[cdl] = np.convolve(ds_h.f_df[cdl], fn)[0:len(ds_h.f_df)]
  File "/usr/local/lib/python2.7/dist-packages/pandas/core/frame.py", line 1997, in __getitem__
    return self._getitem_column(key)
  File "/usr/local/lib/python2.7/dist-packages/pandas/core/frame.py", line 2004, in _getitem_column
    return self._get_item_cache(key)
  File "/usr/local/lib/python2.7/dist-packages/pandas/core/generic.py", line 1350, in _get_item_cache
    values = self._data.get(item)
  File "/usr/local/lib/python2.7/dist-packages/pandas/core/internals.py", line 3290, in get
    loc = self.items.get_loc(item)
  File "/usr/local/lib/python2.7/dist-packages/pandas/indexes/base.py", line 1947, in get_loc
    return self._engine.get_loc(self._maybe_cast_indexer(key))
  File "pandas/index.pyx", line 137, in pandas.index.IndexEngine.get_loc (pandas/index.c:4154)
  File "pandas/index.pyx", line 159, in pandas.index.IndexEngine.get_loc (pandas/index.c:4018)
  File "pandas/hashtable.pyx", line 675, in pandas.hashtable.PyObjectHashTable.get_item (pandas/hashtable.c:12368)
  File "pandas/hashtable.pyx", line 683, in pandas.hashtable.PyObjectHashTable.get_item (pandas/hashtable.c:12322)
KeyError: 'CDL3LINESTRIKE>'
2019-04-28 12:59:55,982 - default - ERROR - Exception occurred
Traceback (most recent call last):
  File "Trading/Dataset/DatasetHolder.py", line 265, in appendTimeframesIntoOneDataset
    ds_h.f_df[cdl] = np.convolve(ds_h.f_df[cdl], fn)[0:len(ds_h.f_df)]
  File "/usr/local/lib/python2.7/dist-packages/pandas/core/frame.py", line 1997, in __getitem__
    return self._getitem_column(key)
  File "/usr/local/lib/python2.7/dist-packages/pandas/core/frame.py", line 2004, in _getitem_column
    return self._get_item_cache(key)
  File "/usr/local/lib/python2.7/dist-packages/pandas/core/generic.py", line 1350, in _get_item_cache
    values = self._data.get(item)
  File "/usr/local/lib/python2.7/dist-packages/pandas/core/internals.py", line 3290, in get
    loc = self.items.get_loc(item)
  File "/usr/local/lib/python2.7/dist-packages/pandas/indexes/base.py", line 1947, in get_loc
    return self._engine.get_loc(self._maybe_cast_indexer(key))
  File "pandas/index.pyx", line 137, in pandas.index.IndexEngine.get_loc (pandas/index.c:4154)
  File "pandas/index.pyx", line 159, in pandas.index.IndexEngine.get_loc (pandas/index.c:4018)
  File "pandas/hashtable.pyx", line 675, in pandas.hashtable.PyObjectHashTable.get_item (pandas/hashtable.c:12368)
  File "pandas/hashtable.pyx", line 683, in pandas.hashtable.PyObjectHashTable.get_item (pandas/hashtable.c:12322)
KeyError: 'CDL3OUTSIDE>'
2019-04-28 12:59:55,986 - default - ERROR - Exception occurred
Traceback (most recent call last):
  File "Trading/Dataset/DatasetHolder.py", line 265, in appendTimeframesIntoOneDataset
    ds_h.f_df[cdl] = np.convolve(ds_h.f_df[cdl], fn)[0:len(ds_h.f_df)]
  File "/usr/local/lib/python2.7/dist-packages/pandas/core/frame.py", line 1997, in __getitem__
    return self._getitem_column(key)
  File "/usr/local/lib/python2.7/dist-packages/pandas/core/frame.py", line 2004, in _getitem_column
    return self._get_item_cache(key)
  File "/usr/local/lib/python2.7/dist-packages/pandas/core/generic.py", line 1350, in _get_item_cache
    values = self._data.get(item)
  File "/usr/local/lib/python2.7/dist-packages/pandas/core/internals.py", line 3290, in get
    loc = self.items.get_loc(item)
  File "/usr/local/lib/python2.7/dist-packages/pandas/indexes/base.py", line 1947, in get_loc
    return self._engine.get_loc(self._maybe_cast_indexer(key))
  File "pandas/index.pyx", line 137, in pandas.index.IndexEngine.get_loc (pandas/index.c:4154)
  File "pandas/index.pyx", line 159, in pandas.index.IndexEngine.get_loc (pandas/index.c:4018)
  File "pandas/hashtable.pyx", line 675, in pandas.hashtable.PyObjectHashTable.get_item (pandas/hashtable.c:12368)
  File "pandas/hashtable.pyx", line 683, in pandas.hashtable.PyObjectHashTable.get_item (pandas/hashtable.c:12322)
KeyError: 'CDL3STARSINSOUTH>'
2019-04-28 12:59:55,989 - default - ERROR - Exception occurred
Traceback (most recent call last):
  File "Trading/Dataset/DatasetHolder.py", line 265, in appendTimeframesIntoOneDataset
    ds_h.f_df[cdl] = np.convolve(ds_h.f_df[cdl], fn)[0:len(ds_h.f_df)]
  File "/usr/local/lib/python2.7/dist-packages/pandas/core/frame.py", line 1997, in __getitem__
    return self._getitem_column(key)
  File "/usr/local/lib/python2.7/dist-packages/pandas/core/frame.py", line 2004, in _getitem_column
    return self._get_item_cache(key)
  File "/usr/local/lib/python2.7/dist-packages/pandas/core/generic.py", line 1350, in _get_item_cache
    values = self._data.get(item)
  File "/usr/local/lib/python2.7/dist-packages/pandas/core/internals.py", line 3290, in get
    loc = self.items.get_loc(item)
  File "/usr/local/lib/python2.7/dist-packages/pandas/indexes/base.py", line 1947, in get_loc
    return self._engine.get_loc(self._maybe_cast_indexer(key))
  File "pandas/index.pyx", line 137, in pandas.index.IndexEngine.get_loc (pandas/index.c:4154)
  File "pandas/index.pyx", line 159, in pandas.index.IndexEngine.get_loc (pandas/index.c:4018)
  File "pandas/hashtable.pyx", line 675, in pandas.hashtable.PyObjectHashTable.get_item (pandas/hashtable.c:12368)
  File "pandas/hashtable.pyx", line 683, in pandas.hashtable.PyObjectHashTable.get_item (pandas/hashtable.c:12322)
KeyError: 'CDL3WHITESOLDIERS>'
2019-04-28 12:59:55,991 - default - ERROR - Exception occurred
Traceback (most recent call last):
  File "Trading/Dataset/DatasetHolder.py", line 265, in appendTimeframesIntoOneDataset
    ds_h.f_df[cdl] = np.convolve(ds_h.f_df[cdl], fn)[0:len(ds_h.f_df)]
  File "/usr/local/lib/python2.7/dist-packages/pandas/core/frame.py", line 1997, in __getitem__
    return self._getitem_column(key)
  File "/usr/local/lib/python2.7/dist-packages/pandas/core/frame.py", line 2004, in _getitem_column
    return self._get_item_cache(key)
  File "/usr/local/lib/python2.7/dist-packages/pandas/core/generic.py", line 1350, in _get_item_cache
    values = self._data.get(item)
  File "/usr/local/lib/python2.7/dist-packages/pandas/core/internals.py", line 3290, in get
    loc = self.items.get_loc(item)
  File "/usr/local/lib/python2.7/dist-packages/pandas/indexes/base.py", line 1947, in get_loc
    return self._engine.get_loc(self._maybe_cast_indexer(key))
  File "pandas/index.pyx", line 137, in pandas.index.IndexEngine.get_loc (pandas/index.c:4154)
  File "pandas/index.pyx", line 159, in pandas.index.IndexEngine.get_loc (pandas/index.c:4018)
  File "pandas/hashtable.pyx", line 675, in pandas.hashtable.PyObjectHashTable.get_item (pandas/hashtable.c:12368)
  File "pandas/hashtable.pyx", line 683, in pandas.hashtable.PyObjectHashTable.get_item (pandas/hashtable.c:12322)
KeyError: 'CDLABANDONEDBABY>'
2019-04-28 12:59:55,994 - default - ERROR - Exception occurred
Traceback (most recent call last):
  File "Trading/Dataset/DatasetHolder.py", line 265, in appendTimeframesIntoOneDataset
    ds_h.f_df[cdl] = np.convolve(ds_h.f_df[cdl], fn)[0:len(ds_h.f_df)]
  File "/usr/local/lib/python2.7/dist-packages/pandas/core/frame.py", line 1997, in __getitem__
    return self._getitem_column(key)
  File "/usr/local/lib/python2.7/dist-packages/pandas/core/frame.py", line 2004, in _getitem_column
    return self._get_item_cache(key)
  File "/usr/local/lib/python2.7/dist-packages/pandas/core/generic.py", line 1350, in _get_item_cache
    values = self._data.get(item)
  File "/usr/local/lib/python2.7/dist-packages/pandas/core/internals.py", line 3290, in get
    loc = self.items.get_loc(item)
  File "/usr/local/lib/python2.7/dist-packages/pandas/indexes/base.py", line 1947, in get_loc
    return self._engine.get_loc(self._maybe_cast_indexer(key))
  File "pandas/index.pyx", line 137, in pandas.index.IndexEngine.get_loc (pandas/index.c:4154)
  File "pandas/index.pyx", line 159, in pandas.index.IndexEngine.get_loc (pandas/index.c:4018)
  File "pandas/hashtable.pyx", line 675, in pandas.hashtable.PyObjectHashTable.get_item (pandas/hashtable.c:12368)
  File "pandas/hashtable.pyx", line 683, in pandas.hashtable.PyObjectHashTable.get_item (pandas/hashtable.c:12322)
KeyError: 'CDLADVANCEBLOCK>'
2019-04-28 12:59:55,997 - default - ERROR - Exception occurred
Traceback (most recent call last):
  File "Trading/Dataset/DatasetHolder.py", line 265, in appendTimeframesIntoOneDataset
    ds_h.f_df[cdl] = np.convolve(ds_h.f_df[cdl], fn)[0:len(ds_h.f_df)]
  File "/usr/local/lib/python2.7/dist-packages/pandas/core/frame.py", line 1997, in __getitem__
    return self._getitem_column(key)
  File "/usr/local/lib/python2.7/dist-packages/pandas/core/frame.py", line 2004, in _getitem_column
    return self._get_item_cache(key)
  File "/usr/local/lib/python2.7/dist-packages/pandas/core/generic.py", line 1350, in _get_item_cache
    values = self._data.get(item)
  File "/usr/local/lib/python2.7/dist-packages/pandas/core/internals.py", line 3290, in get
    loc = self.items.get_loc(item)
  File "/usr/local/lib/python2.7/dist-packages/pandas/indexes/base.py", line 1947, in get_loc
    return self._engine.get_loc(self._maybe_cast_indexer(key))
  File "pandas/index.pyx", line 137, in pandas.index.IndexEngine.get_loc (pandas/index.c:4154)
  File "pandas/index.pyx", line 159, in pandas.index.IndexEngine.get_loc (pandas/index.c:4018)
  File "pandas/hashtable.pyx", line 675, in pandas.hashtable.PyObjectHashTable.get_item (pandas/hashtable.c:12368)
  File "pandas/hashtable.pyx", line 683, in pandas.hashtable.PyObjectHashTable.get_item (pandas/hashtable.c:12322)
KeyError: 'CDLBELTHOLD>'
2019-04-28 12:59:56,000 - default - ERROR - Exception occurred
Traceback (most recent call last):
  File "Trading/Dataset/DatasetHolder.py", line 265, in appendTimeframesIntoOneDataset
    ds_h.f_df[cdl] = np.convolve(ds_h.f_df[cdl], fn)[0:len(ds_h.f_df)]
  File "/usr/local/lib/python2.7/dist-packages/pandas/core/frame.py", line 1997, in __getitem__
    return self._getitem_column(key)
  File "/usr/local/lib/python2.7/dist-packages/pandas/core/frame.py", line 2004, in _getitem_column
    return self._get_item_cache(key)
  File "/usr/local/lib/python2.7/dist-packages/pandas/core/generic.py", line 1350, in _get_item_cache
    values = self._data.get(item)
  File "/usr/local/lib/python2.7/dist-packages/pandas/core/internals.py", line 3290, in get
    loc = self.items.get_loc(item)
  File "/usr/local/lib/python2.7/dist-packages/pandas/indexes/base.py", line 1947, in get_loc
    return self._engine.get_loc(self._maybe_cast_indexer(key))
  File "pandas/index.pyx", line 137, in pandas.index.IndexEngine.get_loc (pandas/index.c:4154)
  File "pandas/index.pyx", line 159, in pandas.index.IndexEngine.get_loc (pandas/index.c:4018)
  File "pandas/hashtable.pyx", line 675, in pandas.hashtable.PyObjectHashTable.get_item (pandas/hashtable.c:12368)
  File "pandas/hashtable.pyx", line 683, in pandas.hashtable.PyObjectHashTable.get_item (pandas/hashtable.c:12322)
KeyError: 'CDLBREAKAWAY>'
2019-04-28 12:59:56,005 - default - ERROR - Exception occurred
Traceback (most recent call last):
  File "Trading/Dataset/DatasetHolder.py", line 265, in appendTimeframesIntoOneDataset
    ds_h.f_df[cdl] = np.convolve(ds_h.f_df[cdl], fn)[0:len(ds_h.f_df)]
  File "/usr/local/lib/python2.7/dist-packages/pandas/core/frame.py", line 1997, in __getitem__
    return self._getitem_column(key)
  File "/usr/local/lib/python2.7/dist-packages/pandas/core/frame.py", line 2004, in _getitem_column
    return self._get_item_cache(key)
  File "/usr/local/lib/python2.7/dist-packages/pandas/core/generic.py", line 1350, in _get_item_cache
    values = self._data.get(item)
  File "/usr/local/lib/python2.7/dist-packages/pandas/core/internals.py", line 3290, in get
    loc = self.items.get_loc(item)
  File "/usr/local/lib/python2.7/dist-packages/pandas/indexes/base.py", line 1947, in get_loc
    return self._engine.get_loc(self._maybe_cast_indexer(key))
  File "pandas/index.pyx", line 137, in pandas.index.IndexEngine.get_loc (pandas/index.c:4154)
  File "pandas/index.pyx", line 159, in pandas.index.IndexEngine.get_loc (pandas/index.c:4018)
  File "pandas/hashtable.pyx", line 675, in pandas.hashtable.PyObjectHashTable.get_item (pandas/hashtable.c:12368)
  File "pandas/hashtable.pyx", line 683, in pandas.hashtable.PyObjectHashTable.get_item (pandas/hashtable.c:12322)
KeyError: 'CDLCLOSINGMARUBOZU>'
2019-04-28 12:59:56,008 - default - ERROR - Exception occurred
Traceback (most recent call last):
  File "Trading/Dataset/DatasetHolder.py", line 265, in appendTimeframesIntoOneDataset
    ds_h.f_df[cdl] = np.convolve(ds_h.f_df[cdl], fn)[0:len(ds_h.f_df)]
  File "/usr/local/lib/python2.7/dist-packages/pandas/core/frame.py", line 1997, in __getitem__
    return self._getitem_column(key)
  File "/usr/local/lib/python2.7/dist-packages/pandas/core/frame.py", line 2004, in _getitem_column
    return self._get_item_cache(key)
  File "/usr/local/lib/python2.7/dist-packages/pandas/core/generic.py", line 1350, in _get_item_cache
    values = self._data.get(item)
  File "/usr/local/lib/python2.7/dist-packages/pandas/core/internals.py", line 3290, in get
    loc = self.items.get_loc(item)
  File "/usr/local/lib/python2.7/dist-packages/pandas/indexes/base.py", line 1947, in get_loc
    return self._engine.get_loc(self._maybe_cast_indexer(key))
  File "pandas/index.pyx", line 137, in pandas.index.IndexEngine.get_loc (pandas/index.c:4154)
  File "pandas/index.pyx", line 159, in pandas.index.IndexEngine.get_loc (pandas/index.c:4018)
  File "pandas/hashtable.pyx", line 675, in pandas.hashtable.PyObjectHashTable.get_item (pandas/hashtable.c:12368)
  File "pandas/hashtable.pyx", line 683, in pandas.hashtable.PyObjectHashTable.get_item (pandas/hashtable.c:12322)
KeyError: 'CDLCONCEALBABYSWALL>'
2019-04-28 12:59:56,011 - default - ERROR - Exception occurred
Traceback (most recent call last):
  File "Trading/Dataset/DatasetHolder.py", line 265, in appendTimeframesIntoOneDataset
    ds_h.f_df[cdl] = np.convolve(ds_h.f_df[cdl], fn)[0:len(ds_h.f_df)]
  File "/usr/local/lib/python2.7/dist-packages/pandas/core/frame.py", line 1997, in __getitem__
    return self._getitem_column(key)
  File "/usr/local/lib/python2.7/dist-packages/pandas/core/frame.py", line 2004, in _getitem_column
    return self._get_item_cache(key)
  File "/usr/local/lib/python2.7/dist-packages/pandas/core/generic.py", line 1350, in _get_item_cache
    values = self._data.get(item)
  File "/usr/local/lib/python2.7/dist-packages/pandas/core/internals.py", line 3290, in get
    loc = self.items.get_loc(item)
  File "/usr/local/lib/python2.7/dist-packages/pandas/indexes/base.py", line 1947, in get_loc
    return self._engine.get_loc(self._maybe_cast_indexer(key))
  File "pandas/index.pyx", line 137, in pandas.index.IndexEngine.get_loc (pandas/index.c:4154)
  File "pandas/index.pyx", line 159, in pandas.index.IndexEngine.get_loc (pandas/index.c:4018)
  File "pandas/hashtable.pyx", line 675, in pandas.hashtable.PyObjectHashTable.get_item (pandas/hashtable.c:12368)
  File "pandas/hashtable.pyx", line 683, in pandas.hashtable.PyObjectHashTable.get_item (pandas/hashtable.c:12322)
KeyError: 'CDLCOUNTERATTACK>'
2019-04-28 12:59:56,014 - default - ERROR - Exception occurred
Traceback (most recent call last):
  File "Trading/Dataset/DatasetHolder.py", line 265, in appendTimeframesIntoOneDataset
    ds_h.f_df[cdl] = np.convolve(ds_h.f_df[cdl], fn)[0:len(ds_h.f_df)]
  File "/usr/local/lib/python2.7/dist-packages/pandas/core/frame.py", line 1997, in __getitem__
    return self._getitem_column(key)
  File "/usr/local/lib/python2.7/dist-packages/pandas/core/frame.py", line 2004, in _getitem_column
    return self._get_item_cache(key)
  File "/usr/local/lib/python2.7/dist-packages/pandas/core/generic.py", line 1350, in _get_item_cache
    values = self._data.get(item)
  File "/usr/local/lib/python2.7/dist-packages/pandas/core/internals.py", line 3290, in get
    loc = self.items.get_loc(item)
  File "/usr/local/lib/python2.7/dist-packages/pandas/indexes/base.py", line 1947, in get_loc
    return self._engine.get_loc(self._maybe_cast_indexer(key))
  File "pandas/index.pyx", line 137, in pandas.index.IndexEngine.get_loc (pandas/index.c:4154)
  File "pandas/index.pyx", line 159, in pandas.index.IndexEngine.get_loc (pandas/index.c:4018)
  File "pandas/hashtable.pyx", line 675, in pandas.hashtable.PyObjectHashTable.get_item (pandas/hashtable.c:12368)
  File "pandas/hashtable.pyx", line 683, in pandas.hashtable.PyObjectHashTable.get_item (pandas/hashtable.c:12322)
KeyError: 'CDLDARKCLOUDCOVER>'
2019-04-28 12:59:56,016 - default - ERROR - Exception occurred
Traceback (most recent call last):
  File "Trading/Dataset/DatasetHolder.py", line 265, in appendTimeframesIntoOneDataset
    ds_h.f_df[cdl] = np.convolve(ds_h.f_df[cdl], fn)[0:len(ds_h.f_df)]
  File "/usr/local/lib/python2.7/dist-packages/pandas/core/frame.py", line 1997, in __getitem__
    return self._getitem_column(key)
  File "/usr/local/lib/python2.7/dist-packages/pandas/core/frame.py", line 2004, in _getitem_column
    return self._get_item_cache(key)
  File "/usr/local/lib/python2.7/dist-packages/pandas/core/generic.py", line 1350, in _get_item_cache
    values = self._data.get(item)
  File "/usr/local/lib/python2.7/dist-packages/pandas/core/internals.py", line 3290, in get
    loc = self.items.get_loc(item)
  File "/usr/local/lib/python2.7/dist-packages/pandas/indexes/base.py", line 1947, in get_loc
    return self._engine.get_loc(self._maybe_cast_indexer(key))
  File "pandas/index.pyx", line 137, in pandas.index.IndexEngine.get_loc (pandas/index.c:4154)
  File "pandas/index.pyx", line 159, in pandas.index.IndexEngine.get_loc (pandas/index.c:4018)
  File "pandas/hashtable.pyx", line 675, in pandas.hashtable.PyObjectHashTable.get_item (pandas/hashtable.c:12368)
  File "pandas/hashtable.pyx", line 683, in pandas.hashtable.PyObjectHashTable.get_item (pandas/hashtable.c:12322)
KeyError: 'CDLDOJI>'
2019-04-28 12:59:56,020 - default - ERROR - Exception occurred
Traceback (most recent call last):
  File "Trading/Dataset/DatasetHolder.py", line 265, in appendTimeframesIntoOneDataset
    ds_h.f_df[cdl] = np.convolve(ds_h.f_df[cdl], fn)[0:len(ds_h.f_df)]
  File "/usr/local/lib/python2.7/dist-packages/pandas/core/frame.py", line 1997, in __getitem__
    return self._getitem_column(key)
  File "/usr/local/lib/python2.7/dist-packages/pandas/core/frame.py", line 2004, in _getitem_column
    return self._get_item_cache(key)
  File "/usr/local/lib/python2.7/dist-packages/pandas/core/generic.py", line 1350, in _get_item_cache
    values = self._data.get(item)
  File "/usr/local/lib/python2.7/dist-packages/pandas/core/internals.py", line 3290, in get
    loc = self.items.get_loc(item)
  File "/usr/local/lib/python2.7/dist-packages/pandas/indexes/base.py", line 1947, in get_loc
    return self._engine.get_loc(self._maybe_cast_indexer(key))
  File "pandas/index.pyx", line 137, in pandas.index.IndexEngine.get_loc (pandas/index.c:4154)
  File "pandas/index.pyx", line 159, in pandas.index.IndexEngine.get_loc (pandas/index.c:4018)
  File "pandas/hashtable.pyx", line 675, in pandas.hashtable.PyObjectHashTable.get_item (pandas/hashtable.c:12368)
  File "pandas/hashtable.pyx", line 683, in pandas.hashtable.PyObjectHashTable.get_item (pandas/hashtable.c:12322)
KeyError: 'CDLDOJISTAR>'
2019-04-28 12:59:56,022 - default - ERROR - Exception occurred
Traceback (most recent call last):
  File "Trading/Dataset/DatasetHolder.py", line 265, in appendTimeframesIntoOneDataset
    ds_h.f_df[cdl] = np.convolve(ds_h.f_df[cdl], fn)[0:len(ds_h.f_df)]
  File "/usr/local/lib/python2.7/dist-packages/pandas/core/frame.py", line 1997, in __getitem__
    return self._getitem_column(key)
  File "/usr/local/lib/python2.7/dist-packages/pandas/core/frame.py", line 2004, in _getitem_column
    return self._get_item_cache(key)
  File "/usr/local/lib/python2.7/dist-packages/pandas/core/generic.py", line 1350, in _get_item_cache
    values = self._data.get(item)
  File "/usr/local/lib/python2.7/dist-packages/pandas/core/internals.py", line 3290, in get
    loc = self.items.get_loc(item)
  File "/usr/local/lib/python2.7/dist-packages/pandas/indexes/base.py", line 1947, in get_loc
    return self._engine.get_loc(self._maybe_cast_indexer(key))
  File "pandas/index.pyx", line 137, in pandas.index.IndexEngine.get_loc (pandas/index.c:4154)
  File "pandas/index.pyx", line 159, in pandas.index.IndexEngine.get_loc (pandas/index.c:4018)
  File "pandas/hashtable.pyx", line 675, in pandas.hashtable.PyObjectHashTable.get_item (pandas/hashtable.c:12368)
  File "pandas/hashtable.pyx", line 683, in pandas.hashtable.PyObjectHashTable.get_item (pandas/hashtable.c:12322)
KeyError: 'CDLDRAGONFLYDOJI>'
2019-04-28 12:59:56,026 - default - ERROR - Exception occurred
Traceback (most recent call last):
  File "Trading/Dataset/DatasetHolder.py", line 265, in appendTimeframesIntoOneDataset
    ds_h.f_df[cdl] = np.convolve(ds_h.f_df[cdl], fn)[0:len(ds_h.f_df)]
  File "/usr/local/lib/python2.7/dist-packages/pandas/core/frame.py", line 1997, in __getitem__
    return self._getitem_column(key)
  File "/usr/local/lib/python2.7/dist-packages/pandas/core/frame.py", line 2004, in _getitem_column
    return self._get_item_cache(key)
  File "/usr/local/lib/python2.7/dist-packages/pandas/core/generic.py", line 1350, in _get_item_cache
    values = self._data.get(item)
  File "/usr/local/lib/python2.7/dist-packages/pandas/core/internals.py", line 3290, in get
    loc = self.items.get_loc(item)
  File "/usr/local/lib/python2.7/dist-packages/pandas/indexes/base.py", line 1947, in get_loc
    return self._engine.get_loc(self._maybe_cast_indexer(key))
  File "pandas/index.pyx", line 137, in pandas.index.IndexEngine.get_loc (pandas/index.c:4154)
  File "pandas/index.pyx", line 159, in pandas.index.IndexEngine.get_loc (pandas/index.c:4018)
  File "pandas/hashtable.pyx", line 675, in pandas.hashtable.PyObjectHashTable.get_item (pandas/hashtable.c:12368)
  File "pandas/hashtable.pyx", line 683, in pandas.hashtable.PyObjectHashTable.get_item (pandas/hashtable.c:12322)
KeyError: 'CDLENGULFING>'
2019-04-28 12:59:56,029 - default - ERROR - Exception occurred
Traceback (most recent call last):
  File "Trading/Dataset/DatasetHolder.py", line 265, in appendTimeframesIntoOneDataset
    ds_h.f_df[cdl] = np.convolve(ds_h.f_df[cdl], fn)[0:len(ds_h.f_df)]
  File "/usr/local/lib/python2.7/dist-packages/pandas/core/frame.py", line 1997, in __getitem__
    return self._getitem_column(key)
  File "/usr/local/lib/python2.7/dist-packages/pandas/core/frame.py", line 2004, in _getitem_column
    return self._get_item_cache(key)
  File "/usr/local/lib/python2.7/dist-packages/pandas/core/generic.py", line 1350, in _get_item_cache
    values = self._data.get(item)
  File "/usr/local/lib/python2.7/dist-packages/pandas/core/internals.py", line 3290, in get
    loc = self.items.get_loc(item)
  File "/usr/local/lib/python2.7/dist-packages/pandas/indexes/base.py", line 1947, in get_loc
    return self._engine.get_loc(self._maybe_cast_indexer(key))
  File "pandas/index.pyx", line 137, in pandas.index.IndexEngine.get_loc (pandas/index.c:4154)
  File "pandas/index.pyx", line 159, in pandas.index.IndexEngine.get_loc (pandas/index.c:4018)
  File "pandas/hashtable.pyx", line 675, in pandas.hashtable.PyObjectHashTable.get_item (pandas/hashtable.c:12368)
  File "pandas/hashtable.pyx", line 683, in pandas.hashtable.PyObjectHashTable.get_item (pandas/hashtable.c:12322)
KeyError: 'CDLEVENINGDOJISTAR>'
2019-04-28 12:59:56,032 - default - ERROR - Exception occurred
Traceback (most recent call last):
  File "Trading/Dataset/DatasetHolder.py", line 265, in appendTimeframesIntoOneDataset
    ds_h.f_df[cdl] = np.convolve(ds_h.f_df[cdl], fn)[0:len(ds_h.f_df)]
  File "/usr/local/lib/python2.7/dist-packages/pandas/core/frame.py", line 1997, in __getitem__
    return self._getitem_column(key)
  File "/usr/local/lib/python2.7/dist-packages/pandas/core/frame.py", line 2004, in _getitem_column
    return self._get_item_cache(key)
  File "/usr/local/lib/python2.7/dist-packages/pandas/core/generic.py", line 1350, in _get_item_cache
    values = self._data.get(item)
  File "/usr/local/lib/python2.7/dist-packages/pandas/core/internals.py", line 3290, in get
    loc = self.items.get_loc(item)
  File "/usr/local/lib/python2.7/dist-packages/pandas/indexes/base.py", line 1947, in get_loc
    return self._engine.get_loc(self._maybe_cast_indexer(key))
  File "pandas/index.pyx", line 137, in pandas.index.IndexEngine.get_loc (pandas/index.c:4154)
  File "pandas/index.pyx", line 159, in pandas.index.IndexEngine.get_loc (pandas/index.c:4018)
  File "pandas/hashtable.pyx", line 675, in pandas.hashtable.PyObjectHashTable.get_item (pandas/hashtable.c:12368)
  File "pandas/hashtable.pyx", line 683, in pandas.hashtable.PyObjectHashTable.get_item (pandas/hashtable.c:12322)
KeyError: 'CDLEVENINGSTAR>'
2019-04-28 12:59:56,035 - default - ERROR - Exception occurred
Traceback (most recent call last):
  File "Trading/Dataset/DatasetHolder.py", line 265, in appendTimeframesIntoOneDataset
    ds_h.f_df[cdl] = np.convolve(ds_h.f_df[cdl], fn)[0:len(ds_h.f_df)]
  File "/usr/local/lib/python2.7/dist-packages/pandas/core/frame.py", line 1997, in __getitem__
    return self._getitem_column(key)
  File "/usr/local/lib/python2.7/dist-packages/pandas/core/frame.py", line 2004, in _getitem_column
    return self._get_item_cache(key)
  File "/usr/local/lib/python2.7/dist-packages/pandas/core/generic.py", line 1350, in _get_item_cache
    values = self._data.get(item)
  File "/usr/local/lib/python2.7/dist-packages/pandas/core/internals.py", line 3290, in get
    loc = self.items.get_loc(item)
  File "/usr/local/lib/python2.7/dist-packages/pandas/indexes/base.py", line 1947, in get_loc
    return self._engine.get_loc(self._maybe_cast_indexer(key))
  File "pandas/index.pyx", line 137, in pandas.index.IndexEngine.get_loc (pandas/index.c:4154)
  File "pandas/index.pyx", line 159, in pandas.index.IndexEngine.get_loc (pandas/index.c:4018)
  File "pandas/hashtable.pyx", line 675, in pandas.hashtable.PyObjectHashTable.get_item (pandas/hashtable.c:12368)
  File "pandas/hashtable.pyx", line 683, in pandas.hashtable.PyObjectHashTable.get_item (pandas/hashtable.c:12322)
KeyError: 'CDLGAPSIDESIDEWHITE>'
2019-04-28 12:59:56,038 - default - ERROR - Exception occurred
Traceback (most recent call last):
  File "Trading/Dataset/DatasetHolder.py", line 265, in appendTimeframesIntoOneDataset
    ds_h.f_df[cdl] = np.convolve(ds_h.f_df[cdl], fn)[0:len(ds_h.f_df)]
  File "/usr/local/lib/python2.7/dist-packages/pandas/core/frame.py", line 1997, in __getitem__
    return self._getitem_column(key)
  File "/usr/local/lib/python2.7/dist-packages/pandas/core/frame.py", line 2004, in _getitem_column
    return self._get_item_cache(key)
  File "/usr/local/lib/python2.7/dist-packages/pandas/core/generic.py", line 1350, in _get_item_cache
    values = self._data.get(item)
  File "/usr/local/lib/python2.7/dist-packages/pandas/core/internals.py", line 3290, in get
    loc = self.items.get_loc(item)
  File "/usr/local/lib/python2.7/dist-packages/pandas/indexes/base.py", line 1947, in get_loc
    return self._engine.get_loc(self._maybe_cast_indexer(key))
  File "pandas/index.pyx", line 137, in pandas.index.IndexEngine.get_loc (pandas/index.c:4154)
  File "pandas/index.pyx", line 159, in pandas.index.IndexEngine.get_loc (pandas/index.c:4018)
  File "pandas/hashtable.pyx", line 675, in pandas.hashtable.PyObjectHashTable.get_item (pandas/hashtable.c:12368)
  File "pandas/hashtable.pyx", line 683, in pandas.hashtable.PyObjectHashTable.get_item (pandas/hashtable.c:12322)
KeyError: 'CDLGRAVESTONEDOJI>'
2019-04-28 12:59:56,041 - default - ERROR - Exception occurred
Traceback (most recent call last):
  File "Trading/Dataset/DatasetHolder.py", line 265, in appendTimeframesIntoOneDataset
    ds_h.f_df[cdl] = np.convolve(ds_h.f_df[cdl], fn)[0:len(ds_h.f_df)]
  File "/usr/local/lib/python2.7/dist-packages/pandas/core/frame.py", line 1997, in __getitem__
    return self._getitem_column(key)
  File "/usr/local/lib/python2.7/dist-packages/pandas/core/frame.py", line 2004, in _getitem_column
    return self._get_item_cache(key)
  File "/usr/local/lib/python2.7/dist-packages/pandas/core/generic.py", line 1350, in _get_item_cache
    values = self._data.get(item)
  File "/usr/local/lib/python2.7/dist-packages/pandas/core/internals.py", line 3290, in get
    loc = self.items.get_loc(item)
  File "/usr/local/lib/python2.7/dist-packages/pandas/indexes/base.py", line 1947, in get_loc
    return self._engine.get_loc(self._maybe_cast_indexer(key))
  File "pandas/index.pyx", line 137, in pandas.index.IndexEngine.get_loc (pandas/index.c:4154)
  File "pandas/index.pyx", line 159, in pandas.index.IndexEngine.get_loc (pandas/index.c:4018)
  File "pandas/hashtable.pyx", line 675, in pandas.hashtable.PyObjectHashTable.get_item (pandas/hashtable.c:12368)
  File "pandas/hashtable.pyx", line 683, in pandas.hashtable.PyObjectHashTable.get_item (pandas/hashtable.c:12322)
KeyError: 'CDLHAMMER>'
2019-04-28 12:59:56,044 - default - ERROR - Exception occurred
Traceback (most recent call last):
  File "Trading/Dataset/DatasetHolder.py", line 265, in appendTimeframesIntoOneDataset
    ds_h.f_df[cdl] = np.convolve(ds_h.f_df[cdl], fn)[0:len(ds_h.f_df)]
  File "/usr/local/lib/python2.7/dist-packages/pandas/core/frame.py", line 1997, in __getitem__
    return self._getitem_column(key)
  File "/usr/local/lib/python2.7/dist-packages/pandas/core/frame.py", line 2004, in _getitem_column
    return self._get_item_cache(key)
  File "/usr/local/lib/python2.7/dist-packages/pandas/core/generic.py", line 1350, in _get_item_cache
    values = self._data.get(item)
  File "/usr/local/lib/python2.7/dist-packages/pandas/core/internals.py", line 3290, in get
    loc = self.items.get_loc(item)
  File "/usr/local/lib/python2.7/dist-packages/pandas/indexes/base.py", line 1947, in get_loc
    return self._engine.get_loc(self._maybe_cast_indexer(key))
  File "pandas/index.pyx", line 137, in pandas.index.IndexEngine.get_loc (pandas/index.c:4154)
  File "pandas/index.pyx", line 159, in pandas.index.IndexEngine.get_loc (pandas/index.c:4018)
  File "pandas/hashtable.pyx", line 675, in pandas.hashtable.PyObjectHashTable.get_item (pandas/hashtable.c:12368)
  File "pandas/hashtable.pyx", line 683, in pandas.hashtable.PyObjectHashTable.get_item (pandas/hashtable.c:12322)
KeyError: 'CDLHANGINGMAN>'
2019-04-28 12:59:56,046 - default - ERROR - Exception occurred
Traceback (most recent call last):
  File "Trading/Dataset/DatasetHolder.py", line 265, in appendTimeframesIntoOneDataset
    ds_h.f_df[cdl] = np.convolve(ds_h.f_df[cdl], fn)[0:len(ds_h.f_df)]
  File "/usr/local/lib/python2.7/dist-packages/pandas/core/frame.py", line 1997, in __getitem__
    return self._getitem_column(key)
  File "/usr/local/lib/python2.7/dist-packages/pandas/core/frame.py", line 2004, in _getitem_column
    return self._get_item_cache(key)
  File "/usr/local/lib/python2.7/dist-packages/pandas/core/generic.py", line 1350, in _get_item_cache
    values = self._data.get(item)
  File "/usr/local/lib/python2.7/dist-packages/pandas/core/internals.py", line 3290, in get
    loc = self.items.get_loc(item)
  File "/usr/local/lib/python2.7/dist-packages/pandas/indexes/base.py", line 1947, in get_loc
    return self._engine.get_loc(self._maybe_cast_indexer(key))
  File "pandas/index.pyx", line 137, in pandas.index.IndexEngine.get_loc (pandas/index.c:4154)
  File "pandas/index.pyx", line 159, in pandas.index.IndexEngine.get_loc (pandas/index.c:4018)
  File "pandas/hashtable.pyx", line 675, in pandas.hashtable.PyObjectHashTable.get_item (pandas/hashtable.c:12368)
  File "pandas/hashtable.pyx", line 683, in pandas.hashtable.PyObjectHashTable.get_item (pandas/hashtable.c:12322)
KeyError: 'CDLHARAMI>'
2019-04-28 12:59:56,049 - default - ERROR - Exception occurred
Traceback (most recent call last):
  File "Trading/Dataset/DatasetHolder.py", line 265, in appendTimeframesIntoOneDataset
    ds_h.f_df[cdl] = np.convolve(ds_h.f_df[cdl], fn)[0:len(ds_h.f_df)]
  File "/usr/local/lib/python2.7/dist-packages/pandas/core/frame.py", line 1997, in __getitem__
    return self._getitem_column(key)
  File "/usr/local/lib/python2.7/dist-packages/pandas/core/frame.py", line 2004, in _getitem_column
    return self._get_item_cache(key)
  File "/usr/local/lib/python2.7/dist-packages/pandas/core/generic.py", line 1350, in _get_item_cache
    values = self._data.get(item)
  File "/usr/local/lib/python2.7/dist-packages/pandas/core/internals.py", line 3290, in get
    loc = self.items.get_loc(item)
  File "/usr/local/lib/python2.7/dist-packages/pandas/indexes/base.py", line 1947, in get_loc
    return self._engine.get_loc(self._maybe_cast_indexer(key))
  File "pandas/index.pyx", line 137, in pandas.index.IndexEngine.get_loc (pandas/index.c:4154)
  File "pandas/index.pyx", line 159, in pandas.index.IndexEngine.get_loc (pandas/index.c:4018)
  File "pandas/hashtable.pyx", line 675, in pandas.hashtable.PyObjectHashTable.get_item (pandas/hashtable.c:12368)
  File "pandas/hashtable.pyx", line 683, in pandas.hashtable.PyObjectHashTable.get_item (pandas/hashtable.c:12322)
KeyError: 'CDLHARAMICROSS>'
2019-04-28 12:59:56,052 - default - ERROR - Exception occurred
Traceback (most recent call last):
  File "Trading/Dataset/DatasetHolder.py", line 265, in appendTimeframesIntoOneDataset
    ds_h.f_df[cdl] = np.convolve(ds_h.f_df[cdl], fn)[0:len(ds_h.f_df)]
  File "/usr/local/lib/python2.7/dist-packages/pandas/core/frame.py", line 1997, in __getitem__
    return self._getitem_column(key)
  File "/usr/local/lib/python2.7/dist-packages/pandas/core/frame.py", line 2004, in _getitem_column
    return self._get_item_cache(key)
  File "/usr/local/lib/python2.7/dist-packages/pandas/core/generic.py", line 1350, in _get_item_cache
    values = self._data.get(item)
  File "/usr/local/lib/python2.7/dist-packages/pandas/core/internals.py", line 3290, in get
    loc = self.items.get_loc(item)
  File "/usr/local/lib/python2.7/dist-packages/pandas/indexes/base.py", line 1947, in get_loc
    return self._engine.get_loc(self._maybe_cast_indexer(key))
  File "pandas/index.pyx", line 137, in pandas.index.IndexEngine.get_loc (pandas/index.c:4154)
  File "pandas/index.pyx", line 159, in pandas.index.IndexEngine.get_loc (pandas/index.c:4018)
  File "pandas/hashtable.pyx", line 675, in pandas.hashtable.PyObjectHashTable.get_item (pandas/hashtable.c:12368)
  File "pandas/hashtable.pyx", line 683, in pandas.hashtable.PyObjectHashTable.get_item (pandas/hashtable.c:12322)
KeyError: 'CDLHIGHWAVE>'
2019-04-28 12:59:56,055 - default - ERROR - Exception occurred
Traceback (most recent call last):
  File "Trading/Dataset/DatasetHolder.py", line 265, in appendTimeframesIntoOneDataset
    ds_h.f_df[cdl] = np.convolve(ds_h.f_df[cdl], fn)[0:len(ds_h.f_df)]
  File "/usr/local/lib/python2.7/dist-packages/pandas/core/frame.py", line 1997, in __getitem__
    return self._getitem_column(key)
  File "/usr/local/lib/python2.7/dist-packages/pandas/core/frame.py", line 2004, in _getitem_column
    return self._get_item_cache(key)
  File "/usr/local/lib/python2.7/dist-packages/pandas/core/generic.py", line 1350, in _get_item_cache
    values = self._data.get(item)
  File "/usr/local/lib/python2.7/dist-packages/pandas/core/internals.py", line 3290, in get
    loc = self.items.get_loc(item)
  File "/usr/local/lib/python2.7/dist-packages/pandas/indexes/base.py", line 1947, in get_loc
    return self._engine.get_loc(self._maybe_cast_indexer(key))
  File "pandas/index.pyx", line 137, in pandas.index.IndexEngine.get_loc (pandas/index.c:4154)
  File "pandas/index.pyx", line 159, in pandas.index.IndexEngine.get_loc (pandas/index.c:4018)
  File "pandas/hashtable.pyx", line 675, in pandas.hashtable.PyObjectHashTable.get_item (pandas/hashtable.c:12368)
  File "pandas/hashtable.pyx", line 683, in pandas.hashtable.PyObjectHashTable.get_item (pandas/hashtable.c:12322)
KeyError: 'CDLHIKKAKE>'
2019-04-28 12:59:56,058 - default - ERROR - Exception occurred
Traceback (most recent call last):
  File "Trading/Dataset/DatasetHolder.py", line 265, in appendTimeframesIntoOneDataset
    ds_h.f_df[cdl] = np.convolve(ds_h.f_df[cdl], fn)[0:len(ds_h.f_df)]
  File "/usr/local/lib/python2.7/dist-packages/pandas/core/frame.py", line 1997, in __getitem__
    return self._getitem_column(key)
  File "/usr/local/lib/python2.7/dist-packages/pandas/core/frame.py", line 2004, in _getitem_column
    return self._get_item_cache(key)
  File "/usr/local/lib/python2.7/dist-packages/pandas/core/generic.py", line 1350, in _get_item_cache
    values = self._data.get(item)
  File "/usr/local/lib/python2.7/dist-packages/pandas/core/internals.py", line 3290, in get
    loc = self.items.get_loc(item)
  File "/usr/local/lib/python2.7/dist-packages/pandas/indexes/base.py", line 1947, in get_loc
    return self._engine.get_loc(self._maybe_cast_indexer(key))
  File "pandas/index.pyx", line 137, in pandas.index.IndexEngine.get_loc (pandas/index.c:4154)
  File "pandas/index.pyx", line 159, in pandas.index.IndexEngine.get_loc (pandas/index.c:4018)
  File "pandas/hashtable.pyx", line 675, in pandas.hashtable.PyObjectHashTable.get_item (pandas/hashtable.c:12368)
  File "pandas/hashtable.pyx", line 683, in pandas.hashtable.PyObjectHashTable.get_item (pandas/hashtable.c:12322)
KeyError: 'CDLHIKKAKEMOD>'
2019-04-28 12:59:56,061 - default - ERROR - Exception occurred
Traceback (most recent call last):
  File "Trading/Dataset/DatasetHolder.py", line 265, in appendTimeframesIntoOneDataset
    ds_h.f_df[cdl] = np.convolve(ds_h.f_df[cdl], fn)[0:len(ds_h.f_df)]
  File "/usr/local/lib/python2.7/dist-packages/pandas/core/frame.py", line 1997, in __getitem__
    return self._getitem_column(key)
  File "/usr/local/lib/python2.7/dist-packages/pandas/core/frame.py", line 2004, in _getitem_column
    return self._get_item_cache(key)
  File "/usr/local/lib/python2.7/dist-packages/pandas/core/generic.py", line 1350, in _get_item_cache
    values = self._data.get(item)
  File "/usr/local/lib/python2.7/dist-packages/pandas/core/internals.py", line 3290, in get
    loc = self.items.get_loc(item)
  File "/usr/local/lib/python2.7/dist-packages/pandas/indexes/base.py", line 1947, in get_loc
    return self._engine.get_loc(self._maybe_cast_indexer(key))
  File "pandas/index.pyx", line 137, in pandas.index.IndexEngine.get_loc (pandas/index.c:4154)
  File "pandas/index.pyx", line 159, in pandas.index.IndexEngine.get_loc (pandas/index.c:4018)
  File "pandas/hashtable.pyx", line 675, in pandas.hashtable.PyObjectHashTable.get_item (pandas/hashtable.c:12368)
  File "pandas/hashtable.pyx", line 683, in pandas.hashtable.PyObjectHashTable.get_item (pandas/hashtable.c:12322)
KeyError: 'CDLHOMINGPIGEON>'
2019-04-28 12:59:56,065 - default - ERROR - Exception occurred
Traceback (most recent call last):
  File "Trading/Dataset/DatasetHolder.py", line 265, in appendTimeframesIntoOneDataset
    ds_h.f_df[cdl] = np.convolve(ds_h.f_df[cdl], fn)[0:len(ds_h.f_df)]
  File "/usr/local/lib/python2.7/dist-packages/pandas/core/frame.py", line 1997, in __getitem__
    return self._getitem_column(key)
  File "/usr/local/lib/python2.7/dist-packages/pandas/core/frame.py", line 2004, in _getitem_column
    return self._get_item_cache(key)
  File "/usr/local/lib/python2.7/dist-packages/pandas/core/generic.py", line 1350, in _get_item_cache
    values = self._data.get(item)
  File "/usr/local/lib/python2.7/dist-packages/pandas/core/internals.py", line 3290, in get
    loc = self.items.get_loc(item)
  File "/usr/local/lib/python2.7/dist-packages/pandas/indexes/base.py", line 1947, in get_loc
    return self._engine.get_loc(self._maybe_cast_indexer(key))
  File "pandas/index.pyx", line 137, in pandas.index.IndexEngine.get_loc (pandas/index.c:4154)
  File "pandas/index.pyx", line 159, in pandas.index.IndexEngine.get_loc (pandas/index.c:4018)
  File "pandas/hashtable.pyx", line 675, in pandas.hashtable.PyObjectHashTable.get_item (pandas/hashtable.c:12368)
  File "pandas/hashtable.pyx", line 683, in pandas.hashtable.PyObjectHashTable.get_item (pandas/hashtable.c:12322)
KeyError: 'CDLIDENTICAL3CROWS>'
2019-04-28 12:59:56,070 - default - ERROR - Exception occurred
Traceback (most recent call last):
  File "Trading/Dataset/DatasetHolder.py", line 265, in appendTimeframesIntoOneDataset
    ds_h.f_df[cdl] = np.convolve(ds_h.f_df[cdl], fn)[0:len(ds_h.f_df)]
  File "/usr/local/lib/python2.7/dist-packages/pandas/core/frame.py", line 1997, in __getitem__
    return self._getitem_column(key)
  File "/usr/local/lib/python2.7/dist-packages/pandas/core/frame.py", line 2004, in _getitem_column
    return self._get_item_cache(key)
  File "/usr/local/lib/python2.7/dist-packages/pandas/core/generic.py", line 1350, in _get_item_cache
    values = self._data.get(item)
  File "/usr/local/lib/python2.7/dist-packages/pandas/core/internals.py", line 3290, in get
    loc = self.items.get_loc(item)
  File "/usr/local/lib/python2.7/dist-packages/pandas/indexes/base.py", line 1947, in get_loc
    return self._engine.get_loc(self._maybe_cast_indexer(key))
  File "pandas/index.pyx", line 137, in pandas.index.IndexEngine.get_loc (pandas/index.c:4154)
  File "pandas/index.pyx", line 159, in pandas.index.IndexEngine.get_loc (pandas/index.c:4018)
  File "pandas/hashtable.pyx", line 675, in pandas.hashtable.PyObjectHashTable.get_item (pandas/hashtable.c:12368)
  File "pandas/hashtable.pyx", line 683, in pandas.hashtable.PyObjectHashTable.get_item (pandas/hashtable.c:12322)
KeyError: 'CDLINNECK>'
2019-04-28 12:59:56,073 - default - ERROR - Exception occurred
Traceback (most recent call last):
  File "Trading/Dataset/DatasetHolder.py", line 265, in appendTimeframesIntoOneDataset
    ds_h.f_df[cdl] = np.convolve(ds_h.f_df[cdl], fn)[0:len(ds_h.f_df)]
  File "/usr/local/lib/python2.7/dist-packages/pandas/core/frame.py", line 1997, in __getitem__
    return self._getitem_column(key)
  File "/usr/local/lib/python2.7/dist-packages/pandas/core/frame.py", line 2004, in _getitem_column
    return self._get_item_cache(key)
  File "/usr/local/lib/python2.7/dist-packages/pandas/core/generic.py", line 1350, in _get_item_cache
    values = self._data.get(item)
  File "/usr/local/lib/python2.7/dist-packages/pandas/core/internals.py", line 3290, in get
    loc = self.items.get_loc(item)
  File "/usr/local/lib/python2.7/dist-packages/pandas/indexes/base.py", line 1947, in get_loc
    return self._engine.get_loc(self._maybe_cast_indexer(key))
  File "pandas/index.pyx", line 137, in pandas.index.IndexEngine.get_loc (pandas/index.c:4154)
  File "pandas/index.pyx", line 159, in pandas.index.IndexEngine.get_loc (pandas/index.c:4018)
  File "pandas/hashtable.pyx", line 675, in pandas.hashtable.PyObjectHashTable.get_item (pandas/hashtable.c:12368)
  File "pandas/hashtable.pyx", line 683, in pandas.hashtable.PyObjectHashTable.get_item (pandas/hashtable.c:12322)
KeyError: 'CDLINVERTEDHAMMER>'
2019-04-28 12:59:56,075 - default - ERROR - Exception occurred
Traceback (most recent call last):
  File "Trading/Dataset/DatasetHolder.py", line 265, in appendTimeframesIntoOneDataset
    ds_h.f_df[cdl] = np.convolve(ds_h.f_df[cdl], fn)[0:len(ds_h.f_df)]
  File "/usr/local/lib/python2.7/dist-packages/pandas/core/frame.py", line 1997, in __getitem__
    return self._getitem_column(key)
  File "/usr/local/lib/python2.7/dist-packages/pandas/core/frame.py", line 2004, in _getitem_column
    return self._get_item_cache(key)
  File "/usr/local/lib/python2.7/dist-packages/pandas/core/generic.py", line 1350, in _get_item_cache
    values = self._data.get(item)
  File "/usr/local/lib/python2.7/dist-packages/pandas/core/internals.py", line 3290, in get
    loc = self.items.get_loc(item)
  File "/usr/local/lib/python2.7/dist-packages/pandas/indexes/base.py", line 1947, in get_loc
    return self._engine.get_loc(self._maybe_cast_indexer(key))
  File "pandas/index.pyx", line 137, in pandas.index.IndexEngine.get_loc (pandas/index.c:4154)
  File "pandas/index.pyx", line 159, in pandas.index.IndexEngine.get_loc (pandas/index.c:4018)
  File "pandas/hashtable.pyx", line 675, in pandas.hashtable.PyObjectHashTable.get_item (pandas/hashtable.c:12368)
  File "pandas/hashtable.pyx", line 683, in pandas.hashtable.PyObjectHashTable.get_item (pandas/hashtable.c:12322)
KeyError: 'CDLKICKING>'
2019-04-28 12:59:56,078 - default - ERROR - Exception occurred
Traceback (most recent call last):
  File "Trading/Dataset/DatasetHolder.py", line 265, in appendTimeframesIntoOneDataset
    ds_h.f_df[cdl] = np.convolve(ds_h.f_df[cdl], fn)[0:len(ds_h.f_df)]
  File "/usr/local/lib/python2.7/dist-packages/pandas/core/frame.py", line 1997, in __getitem__
    return self._getitem_column(key)
  File "/usr/local/lib/python2.7/dist-packages/pandas/core/frame.py", line 2004, in _getitem_column
    return self._get_item_cache(key)
  File "/usr/local/lib/python2.7/dist-packages/pandas/core/generic.py", line 1350, in _get_item_cache
    values = self._data.get(item)
  File "/usr/local/lib/python2.7/dist-packages/pandas/core/internals.py", line 3290, in get
    loc = self.items.get_loc(item)
  File "/usr/local/lib/python2.7/dist-packages/pandas/indexes/base.py", line 1947, in get_loc
    return self._engine.get_loc(self._maybe_cast_indexer(key))
  File "pandas/index.pyx", line 137, in pandas.index.IndexEngine.get_loc (pandas/index.c:4154)
  File "pandas/index.pyx", line 159, in pandas.index.IndexEngine.get_loc (pandas/index.c:4018)
  File "pandas/hashtable.pyx", line 675, in pandas.hashtable.PyObjectHashTable.get_item (pandas/hashtable.c:12368)
  File "pandas/hashtable.pyx", line 683, in pandas.hashtable.PyObjectHashTable.get_item (pandas/hashtable.c:12322)
KeyError: 'CDLKICKINGBYLENGTH>'
2019-04-28 12:59:56,081 - default - ERROR - Exception occurred
Traceback (most recent call last):
  File "Trading/Dataset/DatasetHolder.py", line 265, in appendTimeframesIntoOneDataset
    ds_h.f_df[cdl] = np.convolve(ds_h.f_df[cdl], fn)[0:len(ds_h.f_df)]
  File "/usr/local/lib/python2.7/dist-packages/pandas/core/frame.py", line 1997, in __getitem__
    return self._getitem_column(key)
  File "/usr/local/lib/python2.7/dist-packages/pandas/core/frame.py", line 2004, in _getitem_column
    return self._get_item_cache(key)
  File "/usr/local/lib/python2.7/dist-packages/pandas/core/generic.py", line 1350, in _get_item_cache
    values = self._data.get(item)
  File "/usr/local/lib/python2.7/dist-packages/pandas/core/internals.py", line 3290, in get
    loc = self.items.get_loc(item)
  File "/usr/local/lib/python2.7/dist-packages/pandas/indexes/base.py", line 1947, in get_loc
    return self._engine.get_loc(self._maybe_cast_indexer(key))
  File "pandas/index.pyx", line 137, in pandas.index.IndexEngine.get_loc (pandas/index.c:4154)
  File "pandas/index.pyx", line 159, in pandas.index.IndexEngine.get_loc (pandas/index.c:4018)
  File "pandas/hashtable.pyx", line 675, in pandas.hashtable.PyObjectHashTable.get_item (pandas/hashtable.c:12368)
  File "pandas/hashtable.pyx", line 683, in pandas.hashtable.PyObjectHashTable.get_item (pandas/hashtable.c:12322)
KeyError: 'CDLLADDERBOTTOM>'
2019-04-28 12:59:56,084 - default - ERROR - Exception occurred
Traceback (most recent call last):
  File "Trading/Dataset/DatasetHolder.py", line 265, in appendTimeframesIntoOneDataset
    ds_h.f_df[cdl] = np.convolve(ds_h.f_df[cdl], fn)[0:len(ds_h.f_df)]
  File "/usr/local/lib/python2.7/dist-packages/pandas/core/frame.py", line 1997, in __getitem__
    return self._getitem_column(key)
  File "/usr/local/lib/python2.7/dist-packages/pandas/core/frame.py", line 2004, in _getitem_column
    return self._get_item_cache(key)
  File "/usr/local/lib/python2.7/dist-packages/pandas/core/generic.py", line 1350, in _get_item_cache
    values = self._data.get(item)
  File "/usr/local/lib/python2.7/dist-packages/pandas/core/internals.py", line 3290, in get
    loc = self.items.get_loc(item)
  File "/usr/local/lib/python2.7/dist-packages/pandas/indexes/base.py", line 1947, in get_loc
    return self._engine.get_loc(self._maybe_cast_indexer(key))
  File "pandas/index.pyx", line 137, in pandas.index.IndexEngine.get_loc (pandas/index.c:4154)
  File "pandas/index.pyx", line 159, in pandas.index.IndexEngine.get_loc (pandas/index.c:4018)
  File "pandas/hashtable.pyx", line 675, in pandas.hashtable.PyObjectHashTable.get_item (pandas/hashtable.c:12368)
  File "pandas/hashtable.pyx", line 683, in pandas.hashtable.PyObjectHashTable.get_item (pandas/hashtable.c:12322)
KeyError: 'CDLLONGLEGGEDDOJI>'
2019-04-28 12:59:56,088 - default - ERROR - Exception occurred
Traceback (most recent call last):
  File "Trading/Dataset/DatasetHolder.py", line 265, in appendTimeframesIntoOneDataset
    ds_h.f_df[cdl] = np.convolve(ds_h.f_df[cdl], fn)[0:len(ds_h.f_df)]
  File "/usr/local/lib/python2.7/dist-packages/pandas/core/frame.py", line 1997, in __getitem__
    return self._getitem_column(key)
  File "/usr/local/lib/python2.7/dist-packages/pandas/core/frame.py", line 2004, in _getitem_column
    return self._get_item_cache(key)
  File "/usr/local/lib/python2.7/dist-packages/pandas/core/generic.py", line 1350, in _get_item_cache
    values = self._data.get(item)
  File "/usr/local/lib/python2.7/dist-packages/pandas/core/internals.py", line 3290, in get
    loc = self.items.get_loc(item)
  File "/usr/local/lib/python2.7/dist-packages/pandas/indexes/base.py", line 1947, in get_loc
    return self._engine.get_loc(self._maybe_cast_indexer(key))
  File "pandas/index.pyx", line 137, in pandas.index.IndexEngine.get_loc (pandas/index.c:4154)
  File "pandas/index.pyx", line 159, in pandas.index.IndexEngine.get_loc (pandas/index.c:4018)
  File "pandas/hashtable.pyx", line 675, in pandas.hashtable.PyObjectHashTable.get_item (pandas/hashtable.c:12368)
  File "pandas/hashtable.pyx", line 683, in pandas.hashtable.PyObjectHashTable.get_item (pandas/hashtable.c:12322)
KeyError: 'CDLLONGLINE>'
2019-04-28 12:59:56,092 - default - ERROR - Exception occurred
Traceback (most recent call last):
  File "Trading/Dataset/DatasetHolder.py", line 265, in appendTimeframesIntoOneDataset
    ds_h.f_df[cdl] = np.convolve(ds_h.f_df[cdl], fn)[0:len(ds_h.f_df)]
  File "/usr/local/lib/python2.7/dist-packages/pandas/core/frame.py", line 1997, in __getitem__
    return self._getitem_column(key)
  File "/usr/local/lib/python2.7/dist-packages/pandas/core/frame.py", line 2004, in _getitem_column
    return self._get_item_cache(key)
  File "/usr/local/lib/python2.7/dist-packages/pandas/core/generic.py", line 1350, in _get_item_cache
    values = self._data.get(item)
  File "/usr/local/lib/python2.7/dist-packages/pandas/core/internals.py", line 3290, in get
    loc = self.items.get_loc(item)
  File "/usr/local/lib/python2.7/dist-packages/pandas/indexes/base.py", line 1947, in get_loc
    return self._engine.get_loc(self._maybe_cast_indexer(key))
  File "pandas/index.pyx", line 137, in pandas.index.IndexEngine.get_loc (pandas/index.c:4154)
  File "pandas/index.pyx", line 159, in pandas.index.IndexEngine.get_loc (pandas/index.c:4018)
  File "pandas/hashtable.pyx", line 675, in pandas.hashtable.PyObjectHashTable.get_item (pandas/hashtable.c:12368)
  File "pandas/hashtable.pyx", line 683, in pandas.hashtable.PyObjectHashTable.get_item (pandas/hashtable.c:12322)
KeyError: 'CDLMARUBOZU>'
2019-04-28 12:59:56,095 - default - ERROR - Exception occurred
Traceback (most recent call last):
  File "Trading/Dataset/DatasetHolder.py", line 265, in appendTimeframesIntoOneDataset
    ds_h.f_df[cdl] = np.convolve(ds_h.f_df[cdl], fn)[0:len(ds_h.f_df)]
  File "/usr/local/lib/python2.7/dist-packages/pandas/core/frame.py", line 1997, in __getitem__
    return self._getitem_column(key)
  File "/usr/local/lib/python2.7/dist-packages/pandas/core/frame.py", line 2004, in _getitem_column
    return self._get_item_cache(key)
  File "/usr/local/lib/python2.7/dist-packages/pandas/core/generic.py", line 1350, in _get_item_cache
    values = self._data.get(item)
  File "/usr/local/lib/python2.7/dist-packages/pandas/core/internals.py", line 3290, in get
    loc = self.items.get_loc(item)
  File "/usr/local/lib/python2.7/dist-packages/pandas/indexes/base.py", line 1947, in get_loc
    return self._engine.get_loc(self._maybe_cast_indexer(key))
  File "pandas/index.pyx", line 137, in pandas.index.IndexEngine.get_loc (pandas/index.c:4154)
  File "pandas/index.pyx", line 159, in pandas.index.IndexEngine.get_loc (pandas/index.c:4018)
  File "pandas/hashtable.pyx", line 675, in pandas.hashtable.PyObjectHashTable.get_item (pandas/hashtable.c:12368)
  File "pandas/hashtable.pyx", line 683, in pandas.hashtable.PyObjectHashTable.get_item (pandas/hashtable.c:12322)
KeyError: 'CDLMATCHINGLOW>'
2019-04-28 12:59:56,097 - default - ERROR - Exception occurred
Traceback (most recent call last):
  File "Trading/Dataset/DatasetHolder.py", line 265, in appendTimeframesIntoOneDataset
    ds_h.f_df[cdl] = np.convolve(ds_h.f_df[cdl], fn)[0:len(ds_h.f_df)]
  File "/usr/local/lib/python2.7/dist-packages/pandas/core/frame.py", line 1997, in __getitem__
    return self._getitem_column(key)
  File "/usr/local/lib/python2.7/dist-packages/pandas/core/frame.py", line 2004, in _getitem_column
    return self._get_item_cache(key)
  File "/usr/local/lib/python2.7/dist-packages/pandas/core/generic.py", line 1350, in _get_item_cache
    values = self._data.get(item)
  File "/usr/local/lib/python2.7/dist-packages/pandas/core/internals.py", line 3290, in get
    loc = self.items.get_loc(item)
  File "/usr/local/lib/python2.7/dist-packages/pandas/indexes/base.py", line 1947, in get_loc
    return self._engine.get_loc(self._maybe_cast_indexer(key))
  File "pandas/index.pyx", line 137, in pandas.index.IndexEngine.get_loc (pandas/index.c:4154)
  File "pandas/index.pyx", line 159, in pandas.index.IndexEngine.get_loc (pandas/index.c:4018)
  File "pandas/hashtable.pyx", line 675, in pandas.hashtable.PyObjectHashTable.get_item (pandas/hashtable.c:12368)
  File "pandas/hashtable.pyx", line 683, in pandas.hashtable.PyObjectHashTable.get_item (pandas/hashtable.c:12322)
KeyError: 'CDLMATHOLD>'
2019-04-28 12:59:56,099 - default - ERROR - Exception occurred
Traceback (most recent call last):
  File "Trading/Dataset/DatasetHolder.py", line 265, in appendTimeframesIntoOneDataset
    ds_h.f_df[cdl] = np.convolve(ds_h.f_df[cdl], fn)[0:len(ds_h.f_df)]
  File "/usr/local/lib/python2.7/dist-packages/pandas/core/frame.py", line 1997, in __getitem__
    return self._getitem_column(key)
  File "/usr/local/lib/python2.7/dist-packages/pandas/core/frame.py", line 2004, in _getitem_column
    return self._get_item_cache(key)
  File "/usr/local/lib/python2.7/dist-packages/pandas/core/generic.py", line 1350, in _get_item_cache
    values = self._data.get(item)
  File "/usr/local/lib/python2.7/dist-packages/pandas/core/internals.py", line 3290, in get
    loc = self.items.get_loc(item)
  File "/usr/local/lib/python2.7/dist-packages/pandas/indexes/base.py", line 1947, in get_loc
    return self._engine.get_loc(self._maybe_cast_indexer(key))
  File "pandas/index.pyx", line 137, in pandas.index.IndexEngine.get_loc (pandas/index.c:4154)
  File "pandas/index.pyx", line 159, in pandas.index.IndexEngine.get_loc (pandas/index.c:4018)
  File "pandas/hashtable.pyx", line 675, in pandas.hashtable.PyObjectHashTable.get_item (pandas/hashtable.c:12368)
  File "pandas/hashtable.pyx", line 683, in pandas.hashtable.PyObjectHashTable.get_item (pandas/hashtable.c:12322)
KeyError: 'CDLMORNINGDOJISTAR>'
2019-04-28 12:59:56,108 - default - ERROR - Exception occurred
Traceback (most recent call last):
  File "Trading/Dataset/DatasetHolder.py", line 265, in appendTimeframesIntoOneDataset
    ds_h.f_df[cdl] = np.convolve(ds_h.f_df[cdl], fn)[0:len(ds_h.f_df)]
  File "/usr/local/lib/python2.7/dist-packages/pandas/core/frame.py", line 1997, in __getitem__
    return self._getitem_column(key)
  File "/usr/local/lib/python2.7/dist-packages/pandas/core/frame.py", line 2004, in _getitem_column
    return self._get_item_cache(key)
  File "/usr/local/lib/python2.7/dist-packages/pandas/core/generic.py", line 1350, in _get_item_cache
    values = self._data.get(item)
  File "/usr/local/lib/python2.7/dist-packages/pandas/core/internals.py", line 3290, in get
    loc = self.items.get_loc(item)
  File "/usr/local/lib/python2.7/dist-packages/pandas/indexes/base.py", line 1947, in get_loc
    return self._engine.get_loc(self._maybe_cast_indexer(key))
  File "pandas/index.pyx", line 137, in pandas.index.IndexEngine.get_loc (pandas/index.c:4154)
  File "pandas/index.pyx", line 159, in pandas.index.IndexEngine.get_loc (pandas/index.c:4018)
  File "pandas/hashtable.pyx", line 675, in pandas.hashtable.PyObjectHashTable.get_item (pandas/hashtable.c:12368)
  File "pandas/hashtable.pyx", line 683, in pandas.hashtable.PyObjectHashTable.get_item (pandas/hashtable.c:12322)
KeyError: 'CDLMORNINGSTAR>'
2019-04-28 12:59:56,111 - default - ERROR - Exception occurred
Traceback (most recent call last):
  File "Trading/Dataset/DatasetHolder.py", line 265, in appendTimeframesIntoOneDataset
    ds_h.f_df[cdl] = np.convolve(ds_h.f_df[cdl], fn)[0:len(ds_h.f_df)]
  File "/usr/local/lib/python2.7/dist-packages/pandas/core/frame.py", line 1997, in __getitem__
    return self._getitem_column(key)
  File "/usr/local/lib/python2.7/dist-packages/pandas/core/frame.py", line 2004, in _getitem_column
    return self._get_item_cache(key)
  File "/usr/local/lib/python2.7/dist-packages/pandas/core/generic.py", line 1350, in _get_item_cache
    values = self._data.get(item)
  File "/usr/local/lib/python2.7/dist-packages/pandas/core/internals.py", line 3290, in get
    loc = self.items.get_loc(item)
  File "/usr/local/lib/python2.7/dist-packages/pandas/indexes/base.py", line 1947, in get_loc
    return self._engine.get_loc(self._maybe_cast_indexer(key))
  File "pandas/index.pyx", line 137, in pandas.index.IndexEngine.get_loc (pandas/index.c:4154)
  File "pandas/index.pyx", line 159, in pandas.index.IndexEngine.get_loc (pandas/index.c:4018)
  File "pandas/hashtable.pyx", line 675, in pandas.hashtable.PyObjectHashTable.get_item (pandas/hashtable.c:12368)
  File "pandas/hashtable.pyx", line 683, in pandas.hashtable.PyObjectHashTable.get_item (pandas/hashtable.c:12322)
KeyError: 'CDLONNECK>'
2019-04-28 12:59:56,114 - default - ERROR - Exception occurred
Traceback (most recent call last):
  File "Trading/Dataset/DatasetHolder.py", line 265, in appendTimeframesIntoOneDataset
    ds_h.f_df[cdl] = np.convolve(ds_h.f_df[cdl], fn)[0:len(ds_h.f_df)]
  File "/usr/local/lib/python2.7/dist-packages/pandas/core/frame.py", line 1997, in __getitem__
    return self._getitem_column(key)
  File "/usr/local/lib/python2.7/dist-packages/pandas/core/frame.py", line 2004, in _getitem_column
    return self._get_item_cache(key)
  File "/usr/local/lib/python2.7/dist-packages/pandas/core/generic.py", line 1350, in _get_item_cache
    values = self._data.get(item)
  File "/usr/local/lib/python2.7/dist-packages/pandas/core/internals.py", line 3290, in get
    loc = self.items.get_loc(item)
  File "/usr/local/lib/python2.7/dist-packages/pandas/indexes/base.py", line 1947, in get_loc
    return self._engine.get_loc(self._maybe_cast_indexer(key))
  File "pandas/index.pyx", line 137, in pandas.index.IndexEngine.get_loc (pandas/index.c:4154)
  File "pandas/index.pyx", line 159, in pandas.index.IndexEngine.get_loc (pandas/index.c:4018)
  File "pandas/hashtable.pyx", line 675, in pandas.hashtable.PyObjectHashTable.get_item (pandas/hashtable.c:12368)
  File "pandas/hashtable.pyx", line 683, in pandas.hashtable.PyObjectHashTable.get_item (pandas/hashtable.c:12322)
KeyError: 'CDLPIERCING>'
2019-04-28 12:59:56,117 - default - ERROR - Exception occurred
Traceback (most recent call last):
  File "Trading/Dataset/DatasetHolder.py", line 265, in appendTimeframesIntoOneDataset
    ds_h.f_df[cdl] = np.convolve(ds_h.f_df[cdl], fn)[0:len(ds_h.f_df)]
  File "/usr/local/lib/python2.7/dist-packages/pandas/core/frame.py", line 1997, in __getitem__
    return self._getitem_column(key)
  File "/usr/local/lib/python2.7/dist-packages/pandas/core/frame.py", line 2004, in _getitem_column
    return self._get_item_cache(key)
  File "/usr/local/lib/python2.7/dist-packages/pandas/core/generic.py", line 1350, in _get_item_cache
    values = self._data.get(item)
  File "/usr/local/lib/python2.7/dist-packages/pandas/core/internals.py", line 3290, in get
    loc = self.items.get_loc(item)
  File "/usr/local/lib/python2.7/dist-packages/pandas/indexes/base.py", line 1947, in get_loc
    return self._engine.get_loc(self._maybe_cast_indexer(key))
  File "pandas/index.pyx", line 137, in pandas.index.IndexEngine.get_loc (pandas/index.c:4154)
  File "pandas/index.pyx", line 159, in pandas.index.IndexEngine.get_loc (pandas/index.c:4018)
  File "pandas/hashtable.pyx", line 675, in pandas.hashtable.PyObjectHashTable.get_item (pandas/hashtable.c:12368)
  File "pandas/hashtable.pyx", line 683, in pandas.hashtable.PyObjectHashTable.get_item (pandas/hashtable.c:12322)
KeyError: 'CDLRICKSHAWMAN>'
2019-04-28 12:59:56,121 - default - ERROR - Exception occurred
Traceback (most recent call last):
  File "Trading/Dataset/DatasetHolder.py", line 265, in appendTimeframesIntoOneDataset
    ds_h.f_df[cdl] = np.convolve(ds_h.f_df[cdl], fn)[0:len(ds_h.f_df)]
  File "/usr/local/lib/python2.7/dist-packages/pandas/core/frame.py", line 1997, in __getitem__
    return self._getitem_column(key)
  File "/usr/local/lib/python2.7/dist-packages/pandas/core/frame.py", line 2004, in _getitem_column
    return self._get_item_cache(key)
  File "/usr/local/lib/python2.7/dist-packages/pandas/core/generic.py", line 1350, in _get_item_cache
    values = self._data.get(item)
  File "/usr/local/lib/python2.7/dist-packages/pandas/core/internals.py", line 3290, in get
    loc = self.items.get_loc(item)
  File "/usr/local/lib/python2.7/dist-packages/pandas/indexes/base.py", line 1947, in get_loc
    return self._engine.get_loc(self._maybe_cast_indexer(key))
  File "pandas/index.pyx", line 137, in pandas.index.IndexEngine.get_loc (pandas/index.c:4154)
  File "pandas/index.pyx", line 159, in pandas.index.IndexEngine.get_loc (pandas/index.c:4018)
  File "pandas/hashtable.pyx", line 675, in pandas.hashtable.PyObjectHashTable.get_item (pandas/hashtable.c:12368)
  File "pandas/hashtable.pyx", line 683, in pandas.hashtable.PyObjectHashTable.get_item (pandas/hashtable.c:12322)
KeyError: 'CDLRISEFALL3METHODS>'
2019-04-28 12:59:56,124 - default - ERROR - Exception occurred
Traceback (most recent call last):
  File "Trading/Dataset/DatasetHolder.py", line 265, in appendTimeframesIntoOneDataset
    ds_h.f_df[cdl] = np.convolve(ds_h.f_df[cdl], fn)[0:len(ds_h.f_df)]
  File "/usr/local/lib/python2.7/dist-packages/pandas/core/frame.py", line 1997, in __getitem__
    return self._getitem_column(key)
  File "/usr/local/lib/python2.7/dist-packages/pandas/core/frame.py", line 2004, in _getitem_column
    return self._get_item_cache(key)
  File "/usr/local/lib/python2.7/dist-packages/pandas/core/generic.py", line 1350, in _get_item_cache
    values = self._data.get(item)
  File "/usr/local/lib/python2.7/dist-packages/pandas/core/internals.py", line 3290, in get
    loc = self.items.get_loc(item)
  File "/usr/local/lib/python2.7/dist-packages/pandas/indexes/base.py", line 1947, in get_loc
    return self._engine.get_loc(self._maybe_cast_indexer(key))
  File "pandas/index.pyx", line 137, in pandas.index.IndexEngine.get_loc (pandas/index.c:4154)
  File "pandas/index.pyx", line 159, in pandas.index.IndexEngine.get_loc (pandas/index.c:4018)
  File "pandas/hashtable.pyx", line 675, in pandas.hashtable.PyObjectHashTable.get_item (pandas/hashtable.c:12368)
  File "pandas/hashtable.pyx", line 683, in pandas.hashtable.PyObjectHashTable.get_item (pandas/hashtable.c:12322)
KeyError: 'CDLSEPARATINGLINES>'
2019-04-28 12:59:56,127 - default - ERROR - Exception occurred
Traceback (most recent call last):
  File "Trading/Dataset/DatasetHolder.py", line 265, in appendTimeframesIntoOneDataset
    ds_h.f_df[cdl] = np.convolve(ds_h.f_df[cdl], fn)[0:len(ds_h.f_df)]
  File "/usr/local/lib/python2.7/dist-packages/pandas/core/frame.py", line 1997, in __getitem__
    return self._getitem_column(key)
  File "/usr/local/lib/python2.7/dist-packages/pandas/core/frame.py", line 2004, in _getitem_column
    return self._get_item_cache(key)
  File "/usr/local/lib/python2.7/dist-packages/pandas/core/generic.py", line 1350, in _get_item_cache
    values = self._data.get(item)
  File "/usr/local/lib/python2.7/dist-packages/pandas/core/internals.py", line 3290, in get
    loc = self.items.get_loc(item)
  File "/usr/local/lib/python2.7/dist-packages/pandas/indexes/base.py", line 1947, in get_loc
    return self._engine.get_loc(self._maybe_cast_indexer(key))
  File "pandas/index.pyx", line 137, in pandas.index.IndexEngine.get_loc (pandas/index.c:4154)
  File "pandas/index.pyx", line 159, in pandas.index.IndexEngine.get_loc (pandas/index.c:4018)
  File "pandas/hashtable.pyx", line 675, in pandas.hashtable.PyObjectHashTable.get_item (pandas/hashtable.c:12368)
  File "pandas/hashtable.pyx", line 683, in pandas.hashtable.PyObjectHashTable.get_item (pandas/hashtable.c:12322)
KeyError: 'CDLSHOOTINGSTAR>'
2019-04-28 12:59:56,130 - default - ERROR - Exception occurred
Traceback (most recent call last):
  File "Trading/Dataset/DatasetHolder.py", line 265, in appendTimeframesIntoOneDataset
    ds_h.f_df[cdl] = np.convolve(ds_h.f_df[cdl], fn)[0:len(ds_h.f_df)]
  File "/usr/local/lib/python2.7/dist-packages/pandas/core/frame.py", line 1997, in __getitem__
    return self._getitem_column(key)
  File "/usr/local/lib/python2.7/dist-packages/pandas/core/frame.py", line 2004, in _getitem_column
    return self._get_item_cache(key)
  File "/usr/local/lib/python2.7/dist-packages/pandas/core/generic.py", line 1350, in _get_item_cache
    values = self._data.get(item)
  File "/usr/local/lib/python2.7/dist-packages/pandas/core/internals.py", line 3290, in get
    loc = self.items.get_loc(item)
  File "/usr/local/lib/python2.7/dist-packages/pandas/indexes/base.py", line 1947, in get_loc
    return self._engine.get_loc(self._maybe_cast_indexer(key))
  File "pandas/index.pyx", line 137, in pandas.index.IndexEngine.get_loc (pandas/index.c:4154)
  File "pandas/index.pyx", line 159, in pandas.index.IndexEngine.get_loc (pandas/index.c:4018)
  File "pandas/hashtable.pyx", line 675, in pandas.hashtable.PyObjectHashTable.get_item (pandas/hashtable.c:12368)
  File "pandas/hashtable.pyx", line 683, in pandas.hashtable.PyObjectHashTable.get_item (pandas/hashtable.c:12322)
KeyError: 'CDLSHORTLINE>'
2019-04-28 12:59:56,134 - default - ERROR - Exception occurred
Traceback (most recent call last):
  File "Trading/Dataset/DatasetHolder.py", line 265, in appendTimeframesIntoOneDataset
    ds_h.f_df[cdl] = np.convolve(ds_h.f_df[cdl], fn)[0:len(ds_h.f_df)]
  File "/usr/local/lib/python2.7/dist-packages/pandas/core/frame.py", line 1997, in __getitem__
    return self._getitem_column(key)
  File "/usr/local/lib/python2.7/dist-packages/pandas/core/frame.py", line 2004, in _getitem_column
    return self._get_item_cache(key)
  File "/usr/local/lib/python2.7/dist-packages/pandas/core/generic.py", line 1350, in _get_item_cache
    values = self._data.get(item)
  File "/usr/local/lib/python2.7/dist-packages/pandas/core/internals.py", line 3290, in get
    loc = self.items.get_loc(item)
  File "/usr/local/lib/python2.7/dist-packages/pandas/indexes/base.py", line 1947, in get_loc
    return self._engine.get_loc(self._maybe_cast_indexer(key))
  File "pandas/index.pyx", line 137, in pandas.index.IndexEngine.get_loc (pandas/index.c:4154)
  File "pandas/index.pyx", line 159, in pandas.index.IndexEngine.get_loc (pandas/index.c:4018)
  File "pandas/hashtable.pyx", line 675, in pandas.hashtable.PyObjectHashTable.get_item (pandas/hashtable.c:12368)
  File "pandas/hashtable.pyx", line 683, in pandas.hashtable.PyObjectHashTable.get_item (pandas/hashtable.c:12322)
KeyError: 'CDLSPINNINGTOP>'
2019-04-28 12:59:56,137 - default - ERROR - Exception occurred
Traceback (most recent call last):
  File "Trading/Dataset/DatasetHolder.py", line 265, in appendTimeframesIntoOneDataset
    ds_h.f_df[cdl] = np.convolve(ds_h.f_df[cdl], fn)[0:len(ds_h.f_df)]
  File "/usr/local/lib/python2.7/dist-packages/pandas/core/frame.py", line 1997, in __getitem__
    return self._getitem_column(key)
  File "/usr/local/lib/python2.7/dist-packages/pandas/core/frame.py", line 2004, in _getitem_column
    return self._get_item_cache(key)
  File "/usr/local/lib/python2.7/dist-packages/pandas/core/generic.py", line 1350, in _get_item_cache
    values = self._data.get(item)
  File "/usr/local/lib/python2.7/dist-packages/pandas/core/internals.py", line 3290, in get
    loc = self.items.get_loc(item)
  File "/usr/local/lib/python2.7/dist-packages/pandas/indexes/base.py", line 1947, in get_loc
    return self._engine.get_loc(self._maybe_cast_indexer(key))
  File "pandas/index.pyx", line 137, in pandas.index.IndexEngine.get_loc (pandas/index.c:4154)
  File "pandas/index.pyx", line 159, in pandas.index.IndexEngine.get_loc (pandas/index.c:4018)
  File "pandas/hashtable.pyx", line 675, in pandas.hashtable.PyObjectHashTable.get_item (pandas/hashtable.c:12368)
  File "pandas/hashtable.pyx", line 683, in pandas.hashtable.PyObjectHashTable.get_item (pandas/hashtable.c:12322)
KeyError: 'CDLSTALLEDPATTERN>'
2019-04-28 12:59:56,141 - default - ERROR - Exception occurred
Traceback (most recent call last):
  File "Trading/Dataset/DatasetHolder.py", line 265, in appendTimeframesIntoOneDataset
    ds_h.f_df[cdl] = np.convolve(ds_h.f_df[cdl], fn)[0:len(ds_h.f_df)]
  File "/usr/local/lib/python2.7/dist-packages/pandas/core/frame.py", line 1997, in __getitem__
    return self._getitem_column(key)
  File "/usr/local/lib/python2.7/dist-packages/pandas/core/frame.py", line 2004, in _getitem_column
    return self._get_item_cache(key)
  File "/usr/local/lib/python2.7/dist-packages/pandas/core/generic.py", line 1350, in _get_item_cache
    values = self._data.get(item)
  File "/usr/local/lib/python2.7/dist-packages/pandas/core/internals.py", line 3290, in get
    loc = self.items.get_loc(item)
  File "/usr/local/lib/python2.7/dist-packages/pandas/indexes/base.py", line 1947, in get_loc
    return self._engine.get_loc(self._maybe_cast_indexer(key))
  File "pandas/index.pyx", line 137, in pandas.index.IndexEngine.get_loc (pandas/index.c:4154)
  File "pandas/index.pyx", line 159, in pandas.index.IndexEngine.get_loc (pandas/index.c:4018)
  File "pandas/hashtable.pyx", line 675, in pandas.hashtable.PyObjectHashTable.get_item (pandas/hashtable.c:12368)
  File "pandas/hashtable.pyx", line 683, in pandas.hashtable.PyObjectHashTable.get_item (pandas/hashtable.c:12322)
KeyError: 'CDLSTICKSANDWICH>'
2019-04-28 12:59:56,143 - default - ERROR - Exception occurred
Traceback (most recent call last):
  File "Trading/Dataset/DatasetHolder.py", line 265, in appendTimeframesIntoOneDataset
    ds_h.f_df[cdl] = np.convolve(ds_h.f_df[cdl], fn)[0:len(ds_h.f_df)]
  File "/usr/local/lib/python2.7/dist-packages/pandas/core/frame.py", line 1997, in __getitem__
    return self._getitem_column(key)
  File "/usr/local/lib/python2.7/dist-packages/pandas/core/frame.py", line 2004, in _getitem_column
    return self._get_item_cache(key)
  File "/usr/local/lib/python2.7/dist-packages/pandas/core/generic.py", line 1350, in _get_item_cache
    values = self._data.get(item)
  File "/usr/local/lib/python2.7/dist-packages/pandas/core/internals.py", line 3290, in get
    loc = self.items.get_loc(item)
  File "/usr/local/lib/python2.7/dist-packages/pandas/indexes/base.py", line 1947, in get_loc
    return self._engine.get_loc(self._maybe_cast_indexer(key))
  File "pandas/index.pyx", line 137, in pandas.index.IndexEngine.get_loc (pandas/index.c:4154)
  File "pandas/index.pyx", line 159, in pandas.index.IndexEngine.get_loc (pandas/index.c:4018)
  File "pandas/hashtable.pyx", line 675, in pandas.hashtable.PyObjectHashTable.get_item (pandas/hashtable.c:12368)
  File "pandas/hashtable.pyx", line 683, in pandas.hashtable.PyObjectHashTable.get_item (pandas/hashtable.c:12322)
KeyError: 'CDLTAKURI>'
2019-04-28 12:59:56,146 - default - ERROR - Exception occurred
Traceback (most recent call last):
  File "Trading/Dataset/DatasetHolder.py", line 265, in appendTimeframesIntoOneDataset
    ds_h.f_df[cdl] = np.convolve(ds_h.f_df[cdl], fn)[0:len(ds_h.f_df)]
  File "/usr/local/lib/python2.7/dist-packages/pandas/core/frame.py", line 1997, in __getitem__
    return self._getitem_column(key)
  File "/usr/local/lib/python2.7/dist-packages/pandas/core/frame.py", line 2004, in _getitem_column
    return self._get_item_cache(key)
  File "/usr/local/lib/python2.7/dist-packages/pandas/core/generic.py", line 1350, in _get_item_cache
    values = self._data.get(item)
  File "/usr/local/lib/python2.7/dist-packages/pandas/core/internals.py", line 3290, in get
    loc = self.items.get_loc(item)
  File "/usr/local/lib/python2.7/dist-packages/pandas/indexes/base.py", line 1947, in get_loc
    return self._engine.get_loc(self._maybe_cast_indexer(key))
  File "pandas/index.pyx", line 137, in pandas.index.IndexEngine.get_loc (pandas/index.c:4154)
  File "pandas/index.pyx", line 159, in pandas.index.IndexEngine.get_loc (pandas/index.c:4018)
  File "pandas/hashtable.pyx", line 675, in pandas.hashtable.PyObjectHashTable.get_item (pandas/hashtable.c:12368)
  File "pandas/hashtable.pyx", line 683, in pandas.hashtable.PyObjectHashTable.get_item (pandas/hashtable.c:12322)
KeyError: 'CDLTASUKIGAP>'
2019-04-28 12:59:56,149 - default - ERROR - Exception occurred
Traceback (most recent call last):
  File "Trading/Dataset/DatasetHolder.py", line 265, in appendTimeframesIntoOneDataset
    ds_h.f_df[cdl] = np.convolve(ds_h.f_df[cdl], fn)[0:len(ds_h.f_df)]
  File "/usr/local/lib/python2.7/dist-packages/pandas/core/frame.py", line 1997, in __getitem__
    return self._getitem_column(key)
  File "/usr/local/lib/python2.7/dist-packages/pandas/core/frame.py", line 2004, in _getitem_column
    return self._get_item_cache(key)
  File "/usr/local/lib/python2.7/dist-packages/pandas/core/generic.py", line 1350, in _get_item_cache
    values = self._data.get(item)
  File "/usr/local/lib/python2.7/dist-packages/pandas/core/internals.py", line 3290, in get
    loc = self.items.get_loc(item)
  File "/usr/local/lib/python2.7/dist-packages/pandas/indexes/base.py", line 1947, in get_loc
    return self._engine.get_loc(self._maybe_cast_indexer(key))
  File "pandas/index.pyx", line 137, in pandas.index.IndexEngine.get_loc (pandas/index.c:4154)
  File "pandas/index.pyx", line 159, in pandas.index.IndexEngine.get_loc (pandas/index.c:4018)
  File "pandas/hashtable.pyx", line 675, in pandas.hashtable.PyObjectHashTable.get_item (pandas/hashtable.c:12368)
  File "pandas/hashtable.pyx", line 683, in pandas.hashtable.PyObjectHashTable.get_item (pandas/hashtable.c:12322)
KeyError: 'CDLTHRUSTING>'
2019-04-28 12:59:56,154 - default - ERROR - Exception occurred
Traceback (most recent call last):
  File "Trading/Dataset/DatasetHolder.py", line 265, in appendTimeframesIntoOneDataset
    ds_h.f_df[cdl] = np.convolve(ds_h.f_df[cdl], fn)[0:len(ds_h.f_df)]
  File "/usr/local/lib/python2.7/dist-packages/pandas/core/frame.py", line 1997, in __getitem__
    return self._getitem_column(key)
  File "/usr/local/lib/python2.7/dist-packages/pandas/core/frame.py", line 2004, in _getitem_column
    return self._get_item_cache(key)
  File "/usr/local/lib/python2.7/dist-packages/pandas/core/generic.py", line 1350, in _get_item_cache
    values = self._data.get(item)
  File "/usr/local/lib/python2.7/dist-packages/pandas/core/internals.py", line 3290, in get
    loc = self.items.get_loc(item)
  File "/usr/local/lib/python2.7/dist-packages/pandas/indexes/base.py", line 1947, in get_loc
    return self._engine.get_loc(self._maybe_cast_indexer(key))
  File "pandas/index.pyx", line 137, in pandas.index.IndexEngine.get_loc (pandas/index.c:4154)
  File "pandas/index.pyx", line 159, in pandas.index.IndexEngine.get_loc (pandas/index.c:4018)
  File "pandas/hashtable.pyx", line 675, in pandas.hashtable.PyObjectHashTable.get_item (pandas/hashtable.c:12368)
  File "pandas/hashtable.pyx", line 683, in pandas.hashtable.PyObjectHashTable.get_item (pandas/hashtable.c:12322)
KeyError: 'CDLTRISTAR>'
2019-04-28 12:59:56,157 - default - ERROR - Exception occurred
Traceback (most recent call last):
  File "Trading/Dataset/DatasetHolder.py", line 265, in appendTimeframesIntoOneDataset
    ds_h.f_df[cdl] = np.convolve(ds_h.f_df[cdl], fn)[0:len(ds_h.f_df)]
  File "/usr/local/lib/python2.7/dist-packages/pandas/core/frame.py", line 1997, in __getitem__
    return self._getitem_column(key)
  File "/usr/local/lib/python2.7/dist-packages/pandas/core/frame.py", line 2004, in _getitem_column
    return self._get_item_cache(key)
  File "/usr/local/lib/python2.7/dist-packages/pandas/core/generic.py", line 1350, in _get_item_cache
    values = self._data.get(item)
  File "/usr/local/lib/python2.7/dist-packages/pandas/core/internals.py", line 3290, in get
    loc = self.items.get_loc(item)
  File "/usr/local/lib/python2.7/dist-packages/pandas/indexes/base.py", line 1947, in get_loc
    return self._engine.get_loc(self._maybe_cast_indexer(key))
  File "pandas/index.pyx", line 137, in pandas.index.IndexEngine.get_loc (pandas/index.c:4154)
  File "pandas/index.pyx", line 159, in pandas.index.IndexEngine.get_loc (pandas/index.c:4018)
  File "pandas/hashtable.pyx", line 675, in pandas.hashtable.PyObjectHashTable.get_item (pandas/hashtable.c:12368)
  File "pandas/hashtable.pyx", line 683, in pandas.hashtable.PyObjectHashTable.get_item (pandas/hashtable.c:12322)
KeyError: 'CDLUNIQUE3RIVER>'
2019-04-28 12:59:56,160 - default - ERROR - Exception occurred
Traceback (most recent call last):
  File "Trading/Dataset/DatasetHolder.py", line 265, in appendTimeframesIntoOneDataset
    ds_h.f_df[cdl] = np.convolve(ds_h.f_df[cdl], fn)[0:len(ds_h.f_df)]
  File "/usr/local/lib/python2.7/dist-packages/pandas/core/frame.py", line 1997, in __getitem__
    return self._getitem_column(key)
  File "/usr/local/lib/python2.7/dist-packages/pandas/core/frame.py", line 2004, in _getitem_column
    return self._get_item_cache(key)
  File "/usr/local/lib/python2.7/dist-packages/pandas/core/generic.py", line 1350, in _get_item_cache
    values = self._data.get(item)
  File "/usr/local/lib/python2.7/dist-packages/pandas/core/internals.py", line 3290, in get
    loc = self.items.get_loc(item)
  File "/usr/local/lib/python2.7/dist-packages/pandas/indexes/base.py", line 1947, in get_loc
    return self._engine.get_loc(self._maybe_cast_indexer(key))
  File "pandas/index.pyx", line 137, in pandas.index.IndexEngine.get_loc (pandas/index.c:4154)
  File "pandas/index.pyx", line 159, in pandas.index.IndexEngine.get_loc (pandas/index.c:4018)
  File "pandas/hashtable.pyx", line 675, in pandas.hashtable.PyObjectHashTable.get_item (pandas/hashtable.c:12368)
  File "pandas/hashtable.pyx", line 683, in pandas.hashtable.PyObjectHashTable.get_item (pandas/hashtable.c:12322)
KeyError: 'CDLUPSIDEGAP2CROWS>'
2019-04-28 12:59:56,163 - default - ERROR - Exception occurred
Traceback (most recent call last):
  File "Trading/Dataset/DatasetHolder.py", line 265, in appendTimeframesIntoOneDataset
    ds_h.f_df[cdl] = np.convolve(ds_h.f_df[cdl], fn)[0:len(ds_h.f_df)]
  File "/usr/local/lib/python2.7/dist-packages/pandas/core/frame.py", line 1997, in __getitem__
    return self._getitem_column(key)
  File "/usr/local/lib/python2.7/dist-packages/pandas/core/frame.py", line 2004, in _getitem_column
    return self._get_item_cache(key)
  File "/usr/local/lib/python2.7/dist-packages/pandas/core/generic.py", line 1350, in _get_item_cache
    values = self._data.get(item)
  File "/usr/local/lib/python2.7/dist-packages/pandas/core/internals.py", line 3290, in get
    loc = self.items.get_loc(item)
  File "/usr/local/lib/python2.7/dist-packages/pandas/indexes/base.py", line 1947, in get_loc
    return self._engine.get_loc(self._maybe_cast_indexer(key))
  File "pandas/index.pyx", line 137, in pandas.index.IndexEngine.get_loc (pandas/index.c:4154)
  File "pandas/index.pyx", line 159, in pandas.index.IndexEngine.get_loc (pandas/index.c:4018)
  File "pandas/hashtable.pyx", line 675, in pandas.hashtable.PyObjectHashTable.get_item (pandas/hashtable.c:12368)
  File "pandas/hashtable.pyx", line 683, in pandas.hashtable.PyObjectHashTable.get_item (pandas/hashtable.c:12322)
KeyError: 'CDLXSIDEGAP3METHODS>'
