2018-12-23 21:38:05,254 - default - ERROR - Exception occurred
Traceback (most recent call last):
  File "Trading/Dataset/DatasetHolder.py", line 258, in appendTimeframesIntoOneDataset
    ds_l.f_df[cdl] = np.convolve(ds_l.f_df[cdl], fn)[0:len(ds_l.f_df)]
  File "/usr/local/lib/python2.7/dist-packages/pandas/core/frame.py", line 1997, in __getitem__
    return self._getitem_column(key)
  File "/usr/local/lib/python2.7/dist-packages/pandas/core/frame.py", line 2004, in _getitem_column
    return self._get_item_cache(key)
  File "/usr/local/lib/python2.7/dist-packages/pandas/core/generic.py", line 1350, in _get_item_cache
    values = self._data.get(item)
  File "/usr/local/lib/python2.7/dist-packages/pandas/core/internals.py", line 3290, in get
    loc = self.items.get_loc(item)
  File "/usr/local/lib/python2.7/dist-packages/pandas/indexes/base.py", line 1947, in get_loc
    return self._engine.get_loc(self._maybe_cast_indexer(key))
  File "pandas/index.pyx", line 137, in pandas.index.IndexEngine.get_loc (pandas/index.c:4154)
  File "pandas/index.pyx", line 159, in pandas.index.IndexEngine.get_loc (pandas/index.c:4018)
  File "pandas/hashtable.pyx", line 675, in pandas.hashtable.PyObjectHashTable.get_item (pandas/hashtable.c:12368)
  File "pandas/hashtable.pyx", line 683, in pandas.hashtable.PyObjectHashTable.get_item (pandas/hashtable.c:12322)
KeyError: 'CDL2CROW'
2018-12-23 21:38:05,260 - default - ERROR - Exception occurred
Traceback (most recent call last):
  File "Trading/Dataset/DatasetHolder.py", line 258, in appendTimeframesIntoOneDataset
    ds_l.f_df[cdl] = np.convolve(ds_l.f_df[cdl], fn)[0:len(ds_l.f_df)]
  File "/usr/local/lib/python2.7/dist-packages/pandas/core/frame.py", line 1997, in __getitem__
    return self._getitem_column(key)
  File "/usr/local/lib/python2.7/dist-packages/pandas/core/frame.py", line 2004, in _getitem_column
    return self._get_item_cache(key)
  File "/usr/local/lib/python2.7/dist-packages/pandas/core/generic.py", line 1350, in _get_item_cache
    values = self._data.get(item)
  File "/usr/local/lib/python2.7/dist-packages/pandas/core/internals.py", line 3290, in get
    loc = self.items.get_loc(item)
  File "/usr/local/lib/python2.7/dist-packages/pandas/indexes/base.py", line 1947, in get_loc
    return self._engine.get_loc(self._maybe_cast_indexer(key))
  File "pandas/index.pyx", line 137, in pandas.index.IndexEngine.get_loc (pandas/index.c:4154)
  File "pandas/index.pyx", line 159, in pandas.index.IndexEngine.get_loc (pandas/index.c:4018)
  File "pandas/hashtable.pyx", line 675, in pandas.hashtable.PyObjectHashTable.get_item (pandas/hashtable.c:12368)
  File "pandas/hashtable.pyx", line 683, in pandas.hashtable.PyObjectHashTable.get_item (pandas/hashtable.c:12322)
KeyError: 'CDL3BLACKCROW'
2018-12-23 21:38:05,267 - default - ERROR - Exception occurred
Traceback (most recent call last):
  File "Trading/Dataset/DatasetHolder.py", line 258, in appendTimeframesIntoOneDataset
    ds_l.f_df[cdl] = np.convolve(ds_l.f_df[cdl], fn)[0:len(ds_l.f_df)]
  File "/usr/local/lib/python2.7/dist-packages/pandas/core/frame.py", line 1997, in __getitem__
    return self._getitem_column(key)
  File "/usr/local/lib/python2.7/dist-packages/pandas/core/frame.py", line 2004, in _getitem_column
    return self._get_item_cache(key)
  File "/usr/local/lib/python2.7/dist-packages/pandas/core/generic.py", line 1350, in _get_item_cache
    values = self._data.get(item)
  File "/usr/local/lib/python2.7/dist-packages/pandas/core/internals.py", line 3290, in get
    loc = self.items.get_loc(item)
  File "/usr/local/lib/python2.7/dist-packages/pandas/indexes/base.py", line 1947, in get_loc
    return self._engine.get_loc(self._maybe_cast_indexer(key))
  File "pandas/index.pyx", line 137, in pandas.index.IndexEngine.get_loc (pandas/index.c:4154)
  File "pandas/index.pyx", line 159, in pandas.index.IndexEngine.get_loc (pandas/index.c:4018)
  File "pandas/hashtable.pyx", line 675, in pandas.hashtable.PyObjectHashTable.get_item (pandas/hashtable.c:12368)
  File "pandas/hashtable.pyx", line 683, in pandas.hashtable.PyObjectHashTable.get_item (pandas/hashtable.c:12322)
KeyError: 'CDL3INSID'
2018-12-23 21:38:05,274 - default - ERROR - Exception occurred
Traceback (most recent call last):
  File "Trading/Dataset/DatasetHolder.py", line 258, in appendTimeframesIntoOneDataset
    ds_l.f_df[cdl] = np.convolve(ds_l.f_df[cdl], fn)[0:len(ds_l.f_df)]
  File "/usr/local/lib/python2.7/dist-packages/pandas/core/frame.py", line 1997, in __getitem__
    return self._getitem_column(key)
  File "/usr/local/lib/python2.7/dist-packages/pandas/core/frame.py", line 2004, in _getitem_column
    return self._get_item_cache(key)
  File "/usr/local/lib/python2.7/dist-packages/pandas/core/generic.py", line 1350, in _get_item_cache
    values = self._data.get(item)
  File "/usr/local/lib/python2.7/dist-packages/pandas/core/internals.py", line 3290, in get
    loc = self.items.get_loc(item)
  File "/usr/local/lib/python2.7/dist-packages/pandas/indexes/base.py", line 1947, in get_loc
    return self._engine.get_loc(self._maybe_cast_indexer(key))
  File "pandas/index.pyx", line 137, in pandas.index.IndexEngine.get_loc (pandas/index.c:4154)
  File "pandas/index.pyx", line 159, in pandas.index.IndexEngine.get_loc (pandas/index.c:4018)
  File "pandas/hashtable.pyx", line 675, in pandas.hashtable.PyObjectHashTable.get_item (pandas/hashtable.c:12368)
  File "pandas/hashtable.pyx", line 683, in pandas.hashtable.PyObjectHashTable.get_item (pandas/hashtable.c:12322)
KeyError: 'CDL3LINESTRIK'
2018-12-23 21:38:05,284 - default - ERROR - Exception occurred
Traceback (most recent call last):
  File "Trading/Dataset/DatasetHolder.py", line 258, in appendTimeframesIntoOneDataset
    ds_l.f_df[cdl] = np.convolve(ds_l.f_df[cdl], fn)[0:len(ds_l.f_df)]
  File "/usr/local/lib/python2.7/dist-packages/pandas/core/frame.py", line 1997, in __getitem__
    return self._getitem_column(key)
  File "/usr/local/lib/python2.7/dist-packages/pandas/core/frame.py", line 2004, in _getitem_column
    return self._get_item_cache(key)
  File "/usr/local/lib/python2.7/dist-packages/pandas/core/generic.py", line 1350, in _get_item_cache
    values = self._data.get(item)
  File "/usr/local/lib/python2.7/dist-packages/pandas/core/internals.py", line 3290, in get
    loc = self.items.get_loc(item)
  File "/usr/local/lib/python2.7/dist-packages/pandas/indexes/base.py", line 1947, in get_loc
    return self._engine.get_loc(self._maybe_cast_indexer(key))
  File "pandas/index.pyx", line 137, in pandas.index.IndexEngine.get_loc (pandas/index.c:4154)
  File "pandas/index.pyx", line 159, in pandas.index.IndexEngine.get_loc (pandas/index.c:4018)
  File "pandas/hashtable.pyx", line 675, in pandas.hashtable.PyObjectHashTable.get_item (pandas/hashtable.c:12368)
  File "pandas/hashtable.pyx", line 683, in pandas.hashtable.PyObjectHashTable.get_item (pandas/hashtable.c:12322)
KeyError: 'CDL3OUTSID'
2018-12-23 21:38:05,292 - default - ERROR - Exception occurred
Traceback (most recent call last):
  File "Trading/Dataset/DatasetHolder.py", line 258, in appendTimeframesIntoOneDataset
    ds_l.f_df[cdl] = np.convolve(ds_l.f_df[cdl], fn)[0:len(ds_l.f_df)]
  File "/usr/local/lib/python2.7/dist-packages/pandas/core/frame.py", line 1997, in __getitem__
    return self._getitem_column(key)
  File "/usr/local/lib/python2.7/dist-packages/pandas/core/frame.py", line 2004, in _getitem_column
    return self._get_item_cache(key)
  File "/usr/local/lib/python2.7/dist-packages/pandas/core/generic.py", line 1350, in _get_item_cache
    values = self._data.get(item)
  File "/usr/local/lib/python2.7/dist-packages/pandas/core/internals.py", line 3290, in get
    loc = self.items.get_loc(item)
  File "/usr/local/lib/python2.7/dist-packages/pandas/indexes/base.py", line 1947, in get_loc
    return self._engine.get_loc(self._maybe_cast_indexer(key))
  File "pandas/index.pyx", line 137, in pandas.index.IndexEngine.get_loc (pandas/index.c:4154)
  File "pandas/index.pyx", line 159, in pandas.index.IndexEngine.get_loc (pandas/index.c:4018)
  File "pandas/hashtable.pyx", line 675, in pandas.hashtable.PyObjectHashTable.get_item (pandas/hashtable.c:12368)
  File "pandas/hashtable.pyx", line 683, in pandas.hashtable.PyObjectHashTable.get_item (pandas/hashtable.c:12322)
KeyError: 'CDL3STARSINSOUT'
2018-12-23 21:38:05,299 - default - ERROR - Exception occurred
Traceback (most recent call last):
  File "Trading/Dataset/DatasetHolder.py", line 258, in appendTimeframesIntoOneDataset
    ds_l.f_df[cdl] = np.convolve(ds_l.f_df[cdl], fn)[0:len(ds_l.f_df)]
  File "/usr/local/lib/python2.7/dist-packages/pandas/core/frame.py", line 1997, in __getitem__
    return self._getitem_column(key)
  File "/usr/local/lib/python2.7/dist-packages/pandas/core/frame.py", line 2004, in _getitem_column
    return self._get_item_cache(key)
  File "/usr/local/lib/python2.7/dist-packages/pandas/core/generic.py", line 1350, in _get_item_cache
    values = self._data.get(item)
  File "/usr/local/lib/python2.7/dist-packages/pandas/core/internals.py", line 3290, in get
    loc = self.items.get_loc(item)
  File "/usr/local/lib/python2.7/dist-packages/pandas/indexes/base.py", line 1947, in get_loc
    return self._engine.get_loc(self._maybe_cast_indexer(key))
  File "pandas/index.pyx", line 137, in pandas.index.IndexEngine.get_loc (pandas/index.c:4154)
  File "pandas/index.pyx", line 159, in pandas.index.IndexEngine.get_loc (pandas/index.c:4018)
  File "pandas/hashtable.pyx", line 675, in pandas.hashtable.PyObjectHashTable.get_item (pandas/hashtable.c:12368)
  File "pandas/hashtable.pyx", line 683, in pandas.hashtable.PyObjectHashTable.get_item (pandas/hashtable.c:12322)
KeyError: 'CDL3WHITESOLDIER'
2018-12-23 21:38:05,305 - default - ERROR - Exception occurred
Traceback (most recent call last):
  File "Trading/Dataset/DatasetHolder.py", line 258, in appendTimeframesIntoOneDataset
    ds_l.f_df[cdl] = np.convolve(ds_l.f_df[cdl], fn)[0:len(ds_l.f_df)]
  File "/usr/local/lib/python2.7/dist-packages/pandas/core/frame.py", line 1997, in __getitem__
    return self._getitem_column(key)
  File "/usr/local/lib/python2.7/dist-packages/pandas/core/frame.py", line 2004, in _getitem_column
    return self._get_item_cache(key)
  File "/usr/local/lib/python2.7/dist-packages/pandas/core/generic.py", line 1350, in _get_item_cache
    values = self._data.get(item)
  File "/usr/local/lib/python2.7/dist-packages/pandas/core/internals.py", line 3290, in get
    loc = self.items.get_loc(item)
  File "/usr/local/lib/python2.7/dist-packages/pandas/indexes/base.py", line 1947, in get_loc
    return self._engine.get_loc(self._maybe_cast_indexer(key))
  File "pandas/index.pyx", line 137, in pandas.index.IndexEngine.get_loc (pandas/index.c:4154)
  File "pandas/index.pyx", line 159, in pandas.index.IndexEngine.get_loc (pandas/index.c:4018)
  File "pandas/hashtable.pyx", line 675, in pandas.hashtable.PyObjectHashTable.get_item (pandas/hashtable.c:12368)
  File "pandas/hashtable.pyx", line 683, in pandas.hashtable.PyObjectHashTable.get_item (pandas/hashtable.c:12322)
KeyError: 'CDLABANDONEDBAB'
2018-12-23 21:38:05,313 - default - ERROR - Exception occurred
Traceback (most recent call last):
  File "Trading/Dataset/DatasetHolder.py", line 258, in appendTimeframesIntoOneDataset
    ds_l.f_df[cdl] = np.convolve(ds_l.f_df[cdl], fn)[0:len(ds_l.f_df)]
  File "/usr/local/lib/python2.7/dist-packages/pandas/core/frame.py", line 1997, in __getitem__
    return self._getitem_column(key)
  File "/usr/local/lib/python2.7/dist-packages/pandas/core/frame.py", line 2004, in _getitem_column
    return self._get_item_cache(key)
  File "/usr/local/lib/python2.7/dist-packages/pandas/core/generic.py", line 1350, in _get_item_cache
    values = self._data.get(item)
  File "/usr/local/lib/python2.7/dist-packages/pandas/core/internals.py", line 3290, in get
    loc = self.items.get_loc(item)
  File "/usr/local/lib/python2.7/dist-packages/pandas/indexes/base.py", line 1947, in get_loc
    return self._engine.get_loc(self._maybe_cast_indexer(key))
  File "pandas/index.pyx", line 137, in pandas.index.IndexEngine.get_loc (pandas/index.c:4154)
  File "pandas/index.pyx", line 159, in pandas.index.IndexEngine.get_loc (pandas/index.c:4018)
  File "pandas/hashtable.pyx", line 675, in pandas.hashtable.PyObjectHashTable.get_item (pandas/hashtable.c:12368)
  File "pandas/hashtable.pyx", line 683, in pandas.hashtable.PyObjectHashTable.get_item (pandas/hashtable.c:12322)
KeyError: 'CDLADVANCEBLOC'
2018-12-23 21:38:05,320 - default - ERROR - Exception occurred
Traceback (most recent call last):
  File "Trading/Dataset/DatasetHolder.py", line 258, in appendTimeframesIntoOneDataset
    ds_l.f_df[cdl] = np.convolve(ds_l.f_df[cdl], fn)[0:len(ds_l.f_df)]
  File "/usr/local/lib/python2.7/dist-packages/pandas/core/frame.py", line 1997, in __getitem__
    return self._getitem_column(key)
  File "/usr/local/lib/python2.7/dist-packages/pandas/core/frame.py", line 2004, in _getitem_column
    return self._get_item_cache(key)
  File "/usr/local/lib/python2.7/dist-packages/pandas/core/generic.py", line 1350, in _get_item_cache
    values = self._data.get(item)
  File "/usr/local/lib/python2.7/dist-packages/pandas/core/internals.py", line 3290, in get
    loc = self.items.get_loc(item)
  File "/usr/local/lib/python2.7/dist-packages/pandas/indexes/base.py", line 1947, in get_loc
    return self._engine.get_loc(self._maybe_cast_indexer(key))
  File "pandas/index.pyx", line 137, in pandas.index.IndexEngine.get_loc (pandas/index.c:4154)
  File "pandas/index.pyx", line 159, in pandas.index.IndexEngine.get_loc (pandas/index.c:4018)
  File "pandas/hashtable.pyx", line 675, in pandas.hashtable.PyObjectHashTable.get_item (pandas/hashtable.c:12368)
  File "pandas/hashtable.pyx", line 683, in pandas.hashtable.PyObjectHashTable.get_item (pandas/hashtable.c:12322)
KeyError: 'CDLBELTHOL'
2018-12-23 21:38:05,328 - default - ERROR - Exception occurred
Traceback (most recent call last):
  File "Trading/Dataset/DatasetHolder.py", line 258, in appendTimeframesIntoOneDataset
    ds_l.f_df[cdl] = np.convolve(ds_l.f_df[cdl], fn)[0:len(ds_l.f_df)]
  File "/usr/local/lib/python2.7/dist-packages/pandas/core/frame.py", line 1997, in __getitem__
    return self._getitem_column(key)
  File "/usr/local/lib/python2.7/dist-packages/pandas/core/frame.py", line 2004, in _getitem_column
    return self._get_item_cache(key)
  File "/usr/local/lib/python2.7/dist-packages/pandas/core/generic.py", line 1350, in _get_item_cache
    values = self._data.get(item)
  File "/usr/local/lib/python2.7/dist-packages/pandas/core/internals.py", line 3290, in get
    loc = self.items.get_loc(item)
  File "/usr/local/lib/python2.7/dist-packages/pandas/indexes/base.py", line 1947, in get_loc
    return self._engine.get_loc(self._maybe_cast_indexer(key))
  File "pandas/index.pyx", line 137, in pandas.index.IndexEngine.get_loc (pandas/index.c:4154)
  File "pandas/index.pyx", line 159, in pandas.index.IndexEngine.get_loc (pandas/index.c:4018)
  File "pandas/hashtable.pyx", line 675, in pandas.hashtable.PyObjectHashTable.get_item (pandas/hashtable.c:12368)
  File "pandas/hashtable.pyx", line 683, in pandas.hashtable.PyObjectHashTable.get_item (pandas/hashtable.c:12322)
KeyError: 'CDLBREAKAWA'
2018-12-23 21:38:05,334 - default - ERROR - Exception occurred
Traceback (most recent call last):
  File "Trading/Dataset/DatasetHolder.py", line 258, in appendTimeframesIntoOneDataset
    ds_l.f_df[cdl] = np.convolve(ds_l.f_df[cdl], fn)[0:len(ds_l.f_df)]
  File "/usr/local/lib/python2.7/dist-packages/pandas/core/frame.py", line 1997, in __getitem__
    return self._getitem_column(key)
  File "/usr/local/lib/python2.7/dist-packages/pandas/core/frame.py", line 2004, in _getitem_column
    return self._get_item_cache(key)
  File "/usr/local/lib/python2.7/dist-packages/pandas/core/generic.py", line 1350, in _get_item_cache
    values = self._data.get(item)
  File "/usr/local/lib/python2.7/dist-packages/pandas/core/internals.py", line 3290, in get
    loc = self.items.get_loc(item)
  File "/usr/local/lib/python2.7/dist-packages/pandas/indexes/base.py", line 1947, in get_loc
    return self._engine.get_loc(self._maybe_cast_indexer(key))
  File "pandas/index.pyx", line 137, in pandas.index.IndexEngine.get_loc (pandas/index.c:4154)
  File "pandas/index.pyx", line 159, in pandas.index.IndexEngine.get_loc (pandas/index.c:4018)
  File "pandas/hashtable.pyx", line 675, in pandas.hashtable.PyObjectHashTable.get_item (pandas/hashtable.c:12368)
  File "pandas/hashtable.pyx", line 683, in pandas.hashtable.PyObjectHashTable.get_item (pandas/hashtable.c:12322)
KeyError: 'CDLCLOSINGMARUBOZ'
2018-12-23 21:38:05,342 - default - ERROR - Exception occurred
Traceback (most recent call last):
  File "Trading/Dataset/DatasetHolder.py", line 258, in appendTimeframesIntoOneDataset
    ds_l.f_df[cdl] = np.convolve(ds_l.f_df[cdl], fn)[0:len(ds_l.f_df)]
  File "/usr/local/lib/python2.7/dist-packages/pandas/core/frame.py", line 1997, in __getitem__
    return self._getitem_column(key)
  File "/usr/local/lib/python2.7/dist-packages/pandas/core/frame.py", line 2004, in _getitem_column
    return self._get_item_cache(key)
  File "/usr/local/lib/python2.7/dist-packages/pandas/core/generic.py", line 1350, in _get_item_cache
    values = self._data.get(item)
  File "/usr/local/lib/python2.7/dist-packages/pandas/core/internals.py", line 3290, in get
    loc = self.items.get_loc(item)
  File "/usr/local/lib/python2.7/dist-packages/pandas/indexes/base.py", line 1947, in get_loc
    return self._engine.get_loc(self._maybe_cast_indexer(key))
  File "pandas/index.pyx", line 137, in pandas.index.IndexEngine.get_loc (pandas/index.c:4154)
  File "pandas/index.pyx", line 159, in pandas.index.IndexEngine.get_loc (pandas/index.c:4018)
  File "pandas/hashtable.pyx", line 675, in pandas.hashtable.PyObjectHashTable.get_item (pandas/hashtable.c:12368)
  File "pandas/hashtable.pyx", line 683, in pandas.hashtable.PyObjectHashTable.get_item (pandas/hashtable.c:12322)
KeyError: 'CDLCONCEALBABYSWAL'
2018-12-23 21:38:05,349 - default - ERROR - Exception occurred
Traceback (most recent call last):
  File "Trading/Dataset/DatasetHolder.py", line 258, in appendTimeframesIntoOneDataset
    ds_l.f_df[cdl] = np.convolve(ds_l.f_df[cdl], fn)[0:len(ds_l.f_df)]
  File "/usr/local/lib/python2.7/dist-packages/pandas/core/frame.py", line 1997, in __getitem__
    return self._getitem_column(key)
  File "/usr/local/lib/python2.7/dist-packages/pandas/core/frame.py", line 2004, in _getitem_column
    return self._get_item_cache(key)
  File "/usr/local/lib/python2.7/dist-packages/pandas/core/generic.py", line 1350, in _get_item_cache
    values = self._data.get(item)
  File "/usr/local/lib/python2.7/dist-packages/pandas/core/internals.py", line 3290, in get
    loc = self.items.get_loc(item)
  File "/usr/local/lib/python2.7/dist-packages/pandas/indexes/base.py", line 1947, in get_loc
    return self._engine.get_loc(self._maybe_cast_indexer(key))
  File "pandas/index.pyx", line 137, in pandas.index.IndexEngine.get_loc (pandas/index.c:4154)
  File "pandas/index.pyx", line 159, in pandas.index.IndexEngine.get_loc (pandas/index.c:4018)
  File "pandas/hashtable.pyx", line 675, in pandas.hashtable.PyObjectHashTable.get_item (pandas/hashtable.c:12368)
  File "pandas/hashtable.pyx", line 683, in pandas.hashtable.PyObjectHashTable.get_item (pandas/hashtable.c:12322)
KeyError: 'CDLCOUNTERATTAC'
2018-12-23 21:38:05,356 - default - ERROR - Exception occurred
Traceback (most recent call last):
  File "Trading/Dataset/DatasetHolder.py", line 258, in appendTimeframesIntoOneDataset
    ds_l.f_df[cdl] = np.convolve(ds_l.f_df[cdl], fn)[0:len(ds_l.f_df)]
  File "/usr/local/lib/python2.7/dist-packages/pandas/core/frame.py", line 1997, in __getitem__
    return self._getitem_column(key)
  File "/usr/local/lib/python2.7/dist-packages/pandas/core/frame.py", line 2004, in _getitem_column
    return self._get_item_cache(key)
  File "/usr/local/lib/python2.7/dist-packages/pandas/core/generic.py", line 1350, in _get_item_cache
    values = self._data.get(item)
  File "/usr/local/lib/python2.7/dist-packages/pandas/core/internals.py", line 3290, in get
    loc = self.items.get_loc(item)
  File "/usr/local/lib/python2.7/dist-packages/pandas/indexes/base.py", line 1947, in get_loc
    return self._engine.get_loc(self._maybe_cast_indexer(key))
  File "pandas/index.pyx", line 137, in pandas.index.IndexEngine.get_loc (pandas/index.c:4154)
  File "pandas/index.pyx", line 159, in pandas.index.IndexEngine.get_loc (pandas/index.c:4018)
  File "pandas/hashtable.pyx", line 675, in pandas.hashtable.PyObjectHashTable.get_item (pandas/hashtable.c:12368)
  File "pandas/hashtable.pyx", line 683, in pandas.hashtable.PyObjectHashTable.get_item (pandas/hashtable.c:12322)
KeyError: 'CDLDARKCLOUDCOVE'
2018-12-23 21:38:05,365 - default - ERROR - Exception occurred
Traceback (most recent call last):
  File "Trading/Dataset/DatasetHolder.py", line 258, in appendTimeframesIntoOneDataset
    ds_l.f_df[cdl] = np.convolve(ds_l.f_df[cdl], fn)[0:len(ds_l.f_df)]
  File "/usr/local/lib/python2.7/dist-packages/pandas/core/frame.py", line 1997, in __getitem__
    return self._getitem_column(key)
  File "/usr/local/lib/python2.7/dist-packages/pandas/core/frame.py", line 2004, in _getitem_column
    return self._get_item_cache(key)
  File "/usr/local/lib/python2.7/dist-packages/pandas/core/generic.py", line 1350, in _get_item_cache
    values = self._data.get(item)
  File "/usr/local/lib/python2.7/dist-packages/pandas/core/internals.py", line 3290, in get
    loc = self.items.get_loc(item)
  File "/usr/local/lib/python2.7/dist-packages/pandas/indexes/base.py", line 1947, in get_loc
    return self._engine.get_loc(self._maybe_cast_indexer(key))
  File "pandas/index.pyx", line 137, in pandas.index.IndexEngine.get_loc (pandas/index.c:4154)
  File "pandas/index.pyx", line 159, in pandas.index.IndexEngine.get_loc (pandas/index.c:4018)
  File "pandas/hashtable.pyx", line 675, in pandas.hashtable.PyObjectHashTable.get_item (pandas/hashtable.c:12368)
  File "pandas/hashtable.pyx", line 683, in pandas.hashtable.PyObjectHashTable.get_item (pandas/hashtable.c:12322)
KeyError: 'CDLDOJ'
2018-12-23 21:38:05,372 - default - ERROR - Exception occurred
Traceback (most recent call last):
  File "Trading/Dataset/DatasetHolder.py", line 258, in appendTimeframesIntoOneDataset
    ds_l.f_df[cdl] = np.convolve(ds_l.f_df[cdl], fn)[0:len(ds_l.f_df)]
  File "/usr/local/lib/python2.7/dist-packages/pandas/core/frame.py", line 1997, in __getitem__
    return self._getitem_column(key)
  File "/usr/local/lib/python2.7/dist-packages/pandas/core/frame.py", line 2004, in _getitem_column
    return self._get_item_cache(key)
  File "/usr/local/lib/python2.7/dist-packages/pandas/core/generic.py", line 1350, in _get_item_cache
    values = self._data.get(item)
  File "/usr/local/lib/python2.7/dist-packages/pandas/core/internals.py", line 3290, in get
    loc = self.items.get_loc(item)
  File "/usr/local/lib/python2.7/dist-packages/pandas/indexes/base.py", line 1947, in get_loc
    return self._engine.get_loc(self._maybe_cast_indexer(key))
  File "pandas/index.pyx", line 137, in pandas.index.IndexEngine.get_loc (pandas/index.c:4154)
  File "pandas/index.pyx", line 159, in pandas.index.IndexEngine.get_loc (pandas/index.c:4018)
  File "pandas/hashtable.pyx", line 675, in pandas.hashtable.PyObjectHashTable.get_item (pandas/hashtable.c:12368)
  File "pandas/hashtable.pyx", line 683, in pandas.hashtable.PyObjectHashTable.get_item (pandas/hashtable.c:12322)
KeyError: 'CDLDOJISTA'
2018-12-23 21:38:05,380 - default - ERROR - Exception occurred
Traceback (most recent call last):
  File "Trading/Dataset/DatasetHolder.py", line 258, in appendTimeframesIntoOneDataset
    ds_l.f_df[cdl] = np.convolve(ds_l.f_df[cdl], fn)[0:len(ds_l.f_df)]
  File "/usr/local/lib/python2.7/dist-packages/pandas/core/frame.py", line 1997, in __getitem__
    return self._getitem_column(key)
  File "/usr/local/lib/python2.7/dist-packages/pandas/core/frame.py", line 2004, in _getitem_column
    return self._get_item_cache(key)
  File "/usr/local/lib/python2.7/dist-packages/pandas/core/generic.py", line 1350, in _get_item_cache
    values = self._data.get(item)
  File "/usr/local/lib/python2.7/dist-packages/pandas/core/internals.py", line 3290, in get
    loc = self.items.get_loc(item)
  File "/usr/local/lib/python2.7/dist-packages/pandas/indexes/base.py", line 1947, in get_loc
    return self._engine.get_loc(self._maybe_cast_indexer(key))
  File "pandas/index.pyx", line 137, in pandas.index.IndexEngine.get_loc (pandas/index.c:4154)
  File "pandas/index.pyx", line 159, in pandas.index.IndexEngine.get_loc (pandas/index.c:4018)
  File "pandas/hashtable.pyx", line 675, in pandas.hashtable.PyObjectHashTable.get_item (pandas/hashtable.c:12368)
  File "pandas/hashtable.pyx", line 683, in pandas.hashtable.PyObjectHashTable.get_item (pandas/hashtable.c:12322)
KeyError: 'CDLDRAGONFLYDOJ'
2018-12-23 21:38:05,386 - default - ERROR - Exception occurred
Traceback (most recent call last):
  File "Trading/Dataset/DatasetHolder.py", line 258, in appendTimeframesIntoOneDataset
    ds_l.f_df[cdl] = np.convolve(ds_l.f_df[cdl], fn)[0:len(ds_l.f_df)]
  File "/usr/local/lib/python2.7/dist-packages/pandas/core/frame.py", line 1997, in __getitem__
    return self._getitem_column(key)
  File "/usr/local/lib/python2.7/dist-packages/pandas/core/frame.py", line 2004, in _getitem_column
    return self._get_item_cache(key)
  File "/usr/local/lib/python2.7/dist-packages/pandas/core/generic.py", line 1350, in _get_item_cache
    values = self._data.get(item)
  File "/usr/local/lib/python2.7/dist-packages/pandas/core/internals.py", line 3290, in get
    loc = self.items.get_loc(item)
  File "/usr/local/lib/python2.7/dist-packages/pandas/indexes/base.py", line 1947, in get_loc
    return self._engine.get_loc(self._maybe_cast_indexer(key))
  File "pandas/index.pyx", line 137, in pandas.index.IndexEngine.get_loc (pandas/index.c:4154)
  File "pandas/index.pyx", line 159, in pandas.index.IndexEngine.get_loc (pandas/index.c:4018)
  File "pandas/hashtable.pyx", line 675, in pandas.hashtable.PyObjectHashTable.get_item (pandas/hashtable.c:12368)
  File "pandas/hashtable.pyx", line 683, in pandas.hashtable.PyObjectHashTable.get_item (pandas/hashtable.c:12322)
KeyError: 'CDLENGULFIN'
2018-12-23 21:38:05,392 - default - ERROR - Exception occurred
Traceback (most recent call last):
  File "Trading/Dataset/DatasetHolder.py", line 258, in appendTimeframesIntoOneDataset
    ds_l.f_df[cdl] = np.convolve(ds_l.f_df[cdl], fn)[0:len(ds_l.f_df)]
  File "/usr/local/lib/python2.7/dist-packages/pandas/core/frame.py", line 1997, in __getitem__
    return self._getitem_column(key)
  File "/usr/local/lib/python2.7/dist-packages/pandas/core/frame.py", line 2004, in _getitem_column
    return self._get_item_cache(key)
  File "/usr/local/lib/python2.7/dist-packages/pandas/core/generic.py", line 1350, in _get_item_cache
    values = self._data.get(item)
  File "/usr/local/lib/python2.7/dist-packages/pandas/core/internals.py", line 3290, in get
    loc = self.items.get_loc(item)
  File "/usr/local/lib/python2.7/dist-packages/pandas/indexes/base.py", line 1947, in get_loc
    return self._engine.get_loc(self._maybe_cast_indexer(key))
  File "pandas/index.pyx", line 137, in pandas.index.IndexEngine.get_loc (pandas/index.c:4154)
  File "pandas/index.pyx", line 159, in pandas.index.IndexEngine.get_loc (pandas/index.c:4018)
  File "pandas/hashtable.pyx", line 675, in pandas.hashtable.PyObjectHashTable.get_item (pandas/hashtable.c:12368)
  File "pandas/hashtable.pyx", line 683, in pandas.hashtable.PyObjectHashTable.get_item (pandas/hashtable.c:12322)
KeyError: 'CDLEVENINGDOJISTA'
2018-12-23 21:38:05,399 - default - ERROR - Exception occurred
Traceback (most recent call last):
  File "Trading/Dataset/DatasetHolder.py", line 258, in appendTimeframesIntoOneDataset
    ds_l.f_df[cdl] = np.convolve(ds_l.f_df[cdl], fn)[0:len(ds_l.f_df)]
  File "/usr/local/lib/python2.7/dist-packages/pandas/core/frame.py", line 1997, in __getitem__
    return self._getitem_column(key)
  File "/usr/local/lib/python2.7/dist-packages/pandas/core/frame.py", line 2004, in _getitem_column
    return self._get_item_cache(key)
  File "/usr/local/lib/python2.7/dist-packages/pandas/core/generic.py", line 1350, in _get_item_cache
    values = self._data.get(item)
  File "/usr/local/lib/python2.7/dist-packages/pandas/core/internals.py", line 3290, in get
    loc = self.items.get_loc(item)
  File "/usr/local/lib/python2.7/dist-packages/pandas/indexes/base.py", line 1947, in get_loc
    return self._engine.get_loc(self._maybe_cast_indexer(key))
  File "pandas/index.pyx", line 137, in pandas.index.IndexEngine.get_loc (pandas/index.c:4154)
  File "pandas/index.pyx", line 159, in pandas.index.IndexEngine.get_loc (pandas/index.c:4018)
  File "pandas/hashtable.pyx", line 675, in pandas.hashtable.PyObjectHashTable.get_item (pandas/hashtable.c:12368)
  File "pandas/hashtable.pyx", line 683, in pandas.hashtable.PyObjectHashTable.get_item (pandas/hashtable.c:12322)
KeyError: 'CDLEVENINGSTA'
2018-12-23 21:38:05,404 - default - ERROR - Exception occurred
Traceback (most recent call last):
  File "Trading/Dataset/DatasetHolder.py", line 258, in appendTimeframesIntoOneDataset
    ds_l.f_df[cdl] = np.convolve(ds_l.f_df[cdl], fn)[0:len(ds_l.f_df)]
  File "/usr/local/lib/python2.7/dist-packages/pandas/core/frame.py", line 1997, in __getitem__
    return self._getitem_column(key)
  File "/usr/local/lib/python2.7/dist-packages/pandas/core/frame.py", line 2004, in _getitem_column
    return self._get_item_cache(key)
  File "/usr/local/lib/python2.7/dist-packages/pandas/core/generic.py", line 1350, in _get_item_cache
    values = self._data.get(item)
  File "/usr/local/lib/python2.7/dist-packages/pandas/core/internals.py", line 3290, in get
    loc = self.items.get_loc(item)
  File "/usr/local/lib/python2.7/dist-packages/pandas/indexes/base.py", line 1947, in get_loc
    return self._engine.get_loc(self._maybe_cast_indexer(key))
  File "pandas/index.pyx", line 137, in pandas.index.IndexEngine.get_loc (pandas/index.c:4154)
  File "pandas/index.pyx", line 159, in pandas.index.IndexEngine.get_loc (pandas/index.c:4018)
  File "pandas/hashtable.pyx", line 675, in pandas.hashtable.PyObjectHashTable.get_item (pandas/hashtable.c:12368)
  File "pandas/hashtable.pyx", line 683, in pandas.hashtable.PyObjectHashTable.get_item (pandas/hashtable.c:12322)
KeyError: 'CDLGAPSIDESIDEWHIT'
2018-12-23 21:38:05,411 - default - ERROR - Exception occurred
Traceback (most recent call last):
  File "Trading/Dataset/DatasetHolder.py", line 258, in appendTimeframesIntoOneDataset
    ds_l.f_df[cdl] = np.convolve(ds_l.f_df[cdl], fn)[0:len(ds_l.f_df)]
  File "/usr/local/lib/python2.7/dist-packages/pandas/core/frame.py", line 1997, in __getitem__
    return self._getitem_column(key)
  File "/usr/local/lib/python2.7/dist-packages/pandas/core/frame.py", line 2004, in _getitem_column
    return self._get_item_cache(key)
  File "/usr/local/lib/python2.7/dist-packages/pandas/core/generic.py", line 1350, in _get_item_cache
    values = self._data.get(item)
  File "/usr/local/lib/python2.7/dist-packages/pandas/core/internals.py", line 3290, in get
    loc = self.items.get_loc(item)
  File "/usr/local/lib/python2.7/dist-packages/pandas/indexes/base.py", line 1947, in get_loc
    return self._engine.get_loc(self._maybe_cast_indexer(key))
  File "pandas/index.pyx", line 137, in pandas.index.IndexEngine.get_loc (pandas/index.c:4154)
  File "pandas/index.pyx", line 159, in pandas.index.IndexEngine.get_loc (pandas/index.c:4018)
  File "pandas/hashtable.pyx", line 675, in pandas.hashtable.PyObjectHashTable.get_item (pandas/hashtable.c:12368)
  File "pandas/hashtable.pyx", line 683, in pandas.hashtable.PyObjectHashTable.get_item (pandas/hashtable.c:12322)
KeyError: 'CDLGRAVESTONEDOJ'
2018-12-23 21:38:05,417 - default - ERROR - Exception occurred
Traceback (most recent call last):
  File "Trading/Dataset/DatasetHolder.py", line 258, in appendTimeframesIntoOneDataset
    ds_l.f_df[cdl] = np.convolve(ds_l.f_df[cdl], fn)[0:len(ds_l.f_df)]
  File "/usr/local/lib/python2.7/dist-packages/pandas/core/frame.py", line 1997, in __getitem__
    return self._getitem_column(key)
  File "/usr/local/lib/python2.7/dist-packages/pandas/core/frame.py", line 2004, in _getitem_column
    return self._get_item_cache(key)
  File "/usr/local/lib/python2.7/dist-packages/pandas/core/generic.py", line 1350, in _get_item_cache
    values = self._data.get(item)
  File "/usr/local/lib/python2.7/dist-packages/pandas/core/internals.py", line 3290, in get
    loc = self.items.get_loc(item)
  File "/usr/local/lib/python2.7/dist-packages/pandas/indexes/base.py", line 1947, in get_loc
    return self._engine.get_loc(self._maybe_cast_indexer(key))
  File "pandas/index.pyx", line 137, in pandas.index.IndexEngine.get_loc (pandas/index.c:4154)
  File "pandas/index.pyx", line 159, in pandas.index.IndexEngine.get_loc (pandas/index.c:4018)
  File "pandas/hashtable.pyx", line 675, in pandas.hashtable.PyObjectHashTable.get_item (pandas/hashtable.c:12368)
  File "pandas/hashtable.pyx", line 683, in pandas.hashtable.PyObjectHashTable.get_item (pandas/hashtable.c:12322)
KeyError: 'CDLHAMME'
2018-12-23 21:38:05,424 - default - ERROR - Exception occurred
Traceback (most recent call last):
  File "Trading/Dataset/DatasetHolder.py", line 258, in appendTimeframesIntoOneDataset
    ds_l.f_df[cdl] = np.convolve(ds_l.f_df[cdl], fn)[0:len(ds_l.f_df)]
  File "/usr/local/lib/python2.7/dist-packages/pandas/core/frame.py", line 1997, in __getitem__
    return self._getitem_column(key)
  File "/usr/local/lib/python2.7/dist-packages/pandas/core/frame.py", line 2004, in _getitem_column
    return self._get_item_cache(key)
  File "/usr/local/lib/python2.7/dist-packages/pandas/core/generic.py", line 1350, in _get_item_cache
    values = self._data.get(item)
  File "/usr/local/lib/python2.7/dist-packages/pandas/core/internals.py", line 3290, in get
    loc = self.items.get_loc(item)
  File "/usr/local/lib/python2.7/dist-packages/pandas/indexes/base.py", line 1947, in get_loc
    return self._engine.get_loc(self._maybe_cast_indexer(key))
  File "pandas/index.pyx", line 137, in pandas.index.IndexEngine.get_loc (pandas/index.c:4154)
  File "pandas/index.pyx", line 159, in pandas.index.IndexEngine.get_loc (pandas/index.c:4018)
  File "pandas/hashtable.pyx", line 675, in pandas.hashtable.PyObjectHashTable.get_item (pandas/hashtable.c:12368)
  File "pandas/hashtable.pyx", line 683, in pandas.hashtable.PyObjectHashTable.get_item (pandas/hashtable.c:12322)
KeyError: 'CDLHANGINGMA'
2018-12-23 21:38:05,432 - default - ERROR - Exception occurred
Traceback (most recent call last):
  File "Trading/Dataset/DatasetHolder.py", line 258, in appendTimeframesIntoOneDataset
    ds_l.f_df[cdl] = np.convolve(ds_l.f_df[cdl], fn)[0:len(ds_l.f_df)]
  File "/usr/local/lib/python2.7/dist-packages/pandas/core/frame.py", line 1997, in __getitem__
    return self._getitem_column(key)
  File "/usr/local/lib/python2.7/dist-packages/pandas/core/frame.py", line 2004, in _getitem_column
    return self._get_item_cache(key)
  File "/usr/local/lib/python2.7/dist-packages/pandas/core/generic.py", line 1350, in _get_item_cache
    values = self._data.get(item)
  File "/usr/local/lib/python2.7/dist-packages/pandas/core/internals.py", line 3290, in get
    loc = self.items.get_loc(item)
  File "/usr/local/lib/python2.7/dist-packages/pandas/indexes/base.py", line 1947, in get_loc
    return self._engine.get_loc(self._maybe_cast_indexer(key))
  File "pandas/index.pyx", line 137, in pandas.index.IndexEngine.get_loc (pandas/index.c:4154)
  File "pandas/index.pyx", line 159, in pandas.index.IndexEngine.get_loc (pandas/index.c:4018)
  File "pandas/hashtable.pyx", line 675, in pandas.hashtable.PyObjectHashTable.get_item (pandas/hashtable.c:12368)
  File "pandas/hashtable.pyx", line 683, in pandas.hashtable.PyObjectHashTable.get_item (pandas/hashtable.c:12322)
KeyError: 'CDLHARAM'
2018-12-23 21:38:05,438 - default - ERROR - Exception occurred
Traceback (most recent call last):
  File "Trading/Dataset/DatasetHolder.py", line 258, in appendTimeframesIntoOneDataset
    ds_l.f_df[cdl] = np.convolve(ds_l.f_df[cdl], fn)[0:len(ds_l.f_df)]
  File "/usr/local/lib/python2.7/dist-packages/pandas/core/frame.py", line 1997, in __getitem__
    return self._getitem_column(key)
  File "/usr/local/lib/python2.7/dist-packages/pandas/core/frame.py", line 2004, in _getitem_column
    return self._get_item_cache(key)
  File "/usr/local/lib/python2.7/dist-packages/pandas/core/generic.py", line 1350, in _get_item_cache
    values = self._data.get(item)
  File "/usr/local/lib/python2.7/dist-packages/pandas/core/internals.py", line 3290, in get
    loc = self.items.get_loc(item)
  File "/usr/local/lib/python2.7/dist-packages/pandas/indexes/base.py", line 1947, in get_loc
    return self._engine.get_loc(self._maybe_cast_indexer(key))
  File "pandas/index.pyx", line 137, in pandas.index.IndexEngine.get_loc (pandas/index.c:4154)
  File "pandas/index.pyx", line 159, in pandas.index.IndexEngine.get_loc (pandas/index.c:4018)
  File "pandas/hashtable.pyx", line 675, in pandas.hashtable.PyObjectHashTable.get_item (pandas/hashtable.c:12368)
  File "pandas/hashtable.pyx", line 683, in pandas.hashtable.PyObjectHashTable.get_item (pandas/hashtable.c:12322)
KeyError: 'CDLHARAMICROS'
2018-12-23 21:38:05,445 - default - ERROR - Exception occurred
Traceback (most recent call last):
  File "Trading/Dataset/DatasetHolder.py", line 258, in appendTimeframesIntoOneDataset
    ds_l.f_df[cdl] = np.convolve(ds_l.f_df[cdl], fn)[0:len(ds_l.f_df)]
  File "/usr/local/lib/python2.7/dist-packages/pandas/core/frame.py", line 1997, in __getitem__
    return self._getitem_column(key)
  File "/usr/local/lib/python2.7/dist-packages/pandas/core/frame.py", line 2004, in _getitem_column
    return self._get_item_cache(key)
  File "/usr/local/lib/python2.7/dist-packages/pandas/core/generic.py", line 1350, in _get_item_cache
    values = self._data.get(item)
  File "/usr/local/lib/python2.7/dist-packages/pandas/core/internals.py", line 3290, in get
    loc = self.items.get_loc(item)
  File "/usr/local/lib/python2.7/dist-packages/pandas/indexes/base.py", line 1947, in get_loc
    return self._engine.get_loc(self._maybe_cast_indexer(key))
  File "pandas/index.pyx", line 137, in pandas.index.IndexEngine.get_loc (pandas/index.c:4154)
  File "pandas/index.pyx", line 159, in pandas.index.IndexEngine.get_loc (pandas/index.c:4018)
  File "pandas/hashtable.pyx", line 675, in pandas.hashtable.PyObjectHashTable.get_item (pandas/hashtable.c:12368)
  File "pandas/hashtable.pyx", line 683, in pandas.hashtable.PyObjectHashTable.get_item (pandas/hashtable.c:12322)
KeyError: 'CDLHIGHWAV'
2018-12-23 21:38:05,452 - default - ERROR - Exception occurred
Traceback (most recent call last):
  File "Trading/Dataset/DatasetHolder.py", line 258, in appendTimeframesIntoOneDataset
    ds_l.f_df[cdl] = np.convolve(ds_l.f_df[cdl], fn)[0:len(ds_l.f_df)]
  File "/usr/local/lib/python2.7/dist-packages/pandas/core/frame.py", line 1997, in __getitem__
    return self._getitem_column(key)
  File "/usr/local/lib/python2.7/dist-packages/pandas/core/frame.py", line 2004, in _getitem_column
    return self._get_item_cache(key)
  File "/usr/local/lib/python2.7/dist-packages/pandas/core/generic.py", line 1350, in _get_item_cache
    values = self._data.get(item)
  File "/usr/local/lib/python2.7/dist-packages/pandas/core/internals.py", line 3290, in get
    loc = self.items.get_loc(item)
  File "/usr/local/lib/python2.7/dist-packages/pandas/indexes/base.py", line 1947, in get_loc
    return self._engine.get_loc(self._maybe_cast_indexer(key))
  File "pandas/index.pyx", line 137, in pandas.index.IndexEngine.get_loc (pandas/index.c:4154)
  File "pandas/index.pyx", line 159, in pandas.index.IndexEngine.get_loc (pandas/index.c:4018)
  File "pandas/hashtable.pyx", line 675, in pandas.hashtable.PyObjectHashTable.get_item (pandas/hashtable.c:12368)
  File "pandas/hashtable.pyx", line 683, in pandas.hashtable.PyObjectHashTable.get_item (pandas/hashtable.c:12322)
KeyError: 'CDLHIKKAK'
2018-12-23 21:38:05,459 - default - ERROR - Exception occurred
Traceback (most recent call last):
  File "Trading/Dataset/DatasetHolder.py", line 258, in appendTimeframesIntoOneDataset
    ds_l.f_df[cdl] = np.convolve(ds_l.f_df[cdl], fn)[0:len(ds_l.f_df)]
  File "/usr/local/lib/python2.7/dist-packages/pandas/core/frame.py", line 1997, in __getitem__
    return self._getitem_column(key)
  File "/usr/local/lib/python2.7/dist-packages/pandas/core/frame.py", line 2004, in _getitem_column
    return self._get_item_cache(key)
  File "/usr/local/lib/python2.7/dist-packages/pandas/core/generic.py", line 1350, in _get_item_cache
    values = self._data.get(item)
  File "/usr/local/lib/python2.7/dist-packages/pandas/core/internals.py", line 3290, in get
    loc = self.items.get_loc(item)
  File "/usr/local/lib/python2.7/dist-packages/pandas/indexes/base.py", line 1947, in get_loc
    return self._engine.get_loc(self._maybe_cast_indexer(key))
  File "pandas/index.pyx", line 137, in pandas.index.IndexEngine.get_loc (pandas/index.c:4154)
  File "pandas/index.pyx", line 159, in pandas.index.IndexEngine.get_loc (pandas/index.c:4018)
  File "pandas/hashtable.pyx", line 675, in pandas.hashtable.PyObjectHashTable.get_item (pandas/hashtable.c:12368)
  File "pandas/hashtable.pyx", line 683, in pandas.hashtable.PyObjectHashTable.get_item (pandas/hashtable.c:12322)
KeyError: 'CDLHIKKAKEMO'
2018-12-23 21:38:05,465 - default - ERROR - Exception occurred
Traceback (most recent call last):
  File "Trading/Dataset/DatasetHolder.py", line 258, in appendTimeframesIntoOneDataset
    ds_l.f_df[cdl] = np.convolve(ds_l.f_df[cdl], fn)[0:len(ds_l.f_df)]
  File "/usr/local/lib/python2.7/dist-packages/pandas/core/frame.py", line 1997, in __getitem__
    return self._getitem_column(key)
  File "/usr/local/lib/python2.7/dist-packages/pandas/core/frame.py", line 2004, in _getitem_column
    return self._get_item_cache(key)
  File "/usr/local/lib/python2.7/dist-packages/pandas/core/generic.py", line 1350, in _get_item_cache
    values = self._data.get(item)
  File "/usr/local/lib/python2.7/dist-packages/pandas/core/internals.py", line 3290, in get
    loc = self.items.get_loc(item)
  File "/usr/local/lib/python2.7/dist-packages/pandas/indexes/base.py", line 1947, in get_loc
    return self._engine.get_loc(self._maybe_cast_indexer(key))
  File "pandas/index.pyx", line 137, in pandas.index.IndexEngine.get_loc (pandas/index.c:4154)
  File "pandas/index.pyx", line 159, in pandas.index.IndexEngine.get_loc (pandas/index.c:4018)
  File "pandas/hashtable.pyx", line 675, in pandas.hashtable.PyObjectHashTable.get_item (pandas/hashtable.c:12368)
  File "pandas/hashtable.pyx", line 683, in pandas.hashtable.PyObjectHashTable.get_item (pandas/hashtable.c:12322)
KeyError: 'CDLHOMINGPIGEO'
2018-12-23 21:38:05,476 - default - ERROR - Exception occurred
Traceback (most recent call last):
  File "Trading/Dataset/DatasetHolder.py", line 258, in appendTimeframesIntoOneDataset
    ds_l.f_df[cdl] = np.convolve(ds_l.f_df[cdl], fn)[0:len(ds_l.f_df)]
  File "/usr/local/lib/python2.7/dist-packages/pandas/core/frame.py", line 1997, in __getitem__
    return self._getitem_column(key)
  File "/usr/local/lib/python2.7/dist-packages/pandas/core/frame.py", line 2004, in _getitem_column
    return self._get_item_cache(key)
  File "/usr/local/lib/python2.7/dist-packages/pandas/core/generic.py", line 1350, in _get_item_cache
    values = self._data.get(item)
  File "/usr/local/lib/python2.7/dist-packages/pandas/core/internals.py", line 3290, in get
    loc = self.items.get_loc(item)
  File "/usr/local/lib/python2.7/dist-packages/pandas/indexes/base.py", line 1947, in get_loc
    return self._engine.get_loc(self._maybe_cast_indexer(key))
  File "pandas/index.pyx", line 137, in pandas.index.IndexEngine.get_loc (pandas/index.c:4154)
  File "pandas/index.pyx", line 159, in pandas.index.IndexEngine.get_loc (pandas/index.c:4018)
  File "pandas/hashtable.pyx", line 675, in pandas.hashtable.PyObjectHashTable.get_item (pandas/hashtable.c:12368)
  File "pandas/hashtable.pyx", line 683, in pandas.hashtable.PyObjectHashTable.get_item (pandas/hashtable.c:12322)
KeyError: 'CDLIDENTICAL3CROW'
2018-12-23 21:38:05,483 - default - ERROR - Exception occurred
Traceback (most recent call last):
  File "Trading/Dataset/DatasetHolder.py", line 258, in appendTimeframesIntoOneDataset
    ds_l.f_df[cdl] = np.convolve(ds_l.f_df[cdl], fn)[0:len(ds_l.f_df)]
  File "/usr/local/lib/python2.7/dist-packages/pandas/core/frame.py", line 1997, in __getitem__
    return self._getitem_column(key)
  File "/usr/local/lib/python2.7/dist-packages/pandas/core/frame.py", line 2004, in _getitem_column
    return self._get_item_cache(key)
  File "/usr/local/lib/python2.7/dist-packages/pandas/core/generic.py", line 1350, in _get_item_cache
    values = self._data.get(item)
  File "/usr/local/lib/python2.7/dist-packages/pandas/core/internals.py", line 3290, in get
    loc = self.items.get_loc(item)
  File "/usr/local/lib/python2.7/dist-packages/pandas/indexes/base.py", line 1947, in get_loc
    return self._engine.get_loc(self._maybe_cast_indexer(key))
  File "pandas/index.pyx", line 137, in pandas.index.IndexEngine.get_loc (pandas/index.c:4154)
  File "pandas/index.pyx", line 159, in pandas.index.IndexEngine.get_loc (pandas/index.c:4018)
  File "pandas/hashtable.pyx", line 675, in pandas.hashtable.PyObjectHashTable.get_item (pandas/hashtable.c:12368)
  File "pandas/hashtable.pyx", line 683, in pandas.hashtable.PyObjectHashTable.get_item (pandas/hashtable.c:12322)
KeyError: 'CDLINNEC'
2018-12-23 21:38:05,492 - default - ERROR - Exception occurred
Traceback (most recent call last):
  File "Trading/Dataset/DatasetHolder.py", line 258, in appendTimeframesIntoOneDataset
    ds_l.f_df[cdl] = np.convolve(ds_l.f_df[cdl], fn)[0:len(ds_l.f_df)]
  File "/usr/local/lib/python2.7/dist-packages/pandas/core/frame.py", line 1997, in __getitem__
    return self._getitem_column(key)
  File "/usr/local/lib/python2.7/dist-packages/pandas/core/frame.py", line 2004, in _getitem_column
    return self._get_item_cache(key)
  File "/usr/local/lib/python2.7/dist-packages/pandas/core/generic.py", line 1350, in _get_item_cache
    values = self._data.get(item)
  File "/usr/local/lib/python2.7/dist-packages/pandas/core/internals.py", line 3290, in get
    loc = self.items.get_loc(item)
  File "/usr/local/lib/python2.7/dist-packages/pandas/indexes/base.py", line 1947, in get_loc
    return self._engine.get_loc(self._maybe_cast_indexer(key))
  File "pandas/index.pyx", line 137, in pandas.index.IndexEngine.get_loc (pandas/index.c:4154)
  File "pandas/index.pyx", line 159, in pandas.index.IndexEngine.get_loc (pandas/index.c:4018)
  File "pandas/hashtable.pyx", line 675, in pandas.hashtable.PyObjectHashTable.get_item (pandas/hashtable.c:12368)
  File "pandas/hashtable.pyx", line 683, in pandas.hashtable.PyObjectHashTable.get_item (pandas/hashtable.c:12322)
KeyError: 'CDLINVERTEDHAMME'
2018-12-23 21:38:05,500 - default - ERROR - Exception occurred
Traceback (most recent call last):
  File "Trading/Dataset/DatasetHolder.py", line 258, in appendTimeframesIntoOneDataset
    ds_l.f_df[cdl] = np.convolve(ds_l.f_df[cdl], fn)[0:len(ds_l.f_df)]
  File "/usr/local/lib/python2.7/dist-packages/pandas/core/frame.py", line 1997, in __getitem__
    return self._getitem_column(key)
  File "/usr/local/lib/python2.7/dist-packages/pandas/core/frame.py", line 2004, in _getitem_column
    return self._get_item_cache(key)
  File "/usr/local/lib/python2.7/dist-packages/pandas/core/generic.py", line 1350, in _get_item_cache
    values = self._data.get(item)
  File "/usr/local/lib/python2.7/dist-packages/pandas/core/internals.py", line 3290, in get
    loc = self.items.get_loc(item)
  File "/usr/local/lib/python2.7/dist-packages/pandas/indexes/base.py", line 1947, in get_loc
    return self._engine.get_loc(self._maybe_cast_indexer(key))
  File "pandas/index.pyx", line 137, in pandas.index.IndexEngine.get_loc (pandas/index.c:4154)
  File "pandas/index.pyx", line 159, in pandas.index.IndexEngine.get_loc (pandas/index.c:4018)
  File "pandas/hashtable.pyx", line 675, in pandas.hashtable.PyObjectHashTable.get_item (pandas/hashtable.c:12368)
  File "pandas/hashtable.pyx", line 683, in pandas.hashtable.PyObjectHashTable.get_item (pandas/hashtable.c:12322)
KeyError: 'CDLKICKIN'
2018-12-23 21:38:05,508 - default - ERROR - Exception occurred
Traceback (most recent call last):
  File "Trading/Dataset/DatasetHolder.py", line 258, in appendTimeframesIntoOneDataset
    ds_l.f_df[cdl] = np.convolve(ds_l.f_df[cdl], fn)[0:len(ds_l.f_df)]
  File "/usr/local/lib/python2.7/dist-packages/pandas/core/frame.py", line 1997, in __getitem__
    return self._getitem_column(key)
  File "/usr/local/lib/python2.7/dist-packages/pandas/core/frame.py", line 2004, in _getitem_column
    return self._get_item_cache(key)
  File "/usr/local/lib/python2.7/dist-packages/pandas/core/generic.py", line 1350, in _get_item_cache
    values = self._data.get(item)
  File "/usr/local/lib/python2.7/dist-packages/pandas/core/internals.py", line 3290, in get
    loc = self.items.get_loc(item)
  File "/usr/local/lib/python2.7/dist-packages/pandas/indexes/base.py", line 1947, in get_loc
    return self._engine.get_loc(self._maybe_cast_indexer(key))
  File "pandas/index.pyx", line 137, in pandas.index.IndexEngine.get_loc (pandas/index.c:4154)
  File "pandas/index.pyx", line 159, in pandas.index.IndexEngine.get_loc (pandas/index.c:4018)
  File "pandas/hashtable.pyx", line 675, in pandas.hashtable.PyObjectHashTable.get_item (pandas/hashtable.c:12368)
  File "pandas/hashtable.pyx", line 683, in pandas.hashtable.PyObjectHashTable.get_item (pandas/hashtable.c:12322)
KeyError: 'CDLKICKINGBYLENGT'
2018-12-23 21:38:05,516 - default - ERROR - Exception occurred
Traceback (most recent call last):
  File "Trading/Dataset/DatasetHolder.py", line 258, in appendTimeframesIntoOneDataset
    ds_l.f_df[cdl] = np.convolve(ds_l.f_df[cdl], fn)[0:len(ds_l.f_df)]
  File "/usr/local/lib/python2.7/dist-packages/pandas/core/frame.py", line 1997, in __getitem__
    return self._getitem_column(key)
  File "/usr/local/lib/python2.7/dist-packages/pandas/core/frame.py", line 2004, in _getitem_column
    return self._get_item_cache(key)
  File "/usr/local/lib/python2.7/dist-packages/pandas/core/generic.py", line 1350, in _get_item_cache
    values = self._data.get(item)
  File "/usr/local/lib/python2.7/dist-packages/pandas/core/internals.py", line 3290, in get
    loc = self.items.get_loc(item)
  File "/usr/local/lib/python2.7/dist-packages/pandas/indexes/base.py", line 1947, in get_loc
    return self._engine.get_loc(self._maybe_cast_indexer(key))
  File "pandas/index.pyx", line 137, in pandas.index.IndexEngine.get_loc (pandas/index.c:4154)
  File "pandas/index.pyx", line 159, in pandas.index.IndexEngine.get_loc (pandas/index.c:4018)
  File "pandas/hashtable.pyx", line 675, in pandas.hashtable.PyObjectHashTable.get_item (pandas/hashtable.c:12368)
  File "pandas/hashtable.pyx", line 683, in pandas.hashtable.PyObjectHashTable.get_item (pandas/hashtable.c:12322)
KeyError: 'CDLLADDERBOTTO'
2018-12-23 21:38:05,523 - default - ERROR - Exception occurred
Traceback (most recent call last):
  File "Trading/Dataset/DatasetHolder.py", line 258, in appendTimeframesIntoOneDataset
    ds_l.f_df[cdl] = np.convolve(ds_l.f_df[cdl], fn)[0:len(ds_l.f_df)]
  File "/usr/local/lib/python2.7/dist-packages/pandas/core/frame.py", line 1997, in __getitem__
    return self._getitem_column(key)
  File "/usr/local/lib/python2.7/dist-packages/pandas/core/frame.py", line 2004, in _getitem_column
    return self._get_item_cache(key)
  File "/usr/local/lib/python2.7/dist-packages/pandas/core/generic.py", line 1350, in _get_item_cache
    values = self._data.get(item)
  File "/usr/local/lib/python2.7/dist-packages/pandas/core/internals.py", line 3290, in get
    loc = self.items.get_loc(item)
  File "/usr/local/lib/python2.7/dist-packages/pandas/indexes/base.py", line 1947, in get_loc
    return self._engine.get_loc(self._maybe_cast_indexer(key))
  File "pandas/index.pyx", line 137, in pandas.index.IndexEngine.get_loc (pandas/index.c:4154)
  File "pandas/index.pyx", line 159, in pandas.index.IndexEngine.get_loc (pandas/index.c:4018)
  File "pandas/hashtable.pyx", line 675, in pandas.hashtable.PyObjectHashTable.get_item (pandas/hashtable.c:12368)
  File "pandas/hashtable.pyx", line 683, in pandas.hashtable.PyObjectHashTable.get_item (pandas/hashtable.c:12322)
KeyError: 'CDLLONGLEGGEDDOJ'
2018-12-23 21:38:05,529 - default - ERROR - Exception occurred
Traceback (most recent call last):
  File "Trading/Dataset/DatasetHolder.py", line 258, in appendTimeframesIntoOneDataset
    ds_l.f_df[cdl] = np.convolve(ds_l.f_df[cdl], fn)[0:len(ds_l.f_df)]
  File "/usr/local/lib/python2.7/dist-packages/pandas/core/frame.py", line 1997, in __getitem__
    return self._getitem_column(key)
  File "/usr/local/lib/python2.7/dist-packages/pandas/core/frame.py", line 2004, in _getitem_column
    return self._get_item_cache(key)
  File "/usr/local/lib/python2.7/dist-packages/pandas/core/generic.py", line 1350, in _get_item_cache
    values = self._data.get(item)
  File "/usr/local/lib/python2.7/dist-packages/pandas/core/internals.py", line 3290, in get
    loc = self.items.get_loc(item)
  File "/usr/local/lib/python2.7/dist-packages/pandas/indexes/base.py", line 1947, in get_loc
    return self._engine.get_loc(self._maybe_cast_indexer(key))
  File "pandas/index.pyx", line 137, in pandas.index.IndexEngine.get_loc (pandas/index.c:4154)
  File "pandas/index.pyx", line 159, in pandas.index.IndexEngine.get_loc (pandas/index.c:4018)
  File "pandas/hashtable.pyx", line 675, in pandas.hashtable.PyObjectHashTable.get_item (pandas/hashtable.c:12368)
  File "pandas/hashtable.pyx", line 683, in pandas.hashtable.PyObjectHashTable.get_item (pandas/hashtable.c:12322)
KeyError: 'CDLLONGLIN'
2018-12-23 21:38:05,536 - default - ERROR - Exception occurred
Traceback (most recent call last):
  File "Trading/Dataset/DatasetHolder.py", line 258, in appendTimeframesIntoOneDataset
    ds_l.f_df[cdl] = np.convolve(ds_l.f_df[cdl], fn)[0:len(ds_l.f_df)]
  File "/usr/local/lib/python2.7/dist-packages/pandas/core/frame.py", line 1997, in __getitem__
    return self._getitem_column(key)
  File "/usr/local/lib/python2.7/dist-packages/pandas/core/frame.py", line 2004, in _getitem_column
    return self._get_item_cache(key)
  File "/usr/local/lib/python2.7/dist-packages/pandas/core/generic.py", line 1350, in _get_item_cache
    values = self._data.get(item)
  File "/usr/local/lib/python2.7/dist-packages/pandas/core/internals.py", line 3290, in get
    loc = self.items.get_loc(item)
  File "/usr/local/lib/python2.7/dist-packages/pandas/indexes/base.py", line 1947, in get_loc
    return self._engine.get_loc(self._maybe_cast_indexer(key))
  File "pandas/index.pyx", line 137, in pandas.index.IndexEngine.get_loc (pandas/index.c:4154)
  File "pandas/index.pyx", line 159, in pandas.index.IndexEngine.get_loc (pandas/index.c:4018)
  File "pandas/hashtable.pyx", line 675, in pandas.hashtable.PyObjectHashTable.get_item (pandas/hashtable.c:12368)
  File "pandas/hashtable.pyx", line 683, in pandas.hashtable.PyObjectHashTable.get_item (pandas/hashtable.c:12322)
KeyError: 'CDLMARUBOZ'
2018-12-23 21:38:05,542 - default - ERROR - Exception occurred
Traceback (most recent call last):
  File "Trading/Dataset/DatasetHolder.py", line 258, in appendTimeframesIntoOneDataset
    ds_l.f_df[cdl] = np.convolve(ds_l.f_df[cdl], fn)[0:len(ds_l.f_df)]
  File "/usr/local/lib/python2.7/dist-packages/pandas/core/frame.py", line 1997, in __getitem__
    return self._getitem_column(key)
  File "/usr/local/lib/python2.7/dist-packages/pandas/core/frame.py", line 2004, in _getitem_column
    return self._get_item_cache(key)
  File "/usr/local/lib/python2.7/dist-packages/pandas/core/generic.py", line 1350, in _get_item_cache
    values = self._data.get(item)
  File "/usr/local/lib/python2.7/dist-packages/pandas/core/internals.py", line 3290, in get
    loc = self.items.get_loc(item)
  File "/usr/local/lib/python2.7/dist-packages/pandas/indexes/base.py", line 1947, in get_loc
    return self._engine.get_loc(self._maybe_cast_indexer(key))
  File "pandas/index.pyx", line 137, in pandas.index.IndexEngine.get_loc (pandas/index.c:4154)
  File "pandas/index.pyx", line 159, in pandas.index.IndexEngine.get_loc (pandas/index.c:4018)
  File "pandas/hashtable.pyx", line 675, in pandas.hashtable.PyObjectHashTable.get_item (pandas/hashtable.c:12368)
  File "pandas/hashtable.pyx", line 683, in pandas.hashtable.PyObjectHashTable.get_item (pandas/hashtable.c:12322)
KeyError: 'CDLMATCHINGLO'
2018-12-23 21:38:05,548 - default - ERROR - Exception occurred
Traceback (most recent call last):
  File "Trading/Dataset/DatasetHolder.py", line 258, in appendTimeframesIntoOneDataset
    ds_l.f_df[cdl] = np.convolve(ds_l.f_df[cdl], fn)[0:len(ds_l.f_df)]
  File "/usr/local/lib/python2.7/dist-packages/pandas/core/frame.py", line 1997, in __getitem__
    return self._getitem_column(key)
  File "/usr/local/lib/python2.7/dist-packages/pandas/core/frame.py", line 2004, in _getitem_column
    return self._get_item_cache(key)
  File "/usr/local/lib/python2.7/dist-packages/pandas/core/generic.py", line 1350, in _get_item_cache
    values = self._data.get(item)
  File "/usr/local/lib/python2.7/dist-packages/pandas/core/internals.py", line 3290, in get
    loc = self.items.get_loc(item)
  File "/usr/local/lib/python2.7/dist-packages/pandas/indexes/base.py", line 1947, in get_loc
    return self._engine.get_loc(self._maybe_cast_indexer(key))
  File "pandas/index.pyx", line 137, in pandas.index.IndexEngine.get_loc (pandas/index.c:4154)
  File "pandas/index.pyx", line 159, in pandas.index.IndexEngine.get_loc (pandas/index.c:4018)
  File "pandas/hashtable.pyx", line 675, in pandas.hashtable.PyObjectHashTable.get_item (pandas/hashtable.c:12368)
  File "pandas/hashtable.pyx", line 683, in pandas.hashtable.PyObjectHashTable.get_item (pandas/hashtable.c:12322)
KeyError: 'CDLMATHOL'
2018-12-23 21:38:05,554 - default - ERROR - Exception occurred
Traceback (most recent call last):
  File "Trading/Dataset/DatasetHolder.py", line 258, in appendTimeframesIntoOneDataset
    ds_l.f_df[cdl] = np.convolve(ds_l.f_df[cdl], fn)[0:len(ds_l.f_df)]
  File "/usr/local/lib/python2.7/dist-packages/pandas/core/frame.py", line 1997, in __getitem__
    return self._getitem_column(key)
  File "/usr/local/lib/python2.7/dist-packages/pandas/core/frame.py", line 2004, in _getitem_column
    return self._get_item_cache(key)
  File "/usr/local/lib/python2.7/dist-packages/pandas/core/generic.py", line 1350, in _get_item_cache
    values = self._data.get(item)
  File "/usr/local/lib/python2.7/dist-packages/pandas/core/internals.py", line 3290, in get
    loc = self.items.get_loc(item)
  File "/usr/local/lib/python2.7/dist-packages/pandas/indexes/base.py", line 1947, in get_loc
    return self._engine.get_loc(self._maybe_cast_indexer(key))
  File "pandas/index.pyx", line 137, in pandas.index.IndexEngine.get_loc (pandas/index.c:4154)
  File "pandas/index.pyx", line 159, in pandas.index.IndexEngine.get_loc (pandas/index.c:4018)
  File "pandas/hashtable.pyx", line 675, in pandas.hashtable.PyObjectHashTable.get_item (pandas/hashtable.c:12368)
  File "pandas/hashtable.pyx", line 683, in pandas.hashtable.PyObjectHashTable.get_item (pandas/hashtable.c:12322)
KeyError: 'CDLMORNINGDOJISTA'
2018-12-23 21:38:05,559 - default - ERROR - Exception occurred
Traceback (most recent call last):
  File "Trading/Dataset/DatasetHolder.py", line 258, in appendTimeframesIntoOneDataset
    ds_l.f_df[cdl] = np.convolve(ds_l.f_df[cdl], fn)[0:len(ds_l.f_df)]
  File "/usr/local/lib/python2.7/dist-packages/pandas/core/frame.py", line 1997, in __getitem__
    return self._getitem_column(key)
  File "/usr/local/lib/python2.7/dist-packages/pandas/core/frame.py", line 2004, in _getitem_column
    return self._get_item_cache(key)
  File "/usr/local/lib/python2.7/dist-packages/pandas/core/generic.py", line 1350, in _get_item_cache
    values = self._data.get(item)
  File "/usr/local/lib/python2.7/dist-packages/pandas/core/internals.py", line 3290, in get
    loc = self.items.get_loc(item)
  File "/usr/local/lib/python2.7/dist-packages/pandas/indexes/base.py", line 1947, in get_loc
    return self._engine.get_loc(self._maybe_cast_indexer(key))
  File "pandas/index.pyx", line 137, in pandas.index.IndexEngine.get_loc (pandas/index.c:4154)
  File "pandas/index.pyx", line 159, in pandas.index.IndexEngine.get_loc (pandas/index.c:4018)
  File "pandas/hashtable.pyx", line 675, in pandas.hashtable.PyObjectHashTable.get_item (pandas/hashtable.c:12368)
  File "pandas/hashtable.pyx", line 683, in pandas.hashtable.PyObjectHashTable.get_item (pandas/hashtable.c:12322)
KeyError: 'CDLMORNINGSTA'
2018-12-23 21:38:05,567 - default - ERROR - Exception occurred
Traceback (most recent call last):
  File "Trading/Dataset/DatasetHolder.py", line 258, in appendTimeframesIntoOneDataset
    ds_l.f_df[cdl] = np.convolve(ds_l.f_df[cdl], fn)[0:len(ds_l.f_df)]
  File "/usr/local/lib/python2.7/dist-packages/pandas/core/frame.py", line 1997, in __getitem__
    return self._getitem_column(key)
  File "/usr/local/lib/python2.7/dist-packages/pandas/core/frame.py", line 2004, in _getitem_column
    return self._get_item_cache(key)
  File "/usr/local/lib/python2.7/dist-packages/pandas/core/generic.py", line 1350, in _get_item_cache
    values = self._data.get(item)
  File "/usr/local/lib/python2.7/dist-packages/pandas/core/internals.py", line 3290, in get
    loc = self.items.get_loc(item)
  File "/usr/local/lib/python2.7/dist-packages/pandas/indexes/base.py", line 1947, in get_loc
    return self._engine.get_loc(self._maybe_cast_indexer(key))
  File "pandas/index.pyx", line 137, in pandas.index.IndexEngine.get_loc (pandas/index.c:4154)
  File "pandas/index.pyx", line 159, in pandas.index.IndexEngine.get_loc (pandas/index.c:4018)
  File "pandas/hashtable.pyx", line 675, in pandas.hashtable.PyObjectHashTable.get_item (pandas/hashtable.c:12368)
  File "pandas/hashtable.pyx", line 683, in pandas.hashtable.PyObjectHashTable.get_item (pandas/hashtable.c:12322)
KeyError: 'CDLONNEC'
2018-12-23 21:38:05,578 - default - ERROR - Exception occurred
Traceback (most recent call last):
  File "Trading/Dataset/DatasetHolder.py", line 258, in appendTimeframesIntoOneDataset
    ds_l.f_df[cdl] = np.convolve(ds_l.f_df[cdl], fn)[0:len(ds_l.f_df)]
  File "/usr/local/lib/python2.7/dist-packages/pandas/core/frame.py", line 1997, in __getitem__
    return self._getitem_column(key)
  File "/usr/local/lib/python2.7/dist-packages/pandas/core/frame.py", line 2004, in _getitem_column
    return self._get_item_cache(key)
  File "/usr/local/lib/python2.7/dist-packages/pandas/core/generic.py", line 1350, in _get_item_cache
    values = self._data.get(item)
  File "/usr/local/lib/python2.7/dist-packages/pandas/core/internals.py", line 3290, in get
    loc = self.items.get_loc(item)
  File "/usr/local/lib/python2.7/dist-packages/pandas/indexes/base.py", line 1947, in get_loc
    return self._engine.get_loc(self._maybe_cast_indexer(key))
  File "pandas/index.pyx", line 137, in pandas.index.IndexEngine.get_loc (pandas/index.c:4154)
  File "pandas/index.pyx", line 159, in pandas.index.IndexEngine.get_loc (pandas/index.c:4018)
  File "pandas/hashtable.pyx", line 675, in pandas.hashtable.PyObjectHashTable.get_item (pandas/hashtable.c:12368)
  File "pandas/hashtable.pyx", line 683, in pandas.hashtable.PyObjectHashTable.get_item (pandas/hashtable.c:12322)
KeyError: 'CDLPIERCIN'
2018-12-23 21:38:05,585 - default - ERROR - Exception occurred
Traceback (most recent call last):
  File "Trading/Dataset/DatasetHolder.py", line 258, in appendTimeframesIntoOneDataset
    ds_l.f_df[cdl] = np.convolve(ds_l.f_df[cdl], fn)[0:len(ds_l.f_df)]
  File "/usr/local/lib/python2.7/dist-packages/pandas/core/frame.py", line 1997, in __getitem__
    return self._getitem_column(key)
  File "/usr/local/lib/python2.7/dist-packages/pandas/core/frame.py", line 2004, in _getitem_column
    return self._get_item_cache(key)
  File "/usr/local/lib/python2.7/dist-packages/pandas/core/generic.py", line 1350, in _get_item_cache
    values = self._data.get(item)
  File "/usr/local/lib/python2.7/dist-packages/pandas/core/internals.py", line 3290, in get
    loc = self.items.get_loc(item)
  File "/usr/local/lib/python2.7/dist-packages/pandas/indexes/base.py", line 1947, in get_loc
    return self._engine.get_loc(self._maybe_cast_indexer(key))
  File "pandas/index.pyx", line 137, in pandas.index.IndexEngine.get_loc (pandas/index.c:4154)
  File "pandas/index.pyx", line 159, in pandas.index.IndexEngine.get_loc (pandas/index.c:4018)
  File "pandas/hashtable.pyx", line 675, in pandas.hashtable.PyObjectHashTable.get_item (pandas/hashtable.c:12368)
  File "pandas/hashtable.pyx", line 683, in pandas.hashtable.PyObjectHashTable.get_item (pandas/hashtable.c:12322)
KeyError: 'CDLRICKSHAWMA'
2018-12-23 21:38:05,593 - default - ERROR - Exception occurred
Traceback (most recent call last):
  File "Trading/Dataset/DatasetHolder.py", line 258, in appendTimeframesIntoOneDataset
    ds_l.f_df[cdl] = np.convolve(ds_l.f_df[cdl], fn)[0:len(ds_l.f_df)]
  File "/usr/local/lib/python2.7/dist-packages/pandas/core/frame.py", line 1997, in __getitem__
    return self._getitem_column(key)
  File "/usr/local/lib/python2.7/dist-packages/pandas/core/frame.py", line 2004, in _getitem_column
    return self._get_item_cache(key)
  File "/usr/local/lib/python2.7/dist-packages/pandas/core/generic.py", line 1350, in _get_item_cache
    values = self._data.get(item)
  File "/usr/local/lib/python2.7/dist-packages/pandas/core/internals.py", line 3290, in get
    loc = self.items.get_loc(item)
  File "/usr/local/lib/python2.7/dist-packages/pandas/indexes/base.py", line 1947, in get_loc
    return self._engine.get_loc(self._maybe_cast_indexer(key))
  File "pandas/index.pyx", line 137, in pandas.index.IndexEngine.get_loc (pandas/index.c:4154)
  File "pandas/index.pyx", line 159, in pandas.index.IndexEngine.get_loc (pandas/index.c:4018)
  File "pandas/hashtable.pyx", line 675, in pandas.hashtable.PyObjectHashTable.get_item (pandas/hashtable.c:12368)
  File "pandas/hashtable.pyx", line 683, in pandas.hashtable.PyObjectHashTable.get_item (pandas/hashtable.c:12322)
KeyError: 'CDLRISEFALL3METHOD'
2018-12-23 21:38:05,601 - default - ERROR - Exception occurred
Traceback (most recent call last):
  File "Trading/Dataset/DatasetHolder.py", line 258, in appendTimeframesIntoOneDataset
    ds_l.f_df[cdl] = np.convolve(ds_l.f_df[cdl], fn)[0:len(ds_l.f_df)]
  File "/usr/local/lib/python2.7/dist-packages/pandas/core/frame.py", line 1997, in __getitem__
    return self._getitem_column(key)
  File "/usr/local/lib/python2.7/dist-packages/pandas/core/frame.py", line 2004, in _getitem_column
    return self._get_item_cache(key)
  File "/usr/local/lib/python2.7/dist-packages/pandas/core/generic.py", line 1350, in _get_item_cache
    values = self._data.get(item)
  File "/usr/local/lib/python2.7/dist-packages/pandas/core/internals.py", line 3290, in get
    loc = self.items.get_loc(item)
  File "/usr/local/lib/python2.7/dist-packages/pandas/indexes/base.py", line 1947, in get_loc
    return self._engine.get_loc(self._maybe_cast_indexer(key))
  File "pandas/index.pyx", line 137, in pandas.index.IndexEngine.get_loc (pandas/index.c:4154)
  File "pandas/index.pyx", line 159, in pandas.index.IndexEngine.get_loc (pandas/index.c:4018)
  File "pandas/hashtable.pyx", line 675, in pandas.hashtable.PyObjectHashTable.get_item (pandas/hashtable.c:12368)
  File "pandas/hashtable.pyx", line 683, in pandas.hashtable.PyObjectHashTable.get_item (pandas/hashtable.c:12322)
KeyError: 'CDLSEPARATINGLINE'
2018-12-23 21:38:05,610 - default - ERROR - Exception occurred
Traceback (most recent call last):
  File "Trading/Dataset/DatasetHolder.py", line 258, in appendTimeframesIntoOneDataset
    ds_l.f_df[cdl] = np.convolve(ds_l.f_df[cdl], fn)[0:len(ds_l.f_df)]
  File "/usr/local/lib/python2.7/dist-packages/pandas/core/frame.py", line 1997, in __getitem__
    return self._getitem_column(key)
  File "/usr/local/lib/python2.7/dist-packages/pandas/core/frame.py", line 2004, in _getitem_column
    return self._get_item_cache(key)
  File "/usr/local/lib/python2.7/dist-packages/pandas/core/generic.py", line 1350, in _get_item_cache
    values = self._data.get(item)
  File "/usr/local/lib/python2.7/dist-packages/pandas/core/internals.py", line 3290, in get
    loc = self.items.get_loc(item)
  File "/usr/local/lib/python2.7/dist-packages/pandas/indexes/base.py", line 1947, in get_loc
    return self._engine.get_loc(self._maybe_cast_indexer(key))
  File "pandas/index.pyx", line 137, in pandas.index.IndexEngine.get_loc (pandas/index.c:4154)
  File "pandas/index.pyx", line 159, in pandas.index.IndexEngine.get_loc (pandas/index.c:4018)
  File "pandas/hashtable.pyx", line 675, in pandas.hashtable.PyObjectHashTable.get_item (pandas/hashtable.c:12368)
  File "pandas/hashtable.pyx", line 683, in pandas.hashtable.PyObjectHashTable.get_item (pandas/hashtable.c:12322)
KeyError: 'CDLSHOOTINGSTA'
2018-12-23 21:38:05,618 - default - ERROR - Exception occurred
Traceback (most recent call last):
  File "Trading/Dataset/DatasetHolder.py", line 258, in appendTimeframesIntoOneDataset
    ds_l.f_df[cdl] = np.convolve(ds_l.f_df[cdl], fn)[0:len(ds_l.f_df)]
  File "/usr/local/lib/python2.7/dist-packages/pandas/core/frame.py", line 1997, in __getitem__
    return self._getitem_column(key)
  File "/usr/local/lib/python2.7/dist-packages/pandas/core/frame.py", line 2004, in _getitem_column
    return self._get_item_cache(key)
  File "/usr/local/lib/python2.7/dist-packages/pandas/core/generic.py", line 1350, in _get_item_cache
    values = self._data.get(item)
  File "/usr/local/lib/python2.7/dist-packages/pandas/core/internals.py", line 3290, in get
    loc = self.items.get_loc(item)
  File "/usr/local/lib/python2.7/dist-packages/pandas/indexes/base.py", line 1947, in get_loc
    return self._engine.get_loc(self._maybe_cast_indexer(key))
  File "pandas/index.pyx", line 137, in pandas.index.IndexEngine.get_loc (pandas/index.c:4154)
  File "pandas/index.pyx", line 159, in pandas.index.IndexEngine.get_loc (pandas/index.c:4018)
  File "pandas/hashtable.pyx", line 675, in pandas.hashtable.PyObjectHashTable.get_item (pandas/hashtable.c:12368)
  File "pandas/hashtable.pyx", line 683, in pandas.hashtable.PyObjectHashTable.get_item (pandas/hashtable.c:12322)
KeyError: 'CDLSHORTLIN'
2018-12-23 21:38:05,626 - default - ERROR - Exception occurred
Traceback (most recent call last):
  File "Trading/Dataset/DatasetHolder.py", line 258, in appendTimeframesIntoOneDataset
    ds_l.f_df[cdl] = np.convolve(ds_l.f_df[cdl], fn)[0:len(ds_l.f_df)]
  File "/usr/local/lib/python2.7/dist-packages/pandas/core/frame.py", line 1997, in __getitem__
    return self._getitem_column(key)
  File "/usr/local/lib/python2.7/dist-packages/pandas/core/frame.py", line 2004, in _getitem_column
    return self._get_item_cache(key)
  File "/usr/local/lib/python2.7/dist-packages/pandas/core/generic.py", line 1350, in _get_item_cache
    values = self._data.get(item)
  File "/usr/local/lib/python2.7/dist-packages/pandas/core/internals.py", line 3290, in get
    loc = self.items.get_loc(item)
  File "/usr/local/lib/python2.7/dist-packages/pandas/indexes/base.py", line 1947, in get_loc
    return self._engine.get_loc(self._maybe_cast_indexer(key))
  File "pandas/index.pyx", line 137, in pandas.index.IndexEngine.get_loc (pandas/index.c:4154)
  File "pandas/index.pyx", line 159, in pandas.index.IndexEngine.get_loc (pandas/index.c:4018)
  File "pandas/hashtable.pyx", line 675, in pandas.hashtable.PyObjectHashTable.get_item (pandas/hashtable.c:12368)
  File "pandas/hashtable.pyx", line 683, in pandas.hashtable.PyObjectHashTable.get_item (pandas/hashtable.c:12322)
KeyError: 'CDLSPINNINGTO'
2018-12-23 21:38:05,633 - default - ERROR - Exception occurred
Traceback (most recent call last):
  File "Trading/Dataset/DatasetHolder.py", line 258, in appendTimeframesIntoOneDataset
    ds_l.f_df[cdl] = np.convolve(ds_l.f_df[cdl], fn)[0:len(ds_l.f_df)]
  File "/usr/local/lib/python2.7/dist-packages/pandas/core/frame.py", line 1997, in __getitem__
    return self._getitem_column(key)
  File "/usr/local/lib/python2.7/dist-packages/pandas/core/frame.py", line 2004, in _getitem_column
    return self._get_item_cache(key)
  File "/usr/local/lib/python2.7/dist-packages/pandas/core/generic.py", line 1350, in _get_item_cache
    values = self._data.get(item)
  File "/usr/local/lib/python2.7/dist-packages/pandas/core/internals.py", line 3290, in get
    loc = self.items.get_loc(item)
  File "/usr/local/lib/python2.7/dist-packages/pandas/indexes/base.py", line 1947, in get_loc
    return self._engine.get_loc(self._maybe_cast_indexer(key))
  File "pandas/index.pyx", line 137, in pandas.index.IndexEngine.get_loc (pandas/index.c:4154)
  File "pandas/index.pyx", line 159, in pandas.index.IndexEngine.get_loc (pandas/index.c:4018)
  File "pandas/hashtable.pyx", line 675, in pandas.hashtable.PyObjectHashTable.get_item (pandas/hashtable.c:12368)
  File "pandas/hashtable.pyx", line 683, in pandas.hashtable.PyObjectHashTable.get_item (pandas/hashtable.c:12322)
KeyError: 'CDLSTALLEDPATTER'
2018-12-23 21:38:05,641 - default - ERROR - Exception occurred
Traceback (most recent call last):
  File "Trading/Dataset/DatasetHolder.py", line 258, in appendTimeframesIntoOneDataset
    ds_l.f_df[cdl] = np.convolve(ds_l.f_df[cdl], fn)[0:len(ds_l.f_df)]
  File "/usr/local/lib/python2.7/dist-packages/pandas/core/frame.py", line 1997, in __getitem__
    return self._getitem_column(key)
  File "/usr/local/lib/python2.7/dist-packages/pandas/core/frame.py", line 2004, in _getitem_column
    return self._get_item_cache(key)
  File "/usr/local/lib/python2.7/dist-packages/pandas/core/generic.py", line 1350, in _get_item_cache
    values = self._data.get(item)
  File "/usr/local/lib/python2.7/dist-packages/pandas/core/internals.py", line 3290, in get
    loc = self.items.get_loc(item)
  File "/usr/local/lib/python2.7/dist-packages/pandas/indexes/base.py", line 1947, in get_loc
    return self._engine.get_loc(self._maybe_cast_indexer(key))
  File "pandas/index.pyx", line 137, in pandas.index.IndexEngine.get_loc (pandas/index.c:4154)
  File "pandas/index.pyx", line 159, in pandas.index.IndexEngine.get_loc (pandas/index.c:4018)
  File "pandas/hashtable.pyx", line 675, in pandas.hashtable.PyObjectHashTable.get_item (pandas/hashtable.c:12368)
  File "pandas/hashtable.pyx", line 683, in pandas.hashtable.PyObjectHashTable.get_item (pandas/hashtable.c:12322)
KeyError: 'CDLSTICKSANDWIC'
2018-12-23 21:38:05,649 - default - ERROR - Exception occurred
Traceback (most recent call last):
  File "Trading/Dataset/DatasetHolder.py", line 258, in appendTimeframesIntoOneDataset
    ds_l.f_df[cdl] = np.convolve(ds_l.f_df[cdl], fn)[0:len(ds_l.f_df)]
  File "/usr/local/lib/python2.7/dist-packages/pandas/core/frame.py", line 1997, in __getitem__
    return self._getitem_column(key)
  File "/usr/local/lib/python2.7/dist-packages/pandas/core/frame.py", line 2004, in _getitem_column
    return self._get_item_cache(key)
  File "/usr/local/lib/python2.7/dist-packages/pandas/core/generic.py", line 1350, in _get_item_cache
    values = self._data.get(item)
  File "/usr/local/lib/python2.7/dist-packages/pandas/core/internals.py", line 3290, in get
    loc = self.items.get_loc(item)
  File "/usr/local/lib/python2.7/dist-packages/pandas/indexes/base.py", line 1947, in get_loc
    return self._engine.get_loc(self._maybe_cast_indexer(key))
  File "pandas/index.pyx", line 137, in pandas.index.IndexEngine.get_loc (pandas/index.c:4154)
  File "pandas/index.pyx", line 159, in pandas.index.IndexEngine.get_loc (pandas/index.c:4018)
  File "pandas/hashtable.pyx", line 675, in pandas.hashtable.PyObjectHashTable.get_item (pandas/hashtable.c:12368)
  File "pandas/hashtable.pyx", line 683, in pandas.hashtable.PyObjectHashTable.get_item (pandas/hashtable.c:12322)
KeyError: 'CDLTAKUR'
2018-12-23 21:38:05,657 - default - ERROR - Exception occurred
Traceback (most recent call last):
  File "Trading/Dataset/DatasetHolder.py", line 258, in appendTimeframesIntoOneDataset
    ds_l.f_df[cdl] = np.convolve(ds_l.f_df[cdl], fn)[0:len(ds_l.f_df)]
  File "/usr/local/lib/python2.7/dist-packages/pandas/core/frame.py", line 1997, in __getitem__
    return self._getitem_column(key)
  File "/usr/local/lib/python2.7/dist-packages/pandas/core/frame.py", line 2004, in _getitem_column
    return self._get_item_cache(key)
  File "/usr/local/lib/python2.7/dist-packages/pandas/core/generic.py", line 1350, in _get_item_cache
    values = self._data.get(item)
  File "/usr/local/lib/python2.7/dist-packages/pandas/core/internals.py", line 3290, in get
    loc = self.items.get_loc(item)
  File "/usr/local/lib/python2.7/dist-packages/pandas/indexes/base.py", line 1947, in get_loc
    return self._engine.get_loc(self._maybe_cast_indexer(key))
  File "pandas/index.pyx", line 137, in pandas.index.IndexEngine.get_loc (pandas/index.c:4154)
  File "pandas/index.pyx", line 159, in pandas.index.IndexEngine.get_loc (pandas/index.c:4018)
  File "pandas/hashtable.pyx", line 675, in pandas.hashtable.PyObjectHashTable.get_item (pandas/hashtable.c:12368)
  File "pandas/hashtable.pyx", line 683, in pandas.hashtable.PyObjectHashTable.get_item (pandas/hashtable.c:12322)
KeyError: 'CDLTASUKIGA'
2018-12-23 21:38:05,663 - default - ERROR - Exception occurred
Traceback (most recent call last):
  File "Trading/Dataset/DatasetHolder.py", line 258, in appendTimeframesIntoOneDataset
    ds_l.f_df[cdl] = np.convolve(ds_l.f_df[cdl], fn)[0:len(ds_l.f_df)]
  File "/usr/local/lib/python2.7/dist-packages/pandas/core/frame.py", line 1997, in __getitem__
    return self._getitem_column(key)
  File "/usr/local/lib/python2.7/dist-packages/pandas/core/frame.py", line 2004, in _getitem_column
    return self._get_item_cache(key)
  File "/usr/local/lib/python2.7/dist-packages/pandas/core/generic.py", line 1350, in _get_item_cache
    values = self._data.get(item)
  File "/usr/local/lib/python2.7/dist-packages/pandas/core/internals.py", line 3290, in get
    loc = self.items.get_loc(item)
  File "/usr/local/lib/python2.7/dist-packages/pandas/indexes/base.py", line 1947, in get_loc
    return self._engine.get_loc(self._maybe_cast_indexer(key))
  File "pandas/index.pyx", line 137, in pandas.index.IndexEngine.get_loc (pandas/index.c:4154)
  File "pandas/index.pyx", line 159, in pandas.index.IndexEngine.get_loc (pandas/index.c:4018)
  File "pandas/hashtable.pyx", line 675, in pandas.hashtable.PyObjectHashTable.get_item (pandas/hashtable.c:12368)
  File "pandas/hashtable.pyx", line 683, in pandas.hashtable.PyObjectHashTable.get_item (pandas/hashtable.c:12322)
KeyError: 'CDLTHRUSTIN'
2018-12-23 21:38:05,671 - default - ERROR - Exception occurred
Traceback (most recent call last):
  File "Trading/Dataset/DatasetHolder.py", line 258, in appendTimeframesIntoOneDataset
    ds_l.f_df[cdl] = np.convolve(ds_l.f_df[cdl], fn)[0:len(ds_l.f_df)]
  File "/usr/local/lib/python2.7/dist-packages/pandas/core/frame.py", line 1997, in __getitem__
    return self._getitem_column(key)
  File "/usr/local/lib/python2.7/dist-packages/pandas/core/frame.py", line 2004, in _getitem_column
    return self._get_item_cache(key)
  File "/usr/local/lib/python2.7/dist-packages/pandas/core/generic.py", line 1350, in _get_item_cache
    values = self._data.get(item)
  File "/usr/local/lib/python2.7/dist-packages/pandas/core/internals.py", line 3290, in get
    loc = self.items.get_loc(item)
  File "/usr/local/lib/python2.7/dist-packages/pandas/indexes/base.py", line 1947, in get_loc
    return self._engine.get_loc(self._maybe_cast_indexer(key))
  File "pandas/index.pyx", line 137, in pandas.index.IndexEngine.get_loc (pandas/index.c:4154)
  File "pandas/index.pyx", line 159, in pandas.index.IndexEngine.get_loc (pandas/index.c:4018)
  File "pandas/hashtable.pyx", line 675, in pandas.hashtable.PyObjectHashTable.get_item (pandas/hashtable.c:12368)
  File "pandas/hashtable.pyx", line 683, in pandas.hashtable.PyObjectHashTable.get_item (pandas/hashtable.c:12322)
KeyError: 'CDLTRISTA'
2018-12-23 21:38:05,678 - default - ERROR - Exception occurred
Traceback (most recent call last):
  File "Trading/Dataset/DatasetHolder.py", line 258, in appendTimeframesIntoOneDataset
    ds_l.f_df[cdl] = np.convolve(ds_l.f_df[cdl], fn)[0:len(ds_l.f_df)]
  File "/usr/local/lib/python2.7/dist-packages/pandas/core/frame.py", line 1997, in __getitem__
    return self._getitem_column(key)
  File "/usr/local/lib/python2.7/dist-packages/pandas/core/frame.py", line 2004, in _getitem_column
    return self._get_item_cache(key)
  File "/usr/local/lib/python2.7/dist-packages/pandas/core/generic.py", line 1350, in _get_item_cache
    values = self._data.get(item)
  File "/usr/local/lib/python2.7/dist-packages/pandas/core/internals.py", line 3290, in get
    loc = self.items.get_loc(item)
  File "/usr/local/lib/python2.7/dist-packages/pandas/indexes/base.py", line 1947, in get_loc
    return self._engine.get_loc(self._maybe_cast_indexer(key))
  File "pandas/index.pyx", line 137, in pandas.index.IndexEngine.get_loc (pandas/index.c:4154)
  File "pandas/index.pyx", line 159, in pandas.index.IndexEngine.get_loc (pandas/index.c:4018)
  File "pandas/hashtable.pyx", line 675, in pandas.hashtable.PyObjectHashTable.get_item (pandas/hashtable.c:12368)
  File "pandas/hashtable.pyx", line 683, in pandas.hashtable.PyObjectHashTable.get_item (pandas/hashtable.c:12322)
KeyError: 'CDLUNIQUE3RIVE'
2018-12-23 21:38:05,686 - default - ERROR - Exception occurred
Traceback (most recent call last):
  File "Trading/Dataset/DatasetHolder.py", line 258, in appendTimeframesIntoOneDataset
    ds_l.f_df[cdl] = np.convolve(ds_l.f_df[cdl], fn)[0:len(ds_l.f_df)]
  File "/usr/local/lib/python2.7/dist-packages/pandas/core/frame.py", line 1997, in __getitem__
    return self._getitem_column(key)
  File "/usr/local/lib/python2.7/dist-packages/pandas/core/frame.py", line 2004, in _getitem_column
    return self._get_item_cache(key)
  File "/usr/local/lib/python2.7/dist-packages/pandas/core/generic.py", line 1350, in _get_item_cache
    values = self._data.get(item)
  File "/usr/local/lib/python2.7/dist-packages/pandas/core/internals.py", line 3290, in get
    loc = self.items.get_loc(item)
  File "/usr/local/lib/python2.7/dist-packages/pandas/indexes/base.py", line 1947, in get_loc
    return self._engine.get_loc(self._maybe_cast_indexer(key))
  File "pandas/index.pyx", line 137, in pandas.index.IndexEngine.get_loc (pandas/index.c:4154)
  File "pandas/index.pyx", line 159, in pandas.index.IndexEngine.get_loc (pandas/index.c:4018)
  File "pandas/hashtable.pyx", line 675, in pandas.hashtable.PyObjectHashTable.get_item (pandas/hashtable.c:12368)
  File "pandas/hashtable.pyx", line 683, in pandas.hashtable.PyObjectHashTable.get_item (pandas/hashtable.c:12322)
KeyError: 'CDLUPSIDEGAP2CROW'
2018-12-23 21:38:05,694 - default - ERROR - Exception occurred
Traceback (most recent call last):
  File "Trading/Dataset/DatasetHolder.py", line 258, in appendTimeframesIntoOneDataset
    ds_l.f_df[cdl] = np.convolve(ds_l.f_df[cdl], fn)[0:len(ds_l.f_df)]
  File "/usr/local/lib/python2.7/dist-packages/pandas/core/frame.py", line 1997, in __getitem__
    return self._getitem_column(key)
  File "/usr/local/lib/python2.7/dist-packages/pandas/core/frame.py", line 2004, in _getitem_column
    return self._get_item_cache(key)
  File "/usr/local/lib/python2.7/dist-packages/pandas/core/generic.py", line 1350, in _get_item_cache
    values = self._data.get(item)
  File "/usr/local/lib/python2.7/dist-packages/pandas/core/internals.py", line 3290, in get
    loc = self.items.get_loc(item)
  File "/usr/local/lib/python2.7/dist-packages/pandas/indexes/base.py", line 1947, in get_loc
    return self._engine.get_loc(self._maybe_cast_indexer(key))
  File "pandas/index.pyx", line 137, in pandas.index.IndexEngine.get_loc (pandas/index.c:4154)
  File "pandas/index.pyx", line 159, in pandas.index.IndexEngine.get_loc (pandas/index.c:4018)
  File "pandas/hashtable.pyx", line 675, in pandas.hashtable.PyObjectHashTable.get_item (pandas/hashtable.c:12368)
  File "pandas/hashtable.pyx", line 683, in pandas.hashtable.PyObjectHashTable.get_item (pandas/hashtable.c:12322)
KeyError: 'CDLXSIDEGAP3METHOD'
