2019-04-28 13:08:36,193 - default - ERROR - Exception occurred
Traceback (most recent call last):
  File "Trading/Dataset/DatasetHolder.py", line 266, in appendTimeframesIntoOneDataset
    ds_h.f_df[cdl] = np.convolve(ds_h.f_df[cdl], fn)[0:len(ds_h.f_df)]
  File "/usr/local/lib/python2.7/dist-packages/pandas/core/frame.py", line 1997, in __getitem__
    return self._getitem_column(key)
  File "/usr/local/lib/python2.7/dist-packages/pandas/core/frame.py", line 2004, in _getitem_column
    return self._get_item_cache(key)
  File "/usr/local/lib/python2.7/dist-packages/pandas/core/generic.py", line 1350, in _get_item_cache
    values = self._data.get(item)
  File "/usr/local/lib/python2.7/dist-packages/pandas/core/internals.py", line 3290, in get
    loc = self.items.get_loc(item)
  File "/usr/local/lib/python2.7/dist-packages/pandas/indexes/base.py", line 1947, in get_loc
    return self._engine.get_loc(self._maybe_cast_indexer(key))
  File "pandas/index.pyx", line 137, in pandas.index.IndexEngine.get_loc (pandas/index.c:4154)
  File "pandas/index.pyx", line 159, in pandas.index.IndexEngine.get_loc (pandas/index.c:4018)
  File "pandas/hashtable.pyx", line 675, in pandas.hashtable.PyObjectHashTable.get_item (pandas/hashtable.c:12368)
  File "pandas/hashtable.pyx", line 683, in pandas.hashtable.PyObjectHashTable.get_item (pandas/hashtable.c:12322)
KeyError: 'CDL2CROWS'
2019-04-28 13:08:36,198 - default - ERROR - Exception occurred
Traceback (most recent call last):
  File "Trading/Dataset/DatasetHolder.py", line 266, in appendTimeframesIntoOneDataset
    ds_h.f_df[cdl] = np.convolve(ds_h.f_df[cdl], fn)[0:len(ds_h.f_df)]
  File "/usr/local/lib/python2.7/dist-packages/pandas/core/frame.py", line 1997, in __getitem__
    return self._getitem_column(key)
  File "/usr/local/lib/python2.7/dist-packages/pandas/core/frame.py", line 2004, in _getitem_column
    return self._get_item_cache(key)
  File "/usr/local/lib/python2.7/dist-packages/pandas/core/generic.py", line 1350, in _get_item_cache
    values = self._data.get(item)
  File "/usr/local/lib/python2.7/dist-packages/pandas/core/internals.py", line 3290, in get
    loc = self.items.get_loc(item)
  File "/usr/local/lib/python2.7/dist-packages/pandas/indexes/base.py", line 1947, in get_loc
    return self._engine.get_loc(self._maybe_cast_indexer(key))
  File "pandas/index.pyx", line 137, in pandas.index.IndexEngine.get_loc (pandas/index.c:4154)
  File "pandas/index.pyx", line 159, in pandas.index.IndexEngine.get_loc (pandas/index.c:4018)
  File "pandas/hashtable.pyx", line 675, in pandas.hashtable.PyObjectHashTable.get_item (pandas/hashtable.c:12368)
  File "pandas/hashtable.pyx", line 683, in pandas.hashtable.PyObjectHashTable.get_item (pandas/hashtable.c:12322)
KeyError: 'CDL3BLACKCROWS'
2019-04-28 13:08:36,200 - default - ERROR - Exception occurred
Traceback (most recent call last):
  File "Trading/Dataset/DatasetHolder.py", line 266, in appendTimeframesIntoOneDataset
    ds_h.f_df[cdl] = np.convolve(ds_h.f_df[cdl], fn)[0:len(ds_h.f_df)]
  File "/usr/local/lib/python2.7/dist-packages/pandas/core/frame.py", line 1997, in __getitem__
    return self._getitem_column(key)
  File "/usr/local/lib/python2.7/dist-packages/pandas/core/frame.py", line 2004, in _getitem_column
    return self._get_item_cache(key)
  File "/usr/local/lib/python2.7/dist-packages/pandas/core/generic.py", line 1350, in _get_item_cache
    values = self._data.get(item)
  File "/usr/local/lib/python2.7/dist-packages/pandas/core/internals.py", line 3290, in get
    loc = self.items.get_loc(item)
  File "/usr/local/lib/python2.7/dist-packages/pandas/indexes/base.py", line 1947, in get_loc
    return self._engine.get_loc(self._maybe_cast_indexer(key))
  File "pandas/index.pyx", line 137, in pandas.index.IndexEngine.get_loc (pandas/index.c:4154)
  File "pandas/index.pyx", line 159, in pandas.index.IndexEngine.get_loc (pandas/index.c:4018)
  File "pandas/hashtable.pyx", line 675, in pandas.hashtable.PyObjectHashTable.get_item (pandas/hashtable.c:12368)
  File "pandas/hashtable.pyx", line 683, in pandas.hashtable.PyObjectHashTable.get_item (pandas/hashtable.c:12322)
KeyError: 'CDL3INSIDE'
2019-04-28 13:08:36,203 - default - ERROR - Exception occurred
Traceback (most recent call last):
  File "Trading/Dataset/DatasetHolder.py", line 266, in appendTimeframesIntoOneDataset
    ds_h.f_df[cdl] = np.convolve(ds_h.f_df[cdl], fn)[0:len(ds_h.f_df)]
  File "/usr/local/lib/python2.7/dist-packages/pandas/core/frame.py", line 1997, in __getitem__
    return self._getitem_column(key)
  File "/usr/local/lib/python2.7/dist-packages/pandas/core/frame.py", line 2004, in _getitem_column
    return self._get_item_cache(key)
  File "/usr/local/lib/python2.7/dist-packages/pandas/core/generic.py", line 1350, in _get_item_cache
    values = self._data.get(item)
  File "/usr/local/lib/python2.7/dist-packages/pandas/core/internals.py", line 3290, in get
    loc = self.items.get_loc(item)
  File "/usr/local/lib/python2.7/dist-packages/pandas/indexes/base.py", line 1947, in get_loc
    return self._engine.get_loc(self._maybe_cast_indexer(key))
  File "pandas/index.pyx", line 137, in pandas.index.IndexEngine.get_loc (pandas/index.c:4154)
  File "pandas/index.pyx", line 159, in pandas.index.IndexEngine.get_loc (pandas/index.c:4018)
  File "pandas/hashtable.pyx", line 675, in pandas.hashtable.PyObjectHashTable.get_item (pandas/hashtable.c:12368)
  File "pandas/hashtable.pyx", line 683, in pandas.hashtable.PyObjectHashTable.get_item (pandas/hashtable.c:12322)
KeyError: 'CDL3LINESTRIKE'
2019-04-28 13:08:36,205 - default - ERROR - Exception occurred
Traceback (most recent call last):
  File "Trading/Dataset/DatasetHolder.py", line 266, in appendTimeframesIntoOneDataset
    ds_h.f_df[cdl] = np.convolve(ds_h.f_df[cdl], fn)[0:len(ds_h.f_df)]
  File "/usr/local/lib/python2.7/dist-packages/pandas/core/frame.py", line 1997, in __getitem__
    return self._getitem_column(key)
  File "/usr/local/lib/python2.7/dist-packages/pandas/core/frame.py", line 2004, in _getitem_column
    return self._get_item_cache(key)
  File "/usr/local/lib/python2.7/dist-packages/pandas/core/generic.py", line 1350, in _get_item_cache
    values = self._data.get(item)
  File "/usr/local/lib/python2.7/dist-packages/pandas/core/internals.py", line 3290, in get
    loc = self.items.get_loc(item)
  File "/usr/local/lib/python2.7/dist-packages/pandas/indexes/base.py", line 1947, in get_loc
    return self._engine.get_loc(self._maybe_cast_indexer(key))
  File "pandas/index.pyx", line 137, in pandas.index.IndexEngine.get_loc (pandas/index.c:4154)
  File "pandas/index.pyx", line 159, in pandas.index.IndexEngine.get_loc (pandas/index.c:4018)
  File "pandas/hashtable.pyx", line 675, in pandas.hashtable.PyObjectHashTable.get_item (pandas/hashtable.c:12368)
  File "pandas/hashtable.pyx", line 683, in pandas.hashtable.PyObjectHashTable.get_item (pandas/hashtable.c:12322)
KeyError: 'CDL3OUTSIDE'
2019-04-28 13:08:36,210 - default - ERROR - Exception occurred
Traceback (most recent call last):
  File "Trading/Dataset/DatasetHolder.py", line 266, in appendTimeframesIntoOneDataset
    ds_h.f_df[cdl] = np.convolve(ds_h.f_df[cdl], fn)[0:len(ds_h.f_df)]
  File "/usr/local/lib/python2.7/dist-packages/pandas/core/frame.py", line 1997, in __getitem__
    return self._getitem_column(key)
  File "/usr/local/lib/python2.7/dist-packages/pandas/core/frame.py", line 2004, in _getitem_column
    return self._get_item_cache(key)
  File "/usr/local/lib/python2.7/dist-packages/pandas/core/generic.py", line 1350, in _get_item_cache
    values = self._data.get(item)
  File "/usr/local/lib/python2.7/dist-packages/pandas/core/internals.py", line 3290, in get
    loc = self.items.get_loc(item)
  File "/usr/local/lib/python2.7/dist-packages/pandas/indexes/base.py", line 1947, in get_loc
    return self._engine.get_loc(self._maybe_cast_indexer(key))
  File "pandas/index.pyx", line 137, in pandas.index.IndexEngine.get_loc (pandas/index.c:4154)
  File "pandas/index.pyx", line 159, in pandas.index.IndexEngine.get_loc (pandas/index.c:4018)
  File "pandas/hashtable.pyx", line 675, in pandas.hashtable.PyObjectHashTable.get_item (pandas/hashtable.c:12368)
  File "pandas/hashtable.pyx", line 683, in pandas.hashtable.PyObjectHashTable.get_item (pandas/hashtable.c:12322)
KeyError: 'CDL3STARSINSOUTH'
2019-04-28 13:08:36,213 - default - ERROR - Exception occurred
Traceback (most recent call last):
  File "Trading/Dataset/DatasetHolder.py", line 266, in appendTimeframesIntoOneDataset
    ds_h.f_df[cdl] = np.convolve(ds_h.f_df[cdl], fn)[0:len(ds_h.f_df)]
  File "/usr/local/lib/python2.7/dist-packages/pandas/core/frame.py", line 1997, in __getitem__
    return self._getitem_column(key)
  File "/usr/local/lib/python2.7/dist-packages/pandas/core/frame.py", line 2004, in _getitem_column
    return self._get_item_cache(key)
  File "/usr/local/lib/python2.7/dist-packages/pandas/core/generic.py", line 1350, in _get_item_cache
    values = self._data.get(item)
  File "/usr/local/lib/python2.7/dist-packages/pandas/core/internals.py", line 3290, in get
    loc = self.items.get_loc(item)
  File "/usr/local/lib/python2.7/dist-packages/pandas/indexes/base.py", line 1947, in get_loc
    return self._engine.get_loc(self._maybe_cast_indexer(key))
  File "pandas/index.pyx", line 137, in pandas.index.IndexEngine.get_loc (pandas/index.c:4154)
  File "pandas/index.pyx", line 159, in pandas.index.IndexEngine.get_loc (pandas/index.c:4018)
  File "pandas/hashtable.pyx", line 675, in pandas.hashtable.PyObjectHashTable.get_item (pandas/hashtable.c:12368)
  File "pandas/hashtable.pyx", line 683, in pandas.hashtable.PyObjectHashTable.get_item (pandas/hashtable.c:12322)
KeyError: 'CDL3WHITESOLDIERS'
2019-04-28 13:08:36,216 - default - ERROR - Exception occurred
Traceback (most recent call last):
  File "Trading/Dataset/DatasetHolder.py", line 266, in appendTimeframesIntoOneDataset
    ds_h.f_df[cdl] = np.convolve(ds_h.f_df[cdl], fn)[0:len(ds_h.f_df)]
  File "/usr/local/lib/python2.7/dist-packages/pandas/core/frame.py", line 1997, in __getitem__
    return self._getitem_column(key)
  File "/usr/local/lib/python2.7/dist-packages/pandas/core/frame.py", line 2004, in _getitem_column
    return self._get_item_cache(key)
  File "/usr/local/lib/python2.7/dist-packages/pandas/core/generic.py", line 1350, in _get_item_cache
    values = self._data.get(item)
  File "/usr/local/lib/python2.7/dist-packages/pandas/core/internals.py", line 3290, in get
    loc = self.items.get_loc(item)
  File "/usr/local/lib/python2.7/dist-packages/pandas/indexes/base.py", line 1947, in get_loc
    return self._engine.get_loc(self._maybe_cast_indexer(key))
  File "pandas/index.pyx", line 137, in pandas.index.IndexEngine.get_loc (pandas/index.c:4154)
  File "pandas/index.pyx", line 159, in pandas.index.IndexEngine.get_loc (pandas/index.c:4018)
  File "pandas/hashtable.pyx", line 675, in pandas.hashtable.PyObjectHashTable.get_item (pandas/hashtable.c:12368)
  File "pandas/hashtable.pyx", line 683, in pandas.hashtable.PyObjectHashTable.get_item (pandas/hashtable.c:12322)
KeyError: 'CDLABANDONEDBABY'
2019-04-28 13:08:36,218 - default - ERROR - Exception occurred
Traceback (most recent call last):
  File "Trading/Dataset/DatasetHolder.py", line 266, in appendTimeframesIntoOneDataset
    ds_h.f_df[cdl] = np.convolve(ds_h.f_df[cdl], fn)[0:len(ds_h.f_df)]
  File "/usr/local/lib/python2.7/dist-packages/pandas/core/frame.py", line 1997, in __getitem__
    return self._getitem_column(key)
  File "/usr/local/lib/python2.7/dist-packages/pandas/core/frame.py", line 2004, in _getitem_column
    return self._get_item_cache(key)
  File "/usr/local/lib/python2.7/dist-packages/pandas/core/generic.py", line 1350, in _get_item_cache
    values = self._data.get(item)
  File "/usr/local/lib/python2.7/dist-packages/pandas/core/internals.py", line 3290, in get
    loc = self.items.get_loc(item)
  File "/usr/local/lib/python2.7/dist-packages/pandas/indexes/base.py", line 1947, in get_loc
    return self._engine.get_loc(self._maybe_cast_indexer(key))
  File "pandas/index.pyx", line 137, in pandas.index.IndexEngine.get_loc (pandas/index.c:4154)
  File "pandas/index.pyx", line 159, in pandas.index.IndexEngine.get_loc (pandas/index.c:4018)
  File "pandas/hashtable.pyx", line 675, in pandas.hashtable.PyObjectHashTable.get_item (pandas/hashtable.c:12368)
  File "pandas/hashtable.pyx", line 683, in pandas.hashtable.PyObjectHashTable.get_item (pandas/hashtable.c:12322)
KeyError: 'CDLADVANCEBLOCK'
2019-04-28 13:08:36,221 - default - ERROR - Exception occurred
Traceback (most recent call last):
  File "Trading/Dataset/DatasetHolder.py", line 266, in appendTimeframesIntoOneDataset
    ds_h.f_df[cdl] = np.convolve(ds_h.f_df[cdl], fn)[0:len(ds_h.f_df)]
  File "/usr/local/lib/python2.7/dist-packages/pandas/core/frame.py", line 1997, in __getitem__
    return self._getitem_column(key)
  File "/usr/local/lib/python2.7/dist-packages/pandas/core/frame.py", line 2004, in _getitem_column
    return self._get_item_cache(key)
  File "/usr/local/lib/python2.7/dist-packages/pandas/core/generic.py", line 1350, in _get_item_cache
    values = self._data.get(item)
  File "/usr/local/lib/python2.7/dist-packages/pandas/core/internals.py", line 3290, in get
    loc = self.items.get_loc(item)
  File "/usr/local/lib/python2.7/dist-packages/pandas/indexes/base.py", line 1947, in get_loc
    return self._engine.get_loc(self._maybe_cast_indexer(key))
  File "pandas/index.pyx", line 137, in pandas.index.IndexEngine.get_loc (pandas/index.c:4154)
  File "pandas/index.pyx", line 159, in pandas.index.IndexEngine.get_loc (pandas/index.c:4018)
  File "pandas/hashtable.pyx", line 675, in pandas.hashtable.PyObjectHashTable.get_item (pandas/hashtable.c:12368)
  File "pandas/hashtable.pyx", line 683, in pandas.hashtable.PyObjectHashTable.get_item (pandas/hashtable.c:12322)
KeyError: 'CDLBELTHOLD'
2019-04-28 13:08:36,224 - default - ERROR - Exception occurred
Traceback (most recent call last):
  File "Trading/Dataset/DatasetHolder.py", line 266, in appendTimeframesIntoOneDataset
    ds_h.f_df[cdl] = np.convolve(ds_h.f_df[cdl], fn)[0:len(ds_h.f_df)]
  File "/usr/local/lib/python2.7/dist-packages/pandas/core/frame.py", line 1997, in __getitem__
    return self._getitem_column(key)
  File "/usr/local/lib/python2.7/dist-packages/pandas/core/frame.py", line 2004, in _getitem_column
    return self._get_item_cache(key)
  File "/usr/local/lib/python2.7/dist-packages/pandas/core/generic.py", line 1350, in _get_item_cache
    values = self._data.get(item)
  File "/usr/local/lib/python2.7/dist-packages/pandas/core/internals.py", line 3290, in get
    loc = self.items.get_loc(item)
  File "/usr/local/lib/python2.7/dist-packages/pandas/indexes/base.py", line 1947, in get_loc
    return self._engine.get_loc(self._maybe_cast_indexer(key))
  File "pandas/index.pyx", line 137, in pandas.index.IndexEngine.get_loc (pandas/index.c:4154)
  File "pandas/index.pyx", line 159, in pandas.index.IndexEngine.get_loc (pandas/index.c:4018)
  File "pandas/hashtable.pyx", line 675, in pandas.hashtable.PyObjectHashTable.get_item (pandas/hashtable.c:12368)
  File "pandas/hashtable.pyx", line 683, in pandas.hashtable.PyObjectHashTable.get_item (pandas/hashtable.c:12322)
KeyError: 'CDLBREAKAWAY'
2019-04-28 13:08:36,227 - default - ERROR - Exception occurred
Traceback (most recent call last):
  File "Trading/Dataset/DatasetHolder.py", line 266, in appendTimeframesIntoOneDataset
    ds_h.f_df[cdl] = np.convolve(ds_h.f_df[cdl], fn)[0:len(ds_h.f_df)]
  File "/usr/local/lib/python2.7/dist-packages/pandas/core/frame.py", line 1997, in __getitem__
    return self._getitem_column(key)
  File "/usr/local/lib/python2.7/dist-packages/pandas/core/frame.py", line 2004, in _getitem_column
    return self._get_item_cache(key)
  File "/usr/local/lib/python2.7/dist-packages/pandas/core/generic.py", line 1350, in _get_item_cache
    values = self._data.get(item)
  File "/usr/local/lib/python2.7/dist-packages/pandas/core/internals.py", line 3290, in get
    loc = self.items.get_loc(item)
  File "/usr/local/lib/python2.7/dist-packages/pandas/indexes/base.py", line 1947, in get_loc
    return self._engine.get_loc(self._maybe_cast_indexer(key))
  File "pandas/index.pyx", line 137, in pandas.index.IndexEngine.get_loc (pandas/index.c:4154)
  File "pandas/index.pyx", line 159, in pandas.index.IndexEngine.get_loc (pandas/index.c:4018)
  File "pandas/hashtable.pyx", line 675, in pandas.hashtable.PyObjectHashTable.get_item (pandas/hashtable.c:12368)
  File "pandas/hashtable.pyx", line 683, in pandas.hashtable.PyObjectHashTable.get_item (pandas/hashtable.c:12322)
KeyError: 'CDLCLOSINGMARUBOZU'
2019-04-28 13:08:36,230 - default - ERROR - Exception occurred
Traceback (most recent call last):
  File "Trading/Dataset/DatasetHolder.py", line 266, in appendTimeframesIntoOneDataset
    ds_h.f_df[cdl] = np.convolve(ds_h.f_df[cdl], fn)[0:len(ds_h.f_df)]
  File "/usr/local/lib/python2.7/dist-packages/pandas/core/frame.py", line 1997, in __getitem__
    return self._getitem_column(key)
  File "/usr/local/lib/python2.7/dist-packages/pandas/core/frame.py", line 2004, in _getitem_column
    return self._get_item_cache(key)
  File "/usr/local/lib/python2.7/dist-packages/pandas/core/generic.py", line 1350, in _get_item_cache
    values = self._data.get(item)
  File "/usr/local/lib/python2.7/dist-packages/pandas/core/internals.py", line 3290, in get
    loc = self.items.get_loc(item)
  File "/usr/local/lib/python2.7/dist-packages/pandas/indexes/base.py", line 1947, in get_loc
    return self._engine.get_loc(self._maybe_cast_indexer(key))
  File "pandas/index.pyx", line 137, in pandas.index.IndexEngine.get_loc (pandas/index.c:4154)
  File "pandas/index.pyx", line 159, in pandas.index.IndexEngine.get_loc (pandas/index.c:4018)
  File "pandas/hashtable.pyx", line 675, in pandas.hashtable.PyObjectHashTable.get_item (pandas/hashtable.c:12368)
  File "pandas/hashtable.pyx", line 683, in pandas.hashtable.PyObjectHashTable.get_item (pandas/hashtable.c:12322)
KeyError: 'CDLCONCEALBABYSWALL'
2019-04-28 13:08:36,232 - default - ERROR - Exception occurred
Traceback (most recent call last):
  File "Trading/Dataset/DatasetHolder.py", line 266, in appendTimeframesIntoOneDataset
    ds_h.f_df[cdl] = np.convolve(ds_h.f_df[cdl], fn)[0:len(ds_h.f_df)]
  File "/usr/local/lib/python2.7/dist-packages/pandas/core/frame.py", line 1997, in __getitem__
    return self._getitem_column(key)
  File "/usr/local/lib/python2.7/dist-packages/pandas/core/frame.py", line 2004, in _getitem_column
    return self._get_item_cache(key)
  File "/usr/local/lib/python2.7/dist-packages/pandas/core/generic.py", line 1350, in _get_item_cache
    values = self._data.get(item)
  File "/usr/local/lib/python2.7/dist-packages/pandas/core/internals.py", line 3290, in get
    loc = self.items.get_loc(item)
  File "/usr/local/lib/python2.7/dist-packages/pandas/indexes/base.py", line 1947, in get_loc
    return self._engine.get_loc(self._maybe_cast_indexer(key))
  File "pandas/index.pyx", line 137, in pandas.index.IndexEngine.get_loc (pandas/index.c:4154)
  File "pandas/index.pyx", line 159, in pandas.index.IndexEngine.get_loc (pandas/index.c:4018)
  File "pandas/hashtable.pyx", line 675, in pandas.hashtable.PyObjectHashTable.get_item (pandas/hashtable.c:12368)
  File "pandas/hashtable.pyx", line 683, in pandas.hashtable.PyObjectHashTable.get_item (pandas/hashtable.c:12322)
KeyError: 'CDLCOUNTERATTACK'
2019-04-28 13:08:36,235 - default - ERROR - Exception occurred
Traceback (most recent call last):
  File "Trading/Dataset/DatasetHolder.py", line 266, in appendTimeframesIntoOneDataset
    ds_h.f_df[cdl] = np.convolve(ds_h.f_df[cdl], fn)[0:len(ds_h.f_df)]
  File "/usr/local/lib/python2.7/dist-packages/pandas/core/frame.py", line 1997, in __getitem__
    return self._getitem_column(key)
  File "/usr/local/lib/python2.7/dist-packages/pandas/core/frame.py", line 2004, in _getitem_column
    return self._get_item_cache(key)
  File "/usr/local/lib/python2.7/dist-packages/pandas/core/generic.py", line 1350, in _get_item_cache
    values = self._data.get(item)
  File "/usr/local/lib/python2.7/dist-packages/pandas/core/internals.py", line 3290, in get
    loc = self.items.get_loc(item)
  File "/usr/local/lib/python2.7/dist-packages/pandas/indexes/base.py", line 1947, in get_loc
    return self._engine.get_loc(self._maybe_cast_indexer(key))
  File "pandas/index.pyx", line 137, in pandas.index.IndexEngine.get_loc (pandas/index.c:4154)
  File "pandas/index.pyx", line 159, in pandas.index.IndexEngine.get_loc (pandas/index.c:4018)
  File "pandas/hashtable.pyx", line 675, in pandas.hashtable.PyObjectHashTable.get_item (pandas/hashtable.c:12368)
  File "pandas/hashtable.pyx", line 683, in pandas.hashtable.PyObjectHashTable.get_item (pandas/hashtable.c:12322)
KeyError: 'CDLDARKCLOUDCOVER'
2019-04-28 13:08:36,237 - default - ERROR - Exception occurred
Traceback (most recent call last):
  File "Trading/Dataset/DatasetHolder.py", line 266, in appendTimeframesIntoOneDataset
    ds_h.f_df[cdl] = np.convolve(ds_h.f_df[cdl], fn)[0:len(ds_h.f_df)]
  File "/usr/local/lib/python2.7/dist-packages/pandas/core/frame.py", line 1997, in __getitem__
    return self._getitem_column(key)
  File "/usr/local/lib/python2.7/dist-packages/pandas/core/frame.py", line 2004, in _getitem_column
    return self._get_item_cache(key)
  File "/usr/local/lib/python2.7/dist-packages/pandas/core/generic.py", line 1350, in _get_item_cache
    values = self._data.get(item)
  File "/usr/local/lib/python2.7/dist-packages/pandas/core/internals.py", line 3290, in get
    loc = self.items.get_loc(item)
  File "/usr/local/lib/python2.7/dist-packages/pandas/indexes/base.py", line 1947, in get_loc
    return self._engine.get_loc(self._maybe_cast_indexer(key))
  File "pandas/index.pyx", line 137, in pandas.index.IndexEngine.get_loc (pandas/index.c:4154)
  File "pandas/index.pyx", line 159, in pandas.index.IndexEngine.get_loc (pandas/index.c:4018)
  File "pandas/hashtable.pyx", line 675, in pandas.hashtable.PyObjectHashTable.get_item (pandas/hashtable.c:12368)
  File "pandas/hashtable.pyx", line 683, in pandas.hashtable.PyObjectHashTable.get_item (pandas/hashtable.c:12322)
KeyError: 'CDLDOJI'
2019-04-28 13:08:36,240 - default - ERROR - Exception occurred
Traceback (most recent call last):
  File "Trading/Dataset/DatasetHolder.py", line 266, in appendTimeframesIntoOneDataset
    ds_h.f_df[cdl] = np.convolve(ds_h.f_df[cdl], fn)[0:len(ds_h.f_df)]
  File "/usr/local/lib/python2.7/dist-packages/pandas/core/frame.py", line 1997, in __getitem__
    return self._getitem_column(key)
  File "/usr/local/lib/python2.7/dist-packages/pandas/core/frame.py", line 2004, in _getitem_column
    return self._get_item_cache(key)
  File "/usr/local/lib/python2.7/dist-packages/pandas/core/generic.py", line 1350, in _get_item_cache
    values = self._data.get(item)
  File "/usr/local/lib/python2.7/dist-packages/pandas/core/internals.py", line 3290, in get
    loc = self.items.get_loc(item)
  File "/usr/local/lib/python2.7/dist-packages/pandas/indexes/base.py", line 1947, in get_loc
    return self._engine.get_loc(self._maybe_cast_indexer(key))
  File "pandas/index.pyx", line 137, in pandas.index.IndexEngine.get_loc (pandas/index.c:4154)
  File "pandas/index.pyx", line 159, in pandas.index.IndexEngine.get_loc (pandas/index.c:4018)
  File "pandas/hashtable.pyx", line 675, in pandas.hashtable.PyObjectHashTable.get_item (pandas/hashtable.c:12368)
  File "pandas/hashtable.pyx", line 683, in pandas.hashtable.PyObjectHashTable.get_item (pandas/hashtable.c:12322)
KeyError: 'CDLDOJISTAR'
2019-04-28 13:08:36,243 - default - ERROR - Exception occurred
Traceback (most recent call last):
  File "Trading/Dataset/DatasetHolder.py", line 266, in appendTimeframesIntoOneDataset
    ds_h.f_df[cdl] = np.convolve(ds_h.f_df[cdl], fn)[0:len(ds_h.f_df)]
  File "/usr/local/lib/python2.7/dist-packages/pandas/core/frame.py", line 1997, in __getitem__
    return self._getitem_column(key)
  File "/usr/local/lib/python2.7/dist-packages/pandas/core/frame.py", line 2004, in _getitem_column
    return self._get_item_cache(key)
  File "/usr/local/lib/python2.7/dist-packages/pandas/core/generic.py", line 1350, in _get_item_cache
    values = self._data.get(item)
  File "/usr/local/lib/python2.7/dist-packages/pandas/core/internals.py", line 3290, in get
    loc = self.items.get_loc(item)
  File "/usr/local/lib/python2.7/dist-packages/pandas/indexes/base.py", line 1947, in get_loc
    return self._engine.get_loc(self._maybe_cast_indexer(key))
  File "pandas/index.pyx", line 137, in pandas.index.IndexEngine.get_loc (pandas/index.c:4154)
  File "pandas/index.pyx", line 159, in pandas.index.IndexEngine.get_loc (pandas/index.c:4018)
  File "pandas/hashtable.pyx", line 675, in pandas.hashtable.PyObjectHashTable.get_item (pandas/hashtable.c:12368)
  File "pandas/hashtable.pyx", line 683, in pandas.hashtable.PyObjectHashTable.get_item (pandas/hashtable.c:12322)
KeyError: 'CDLDRAGONFLYDOJI'
2019-04-28 13:08:36,246 - default - ERROR - Exception occurred
Traceback (most recent call last):
  File "Trading/Dataset/DatasetHolder.py", line 266, in appendTimeframesIntoOneDataset
    ds_h.f_df[cdl] = np.convolve(ds_h.f_df[cdl], fn)[0:len(ds_h.f_df)]
  File "/usr/local/lib/python2.7/dist-packages/pandas/core/frame.py", line 1997, in __getitem__
    return self._getitem_column(key)
  File "/usr/local/lib/python2.7/dist-packages/pandas/core/frame.py", line 2004, in _getitem_column
    return self._get_item_cache(key)
  File "/usr/local/lib/python2.7/dist-packages/pandas/core/generic.py", line 1350, in _get_item_cache
    values = self._data.get(item)
  File "/usr/local/lib/python2.7/dist-packages/pandas/core/internals.py", line 3290, in get
    loc = self.items.get_loc(item)
  File "/usr/local/lib/python2.7/dist-packages/pandas/indexes/base.py", line 1947, in get_loc
    return self._engine.get_loc(self._maybe_cast_indexer(key))
  File "pandas/index.pyx", line 137, in pandas.index.IndexEngine.get_loc (pandas/index.c:4154)
  File "pandas/index.pyx", line 159, in pandas.index.IndexEngine.get_loc (pandas/index.c:4018)
  File "pandas/hashtable.pyx", line 675, in pandas.hashtable.PyObjectHashTable.get_item (pandas/hashtable.c:12368)
  File "pandas/hashtable.pyx", line 683, in pandas.hashtable.PyObjectHashTable.get_item (pandas/hashtable.c:12322)
KeyError: 'CDLENGULFING'
2019-04-28 13:08:36,250 - default - ERROR - Exception occurred
Traceback (most recent call last):
  File "Trading/Dataset/DatasetHolder.py", line 266, in appendTimeframesIntoOneDataset
    ds_h.f_df[cdl] = np.convolve(ds_h.f_df[cdl], fn)[0:len(ds_h.f_df)]
  File "/usr/local/lib/python2.7/dist-packages/pandas/core/frame.py", line 1997, in __getitem__
    return self._getitem_column(key)
  File "/usr/local/lib/python2.7/dist-packages/pandas/core/frame.py", line 2004, in _getitem_column
    return self._get_item_cache(key)
  File "/usr/local/lib/python2.7/dist-packages/pandas/core/generic.py", line 1350, in _get_item_cache
    values = self._data.get(item)
  File "/usr/local/lib/python2.7/dist-packages/pandas/core/internals.py", line 3290, in get
    loc = self.items.get_loc(item)
  File "/usr/local/lib/python2.7/dist-packages/pandas/indexes/base.py", line 1947, in get_loc
    return self._engine.get_loc(self._maybe_cast_indexer(key))
  File "pandas/index.pyx", line 137, in pandas.index.IndexEngine.get_loc (pandas/index.c:4154)
  File "pandas/index.pyx", line 159, in pandas.index.IndexEngine.get_loc (pandas/index.c:4018)
  File "pandas/hashtable.pyx", line 675, in pandas.hashtable.PyObjectHashTable.get_item (pandas/hashtable.c:12368)
  File "pandas/hashtable.pyx", line 683, in pandas.hashtable.PyObjectHashTable.get_item (pandas/hashtable.c:12322)
KeyError: 'CDLEVENINGDOJISTAR'
2019-04-28 13:08:36,252 - default - ERROR - Exception occurred
Traceback (most recent call last):
  File "Trading/Dataset/DatasetHolder.py", line 266, in appendTimeframesIntoOneDataset
    ds_h.f_df[cdl] = np.convolve(ds_h.f_df[cdl], fn)[0:len(ds_h.f_df)]
  File "/usr/local/lib/python2.7/dist-packages/pandas/core/frame.py", line 1997, in __getitem__
    return self._getitem_column(key)
  File "/usr/local/lib/python2.7/dist-packages/pandas/core/frame.py", line 2004, in _getitem_column
    return self._get_item_cache(key)
  File "/usr/local/lib/python2.7/dist-packages/pandas/core/generic.py", line 1350, in _get_item_cache
    values = self._data.get(item)
  File "/usr/local/lib/python2.7/dist-packages/pandas/core/internals.py", line 3290, in get
    loc = self.items.get_loc(item)
  File "/usr/local/lib/python2.7/dist-packages/pandas/indexes/base.py", line 1947, in get_loc
    return self._engine.get_loc(self._maybe_cast_indexer(key))
  File "pandas/index.pyx", line 137, in pandas.index.IndexEngine.get_loc (pandas/index.c:4154)
  File "pandas/index.pyx", line 159, in pandas.index.IndexEngine.get_loc (pandas/index.c:4018)
  File "pandas/hashtable.pyx", line 675, in pandas.hashtable.PyObjectHashTable.get_item (pandas/hashtable.c:12368)
  File "pandas/hashtable.pyx", line 683, in pandas.hashtable.PyObjectHashTable.get_item (pandas/hashtable.c:12322)
KeyError: 'CDLEVENINGSTAR'
2019-04-28 13:08:36,255 - default - ERROR - Exception occurred
Traceback (most recent call last):
  File "Trading/Dataset/DatasetHolder.py", line 266, in appendTimeframesIntoOneDataset
    ds_h.f_df[cdl] = np.convolve(ds_h.f_df[cdl], fn)[0:len(ds_h.f_df)]
  File "/usr/local/lib/python2.7/dist-packages/pandas/core/frame.py", line 1997, in __getitem__
    return self._getitem_column(key)
  File "/usr/local/lib/python2.7/dist-packages/pandas/core/frame.py", line 2004, in _getitem_column
    return self._get_item_cache(key)
  File "/usr/local/lib/python2.7/dist-packages/pandas/core/generic.py", line 1350, in _get_item_cache
    values = self._data.get(item)
  File "/usr/local/lib/python2.7/dist-packages/pandas/core/internals.py", line 3290, in get
    loc = self.items.get_loc(item)
  File "/usr/local/lib/python2.7/dist-packages/pandas/indexes/base.py", line 1947, in get_loc
    return self._engine.get_loc(self._maybe_cast_indexer(key))
  File "pandas/index.pyx", line 137, in pandas.index.IndexEngine.get_loc (pandas/index.c:4154)
  File "pandas/index.pyx", line 159, in pandas.index.IndexEngine.get_loc (pandas/index.c:4018)
  File "pandas/hashtable.pyx", line 675, in pandas.hashtable.PyObjectHashTable.get_item (pandas/hashtable.c:12368)
  File "pandas/hashtable.pyx", line 683, in pandas.hashtable.PyObjectHashTable.get_item (pandas/hashtable.c:12322)
KeyError: 'CDLGAPSIDESIDEWHITE'
2019-04-28 13:08:36,259 - default - ERROR - Exception occurred
Traceback (most recent call last):
  File "Trading/Dataset/DatasetHolder.py", line 266, in appendTimeframesIntoOneDataset
    ds_h.f_df[cdl] = np.convolve(ds_h.f_df[cdl], fn)[0:len(ds_h.f_df)]
  File "/usr/local/lib/python2.7/dist-packages/pandas/core/frame.py", line 1997, in __getitem__
    return self._getitem_column(key)
  File "/usr/local/lib/python2.7/dist-packages/pandas/core/frame.py", line 2004, in _getitem_column
    return self._get_item_cache(key)
  File "/usr/local/lib/python2.7/dist-packages/pandas/core/generic.py", line 1350, in _get_item_cache
    values = self._data.get(item)
  File "/usr/local/lib/python2.7/dist-packages/pandas/core/internals.py", line 3290, in get
    loc = self.items.get_loc(item)
  File "/usr/local/lib/python2.7/dist-packages/pandas/indexes/base.py", line 1947, in get_loc
    return self._engine.get_loc(self._maybe_cast_indexer(key))
  File "pandas/index.pyx", line 137, in pandas.index.IndexEngine.get_loc (pandas/index.c:4154)
  File "pandas/index.pyx", line 159, in pandas.index.IndexEngine.get_loc (pandas/index.c:4018)
  File "pandas/hashtable.pyx", line 675, in pandas.hashtable.PyObjectHashTable.get_item (pandas/hashtable.c:12368)
  File "pandas/hashtable.pyx", line 683, in pandas.hashtable.PyObjectHashTable.get_item (pandas/hashtable.c:12322)
KeyError: 'CDLGRAVESTONEDOJI'
2019-04-28 13:08:36,261 - default - ERROR - Exception occurred
Traceback (most recent call last):
  File "Trading/Dataset/DatasetHolder.py", line 266, in appendTimeframesIntoOneDataset
    ds_h.f_df[cdl] = np.convolve(ds_h.f_df[cdl], fn)[0:len(ds_h.f_df)]
  File "/usr/local/lib/python2.7/dist-packages/pandas/core/frame.py", line 1997, in __getitem__
    return self._getitem_column(key)
  File "/usr/local/lib/python2.7/dist-packages/pandas/core/frame.py", line 2004, in _getitem_column
    return self._get_item_cache(key)
  File "/usr/local/lib/python2.7/dist-packages/pandas/core/generic.py", line 1350, in _get_item_cache
    values = self._data.get(item)
  File "/usr/local/lib/python2.7/dist-packages/pandas/core/internals.py", line 3290, in get
    loc = self.items.get_loc(item)
  File "/usr/local/lib/python2.7/dist-packages/pandas/indexes/base.py", line 1947, in get_loc
    return self._engine.get_loc(self._maybe_cast_indexer(key))
  File "pandas/index.pyx", line 137, in pandas.index.IndexEngine.get_loc (pandas/index.c:4154)
  File "pandas/index.pyx", line 159, in pandas.index.IndexEngine.get_loc (pandas/index.c:4018)
  File "pandas/hashtable.pyx", line 675, in pandas.hashtable.PyObjectHashTable.get_item (pandas/hashtable.c:12368)
  File "pandas/hashtable.pyx", line 683, in pandas.hashtable.PyObjectHashTable.get_item (pandas/hashtable.c:12322)
KeyError: 'CDLHAMMER'
2019-04-28 13:08:36,265 - default - ERROR - Exception occurred
Traceback (most recent call last):
  File "Trading/Dataset/DatasetHolder.py", line 266, in appendTimeframesIntoOneDataset
    ds_h.f_df[cdl] = np.convolve(ds_h.f_df[cdl], fn)[0:len(ds_h.f_df)]
  File "/usr/local/lib/python2.7/dist-packages/pandas/core/frame.py", line 1997, in __getitem__
    return self._getitem_column(key)
  File "/usr/local/lib/python2.7/dist-packages/pandas/core/frame.py", line 2004, in _getitem_column
    return self._get_item_cache(key)
  File "/usr/local/lib/python2.7/dist-packages/pandas/core/generic.py", line 1350, in _get_item_cache
    values = self._data.get(item)
  File "/usr/local/lib/python2.7/dist-packages/pandas/core/internals.py", line 3290, in get
    loc = self.items.get_loc(item)
  File "/usr/local/lib/python2.7/dist-packages/pandas/indexes/base.py", line 1947, in get_loc
    return self._engine.get_loc(self._maybe_cast_indexer(key))
  File "pandas/index.pyx", line 137, in pandas.index.IndexEngine.get_loc (pandas/index.c:4154)
  File "pandas/index.pyx", line 159, in pandas.index.IndexEngine.get_loc (pandas/index.c:4018)
  File "pandas/hashtable.pyx", line 675, in pandas.hashtable.PyObjectHashTable.get_item (pandas/hashtable.c:12368)
  File "pandas/hashtable.pyx", line 683, in pandas.hashtable.PyObjectHashTable.get_item (pandas/hashtable.c:12322)
KeyError: 'CDLHANGINGMAN'
2019-04-28 13:08:36,268 - default - ERROR - Exception occurred
Traceback (most recent call last):
  File "Trading/Dataset/DatasetHolder.py", line 266, in appendTimeframesIntoOneDataset
    ds_h.f_df[cdl] = np.convolve(ds_h.f_df[cdl], fn)[0:len(ds_h.f_df)]
  File "/usr/local/lib/python2.7/dist-packages/pandas/core/frame.py", line 1997, in __getitem__
    return self._getitem_column(key)
  File "/usr/local/lib/python2.7/dist-packages/pandas/core/frame.py", line 2004, in _getitem_column
    return self._get_item_cache(key)
  File "/usr/local/lib/python2.7/dist-packages/pandas/core/generic.py", line 1350, in _get_item_cache
    values = self._data.get(item)
  File "/usr/local/lib/python2.7/dist-packages/pandas/core/internals.py", line 3290, in get
    loc = self.items.get_loc(item)
  File "/usr/local/lib/python2.7/dist-packages/pandas/indexes/base.py", line 1947, in get_loc
    return self._engine.get_loc(self._maybe_cast_indexer(key))
  File "pandas/index.pyx", line 137, in pandas.index.IndexEngine.get_loc (pandas/index.c:4154)
  File "pandas/index.pyx", line 159, in pandas.index.IndexEngine.get_loc (pandas/index.c:4018)
  File "pandas/hashtable.pyx", line 675, in pandas.hashtable.PyObjectHashTable.get_item (pandas/hashtable.c:12368)
  File "pandas/hashtable.pyx", line 683, in pandas.hashtable.PyObjectHashTable.get_item (pandas/hashtable.c:12322)
KeyError: 'CDLHARAMI'
2019-04-28 13:08:36,271 - default - ERROR - Exception occurred
Traceback (most recent call last):
  File "Trading/Dataset/DatasetHolder.py", line 266, in appendTimeframesIntoOneDataset
    ds_h.f_df[cdl] = np.convolve(ds_h.f_df[cdl], fn)[0:len(ds_h.f_df)]
  File "/usr/local/lib/python2.7/dist-packages/pandas/core/frame.py", line 1997, in __getitem__
    return self._getitem_column(key)
  File "/usr/local/lib/python2.7/dist-packages/pandas/core/frame.py", line 2004, in _getitem_column
    return self._get_item_cache(key)
  File "/usr/local/lib/python2.7/dist-packages/pandas/core/generic.py", line 1350, in _get_item_cache
    values = self._data.get(item)
  File "/usr/local/lib/python2.7/dist-packages/pandas/core/internals.py", line 3290, in get
    loc = self.items.get_loc(item)
  File "/usr/local/lib/python2.7/dist-packages/pandas/indexes/base.py", line 1947, in get_loc
    return self._engine.get_loc(self._maybe_cast_indexer(key))
  File "pandas/index.pyx", line 137, in pandas.index.IndexEngine.get_loc (pandas/index.c:4154)
  File "pandas/index.pyx", line 159, in pandas.index.IndexEngine.get_loc (pandas/index.c:4018)
  File "pandas/hashtable.pyx", line 675, in pandas.hashtable.PyObjectHashTable.get_item (pandas/hashtable.c:12368)
  File "pandas/hashtable.pyx", line 683, in pandas.hashtable.PyObjectHashTable.get_item (pandas/hashtable.c:12322)
KeyError: 'CDLHARAMICROSS'
2019-04-28 13:08:36,274 - default - ERROR - Exception occurred
Traceback (most recent call last):
  File "Trading/Dataset/DatasetHolder.py", line 266, in appendTimeframesIntoOneDataset
    ds_h.f_df[cdl] = np.convolve(ds_h.f_df[cdl], fn)[0:len(ds_h.f_df)]
  File "/usr/local/lib/python2.7/dist-packages/pandas/core/frame.py", line 1997, in __getitem__
    return self._getitem_column(key)
  File "/usr/local/lib/python2.7/dist-packages/pandas/core/frame.py", line 2004, in _getitem_column
    return self._get_item_cache(key)
  File "/usr/local/lib/python2.7/dist-packages/pandas/core/generic.py", line 1350, in _get_item_cache
    values = self._data.get(item)
  File "/usr/local/lib/python2.7/dist-packages/pandas/core/internals.py", line 3290, in get
    loc = self.items.get_loc(item)
  File "/usr/local/lib/python2.7/dist-packages/pandas/indexes/base.py", line 1947, in get_loc
    return self._engine.get_loc(self._maybe_cast_indexer(key))
  File "pandas/index.pyx", line 137, in pandas.index.IndexEngine.get_loc (pandas/index.c:4154)
  File "pandas/index.pyx", line 159, in pandas.index.IndexEngine.get_loc (pandas/index.c:4018)
  File "pandas/hashtable.pyx", line 675, in pandas.hashtable.PyObjectHashTable.get_item (pandas/hashtable.c:12368)
  File "pandas/hashtable.pyx", line 683, in pandas.hashtable.PyObjectHashTable.get_item (pandas/hashtable.c:12322)
KeyError: 'CDLHIGHWAVE'
2019-04-28 13:08:36,277 - default - ERROR - Exception occurred
Traceback (most recent call last):
  File "Trading/Dataset/DatasetHolder.py", line 266, in appendTimeframesIntoOneDataset
    ds_h.f_df[cdl] = np.convolve(ds_h.f_df[cdl], fn)[0:len(ds_h.f_df)]
  File "/usr/local/lib/python2.7/dist-packages/pandas/core/frame.py", line 1997, in __getitem__
    return self._getitem_column(key)
  File "/usr/local/lib/python2.7/dist-packages/pandas/core/frame.py", line 2004, in _getitem_column
    return self._get_item_cache(key)
  File "/usr/local/lib/python2.7/dist-packages/pandas/core/generic.py", line 1350, in _get_item_cache
    values = self._data.get(item)
  File "/usr/local/lib/python2.7/dist-packages/pandas/core/internals.py", line 3290, in get
    loc = self.items.get_loc(item)
  File "/usr/local/lib/python2.7/dist-packages/pandas/indexes/base.py", line 1947, in get_loc
    return self._engine.get_loc(self._maybe_cast_indexer(key))
  File "pandas/index.pyx", line 137, in pandas.index.IndexEngine.get_loc (pandas/index.c:4154)
  File "pandas/index.pyx", line 159, in pandas.index.IndexEngine.get_loc (pandas/index.c:4018)
  File "pandas/hashtable.pyx", line 675, in pandas.hashtable.PyObjectHashTable.get_item (pandas/hashtable.c:12368)
  File "pandas/hashtable.pyx", line 683, in pandas.hashtable.PyObjectHashTable.get_item (pandas/hashtable.c:12322)
KeyError: 'CDLHIKKAKE'
2019-04-28 13:08:36,281 - default - ERROR - Exception occurred
Traceback (most recent call last):
  File "Trading/Dataset/DatasetHolder.py", line 266, in appendTimeframesIntoOneDataset
    ds_h.f_df[cdl] = np.convolve(ds_h.f_df[cdl], fn)[0:len(ds_h.f_df)]
  File "/usr/local/lib/python2.7/dist-packages/pandas/core/frame.py", line 1997, in __getitem__
    return self._getitem_column(key)
  File "/usr/local/lib/python2.7/dist-packages/pandas/core/frame.py", line 2004, in _getitem_column
    return self._get_item_cache(key)
  File "/usr/local/lib/python2.7/dist-packages/pandas/core/generic.py", line 1350, in _get_item_cache
    values = self._data.get(item)
  File "/usr/local/lib/python2.7/dist-packages/pandas/core/internals.py", line 3290, in get
    loc = self.items.get_loc(item)
  File "/usr/local/lib/python2.7/dist-packages/pandas/indexes/base.py", line 1947, in get_loc
    return self._engine.get_loc(self._maybe_cast_indexer(key))
  File "pandas/index.pyx", line 137, in pandas.index.IndexEngine.get_loc (pandas/index.c:4154)
  File "pandas/index.pyx", line 159, in pandas.index.IndexEngine.get_loc (pandas/index.c:4018)
  File "pandas/hashtable.pyx", line 675, in pandas.hashtable.PyObjectHashTable.get_item (pandas/hashtable.c:12368)
  File "pandas/hashtable.pyx", line 683, in pandas.hashtable.PyObjectHashTable.get_item (pandas/hashtable.c:12322)
KeyError: 'CDLHIKKAKEMOD'
2019-04-28 13:08:36,283 - default - ERROR - Exception occurred
Traceback (most recent call last):
  File "Trading/Dataset/DatasetHolder.py", line 266, in appendTimeframesIntoOneDataset
    ds_h.f_df[cdl] = np.convolve(ds_h.f_df[cdl], fn)[0:len(ds_h.f_df)]
  File "/usr/local/lib/python2.7/dist-packages/pandas/core/frame.py", line 1997, in __getitem__
    return self._getitem_column(key)
  File "/usr/local/lib/python2.7/dist-packages/pandas/core/frame.py", line 2004, in _getitem_column
    return self._get_item_cache(key)
  File "/usr/local/lib/python2.7/dist-packages/pandas/core/generic.py", line 1350, in _get_item_cache
    values = self._data.get(item)
  File "/usr/local/lib/python2.7/dist-packages/pandas/core/internals.py", line 3290, in get
    loc = self.items.get_loc(item)
  File "/usr/local/lib/python2.7/dist-packages/pandas/indexes/base.py", line 1947, in get_loc
    return self._engine.get_loc(self._maybe_cast_indexer(key))
  File "pandas/index.pyx", line 137, in pandas.index.IndexEngine.get_loc (pandas/index.c:4154)
  File "pandas/index.pyx", line 159, in pandas.index.IndexEngine.get_loc (pandas/index.c:4018)
  File "pandas/hashtable.pyx", line 675, in pandas.hashtable.PyObjectHashTable.get_item (pandas/hashtable.c:12368)
  File "pandas/hashtable.pyx", line 683, in pandas.hashtable.PyObjectHashTable.get_item (pandas/hashtable.c:12322)
KeyError: 'CDLHOMINGPIGEON'
2019-04-28 13:08:36,286 - default - ERROR - Exception occurred
Traceback (most recent call last):
  File "Trading/Dataset/DatasetHolder.py", line 266, in appendTimeframesIntoOneDataset
    ds_h.f_df[cdl] = np.convolve(ds_h.f_df[cdl], fn)[0:len(ds_h.f_df)]
  File "/usr/local/lib/python2.7/dist-packages/pandas/core/frame.py", line 1997, in __getitem__
    return self._getitem_column(key)
  File "/usr/local/lib/python2.7/dist-packages/pandas/core/frame.py", line 2004, in _getitem_column
    return self._get_item_cache(key)
  File "/usr/local/lib/python2.7/dist-packages/pandas/core/generic.py", line 1350, in _get_item_cache
    values = self._data.get(item)
  File "/usr/local/lib/python2.7/dist-packages/pandas/core/internals.py", line 3290, in get
    loc = self.items.get_loc(item)
  File "/usr/local/lib/python2.7/dist-packages/pandas/indexes/base.py", line 1947, in get_loc
    return self._engine.get_loc(self._maybe_cast_indexer(key))
  File "pandas/index.pyx", line 137, in pandas.index.IndexEngine.get_loc (pandas/index.c:4154)
  File "pandas/index.pyx", line 159, in pandas.index.IndexEngine.get_loc (pandas/index.c:4018)
  File "pandas/hashtable.pyx", line 675, in pandas.hashtable.PyObjectHashTable.get_item (pandas/hashtable.c:12368)
  File "pandas/hashtable.pyx", line 683, in pandas.hashtable.PyObjectHashTable.get_item (pandas/hashtable.c:12322)
KeyError: 'CDLIDENTICAL3CROWS'
2019-04-28 13:08:36,288 - default - ERROR - Exception occurred
Traceback (most recent call last):
  File "Trading/Dataset/DatasetHolder.py", line 266, in appendTimeframesIntoOneDataset
    ds_h.f_df[cdl] = np.convolve(ds_h.f_df[cdl], fn)[0:len(ds_h.f_df)]
  File "/usr/local/lib/python2.7/dist-packages/pandas/core/frame.py", line 1997, in __getitem__
    return self._getitem_column(key)
  File "/usr/local/lib/python2.7/dist-packages/pandas/core/frame.py", line 2004, in _getitem_column
    return self._get_item_cache(key)
  File "/usr/local/lib/python2.7/dist-packages/pandas/core/generic.py", line 1350, in _get_item_cache
    values = self._data.get(item)
  File "/usr/local/lib/python2.7/dist-packages/pandas/core/internals.py", line 3290, in get
    loc = self.items.get_loc(item)
  File "/usr/local/lib/python2.7/dist-packages/pandas/indexes/base.py", line 1947, in get_loc
    return self._engine.get_loc(self._maybe_cast_indexer(key))
  File "pandas/index.pyx", line 137, in pandas.index.IndexEngine.get_loc (pandas/index.c:4154)
  File "pandas/index.pyx", line 159, in pandas.index.IndexEngine.get_loc (pandas/index.c:4018)
  File "pandas/hashtable.pyx", line 675, in pandas.hashtable.PyObjectHashTable.get_item (pandas/hashtable.c:12368)
  File "pandas/hashtable.pyx", line 683, in pandas.hashtable.PyObjectHashTable.get_item (pandas/hashtable.c:12322)
KeyError: 'CDLINNECK'
2019-04-28 13:08:36,291 - default - ERROR - Exception occurred
Traceback (most recent call last):
  File "Trading/Dataset/DatasetHolder.py", line 266, in appendTimeframesIntoOneDataset
    ds_h.f_df[cdl] = np.convolve(ds_h.f_df[cdl], fn)[0:len(ds_h.f_df)]
  File "/usr/local/lib/python2.7/dist-packages/pandas/core/frame.py", line 1997, in __getitem__
    return self._getitem_column(key)
  File "/usr/local/lib/python2.7/dist-packages/pandas/core/frame.py", line 2004, in _getitem_column
    return self._get_item_cache(key)
  File "/usr/local/lib/python2.7/dist-packages/pandas/core/generic.py", line 1350, in _get_item_cache
    values = self._data.get(item)
  File "/usr/local/lib/python2.7/dist-packages/pandas/core/internals.py", line 3290, in get
    loc = self.items.get_loc(item)
  File "/usr/local/lib/python2.7/dist-packages/pandas/indexes/base.py", line 1947, in get_loc
    return self._engine.get_loc(self._maybe_cast_indexer(key))
  File "pandas/index.pyx", line 137, in pandas.index.IndexEngine.get_loc (pandas/index.c:4154)
  File "pandas/index.pyx", line 159, in pandas.index.IndexEngine.get_loc (pandas/index.c:4018)
  File "pandas/hashtable.pyx", line 675, in pandas.hashtable.PyObjectHashTable.get_item (pandas/hashtable.c:12368)
  File "pandas/hashtable.pyx", line 683, in pandas.hashtable.PyObjectHashTable.get_item (pandas/hashtable.c:12322)
KeyError: 'CDLINVERTEDHAMMER'
2019-04-28 13:08:36,294 - default - ERROR - Exception occurred
Traceback (most recent call last):
  File "Trading/Dataset/DatasetHolder.py", line 266, in appendTimeframesIntoOneDataset
    ds_h.f_df[cdl] = np.convolve(ds_h.f_df[cdl], fn)[0:len(ds_h.f_df)]
  File "/usr/local/lib/python2.7/dist-packages/pandas/core/frame.py", line 1997, in __getitem__
    return self._getitem_column(key)
  File "/usr/local/lib/python2.7/dist-packages/pandas/core/frame.py", line 2004, in _getitem_column
    return self._get_item_cache(key)
  File "/usr/local/lib/python2.7/dist-packages/pandas/core/generic.py", line 1350, in _get_item_cache
    values = self._data.get(item)
  File "/usr/local/lib/python2.7/dist-packages/pandas/core/internals.py", line 3290, in get
    loc = self.items.get_loc(item)
  File "/usr/local/lib/python2.7/dist-packages/pandas/indexes/base.py", line 1947, in get_loc
    return self._engine.get_loc(self._maybe_cast_indexer(key))
  File "pandas/index.pyx", line 137, in pandas.index.IndexEngine.get_loc (pandas/index.c:4154)
  File "pandas/index.pyx", line 159, in pandas.index.IndexEngine.get_loc (pandas/index.c:4018)
  File "pandas/hashtable.pyx", line 675, in pandas.hashtable.PyObjectHashTable.get_item (pandas/hashtable.c:12368)
  File "pandas/hashtable.pyx", line 683, in pandas.hashtable.PyObjectHashTable.get_item (pandas/hashtable.c:12322)
KeyError: 'CDLKICKING'
2019-04-28 13:08:36,298 - default - ERROR - Exception occurred
Traceback (most recent call last):
  File "Trading/Dataset/DatasetHolder.py", line 266, in appendTimeframesIntoOneDataset
    ds_h.f_df[cdl] = np.convolve(ds_h.f_df[cdl], fn)[0:len(ds_h.f_df)]
  File "/usr/local/lib/python2.7/dist-packages/pandas/core/frame.py", line 1997, in __getitem__
    return self._getitem_column(key)
  File "/usr/local/lib/python2.7/dist-packages/pandas/core/frame.py", line 2004, in _getitem_column
    return self._get_item_cache(key)
  File "/usr/local/lib/python2.7/dist-packages/pandas/core/generic.py", line 1350, in _get_item_cache
    values = self._data.get(item)
  File "/usr/local/lib/python2.7/dist-packages/pandas/core/internals.py", line 3290, in get
    loc = self.items.get_loc(item)
  File "/usr/local/lib/python2.7/dist-packages/pandas/indexes/base.py", line 1947, in get_loc
    return self._engine.get_loc(self._maybe_cast_indexer(key))
  File "pandas/index.pyx", line 137, in pandas.index.IndexEngine.get_loc (pandas/index.c:4154)
  File "pandas/index.pyx", line 159, in pandas.index.IndexEngine.get_loc (pandas/index.c:4018)
  File "pandas/hashtable.pyx", line 675, in pandas.hashtable.PyObjectHashTable.get_item (pandas/hashtable.c:12368)
  File "pandas/hashtable.pyx", line 683, in pandas.hashtable.PyObjectHashTable.get_item (pandas/hashtable.c:12322)
KeyError: 'CDLKICKINGBYLENGTH'
2019-04-28 13:08:36,300 - default - ERROR - Exception occurred
Traceback (most recent call last):
  File "Trading/Dataset/DatasetHolder.py", line 266, in appendTimeframesIntoOneDataset
    ds_h.f_df[cdl] = np.convolve(ds_h.f_df[cdl], fn)[0:len(ds_h.f_df)]
  File "/usr/local/lib/python2.7/dist-packages/pandas/core/frame.py", line 1997, in __getitem__
    return self._getitem_column(key)
  File "/usr/local/lib/python2.7/dist-packages/pandas/core/frame.py", line 2004, in _getitem_column
    return self._get_item_cache(key)
  File "/usr/local/lib/python2.7/dist-packages/pandas/core/generic.py", line 1350, in _get_item_cache
    values = self._data.get(item)
  File "/usr/local/lib/python2.7/dist-packages/pandas/core/internals.py", line 3290, in get
    loc = self.items.get_loc(item)
  File "/usr/local/lib/python2.7/dist-packages/pandas/indexes/base.py", line 1947, in get_loc
    return self._engine.get_loc(self._maybe_cast_indexer(key))
  File "pandas/index.pyx", line 137, in pandas.index.IndexEngine.get_loc (pandas/index.c:4154)
  File "pandas/index.pyx", line 159, in pandas.index.IndexEngine.get_loc (pandas/index.c:4018)
  File "pandas/hashtable.pyx", line 675, in pandas.hashtable.PyObjectHashTable.get_item (pandas/hashtable.c:12368)
  File "pandas/hashtable.pyx", line 683, in pandas.hashtable.PyObjectHashTable.get_item (pandas/hashtable.c:12322)
KeyError: 'CDLLADDERBOTTOM'
2019-04-28 13:08:36,303 - default - ERROR - Exception occurred
Traceback (most recent call last):
  File "Trading/Dataset/DatasetHolder.py", line 266, in appendTimeframesIntoOneDataset
    ds_h.f_df[cdl] = np.convolve(ds_h.f_df[cdl], fn)[0:len(ds_h.f_df)]
  File "/usr/local/lib/python2.7/dist-packages/pandas/core/frame.py", line 1997, in __getitem__
    return self._getitem_column(key)
  File "/usr/local/lib/python2.7/dist-packages/pandas/core/frame.py", line 2004, in _getitem_column
    return self._get_item_cache(key)
  File "/usr/local/lib/python2.7/dist-packages/pandas/core/generic.py", line 1350, in _get_item_cache
    values = self._data.get(item)
  File "/usr/local/lib/python2.7/dist-packages/pandas/core/internals.py", line 3290, in get
    loc = self.items.get_loc(item)
  File "/usr/local/lib/python2.7/dist-packages/pandas/indexes/base.py", line 1947, in get_loc
    return self._engine.get_loc(self._maybe_cast_indexer(key))
  File "pandas/index.pyx", line 137, in pandas.index.IndexEngine.get_loc (pandas/index.c:4154)
  File "pandas/index.pyx", line 159, in pandas.index.IndexEngine.get_loc (pandas/index.c:4018)
  File "pandas/hashtable.pyx", line 675, in pandas.hashtable.PyObjectHashTable.get_item (pandas/hashtable.c:12368)
  File "pandas/hashtable.pyx", line 683, in pandas.hashtable.PyObjectHashTable.get_item (pandas/hashtable.c:12322)
KeyError: 'CDLLONGLEGGEDDOJI'
2019-04-28 13:08:36,306 - default - ERROR - Exception occurred
Traceback (most recent call last):
  File "Trading/Dataset/DatasetHolder.py", line 266, in appendTimeframesIntoOneDataset
    ds_h.f_df[cdl] = np.convolve(ds_h.f_df[cdl], fn)[0:len(ds_h.f_df)]
  File "/usr/local/lib/python2.7/dist-packages/pandas/core/frame.py", line 1997, in __getitem__
    return self._getitem_column(key)
  File "/usr/local/lib/python2.7/dist-packages/pandas/core/frame.py", line 2004, in _getitem_column
    return self._get_item_cache(key)
  File "/usr/local/lib/python2.7/dist-packages/pandas/core/generic.py", line 1350, in _get_item_cache
    values = self._data.get(item)
  File "/usr/local/lib/python2.7/dist-packages/pandas/core/internals.py", line 3290, in get
    loc = self.items.get_loc(item)
  File "/usr/local/lib/python2.7/dist-packages/pandas/indexes/base.py", line 1947, in get_loc
    return self._engine.get_loc(self._maybe_cast_indexer(key))
  File "pandas/index.pyx", line 137, in pandas.index.IndexEngine.get_loc (pandas/index.c:4154)
  File "pandas/index.pyx", line 159, in pandas.index.IndexEngine.get_loc (pandas/index.c:4018)
  File "pandas/hashtable.pyx", line 675, in pandas.hashtable.PyObjectHashTable.get_item (pandas/hashtable.c:12368)
  File "pandas/hashtable.pyx", line 683, in pandas.hashtable.PyObjectHashTable.get_item (pandas/hashtable.c:12322)
KeyError: 'CDLLONGLINE'
2019-04-28 13:08:36,309 - default - ERROR - Exception occurred
Traceback (most recent call last):
  File "Trading/Dataset/DatasetHolder.py", line 266, in appendTimeframesIntoOneDataset
    ds_h.f_df[cdl] = np.convolve(ds_h.f_df[cdl], fn)[0:len(ds_h.f_df)]
  File "/usr/local/lib/python2.7/dist-packages/pandas/core/frame.py", line 1997, in __getitem__
    return self._getitem_column(key)
  File "/usr/local/lib/python2.7/dist-packages/pandas/core/frame.py", line 2004, in _getitem_column
    return self._get_item_cache(key)
  File "/usr/local/lib/python2.7/dist-packages/pandas/core/generic.py", line 1350, in _get_item_cache
    values = self._data.get(item)
  File "/usr/local/lib/python2.7/dist-packages/pandas/core/internals.py", line 3290, in get
    loc = self.items.get_loc(item)
  File "/usr/local/lib/python2.7/dist-packages/pandas/indexes/base.py", line 1947, in get_loc
    return self._engine.get_loc(self._maybe_cast_indexer(key))
  File "pandas/index.pyx", line 137, in pandas.index.IndexEngine.get_loc (pandas/index.c:4154)
  File "pandas/index.pyx", line 159, in pandas.index.IndexEngine.get_loc (pandas/index.c:4018)
  File "pandas/hashtable.pyx", line 675, in pandas.hashtable.PyObjectHashTable.get_item (pandas/hashtable.c:12368)
  File "pandas/hashtable.pyx", line 683, in pandas.hashtable.PyObjectHashTable.get_item (pandas/hashtable.c:12322)
KeyError: 'CDLMARUBOZU'
2019-04-28 13:08:36,312 - default - ERROR - Exception occurred
Traceback (most recent call last):
  File "Trading/Dataset/DatasetHolder.py", line 266, in appendTimeframesIntoOneDataset
    ds_h.f_df[cdl] = np.convolve(ds_h.f_df[cdl], fn)[0:len(ds_h.f_df)]
  File "/usr/local/lib/python2.7/dist-packages/pandas/core/frame.py", line 1997, in __getitem__
    return self._getitem_column(key)
  File "/usr/local/lib/python2.7/dist-packages/pandas/core/frame.py", line 2004, in _getitem_column
    return self._get_item_cache(key)
  File "/usr/local/lib/python2.7/dist-packages/pandas/core/generic.py", line 1350, in _get_item_cache
    values = self._data.get(item)
  File "/usr/local/lib/python2.7/dist-packages/pandas/core/internals.py", line 3290, in get
    loc = self.items.get_loc(item)
  File "/usr/local/lib/python2.7/dist-packages/pandas/indexes/base.py", line 1947, in get_loc
    return self._engine.get_loc(self._maybe_cast_indexer(key))
  File "pandas/index.pyx", line 137, in pandas.index.IndexEngine.get_loc (pandas/index.c:4154)
  File "pandas/index.pyx", line 159, in pandas.index.IndexEngine.get_loc (pandas/index.c:4018)
  File "pandas/hashtable.pyx", line 675, in pandas.hashtable.PyObjectHashTable.get_item (pandas/hashtable.c:12368)
  File "pandas/hashtable.pyx", line 683, in pandas.hashtable.PyObjectHashTable.get_item (pandas/hashtable.c:12322)
KeyError: 'CDLMATCHINGLOW'
2019-04-28 13:08:36,316 - default - ERROR - Exception occurred
Traceback (most recent call last):
  File "Trading/Dataset/DatasetHolder.py", line 266, in appendTimeframesIntoOneDataset
    ds_h.f_df[cdl] = np.convolve(ds_h.f_df[cdl], fn)[0:len(ds_h.f_df)]
  File "/usr/local/lib/python2.7/dist-packages/pandas/core/frame.py", line 1997, in __getitem__
    return self._getitem_column(key)
  File "/usr/local/lib/python2.7/dist-packages/pandas/core/frame.py", line 2004, in _getitem_column
    return self._get_item_cache(key)
  File "/usr/local/lib/python2.7/dist-packages/pandas/core/generic.py", line 1350, in _get_item_cache
    values = self._data.get(item)
  File "/usr/local/lib/python2.7/dist-packages/pandas/core/internals.py", line 3290, in get
    loc = self.items.get_loc(item)
  File "/usr/local/lib/python2.7/dist-packages/pandas/indexes/base.py", line 1947, in get_loc
    return self._engine.get_loc(self._maybe_cast_indexer(key))
  File "pandas/index.pyx", line 137, in pandas.index.IndexEngine.get_loc (pandas/index.c:4154)
  File "pandas/index.pyx", line 159, in pandas.index.IndexEngine.get_loc (pandas/index.c:4018)
  File "pandas/hashtable.pyx", line 675, in pandas.hashtable.PyObjectHashTable.get_item (pandas/hashtable.c:12368)
  File "pandas/hashtable.pyx", line 683, in pandas.hashtable.PyObjectHashTable.get_item (pandas/hashtable.c:12322)
KeyError: 'CDLMATHOLD'
2019-04-28 13:08:36,320 - default - ERROR - Exception occurred
Traceback (most recent call last):
  File "Trading/Dataset/DatasetHolder.py", line 266, in appendTimeframesIntoOneDataset
    ds_h.f_df[cdl] = np.convolve(ds_h.f_df[cdl], fn)[0:len(ds_h.f_df)]
  File "/usr/local/lib/python2.7/dist-packages/pandas/core/frame.py", line 1997, in __getitem__
    return self._getitem_column(key)
  File "/usr/local/lib/python2.7/dist-packages/pandas/core/frame.py", line 2004, in _getitem_column
    return self._get_item_cache(key)
  File "/usr/local/lib/python2.7/dist-packages/pandas/core/generic.py", line 1350, in _get_item_cache
    values = self._data.get(item)
  File "/usr/local/lib/python2.7/dist-packages/pandas/core/internals.py", line 3290, in get
    loc = self.items.get_loc(item)
  File "/usr/local/lib/python2.7/dist-packages/pandas/indexes/base.py", line 1947, in get_loc
    return self._engine.get_loc(self._maybe_cast_indexer(key))
  File "pandas/index.pyx", line 137, in pandas.index.IndexEngine.get_loc (pandas/index.c:4154)
  File "pandas/index.pyx", line 159, in pandas.index.IndexEngine.get_loc (pandas/index.c:4018)
  File "pandas/hashtable.pyx", line 675, in pandas.hashtable.PyObjectHashTable.get_item (pandas/hashtable.c:12368)
  File "pandas/hashtable.pyx", line 683, in pandas.hashtable.PyObjectHashTable.get_item (pandas/hashtable.c:12322)
KeyError: 'CDLMORNINGDOJISTAR'
2019-04-28 13:08:36,323 - default - ERROR - Exception occurred
Traceback (most recent call last):
  File "Trading/Dataset/DatasetHolder.py", line 266, in appendTimeframesIntoOneDataset
    ds_h.f_df[cdl] = np.convolve(ds_h.f_df[cdl], fn)[0:len(ds_h.f_df)]
  File "/usr/local/lib/python2.7/dist-packages/pandas/core/frame.py", line 1997, in __getitem__
    return self._getitem_column(key)
  File "/usr/local/lib/python2.7/dist-packages/pandas/core/frame.py", line 2004, in _getitem_column
    return self._get_item_cache(key)
  File "/usr/local/lib/python2.7/dist-packages/pandas/core/generic.py", line 1350, in _get_item_cache
    values = self._data.get(item)
  File "/usr/local/lib/python2.7/dist-packages/pandas/core/internals.py", line 3290, in get
    loc = self.items.get_loc(item)
  File "/usr/local/lib/python2.7/dist-packages/pandas/indexes/base.py", line 1947, in get_loc
    return self._engine.get_loc(self._maybe_cast_indexer(key))
  File "pandas/index.pyx", line 137, in pandas.index.IndexEngine.get_loc (pandas/index.c:4154)
  File "pandas/index.pyx", line 159, in pandas.index.IndexEngine.get_loc (pandas/index.c:4018)
  File "pandas/hashtable.pyx", line 675, in pandas.hashtable.PyObjectHashTable.get_item (pandas/hashtable.c:12368)
  File "pandas/hashtable.pyx", line 683, in pandas.hashtable.PyObjectHashTable.get_item (pandas/hashtable.c:12322)
KeyError: 'CDLMORNINGSTAR'
2019-04-28 13:08:36,325 - default - ERROR - Exception occurred
Traceback (most recent call last):
  File "Trading/Dataset/DatasetHolder.py", line 266, in appendTimeframesIntoOneDataset
    ds_h.f_df[cdl] = np.convolve(ds_h.f_df[cdl], fn)[0:len(ds_h.f_df)]
  File "/usr/local/lib/python2.7/dist-packages/pandas/core/frame.py", line 1997, in __getitem__
    return self._getitem_column(key)
  File "/usr/local/lib/python2.7/dist-packages/pandas/core/frame.py", line 2004, in _getitem_column
    return self._get_item_cache(key)
  File "/usr/local/lib/python2.7/dist-packages/pandas/core/generic.py", line 1350, in _get_item_cache
    values = self._data.get(item)
  File "/usr/local/lib/python2.7/dist-packages/pandas/core/internals.py", line 3290, in get
    loc = self.items.get_loc(item)
  File "/usr/local/lib/python2.7/dist-packages/pandas/indexes/base.py", line 1947, in get_loc
    return self._engine.get_loc(self._maybe_cast_indexer(key))
  File "pandas/index.pyx", line 137, in pandas.index.IndexEngine.get_loc (pandas/index.c:4154)
  File "pandas/index.pyx", line 159, in pandas.index.IndexEngine.get_loc (pandas/index.c:4018)
  File "pandas/hashtable.pyx", line 675, in pandas.hashtable.PyObjectHashTable.get_item (pandas/hashtable.c:12368)
  File "pandas/hashtable.pyx", line 683, in pandas.hashtable.PyObjectHashTable.get_item (pandas/hashtable.c:12322)
KeyError: 'CDLONNECK'
2019-04-28 13:08:36,328 - default - ERROR - Exception occurred
Traceback (most recent call last):
  File "Trading/Dataset/DatasetHolder.py", line 266, in appendTimeframesIntoOneDataset
    ds_h.f_df[cdl] = np.convolve(ds_h.f_df[cdl], fn)[0:len(ds_h.f_df)]
  File "/usr/local/lib/python2.7/dist-packages/pandas/core/frame.py", line 1997, in __getitem__
    return self._getitem_column(key)
  File "/usr/local/lib/python2.7/dist-packages/pandas/core/frame.py", line 2004, in _getitem_column
    return self._get_item_cache(key)
  File "/usr/local/lib/python2.7/dist-packages/pandas/core/generic.py", line 1350, in _get_item_cache
    values = self._data.get(item)
  File "/usr/local/lib/python2.7/dist-packages/pandas/core/internals.py", line 3290, in get
    loc = self.items.get_loc(item)
  File "/usr/local/lib/python2.7/dist-packages/pandas/indexes/base.py", line 1947, in get_loc
    return self._engine.get_loc(self._maybe_cast_indexer(key))
  File "pandas/index.pyx", line 137, in pandas.index.IndexEngine.get_loc (pandas/index.c:4154)
  File "pandas/index.pyx", line 159, in pandas.index.IndexEngine.get_loc (pandas/index.c:4018)
  File "pandas/hashtable.pyx", line 675, in pandas.hashtable.PyObjectHashTable.get_item (pandas/hashtable.c:12368)
  File "pandas/hashtable.pyx", line 683, in pandas.hashtable.PyObjectHashTable.get_item (pandas/hashtable.c:12322)
KeyError: 'CDLPIERCING'
2019-04-28 13:08:36,332 - default - ERROR - Exception occurred
Traceback (most recent call last):
  File "Trading/Dataset/DatasetHolder.py", line 266, in appendTimeframesIntoOneDataset
    ds_h.f_df[cdl] = np.convolve(ds_h.f_df[cdl], fn)[0:len(ds_h.f_df)]
  File "/usr/local/lib/python2.7/dist-packages/pandas/core/frame.py", line 1997, in __getitem__
    return self._getitem_column(key)
  File "/usr/local/lib/python2.7/dist-packages/pandas/core/frame.py", line 2004, in _getitem_column
    return self._get_item_cache(key)
  File "/usr/local/lib/python2.7/dist-packages/pandas/core/generic.py", line 1350, in _get_item_cache
    values = self._data.get(item)
  File "/usr/local/lib/python2.7/dist-packages/pandas/core/internals.py", line 3290, in get
    loc = self.items.get_loc(item)
  File "/usr/local/lib/python2.7/dist-packages/pandas/indexes/base.py", line 1947, in get_loc
    return self._engine.get_loc(self._maybe_cast_indexer(key))
  File "pandas/index.pyx", line 137, in pandas.index.IndexEngine.get_loc (pandas/index.c:4154)
  File "pandas/index.pyx", line 159, in pandas.index.IndexEngine.get_loc (pandas/index.c:4018)
  File "pandas/hashtable.pyx", line 675, in pandas.hashtable.PyObjectHashTable.get_item (pandas/hashtable.c:12368)
  File "pandas/hashtable.pyx", line 683, in pandas.hashtable.PyObjectHashTable.get_item (pandas/hashtable.c:12322)
KeyError: 'CDLRICKSHAWMAN'
2019-04-28 13:08:36,339 - default - ERROR - Exception occurred
Traceback (most recent call last):
  File "Trading/Dataset/DatasetHolder.py", line 266, in appendTimeframesIntoOneDataset
    ds_h.f_df[cdl] = np.convolve(ds_h.f_df[cdl], fn)[0:len(ds_h.f_df)]
  File "/usr/local/lib/python2.7/dist-packages/pandas/core/frame.py", line 1997, in __getitem__
    return self._getitem_column(key)
  File "/usr/local/lib/python2.7/dist-packages/pandas/core/frame.py", line 2004, in _getitem_column
    return self._get_item_cache(key)
  File "/usr/local/lib/python2.7/dist-packages/pandas/core/generic.py", line 1350, in _get_item_cache
    values = self._data.get(item)
  File "/usr/local/lib/python2.7/dist-packages/pandas/core/internals.py", line 3290, in get
    loc = self.items.get_loc(item)
  File "/usr/local/lib/python2.7/dist-packages/pandas/indexes/base.py", line 1947, in get_loc
    return self._engine.get_loc(self._maybe_cast_indexer(key))
  File "pandas/index.pyx", line 137, in pandas.index.IndexEngine.get_loc (pandas/index.c:4154)
  File "pandas/index.pyx", line 159, in pandas.index.IndexEngine.get_loc (pandas/index.c:4018)
  File "pandas/hashtable.pyx", line 675, in pandas.hashtable.PyObjectHashTable.get_item (pandas/hashtable.c:12368)
  File "pandas/hashtable.pyx", line 683, in pandas.hashtable.PyObjectHashTable.get_item (pandas/hashtable.c:12322)
KeyError: 'CDLRISEFALL3METHODS'
2019-04-28 13:08:36,342 - default - ERROR - Exception occurred
Traceback (most recent call last):
  File "Trading/Dataset/DatasetHolder.py", line 266, in appendTimeframesIntoOneDataset
    ds_h.f_df[cdl] = np.convolve(ds_h.f_df[cdl], fn)[0:len(ds_h.f_df)]
  File "/usr/local/lib/python2.7/dist-packages/pandas/core/frame.py", line 1997, in __getitem__
    return self._getitem_column(key)
  File "/usr/local/lib/python2.7/dist-packages/pandas/core/frame.py", line 2004, in _getitem_column
    return self._get_item_cache(key)
  File "/usr/local/lib/python2.7/dist-packages/pandas/core/generic.py", line 1350, in _get_item_cache
    values = self._data.get(item)
  File "/usr/local/lib/python2.7/dist-packages/pandas/core/internals.py", line 3290, in get
    loc = self.items.get_loc(item)
  File "/usr/local/lib/python2.7/dist-packages/pandas/indexes/base.py", line 1947, in get_loc
    return self._engine.get_loc(self._maybe_cast_indexer(key))
  File "pandas/index.pyx", line 137, in pandas.index.IndexEngine.get_loc (pandas/index.c:4154)
  File "pandas/index.pyx", line 159, in pandas.index.IndexEngine.get_loc (pandas/index.c:4018)
  File "pandas/hashtable.pyx", line 675, in pandas.hashtable.PyObjectHashTable.get_item (pandas/hashtable.c:12368)
  File "pandas/hashtable.pyx", line 683, in pandas.hashtable.PyObjectHashTable.get_item (pandas/hashtable.c:12322)
KeyError: 'CDLSEPARATINGLINES'
2019-04-28 13:08:36,346 - default - ERROR - Exception occurred
Traceback (most recent call last):
  File "Trading/Dataset/DatasetHolder.py", line 266, in appendTimeframesIntoOneDataset
    ds_h.f_df[cdl] = np.convolve(ds_h.f_df[cdl], fn)[0:len(ds_h.f_df)]
  File "/usr/local/lib/python2.7/dist-packages/pandas/core/frame.py", line 1997, in __getitem__
    return self._getitem_column(key)
  File "/usr/local/lib/python2.7/dist-packages/pandas/core/frame.py", line 2004, in _getitem_column
    return self._get_item_cache(key)
  File "/usr/local/lib/python2.7/dist-packages/pandas/core/generic.py", line 1350, in _get_item_cache
    values = self._data.get(item)
  File "/usr/local/lib/python2.7/dist-packages/pandas/core/internals.py", line 3290, in get
    loc = self.items.get_loc(item)
  File "/usr/local/lib/python2.7/dist-packages/pandas/indexes/base.py", line 1947, in get_loc
    return self._engine.get_loc(self._maybe_cast_indexer(key))
  File "pandas/index.pyx", line 137, in pandas.index.IndexEngine.get_loc (pandas/index.c:4154)
  File "pandas/index.pyx", line 159, in pandas.index.IndexEngine.get_loc (pandas/index.c:4018)
  File "pandas/hashtable.pyx", line 675, in pandas.hashtable.PyObjectHashTable.get_item (pandas/hashtable.c:12368)
  File "pandas/hashtable.pyx", line 683, in pandas.hashtable.PyObjectHashTable.get_item (pandas/hashtable.c:12322)
KeyError: 'CDLSHOOTINGSTAR'
2019-04-28 13:08:36,349 - default - ERROR - Exception occurred
Traceback (most recent call last):
  File "Trading/Dataset/DatasetHolder.py", line 266, in appendTimeframesIntoOneDataset
    ds_h.f_df[cdl] = np.convolve(ds_h.f_df[cdl], fn)[0:len(ds_h.f_df)]
  File "/usr/local/lib/python2.7/dist-packages/pandas/core/frame.py", line 1997, in __getitem__
    return self._getitem_column(key)
  File "/usr/local/lib/python2.7/dist-packages/pandas/core/frame.py", line 2004, in _getitem_column
    return self._get_item_cache(key)
  File "/usr/local/lib/python2.7/dist-packages/pandas/core/generic.py", line 1350, in _get_item_cache
    values = self._data.get(item)
  File "/usr/local/lib/python2.7/dist-packages/pandas/core/internals.py", line 3290, in get
    loc = self.items.get_loc(item)
  File "/usr/local/lib/python2.7/dist-packages/pandas/indexes/base.py", line 1947, in get_loc
    return self._engine.get_loc(self._maybe_cast_indexer(key))
  File "pandas/index.pyx", line 137, in pandas.index.IndexEngine.get_loc (pandas/index.c:4154)
  File "pandas/index.pyx", line 159, in pandas.index.IndexEngine.get_loc (pandas/index.c:4018)
  File "pandas/hashtable.pyx", line 675, in pandas.hashtable.PyObjectHashTable.get_item (pandas/hashtable.c:12368)
  File "pandas/hashtable.pyx", line 683, in pandas.hashtable.PyObjectHashTable.get_item (pandas/hashtable.c:12322)
KeyError: 'CDLSHORTLINE'
2019-04-28 13:08:36,352 - default - ERROR - Exception occurred
Traceback (most recent call last):
  File "Trading/Dataset/DatasetHolder.py", line 266, in appendTimeframesIntoOneDataset
    ds_h.f_df[cdl] = np.convolve(ds_h.f_df[cdl], fn)[0:len(ds_h.f_df)]
  File "/usr/local/lib/python2.7/dist-packages/pandas/core/frame.py", line 1997, in __getitem__
    return self._getitem_column(key)
  File "/usr/local/lib/python2.7/dist-packages/pandas/core/frame.py", line 2004, in _getitem_column
    return self._get_item_cache(key)
  File "/usr/local/lib/python2.7/dist-packages/pandas/core/generic.py", line 1350, in _get_item_cache
    values = self._data.get(item)
  File "/usr/local/lib/python2.7/dist-packages/pandas/core/internals.py", line 3290, in get
    loc = self.items.get_loc(item)
  File "/usr/local/lib/python2.7/dist-packages/pandas/indexes/base.py", line 1947, in get_loc
    return self._engine.get_loc(self._maybe_cast_indexer(key))
  File "pandas/index.pyx", line 137, in pandas.index.IndexEngine.get_loc (pandas/index.c:4154)
  File "pandas/index.pyx", line 159, in pandas.index.IndexEngine.get_loc (pandas/index.c:4018)
  File "pandas/hashtable.pyx", line 675, in pandas.hashtable.PyObjectHashTable.get_item (pandas/hashtable.c:12368)
  File "pandas/hashtable.pyx", line 683, in pandas.hashtable.PyObjectHashTable.get_item (pandas/hashtable.c:12322)
KeyError: 'CDLSPINNINGTOP'
2019-04-28 13:08:36,355 - default - ERROR - Exception occurred
Traceback (most recent call last):
  File "Trading/Dataset/DatasetHolder.py", line 266, in appendTimeframesIntoOneDataset
    ds_h.f_df[cdl] = np.convolve(ds_h.f_df[cdl], fn)[0:len(ds_h.f_df)]
  File "/usr/local/lib/python2.7/dist-packages/pandas/core/frame.py", line 1997, in __getitem__
    return self._getitem_column(key)
  File "/usr/local/lib/python2.7/dist-packages/pandas/core/frame.py", line 2004, in _getitem_column
    return self._get_item_cache(key)
  File "/usr/local/lib/python2.7/dist-packages/pandas/core/generic.py", line 1350, in _get_item_cache
    values = self._data.get(item)
  File "/usr/local/lib/python2.7/dist-packages/pandas/core/internals.py", line 3290, in get
    loc = self.items.get_loc(item)
  File "/usr/local/lib/python2.7/dist-packages/pandas/indexes/base.py", line 1947, in get_loc
    return self._engine.get_loc(self._maybe_cast_indexer(key))
  File "pandas/index.pyx", line 137, in pandas.index.IndexEngine.get_loc (pandas/index.c:4154)
  File "pandas/index.pyx", line 159, in pandas.index.IndexEngine.get_loc (pandas/index.c:4018)
  File "pandas/hashtable.pyx", line 675, in pandas.hashtable.PyObjectHashTable.get_item (pandas/hashtable.c:12368)
  File "pandas/hashtable.pyx", line 683, in pandas.hashtable.PyObjectHashTable.get_item (pandas/hashtable.c:12322)
KeyError: 'CDLSTALLEDPATTERN'
2019-04-28 13:08:36,358 - default - ERROR - Exception occurred
Traceback (most recent call last):
  File "Trading/Dataset/DatasetHolder.py", line 266, in appendTimeframesIntoOneDataset
    ds_h.f_df[cdl] = np.convolve(ds_h.f_df[cdl], fn)[0:len(ds_h.f_df)]
  File "/usr/local/lib/python2.7/dist-packages/pandas/core/frame.py", line 1997, in __getitem__
    return self._getitem_column(key)
  File "/usr/local/lib/python2.7/dist-packages/pandas/core/frame.py", line 2004, in _getitem_column
    return self._get_item_cache(key)
  File "/usr/local/lib/python2.7/dist-packages/pandas/core/generic.py", line 1350, in _get_item_cache
    values = self._data.get(item)
  File "/usr/local/lib/python2.7/dist-packages/pandas/core/internals.py", line 3290, in get
    loc = self.items.get_loc(item)
  File "/usr/local/lib/python2.7/dist-packages/pandas/indexes/base.py", line 1947, in get_loc
    return self._engine.get_loc(self._maybe_cast_indexer(key))
  File "pandas/index.pyx", line 137, in pandas.index.IndexEngine.get_loc (pandas/index.c:4154)
  File "pandas/index.pyx", line 159, in pandas.index.IndexEngine.get_loc (pandas/index.c:4018)
  File "pandas/hashtable.pyx", line 675, in pandas.hashtable.PyObjectHashTable.get_item (pandas/hashtable.c:12368)
  File "pandas/hashtable.pyx", line 683, in pandas.hashtable.PyObjectHashTable.get_item (pandas/hashtable.c:12322)
KeyError: 'CDLSTICKSANDWICH'
2019-04-28 13:08:36,361 - default - ERROR - Exception occurred
Traceback (most recent call last):
  File "Trading/Dataset/DatasetHolder.py", line 266, in appendTimeframesIntoOneDataset
    ds_h.f_df[cdl] = np.convolve(ds_h.f_df[cdl], fn)[0:len(ds_h.f_df)]
  File "/usr/local/lib/python2.7/dist-packages/pandas/core/frame.py", line 1997, in __getitem__
    return self._getitem_column(key)
  File "/usr/local/lib/python2.7/dist-packages/pandas/core/frame.py", line 2004, in _getitem_column
    return self._get_item_cache(key)
  File "/usr/local/lib/python2.7/dist-packages/pandas/core/generic.py", line 1350, in _get_item_cache
    values = self._data.get(item)
  File "/usr/local/lib/python2.7/dist-packages/pandas/core/internals.py", line 3290, in get
    loc = self.items.get_loc(item)
  File "/usr/local/lib/python2.7/dist-packages/pandas/indexes/base.py", line 1947, in get_loc
    return self._engine.get_loc(self._maybe_cast_indexer(key))
  File "pandas/index.pyx", line 137, in pandas.index.IndexEngine.get_loc (pandas/index.c:4154)
  File "pandas/index.pyx", line 159, in pandas.index.IndexEngine.get_loc (pandas/index.c:4018)
  File "pandas/hashtable.pyx", line 675, in pandas.hashtable.PyObjectHashTable.get_item (pandas/hashtable.c:12368)
  File "pandas/hashtable.pyx", line 683, in pandas.hashtable.PyObjectHashTable.get_item (pandas/hashtable.c:12322)
KeyError: 'CDLTAKURI'
2019-04-28 13:08:36,364 - default - ERROR - Exception occurred
Traceback (most recent call last):
  File "Trading/Dataset/DatasetHolder.py", line 266, in appendTimeframesIntoOneDataset
    ds_h.f_df[cdl] = np.convolve(ds_h.f_df[cdl], fn)[0:len(ds_h.f_df)]
  File "/usr/local/lib/python2.7/dist-packages/pandas/core/frame.py", line 1997, in __getitem__
    return self._getitem_column(key)
  File "/usr/local/lib/python2.7/dist-packages/pandas/core/frame.py", line 2004, in _getitem_column
    return self._get_item_cache(key)
  File "/usr/local/lib/python2.7/dist-packages/pandas/core/generic.py", line 1350, in _get_item_cache
    values = self._data.get(item)
  File "/usr/local/lib/python2.7/dist-packages/pandas/core/internals.py", line 3290, in get
    loc = self.items.get_loc(item)
  File "/usr/local/lib/python2.7/dist-packages/pandas/indexes/base.py", line 1947, in get_loc
    return self._engine.get_loc(self._maybe_cast_indexer(key))
  File "pandas/index.pyx", line 137, in pandas.index.IndexEngine.get_loc (pandas/index.c:4154)
  File "pandas/index.pyx", line 159, in pandas.index.IndexEngine.get_loc (pandas/index.c:4018)
  File "pandas/hashtable.pyx", line 675, in pandas.hashtable.PyObjectHashTable.get_item (pandas/hashtable.c:12368)
  File "pandas/hashtable.pyx", line 683, in pandas.hashtable.PyObjectHashTable.get_item (pandas/hashtable.c:12322)
KeyError: 'CDLTASUKIGAP'
2019-04-28 13:08:36,366 - default - ERROR - Exception occurred
Traceback (most recent call last):
  File "Trading/Dataset/DatasetHolder.py", line 266, in appendTimeframesIntoOneDataset
    ds_h.f_df[cdl] = np.convolve(ds_h.f_df[cdl], fn)[0:len(ds_h.f_df)]
  File "/usr/local/lib/python2.7/dist-packages/pandas/core/frame.py", line 1997, in __getitem__
    return self._getitem_column(key)
  File "/usr/local/lib/python2.7/dist-packages/pandas/core/frame.py", line 2004, in _getitem_column
    return self._get_item_cache(key)
  File "/usr/local/lib/python2.7/dist-packages/pandas/core/generic.py", line 1350, in _get_item_cache
    values = self._data.get(item)
  File "/usr/local/lib/python2.7/dist-packages/pandas/core/internals.py", line 3290, in get
    loc = self.items.get_loc(item)
  File "/usr/local/lib/python2.7/dist-packages/pandas/indexes/base.py", line 1947, in get_loc
    return self._engine.get_loc(self._maybe_cast_indexer(key))
  File "pandas/index.pyx", line 137, in pandas.index.IndexEngine.get_loc (pandas/index.c:4154)
  File "pandas/index.pyx", line 159, in pandas.index.IndexEngine.get_loc (pandas/index.c:4018)
  File "pandas/hashtable.pyx", line 675, in pandas.hashtable.PyObjectHashTable.get_item (pandas/hashtable.c:12368)
  File "pandas/hashtable.pyx", line 683, in pandas.hashtable.PyObjectHashTable.get_item (pandas/hashtable.c:12322)
KeyError: 'CDLTHRUSTING'
2019-04-28 13:08:36,369 - default - ERROR - Exception occurred
Traceback (most recent call last):
  File "Trading/Dataset/DatasetHolder.py", line 266, in appendTimeframesIntoOneDataset
    ds_h.f_df[cdl] = np.convolve(ds_h.f_df[cdl], fn)[0:len(ds_h.f_df)]
  File "/usr/local/lib/python2.7/dist-packages/pandas/core/frame.py", line 1997, in __getitem__
    return self._getitem_column(key)
  File "/usr/local/lib/python2.7/dist-packages/pandas/core/frame.py", line 2004, in _getitem_column
    return self._get_item_cache(key)
  File "/usr/local/lib/python2.7/dist-packages/pandas/core/generic.py", line 1350, in _get_item_cache
    values = self._data.get(item)
  File "/usr/local/lib/python2.7/dist-packages/pandas/core/internals.py", line 3290, in get
    loc = self.items.get_loc(item)
  File "/usr/local/lib/python2.7/dist-packages/pandas/indexes/base.py", line 1947, in get_loc
    return self._engine.get_loc(self._maybe_cast_indexer(key))
  File "pandas/index.pyx", line 137, in pandas.index.IndexEngine.get_loc (pandas/index.c:4154)
  File "pandas/index.pyx", line 159, in pandas.index.IndexEngine.get_loc (pandas/index.c:4018)
  File "pandas/hashtable.pyx", line 675, in pandas.hashtable.PyObjectHashTable.get_item (pandas/hashtable.c:12368)
  File "pandas/hashtable.pyx", line 683, in pandas.hashtable.PyObjectHashTable.get_item (pandas/hashtable.c:12322)
KeyError: 'CDLTRISTAR'
2019-04-28 13:08:36,372 - default - ERROR - Exception occurred
Traceback (most recent call last):
  File "Trading/Dataset/DatasetHolder.py", line 266, in appendTimeframesIntoOneDataset
    ds_h.f_df[cdl] = np.convolve(ds_h.f_df[cdl], fn)[0:len(ds_h.f_df)]
  File "/usr/local/lib/python2.7/dist-packages/pandas/core/frame.py", line 1997, in __getitem__
    return self._getitem_column(key)
  File "/usr/local/lib/python2.7/dist-packages/pandas/core/frame.py", line 2004, in _getitem_column
    return self._get_item_cache(key)
  File "/usr/local/lib/python2.7/dist-packages/pandas/core/generic.py", line 1350, in _get_item_cache
    values = self._data.get(item)
  File "/usr/local/lib/python2.7/dist-packages/pandas/core/internals.py", line 3290, in get
    loc = self.items.get_loc(item)
  File "/usr/local/lib/python2.7/dist-packages/pandas/indexes/base.py", line 1947, in get_loc
    return self._engine.get_loc(self._maybe_cast_indexer(key))
  File "pandas/index.pyx", line 137, in pandas.index.IndexEngine.get_loc (pandas/index.c:4154)
  File "pandas/index.pyx", line 159, in pandas.index.IndexEngine.get_loc (pandas/index.c:4018)
  File "pandas/hashtable.pyx", line 675, in pandas.hashtable.PyObjectHashTable.get_item (pandas/hashtable.c:12368)
  File "pandas/hashtable.pyx", line 683, in pandas.hashtable.PyObjectHashTable.get_item (pandas/hashtable.c:12322)
KeyError: 'CDLUNIQUE3RIVER'
2019-04-28 13:08:36,375 - default - ERROR - Exception occurred
Traceback (most recent call last):
  File "Trading/Dataset/DatasetHolder.py", line 266, in appendTimeframesIntoOneDataset
    ds_h.f_df[cdl] = np.convolve(ds_h.f_df[cdl], fn)[0:len(ds_h.f_df)]
  File "/usr/local/lib/python2.7/dist-packages/pandas/core/frame.py", line 1997, in __getitem__
    return self._getitem_column(key)
  File "/usr/local/lib/python2.7/dist-packages/pandas/core/frame.py", line 2004, in _getitem_column
    return self._get_item_cache(key)
  File "/usr/local/lib/python2.7/dist-packages/pandas/core/generic.py", line 1350, in _get_item_cache
    values = self._data.get(item)
  File "/usr/local/lib/python2.7/dist-packages/pandas/core/internals.py", line 3290, in get
    loc = self.items.get_loc(item)
  File "/usr/local/lib/python2.7/dist-packages/pandas/indexes/base.py", line 1947, in get_loc
    return self._engine.get_loc(self._maybe_cast_indexer(key))
  File "pandas/index.pyx", line 137, in pandas.index.IndexEngine.get_loc (pandas/index.c:4154)
  File "pandas/index.pyx", line 159, in pandas.index.IndexEngine.get_loc (pandas/index.c:4018)
  File "pandas/hashtable.pyx", line 675, in pandas.hashtable.PyObjectHashTable.get_item (pandas/hashtable.c:12368)
  File "pandas/hashtable.pyx", line 683, in pandas.hashtable.PyObjectHashTable.get_item (pandas/hashtable.c:12322)
KeyError: 'CDLUPSIDEGAP2CROWS'
2019-04-28 13:08:36,378 - default - ERROR - Exception occurred
Traceback (most recent call last):
  File "Trading/Dataset/DatasetHolder.py", line 266, in appendTimeframesIntoOneDataset
    ds_h.f_df[cdl] = np.convolve(ds_h.f_df[cdl], fn)[0:len(ds_h.f_df)]
  File "/usr/local/lib/python2.7/dist-packages/pandas/core/frame.py", line 1997, in __getitem__
    return self._getitem_column(key)
  File "/usr/local/lib/python2.7/dist-packages/pandas/core/frame.py", line 2004, in _getitem_column
    return self._get_item_cache(key)
  File "/usr/local/lib/python2.7/dist-packages/pandas/core/generic.py", line 1350, in _get_item_cache
    values = self._data.get(item)
  File "/usr/local/lib/python2.7/dist-packages/pandas/core/internals.py", line 3290, in get
    loc = self.items.get_loc(item)
  File "/usr/local/lib/python2.7/dist-packages/pandas/indexes/base.py", line 1947, in get_loc
    return self._engine.get_loc(self._maybe_cast_indexer(key))
  File "pandas/index.pyx", line 137, in pandas.index.IndexEngine.get_loc (pandas/index.c:4154)
  File "pandas/index.pyx", line 159, in pandas.index.IndexEngine.get_loc (pandas/index.c:4018)
  File "pandas/hashtable.pyx", line 675, in pandas.hashtable.PyObjectHashTable.get_item (pandas/hashtable.c:12368)
  File "pandas/hashtable.pyx", line 683, in pandas.hashtable.PyObjectHashTable.get_item (pandas/hashtable.c:12322)
KeyError: 'CDLXSIDEGAP3METHODS'
